<?xml version="1.0" ?><robot name="right_arm_gripper">  
  <link name="sho_pitch_link">    
    <visual>      
      <origin xyz="0 0 0" rpy="0 -0 0"/>      
      <geometry>        
        <mesh filename="package:///meshes/right_sho_pitch_link_visual.stl"/>        
      </geometry>      
      <material name="sho_pitch_link_material">        
        <color rgba="0.61568627450980395466 0.81176470588235294379 0.92941176470588227065 1.0"/>        
      </material>      
    </visual>    
    <collision>      
      <origin xyz="0 0 0" rpy="0 -0 0"/>      
      <geometry>        
        <mesh filename="package:///meshes/right_sho_pitch_link_collision.stl"/>        
      </geometry>      
    </collision>    
    <inertial>      
      <origin xyz="1.8449019812287260885e-18 -2.0802238039556934046e-18 0.012913250798677599132" rpy="0 0 0"/>      
      <mass value="0.0085999999999999982708"/>      
      <inertia ixx="1.8365636406635822849e-06" ixy="-6.8542962956938853498e-57" ixz="1.6528758011273076664e-97" iyy="4.0110869076839152165e-06" iyz="-2.646223959247617687e-46" izz="3.5160516450492493809e-06"/>      
    </inertial>    
  </link>  

  <link name="2xl430_gears">    
    <visual>      
      <origin xyz="0 0 0" rpy="0 -0 0"/>      
      <geometry>        
        <mesh filename="package:///meshes/right_2xl430_gears_visual.stl"/>        
      </geometry>      
      <material name="2xl430_gears_material">        
        <color rgba="0.7591476792056923717 0.85560384745670914342 0.90519468321360618823 1.0"/>        
      </material>      
    </visual>    
    <collision>      
      <origin xyz="0 0 0" rpy="0 -0 0"/>      
      <geometry>        
        <mesh filename="package:///meshes/right_2xl430_gears_collision.stl"/>        
      </geometry>      
    </collision>    
    <inertial>      
      <origin xyz="-0.01159290573797803689 -0.0024238553642550869638 -0.018551095523802667991" rpy="0 0 0"/>      
      <mass value="0.11800003674524908726"/>      
      <inertia ixx="2.7511021050424503716e-05" ixy="9.0043904315214347989e-07" ixz="-2.3349710124170355681e-08" iyy="3.2796197843345875145e-05" iyz="-6.5715119654636793758e-07" izz="3.5775739835741188688e-05"/>      
    </inertial>    
  </link>  

  <link name="spur_1m_24t_drive">    
    <visual>      
      <origin xyz="0 0 0" rpy="0 -0 0"/>      
      <geometry>        
        <mesh filename="package:///meshes/right_spur_1m_24t_drive_visual.stl"/>        
      </geometry>      
      <material name="spur_1m_24t_drive_material">        
        <color rgba="0.61568627450980406568 0.81176470588235294379 0.92941176470588238168 1.0"/>        
      </material>      
    </visual>    
    <collision>      
      <origin xyz="0 0 0" rpy="0 -0 0"/>      
      <geometry>        
        <mesh filename="package:///meshes/right_spur_1m_24t_drive_collision.stl"/>        
      </geometry>      
    </collision>    
    <inertial>      
      <origin xyz="3.0326539266682484979e-15 -3.3909557262182693158e-16 0.0048096451474092995898" rpy="0 0 0"/>      
      <mass value="0.0032000000000000001533"/>      
      <inertia ixx="1.4097598887016956026e-07" ixy="1.556282310200251252e-15" ixz="-1.8992294521396918766e-37" iyy="1.4097598803636001492e-07" iyz="-4.7745011531954772327e-37" izz="2.4107776386988835496e-07"/>      
    </inertial>    
  </link>  

  <joint name="right_sho_yaw_drive" type="revolute">    
    <origin xyz="-0.024000000716137347839 -0.019000000152448161261 -0.019000000152444761203" rpy="1.5707963267947397945 -3.199580565278813612e-14 1.8339090108977180652e-14"/>    
    <parent link="2xl430_gears"/>    
    <child link="spur_1m_24t_drive"/>    
    <axis xyz="0 0 1"/>    
    <limit effort="1" velocity="20" lower="-2.6179938779914944114" upper="2.6179938779914944114"/>    
    <joint_properties friction="0.0"/>    
  </joint>  

  <link name="spur_1m_24t_driven">    
    <visual>      
      <origin xyz="0 0 0" rpy="0 -0 0"/>      
      <geometry>        
        <mesh filename="package:///meshes/right_spur_1m_24t_driven_visual.stl"/>        
      </geometry>      
      <material name="spur_1m_24t_driven_material">        
        <color rgba="0.23137254901960788156 0.38039215686274502337 0.7058823529411765163 1.0"/>        
      </material>      
    </visual>    
    <collision>      
      <origin xyz="0 0 0" rpy="0 -0 0"/>      
      <geometry>        
        <mesh filename="package:///meshes/right_spur_1m_24t_driven_collision.stl"/>        
      </geometry>      
    </collision>    
    <inertial>      
      <origin xyz="-2.921394639790185015e-18 -1.6886349105605202767e-15 -0.00097237500038396460205" rpy="0 0 0"/>      
      <mass value="0.0026999999999999997093"/>      
      <inertia ixx="1.2202334915684083145e-07" ixy="-2.0003916890172096188e-37" ixz="1.9017102850262393928e-37" iyy="1.2202334915684064616e-07" iyz="-9.770592987438706564e-37" izz="2.3180293204341257533e-07"/>      
    </inertial>    
  </link>  

  <link name="sho_yaw_link">    
    <visual>      
      <origin xyz="0 0 0" rpy="0 -0 0"/>      
      <geometry>        
        <mesh filename="package:///meshes/right_sho_yaw_link_visual.stl"/>        
      </geometry>      
      <material name="sho_yaw_link_material">        
        <color rgba="0.61568627450980395466 0.81176470588235294379 0.92941176470588238168 1.0"/>        
      </material>      
    </visual>    
    <collision>      
      <origin xyz="0 0 0" rpy="0 -0 0"/>      
      <geometry>        
        <mesh filename="package:///meshes/right_sho_yaw_link_collision.stl"/>        
      </geometry>      
    </collision>    
    <inertial>      
      <origin xyz="4.5036404713680668847e-18 2.8819643225832177286e-18 -0.024649285094360068316" rpy="0 0 0"/>      
      <mass value="0.014500000000000004205"/>      
      <inertia ixx="9.2365904614004439553e-06" ixy="3.5862833440690446869e-13" ixz="3.8159565285815172758e-35" iyy="5.8163826335078791714e-06" iyz="-1.0924832696280288326e-35" izz="4.5074356741562113561e-06"/>      
    </inertial>    
  </link>  

  <link name="2xl430_gears_2">    
    <visual>      
      <origin xyz="0 0 0" rpy="0 -0 0"/>      
      <geometry>        
        <mesh filename="package:///meshes/right_2xl430_gears_2_visual.stl"/>        
      </geometry>      
      <material name="2xl430_gears_2_material">        
        <color rgba="0.7591476792056923717 0.85560384745670914342 0.90519468321360618823 1.0"/>        
      </material>      
    </visual>    
    <collision>      
      <origin xyz="0 0 0" rpy="0 -0 0"/>      
      <geometry>        
        <mesh filename="package:///meshes/right_2xl430_gears_2_collision.stl"/>        
      </geometry>      
    </collision>    
    <inertial>      
      <origin xyz="-0.011592905737986073864 -0.0024238553642542347809 -0.018551095523808777688" rpy="0 0 0"/>      
      <mass value="0.11800003674524908726"/>      
      <inertia ixx="2.7511021050428857465e-05" ixy="9.0043904315091549388e-07" ixz="-2.3349710123664839139e-08" iyy="3.2796197843347636974e-05" iyz="-6.5715119654794606584e-07" izz="3.5775739835744908856e-05"/>      
    </inertial>    
  </link>  

  <link name="spur_1m_24t_drive_2">    
    <visual>      
      <origin xyz="0 0 0" rpy="0 -0 0"/>      
      <geometry>        
        <mesh filename="package:///meshes/right_spur_1m_24t_drive_2_visual.stl"/>        
      </geometry>      
      <material name="spur_1m_24t_drive_2_material">        
        <color rgba="0.61568627450980406568 0.81176470588235294379 0.92941176470588238168 1.0"/>        
      </material>      
    </visual>    
    <collision>      
      <origin xyz="0 0 0" rpy="0 -0 0"/>      
      <geometry>        
        <mesh filename="package:///meshes/right_spur_1m_24t_drive_2_collision.stl"/>        
      </geometry>      
    </collision>    
    <inertial>      
      <origin xyz="3.0395928205721565152e-15 -3.3909557262182688227e-16 0.0048096451474092995898" rpy="0 0 0"/>      
      <mass value="0.0032000000000000001533"/>      
      <inertia ixx="1.4097598887016963967e-07" ixy="1.5562823101719447534e-15" ixz="-1.8419223123432015677e-37" iyy="1.4097598803636001492e-07" iyz="-3.0576269564019315824e-36" izz="2.4107776386988835496e-07"/>      
    </inertial>    
  </link>  

  <joint name="right_elbow_yaw_drive" type="revolute">    
    <origin xyz="-0.024000000716148717217 -0.019000000152453275226 -0.01900000015245205745" rpy="1.5707963267949269781 1.6254659840047312022e-13 -8.5511976043092269184e-14"/>    
    <parent link="2xl430_gears_2"/>    
    <child link="spur_1m_24t_drive_2"/>    
    <axis xyz="0 0 1"/>    
    <limit effort="1" velocity="20" lower="-2.6179938779914944114" upper="2.6179938779914944114"/>    
    <joint_properties friction="0.0"/>    
  </joint>  

  <link name="spur_1m_24t_driven_2">    
    <visual>      
      <origin xyz="0 0 0" rpy="0 -0 0"/>      
      <geometry>        
        <mesh filename="package:///meshes/right_spur_1m_24t_driven_2_visual.stl"/>        
      </geometry>      
      <material name="spur_1m_24t_driven_2_material">        
        <color rgba="0.23137254901960788156 0.38039215686274502337 0.7058823529411765163 1.0"/>        
      </material>      
    </visual>    
    <collision>      
      <origin xyz="0 0 0" rpy="0 -0 0"/>      
      <geometry>        
        <mesh filename="package:///meshes/right_spur_1m_24t_driven_2_collision.stl"/>        
      </geometry>      
    </collision>    
    <inertial>      
      <origin xyz="-2.9213946397908421423e-18 -1.6886349105605210655e-15 -0.00097237500038396460205" rpy="0 0 0"/>      
      <mass value="0.0026999999999999997093"/>      
      <inertia ixx="1.2202334915684083145e-07" ixy="8.1931871200334274295e-66" ixz="-5.8515286657488374315e-36" iyy="1.2202334915684064616e-07" iyz="-7.8749785833428115979e-37" izz="2.3180293204341268121e-07"/>      
    </inertial>    
  </link>  

  <link name="elb_yaw_link">    
    <visual>      
      <origin xyz="0 0 0" rpy="0 -0 0"/>      
      <geometry>        
        <mesh filename="package:///meshes/right_elb_yaw_link_visual.stl"/>        
      </geometry>      
      <material name="elb_yaw_link_material">        
        <color rgba="0.61568627450980395466 0.81176470588235294379 0.92941176470588227065 1.0"/>        
      </material>      
    </visual>    
    <collision>      
      <origin xyz="0 0 0" rpy="0 -0 0"/>      
      <geometry>        
        <mesh filename="package:///meshes/right_elb_yaw_link_collision.stl"/>        
      </geometry>      
    </collision>    
    <inertial>      
      <origin xyz="5.3127688027189133061e-08 0.0019833638641961665906 -0.023416643551549935071" rpy="0 0 0"/>      
      <mass value="0.017500000000000001665"/>      
      <inertia ixx="1.4134344903109196387e-05" ixy="1.6945783921929356084e-12" ixz="-1.1286398721892709078e-11" iyy="6.6435900776211340404e-06" iyz="1.0545227077253057579e-06" izz="8.9925290757998976773e-06"/>      
    </inertial>    
  </link>  

  <link name="spur_1m_24t_driven_3">    
    <visual>      
      <origin xyz="0 0 0" rpy="0 -0 0"/>      
      <geometry>        
        <mesh filename="package:///meshes/right_spur_1m_24t_driven_3_visual.stl"/>        
      </geometry>      
      <material name="spur_1m_24t_driven_3_material">        
        <color rgba="0.23137254901960788156 0.38039215686274502337 0.7058823529411765163 1.0"/>        
      </material>      
    </visual>    
    <collision>      
      <origin xyz="0 0 0" rpy="0 -0 0"/>      
      <geometry>        
        <mesh filename="package:///meshes/right_spur_1m_24t_driven_3_collision.stl"/>        
      </geometry>      
    </collision>    
    <inertial>      
      <origin xyz="-2.9213946397905324528e-18 -1.6886349105605188962e-15 -0.0025723750003839584988" rpy="0 0 0"/>      
      <mass value="0.0026999999999999997093"/>      
      <inertia ixx="1.2202334915684088439e-07" ixy="1.7934156310550399505e-36" ixz="-4.3202421904481218274e-36" iyy="1.2202334915684064616e-07" iyz="-9.0295837999359508427e-37" izz="2.3180293204341257533e-07"/>      
    </inertial>    
  </link>  

  <link name="2xl430_gears_3">    
    <visual>      
      <origin xyz="0 0 0" rpy="0 -0 0"/>      
      <geometry>        
        <mesh filename="package:///meshes/right_2xl430_gears_3_visual.stl"/>        
      </geometry>      
      <material name="2xl430_gears_3_material">        
        <color rgba="0.7591476792056923717 0.85560384745670914342 0.90519468321360618823 1.0"/>        
      </material>      
    </visual>    
    <collision>      
      <origin xyz="0 0 0" rpy="0 -0 0"/>      
      <geometry>        
        <mesh filename="package:///meshes/right_2xl430_gears_3_collision.stl"/>        
      </geometry>      
    </collision>    
    <inertial>      
      <origin xyz="0.00044890447619846317274 0.011592905379916402728 -0.024576144788201300523" rpy="0 0 0"/>      
      <mass value="0.11800003674524908726"/>      
      <inertia ixx="3.5775739835743350316e-05" ixy="2.334971012439249338e-08" ixz="6.5715119654781382282e-07" iyy="2.7511021050426370577e-05" iyz="9.004390431514573832e-07" izz="3.279619784334753533e-05"/>      
    </inertial>    
  </link>  

  <link name="spur_1m_24t_drive_3">    
    <visual>      
      <origin xyz="0 0 0" rpy="0 -0 0"/>      
      <geometry>        
        <mesh filename="package:///meshes/right_spur_1m_24t_drive_3_visual.stl"/>        
      </geometry>      
      <material name="spur_1m_24t_drive_3_material">        
        <color rgba="0.61568627450980406568 0.81176470588235294379 0.92941176470588238168 1.0"/>        
      </material>      
    </visual>    
    <collision>      
      <origin xyz="0 0 0" rpy="0 -0 0"/>      
      <geometry>        
        <mesh filename="package:///meshes/right_spur_1m_24t_drive_3_collision.stl"/>        
      </geometry>      
    </collision>    
    <inertial>      
      <origin xyz="3.0326539266682488924e-15 -3.3909557259597738952e-16 0.0048096451474093021919" rpy="0 0 0"/>      
      <mass value="0.0032000000000000001533"/>      
      <inertia ixx="1.409759888701696132e-07" ixy="1.556282310200251252e-15" ixz="-1.0651936719748417848e-37" iyy="1.4097598803636001492e-07" iyz="-6.7795798897996087278e-37" izz="2.4107776386988846083e-07"/>      
    </inertial>    
  </link>  

  <joint name="right_wrist_pitch_drive" type="revolute">    
    <origin xyz="-1.5244632210886674996e-10 0.024000000358075396223 -0.0080000000000023368391" rpy="1.8404832493348406963e-14 1.1899813043699589138e-13 -1.5707963267947944175"/>    
    <parent link="2xl430_gears_3"/>    
    <child link="spur_1m_24t_drive_3"/>    
    <axis xyz="0 0 1"/>    
    <limit effort="1" velocity="20" lower="-1.3962634015954635824" upper="1.9198621771937625091"/>    
    <joint_properties friction="0.0"/>    
  </joint>  

  <link name="gripper_connector">    
    <visual>      
      <origin xyz="0 0 0" rpy="0 -0 0"/>      
      <geometry>        
        <mesh filename="package:///meshes/right_gripper_connector_visual.stl"/>        
      </geometry>      
      <material name="gripper_connector_material">        
        <color rgba="0.61568627450980395466 0.81176470588235294379 0.92941176470588238168 1.0"/>        
      </material>      
    </visual>    
    <collision>      
      <origin xyz="0 0 0" rpy="0 -0 0"/>      
      <geometry>        
        <mesh filename="package:///meshes/right_gripper_connector_collision.stl"/>        
      </geometry>      
    </collision>    
    <inertial>      
      <origin xyz="-0.00018842170188954562057 0.022508162473387258173 -0.027103952522535709746" rpy="0 0 0"/>      
      <mass value="0.0099999999999999967387"/>      
      <inertia ixx="5.9456375734536726584e-06" ixy="2.4479055491886681531e-08" ixz="4.0329437936864279052e-08" iyy="4.2603724874314054683e-06" iyz="4.585261274976229064e-07" izz="2.4669632528047159756e-06"/>      
    </inertial>    
  </link>  

  <link name="right_rail_guide">    
    <visual>      
      <origin xyz="0 0 0" rpy="0 -0 0"/>      
      <geometry>        
        <mesh filename="package:///meshes/right_rail_guide_visual.stl"/>        
      </geometry>      
      <material name="right_rail_guide_material">        
        <color rgba="0.63183631947442864263 0.80464761899488657093 0.89969354135356638391 1.0"/>        
      </material>      
    </visual>    
    <collision>      
      <origin xyz="0 0 0" rpy="0 -0 0"/>      
      <geometry>        
        <mesh filename="package:///meshes/right_rail_guide_collision.stl"/>        
      </geometry>      
    </collision>    
    <inertial>      
      <origin xyz="0.010819769137967562636 -0.0021113011985218615996 -7.7620928513509046e-05" rpy="0 0 0"/>      
      <mass value="0.031084136786219594695"/>      
      <inertia ixx="7.8430666236070228507e-06" ixy="-2.0644517679574144074e-06" ixz="4.0045882799668568733e-06" iyy="2.7294704119451736191e-05" iyz="8.8949075530050562942e-07" izz="3.0492488744516627947e-05"/>      
    </inertial>    
  </link>  

  <link name="rail">    
    <visual>      
      <origin xyz="0 0 0" rpy="0 -0 0"/>      
      <geometry>        
        <mesh filename="package:///meshes/right_rail_visual.stl"/>        
      </geometry>      
      <material name="rail_material">        
        <color rgba="0.64705882352941179736 0.64705882352941179736 0.64705882352941179736 1.0"/>        
      </material>      
    </visual>    
    <collision>      
      <origin xyz="0 0 0" rpy="0 -0 0"/>      
      <geometry>        
        <mesh filename="package:///meshes/right_rail_collision.stl"/>        
      </geometry>      
    </collision>    
    <inertial>      
      <origin xyz="0.029554714214719168819 -0.015933051259988690457 -0.010638774525132295434" rpy="0 0 0"/>      
      <mass value="0.017100000000000004086"/>      
      <inertia ixx="3.6591938331681682466e-06" ixy="2.101313841244636705e-08" ixz="-1.1335092663308559672e-07" iyy="4.7380338190523213965e-06" iyz="3.1225833654311399591e-08" izz="6.0956112819844626417e-06"/>      
    </inertial>    
  </link>  

  <joint name="right_gripper_pinion" type="prismatic">    
    <origin xyz="-0.028872600000000046838 -0.01597499999999998227 -0.0053500000000018255175" rpy="-3.141592653589793116 1.570796326794896336 0"/>    
    <parent link="right_rail_guide"/>    
    <child link="rail"/>    
    <axis xyz="0 0 1"/>    
    <limit effort="1" velocity="20" lower="-0.025000000000000001388" upper="0"/>    
    <joint_properties friction="0.0"/>    
  </joint>  

  <link name="rail_2">    
    <visual>      
      <origin xyz="0 0 0" rpy="0 -0 0"/>      
      <geometry>        
        <mesh filename="package:///meshes/right_rail_2_visual.stl"/>        
      </geometry>      
      <material name="rail_2_material">        
        <color rgba="0.64705882352941179736 0.64705882352941179736 0.64705882352941179736 1.0"/>        
      </material>      
    </visual>    
    <collision>      
      <origin xyz="0 0 0" rpy="0 -0 0"/>      
      <geometry>        
        <mesh filename="package:///meshes/right_rail_2_collision.stl"/>        
      </geometry>      
    </collision>    
    <inertial>      
      <origin xyz="0.029554714214719151472 -0.015933051259988690457 -0.010638774525132281557" rpy="0 0 0"/>      
      <mass value="0.017100000000000004086"/>      
      <inertia ixx="3.6591938331681699406e-06" ixy="2.1013138412446370359e-08" ixz="-1.1335092663308562319e-07" iyy="4.7380338190523213965e-06" iyz="3.1225833654311399591e-08" izz="6.0956112819844626417e-06"/>      
    </inertial>    
  </link>  

  <joint name="right_gripper_pinion_mirror" type="prismatic">    
    <origin xyz="0.062872600000000000708 0.015974999999999996148 -0.0053500000000018255175" rpy="-5.5077470362028772728e-17 1.570796326794896336 0"/>    
    <parent link="right_rail_guide"/>    
    <child link="rail_2"/>    
    <axis xyz="0 0 1"/>    
    <limit effort="1" velocity="20" lower="-0.025000000000000001388" upper="0"/>    
    <joint_properties friction="0.0"/>    
  </joint>  

  <link name="xc330">    
    <visual>      
      <origin xyz="0 0 0" rpy="0 -0 0"/>      
      <geometry>        
        <mesh filename="package:///meshes/right_xc330_visual.stl"/>        
      </geometry>      
      <material name="xc330_material">        
        <color rgba="0.66932535752643762539 0.72911795671409951325 0.67547870389434383487 1.0"/>        
      </material>      
    </visual>    
    <collision>      
      <origin xyz="0 0 0" rpy="0 -0 0"/>      
      <geometry>        
        <mesh filename="package:///meshes/right_xc330_collision.stl"/>        
      </geometry>      
    </collision>    
    <inertial>      
      <origin xyz="0.0080045171539636656571 -0.015558009851632038575 -0.011717805512818681157" rpy="0 0 0"/>      
      <mass value="0.026599999993091757305"/>      
      <inertia ixx="3.8683410666514873223e-06" ixy="-7.7688424001884118559e-10" ixz="5.7969695832743633125e-10" iyy="2.1626767907495288038e-06" iyz="8.3590274792655130141e-09" izz="3.3158761130056373734e-06"/>      
    </inertial>    
  </link>  

  <link name="spur_gear_(18_teeth)">    
    <visual>      
      <origin xyz="0 0 0" rpy="0 -0 0"/>      
      <geometry>        
        <mesh filename="package:///meshes/right_spur_gear_(18_teeth)_visual.stl"/>        
      </geometry>      
      <material name="spur_gear_(18_teeth)_material">        
        <color rgba="0.91764705882352926025 0.91764705882352926025 0.91764705882352926025 1.0"/>        
      </material>      
    </visual>    
    <collision>      
      <origin xyz="0 0 0" rpy="0 -0 0"/>      
      <geometry>        
        <mesh filename="package:///meshes/right_spur_gear_(18_teeth)_collision.stl"/>        
      </geometry>      
    </collision>    
    <inertial>      
      <origin xyz="5.5511151231257827021e-17 -3.1225022567582527699e-17 -0.0025000000000000074246" rpy="0 0 0"/>      
      <mass value="0.0012999999999999999403"/>      
      <inertia ixx="3.3282842836137718203e-08" ixy="-1.5837813884372199342e-22" ixz="-2.8752104509266030915e-38" iyy="3.3282842836137453506e-08" iyz="-1.0904371075711416333e-36" izz="6.1149428795799489038e-08"/>      
    </inertial>    
  </link>  

  <joint name="right_gripper_rack" type="revolute">    
    <origin xyz="0.0079999999999993201549 -0.022499999999995502764 -0.026000000000000439426" rpy="7.3432579397082090565e-14 3.5141900076851877937e-14 -3.1415926535897820138"/>    
    <parent link="xc330"/>    
    <child link="spur_gear_(18_teeth)"/>    
    <axis xyz="0 0 1"/>    
    <limit effort="1" velocity="20" lower="0" upper="2.7052603405912107881"/>    
    <joint_properties friction="0.0"/>    
  </joint>  

  <joint name="right_gripper_motor" type="fixed">    
    <origin xyz="-0.0059500000000000073663 -0.022600000000000008971 0.023299999999999987388" rpy="3.6776137690705712091e-16 1.2671612890944486003e-16 3.141592653589793116"/>    
    <parent link="right_rail_guide"/>    
    <child link="xc330"/>    
    <axis xyz="0 0 1"/>    
    <limit effort="1" velocity="20"/>    
    <joint_properties friction="0.0"/>    
  </joint>  

  <joint name="right_gripper_fixed" type="fixed">    
    <origin xyz="0 0.037000000000000005107 -0.0019999999999999983069" rpy="1.5707963267948970021 1.570796326794896558 0"/>    
    <parent link="gripper_connector"/>    
    <child link="right_rail_guide"/>    
    <axis xyz="0 0 1"/>    
    <limit effort="1" velocity="20"/>    
    <joint_properties friction="0.0"/>    
  </joint>  

  <joint name="right_wrist_roll" type="revolute">    
    <origin xyz="0.019000000000004482054 -3.580631624533481272e-10 -0.027000000152456495039" rpy="-3.141592653589758477 -1.5707963267948275021 0"/>    
    <parent link="2xl430_gears_3"/>    
    <child link="gripper_connector"/>    
    <axis xyz="0 0 1"/>    
    <limit effort="1" velocity="20" lower="-1.3962634015954635824" upper="1.9198621771937625091"/>    
    <joint_properties friction="0.0"/>    
  </joint>  

  <link name="wrist_bearing_plate">    
    <visual>      
      <origin xyz="0 0 0" rpy="0 -0 0"/>      
      <geometry>        
        <mesh filename="package:///meshes/right_wrist_bearing_plate_visual.stl"/>        
      </geometry>      
      <material name="wrist_bearing_plate_material">        
        <color rgba="0.71932243125689065977 0.63128434304969727187 0.52422389360984933404 1.0"/>        
      </material>      
    </visual>    
    <collision>      
      <origin xyz="0 0 0" rpy="0 -0 0"/>      
      <geometry>        
        <mesh filename="package:///meshes/right_wrist_bearing_plate_collision.stl"/>        
      </geometry>      
    </collision>    
    <inertial>      
      <origin xyz="-0.0075835583121500052886 -0.015499999999999980807 -0.0018386323705903270722" rpy="0 0 0"/>      
      <mass value="0.0049000367468305548388"/>      
      <inertia ixx="4.9707430109150107956e-07" ixy="8.1070294502442220436e-23" ixz="1.8100904820814048483e-08" iyy="7.1268523603538595411e-07" iyz="1.2144016459131329602e-23" izz="1.1919657811600109234e-06"/>      
    </inertial>    
  </link>  

  <joint name="right_wrist_pitch_fixed" type="fixed">    
    <origin xyz="0.015500000000004740888 1.2045919817182948464e-14 -0.045000000000007915613" rpy="3.9795857581529944641e-14 1.8629542353210303453e-13 -1.5707963267947884223"/>    
    <parent link="2xl430_gears_3"/>    
    <child link="wrist_bearing_plate"/>    
    <axis xyz="0 0 1"/>    
    <limit effort="1" velocity="20"/>    
    <joint_properties friction="0.0"/>    
  </joint>  

  <joint name="right_wrist_pitch_driven" type="revolute">    
    <origin xyz="0 2.5637979419682883676e-30 -0.0015999999999999950893" rpy="1.5612511284236928353e-16 1.0061396160670370853e-16 1.570796326794896336"/>    
    <parent link="spur_1m_24t_driven_3"/>    
    <child link="2xl430_gears_3"/>    
    <axis xyz="0 0 1"/>    
    <limit effort="1" velocity="20" lower="-1.9198621771937625091" upper="1.3962634015954635824"/>    
    <joint_properties friction="0.0"/>    
  </joint>  

  <joint name="right_wrist_roll_fixed" type="fixed">    
    <origin xyz="-9.8607613152626475676e-31 -0.025300000000000003042 -0.051999999999999990674" rpy="1.570796326794896558 1.570796326794896558 0"/>    
    <parent link="elb_yaw_link"/>    
    <child link="spur_1m_24t_driven_3"/>    
    <axis xyz="0 0 1"/>    
    <limit effort="1" velocity="20"/>    
    <joint_properties friction="0.0"/>    
  </joint>  

  <joint name="right_elbow_yaw_fixed" type="fixed">    
    <origin xyz="0 -5.9164567891575885406e-31 0.0016000000000000041966" rpy="3.141592653589793116 -1.6415575270060996837e-29 -1.570796326794896558"/>    
    <parent link="spur_1m_24t_driven_2"/>    
    <child link="elb_yaw_link"/>    
    <axis xyz="0 0 1"/>    
    <limit effort="1" velocity="20"/>    
    <joint_properties friction="0.0"/>    
  </joint>  

  <joint name="right_elbow_yaw_driven" type="revolute">    
    <origin xyz="-3.5807057666148445207e-10 -0.027000000152458056291 -0.019000000000001949357" rpy="1.5707963267949378583 3.9690473130355310109e-14 -5.221292488511941966e-14"/>    
    <parent link="2xl430_gears_2"/>    
    <child link="spur_1m_24t_driven_2"/>    
    <axis xyz="0 0 1"/>    
    <limit effort="1" velocity="20" lower="-2.6179938779914944114" upper="2.6179938779914944114"/>    
    <joint_properties friction="0.0"/>    
  </joint>  

  <joint name="right_elbow_roll" type="revolute">    
    <origin xyz="6.9388939039072283776e-18 -0.018999999999999992589 -0.058999999999999983014" rpy="1.570796326794896558 1.8613243021562443989e-16 2.7317207594485797632e-14"/>    
    <parent link="sho_yaw_link"/>    
    <child link="2xl430_gears_2"/>    
    <axis xyz="0 0 1"/>    
    <limit effort="1" velocity="20" lower="-1.9198621771937625091" upper="2.4434609527920612138"/>    
    <joint_properties friction="0.0"/>    
  </joint>  

  <joint name="right_sho_yaw_fixed" type="fixed">    
    <origin xyz="0 1.9721522630525295135e-31 0.0016000000000000007272" rpy="-3.141592653589793116 6.0982645760524304742e-30 -1.2655675810200602945e-30"/>    
    <parent link="spur_1m_24t_driven"/>    
    <child link="sho_yaw_link"/>    
    <axis xyz="0 0 1"/>    
    <limit effort="1" velocity="20"/>    
    <joint_properties friction="0.0"/>    
  </joint>  

  <joint name="right_sho_yaw_driven" type="revolute">    
    <origin xyz="-3.5806868581289563735e-10 -0.027000000152448175306 -0.018999999999998452155" rpy="1.5707963267947739894 -2.7015357376462180631e-14 4.23468517903597816e-14"/>    
    <parent link="2xl430_gears"/>    
    <child link="spur_1m_24t_driven"/>    
    <axis xyz="0 0 1"/>    
    <limit effort="1" velocity="20" lower="-2.6179938779914944114" upper="2.6179938779914944114"/>    
    <joint_properties friction="0.0"/>    
  </joint>  

  <joint name="right_sho_roll" type="revolute">    
    <origin xyz="-0.018999999999999999528 9.324138683375341214e-18 0.027000000000000006634" rpy="-3.141592653589793116 1.5707963267947613328 0"/>    
    <parent link="sho_pitch_link"/>    
    <child link="2xl430_gears"/>    
    <axis xyz="0 0 1"/>    
    <limit effort="1" velocity="20" lower="-1.570796326794896558" upper="0.34906585039886589561"/>    
    <joint_properties friction="0.0"/>    
  </joint>  


</robot>