<mujoco model="T1">
  <compiler angle="radian" meshdir="meshes/"/>

  <default>
    <joint limited="true" damping="0.01" armature="0.01" frictionloss="0.0" />
    <equality solref="0.001 2" />
    <default class="visual">
      <geom type="mesh" contype="0" conaffinity="0" group="2" density="0"/>
    </default>
      <default class="collision">
        <geom group="3" material="transparent" priority="1" friction="1. 0.01 0.005"/>
    </default>
  </default>

  <asset>
    <material name="metal" rgba=".9 .95 .95 1"/>
    <material name="black" rgba="0 0 0 1"/>
    <material name="white" rgba="1 1 1 1"/>
    <material name="gray" rgba="0.4 0.4 0.4 1"/>
    <material name="transparent" rgba="0.5 0.5 0.5 1"/>
    <mesh name="Trunk" file="Trunk.STL"/>
    <mesh name="H1" file="H1.STL"/>
    <mesh name="H2" file="H2.STL"/>
    <mesh name="AL1" file="AL1.STL"/>
    <mesh name="AL2" file="AL2.STL"/>
    <mesh name="AL3" file="AL3.STL"/>
    <mesh name="left_hand_link" file="left_hand_link.STL"/>
    <mesh name="AR1" file="AR1.STL"/>
    <mesh name="AR2" file="AR2.STL"/>
    <mesh name="AR3" file="AR3.STL"/>
    <mesh name="right_hand_link" file="right_hand_link.STL"/>
    <mesh name="Waist" file="Waist.STL"/>
    <mesh name="Hip_Pitch_Left" file="Hip_Pitch_Left.STL"/>
    <mesh name="Hip_Roll_Left" file="Hip_Roll_Left.STL"/>
    <mesh name="Hip_Yaw_Left" file="Hip_Yaw_Left.STL"/>
    <mesh name="Shank_Left" file="Shank_Left.STL"/>
    <mesh name="Ankle_Cross_Left" file="Ankle_Cross_Left.STL"/>
    <mesh name="left_foot_link" file="left_foot_link.STL"/>
    <mesh name="Hip_Pitch_Right" file="Hip_Pitch_Right.STL"/>
    <mesh name="Hip_Roll_Right" file="Hip_Roll_Right.STL"/>
    <mesh name="Hip_Yaw_Right" file="Hip_Yaw_Right.STL"/>
    <mesh name="Shank_Right" file="Shank_Right.STL"/>
    <mesh name="Ankle_Cross_Right" file="Ankle_Cross_Right.STL"/>
    <mesh name="right_foot_link" file="right_foot_link.STL"/>
  </asset>

  <worldbody>
    <body name="Trunk" pos="0 0 1.68">
    <geom class="visual" material="gray" mesh="Trunk"/>
    <geom size="0.09 0.09" pos="0.055 0.022 0.1" type="capsule" quat="0.997189 -0.074930 0 0" class="collision" name="torso_left"/>
    <geom size="0.09 0.09" pos="0.055 -0.022 0.1" type="capsule" quat="0.997189 0.074930 0 0" class="collision" name="torso_right"/>
    <freejoint/>
    <body name="H1" pos="0.0625 0 0.243">
      <inertial pos="-0.000508 -0.001403 0.057432" quat="0.763881 -0.0132172 0.00173419 0.645219" mass="0.44391" diaginertia="0.000241549 0.00022351 0.000149941"/>
      <joint name="AAHead_yaw" pos="0 0 0" axis="0 0 1" range="-1.57 1.57" actuatorfrcrange="-7 7"/>
      <geom class="visual" material="gray" mesh="H1"/>
      <body name="H2" pos="0 0 0.06185">
        <inertial pos="0.007802 0.001262 0.098631" quat="0.988453 0.106172 -0.0745686 -0.0782786" mass="0.631019" diaginertia="0.00203553 0.00192467 0.00172381"/>
        <joint name="Head_pitch" pos="0 0 0" axis="0 1 0" range="-0.35 1.22" actuatorfrcrange="-7 7"/>
        <geom class="visual" material="gray" mesh="H2"/>
        <geom size="0.08" pos="0.01 0 0.11" class="collision" name="head"/>
      </body>
    </body>
    <body name="AL1" pos="0.0575 0.1063 0.219" quat="1 0 0.000440565 0">
      <inertial pos="-0.000677 0.044974 0" quat="0.50423 0.495734 -0.50423 0.495734" mass="0.53" diaginertia="0.001367 0.00129329 0.000292711"/>
      <joint name="Left_Shoulder_Pitch" pos="0 0 0" axis="0 1 0" range="-3.31 1.22" actuatorfrcrange="-18 18"/>
      <geom class="visual" material="gray" mesh="AL1"/>
      <body name="AL2" pos="0 0.047 0">
        <inertial pos="0.003862 0.037976 0" quat="0.487991 0.511727 -0.487991 0.511727" mass="0.16" diaginertia="0.000401 0.00034538 0.00017662"/>
        <joint name="Left_Shoulder_Roll" pos="0 0 0" axis="1 0 0" range="-1.74 1.57" actuatorfrcrange="-18 18"/>
        <geom class="visual" material="gray" mesh="AL2"/>
        <body name="AL3" pos="0.00025 0.0605 0">
          <inertial pos="0 0.085353 -9.9e-05" quat="0.70641 0.707803 0 0" mass="1.02" diaginertia="0.012869 0.012798 0.000620953"/>
          <joint name="Left_Elbow_Pitch" pos="0 0 0" axis="0 1 0" range="-2.27 2.27" actuatorfrcrange="-18 18"/>
          <geom class="visual" material="gray" mesh="AL3"/>
          <geom size="0.03 0.075" pos="0 0.05 0" quat="0.707105 0.707108 0 0" type="capsule" class="collision" name="left_forearm"/>
          <body name="left_hand_link" pos="0 0.1471 0">
            <inertial pos="-0.000108 0.109573 0.000591" quat="0.707866 0.706347 -5.22939e-05 -0.000214913" mass="0.327214" diaginertia="0.008159 0.00813104 0.000214962"/>
            <joint name="Left_Elbow_Yaw" pos="0 0 0" axis="0 0 1" range="-2.44 0" actuatorfrcrange="-18 18"/>
            <geom class="visual" material="gray" mesh="left_hand_link"/>
            <geom size="0.03 0.0875" pos="0 0.13 0" quat="0.707105 0.707108 0 0" type="capsule" class="collision" name="left_hand"/>
          </body>
        </body>
      </body>
    </body>
    <body name="AR1" pos="0.0575 -0.1063 0.219" quat="1 0 0.000440565 0">
      <inertial pos="-0.000677 -0.044974 0" quat="0.50423 0.495734 -0.50423 0.495734" mass="0.53" diaginertia="0.001367 0.00129329 0.000292711"/>
      <joint name="Right_Shoulder_Pitch" pos="0 0 0" axis="0 1 0" range="-3.31 1.22" actuatorfrcrange="-18 18"/>
      <geom class="visual" material="gray" mesh="AR1"/>
      <body name="AR2" pos="0 -0.047 0">
        <inertial pos="0.003862 -0.037976 0" quat="0.511727 0.487991 -0.511727 0.487991" mass="0.16" diaginertia="0.000401 0.00034538 0.00017662"/>
        <joint name="Right_Shoulder_Roll" pos="0 0 0" axis="1 0 0" range="-1.57 1.74" actuatorfrcrange="-18 18"/>
        <geom class="visual" material="gray" mesh="AR2"/>
        <body name="AR3" pos="0.00025 -0.0605 0">
          <inertial pos="0 -0.085353 -9.9e-05" quat="0.707803 0.70641 0 0" mass="1.02" diaginertia="0.012869 0.012798 0.000620953"/>
          <joint name="Right_Elbow_Pitch" pos="0 0 0" axis="0 1 0" range="-2.27 2.27" actuatorfrcrange="-18 18"/>
          <geom class="visual" material="gray" mesh="AR3"/>
          <geom size="0.03 0.075" pos="0 -0.05 0" quat="0.707105 0.707108 0 0" type="capsule" class="collision" name="right_forearm"/>
          <body name="right_hand_link" pos="0 -0.1471 0">
            <inertial pos="-0.000108 -0.109573 0.000591" quat="0.706347 0.707866 0.000214913 5.22939e-05" mass="0.327214" diaginertia="0.008159 0.00813104 0.000214962"/>
            <joint name="Right_Elbow_Yaw" pos="0 0 0" axis="0 0 1" range="0 2.44" actuatorfrcrange="-18 18"/>
            <geom class="visual" material="gray" mesh="right_hand_link"/>
            <geom size="0.03 0.0875" pos="0 -0.13 0" quat="0.707105 0.707108 0 0" type="capsule" class="collision" name="right_hand"/>
          </body>
        </body>
      </body>
    </body>
    <body name="Waist" pos="0.0625 0 -0.1155">
      <inertial pos="0.002284 3e-06 0.007301" quat="0.983649 0.000360386 -0.180076 0.00269791" mass="2.581" diaginertia="0.00536742 0.005299 0.00474258"/>
      <joint name="Waist" pos="0 0 0" axis="0 0 1" range="-1.57 1.57" actuatorfrcrange="-30 30"/>
      <geom class="visual" material="gray" mesh="Waist"/>
      <body name="Hip_Pitch_Left" pos="0 0.106 0">
        <inertial pos="0.000534 -0.007296 -0.018083" quat="0.975141 0.2211 0.0145808 0.0017406" mass="1.021" diaginertia="0.00180547 0.00145926 0.00125327"/>
        <joint name="Left_Hip_Pitch" pos="0 0 0" axis="0 1 0" range="-1.8 1.57" actuatorfrcrange="-45 45"/>
        <geom class="visual" material="gray" mesh="Hip_Pitch_Left"/>
        <body name="Hip_Roll_Left" pos="0 0 -0.02">
          <inertial pos="0.001101 2.4e-05 -0.05375" quat="0.707081 -0.00599604 -0.00599604 0.707081" mass="0.385" diaginertia="0.001743 0.00151729 0.000514712"/>
          <joint name="Left_Hip_Roll" pos="0 0 0" axis="1 0 0" range="-0.2 1.57" actuatorfrcrange="-30 30"/>
          <geom class="visual" material="gray" mesh="Hip_Roll_Left"/>
          <geom size="0.05 0.08" pos="0 0 -0.08" type="capsule" class="collision" name="left_thigh"/>
          <body name="Hip_Yaw_Left" pos="0 0 -0.081854">
            <inertial pos="-0.007233 0.000206 -0.089184" quat="0.696808 -0.033953 -0.0315708 0.715758" mass="2.166" diaginertia="0.0257334 0.0253024 0.00259215"/>
            <joint name="Left_Hip_Yaw" pos="0 0 0" axis="0 0 1" range="-1 1" actuatorfrcrange="-30 30"/>
            <geom class="visual" material="gray" mesh="Hip_Yaw_Left"/>
            <body name="Shank_Left" pos="-0.014 0 -0.134">
              <inertial pos="-0.006012 0.000259 -0.124318" quat="0.997573 0.00144024 -0.023949 0.0653706" mass="1.73" diaginertia="0.0346951 0.0345375 0.00185844"/>
              <joint name="Left_Knee_Pitch" pos="0 0 0" axis="0 1 0" range="0 2.34" actuatorfrcrange="-60 60"/>
              <geom class="visual" material="gray" mesh="Shank_Left"/>
              <geom size="0.05 0.075" pos="0 0 -0.12" type="capsule" class="collision" name="left_calf"/>
              <body name="Ankle_Cross_Left" pos="0 0 -0.28">
                <inertial pos="-0.003722 0 -0.007981" quat="0.443136 0.551027 0.551027 0.443136" mass="0.073" diaginertia="2.9e-05 2.56589e-05 1.13411e-05"/>
                <joint name="Left_Ankle_Pitch" pos="0 0 0" axis="0 1 0" range="-0.87 0.35" actuatorfrcrange="-20 20"/>
                <geom class="visual" material="gray" mesh="Ankle_Cross_Left"/>
                <body name="left_foot_link" pos="0 0.00025 -0.012">
                  <inertial pos="-0.000249 0 -0.00914" quat="0 0.679927 0 0.733279" mass="0.685" diaginertia="0.00268212 0.002385 0.000726885"/>
                  <joint name="Left_Ankle_Roll" pos="0 0 0" axis="1 0 0" range="-0.44 0.44" actuatorfrcrange="-15 15"/>
                  <geom class="visual" material="gray" mesh="left_foot_link"/>
                  <geom size="0.02 0.0915" pos="0.01 0.035 -0.01"  quat="0.707105 0 0.707108 0" type="capsule" class="collision" name="left_foot_1"/>
                  <geom size="0.02 0.0915" pos="0.01 -0.035 -0.01"  quat="0.707105 0 0.707108 0" type="capsule" class="collision" name="left_foot_2"/>
                </body>
              </body>
            </body>
          </body>
        </body>
      </body>
      <body name="Hip_Pitch_Right" pos="0 -0.106 0">
        <inertial pos="0.000534 0.007514 -0.018082" quat="0.973446 -0.228403 0.0147148 -0.00419349" mass="1.021" diaginertia="0.00180552 0.0014632 0.00124928"/>
        <joint name="Right_Hip_Pitch" pos="0 0 0" axis="0 1 0" range="-1.8 1.57" actuatorfrcrange="-45 45"/>
        <geom class="visual" material="gray" mesh="Hip_Pitch_Right"/>
        <body name="Hip_Roll_Right" pos="0 0 -0.02">
          <inertial pos="0.001099 2.4e-05 -0.053748" quat="0.707081 -0.00599604 -0.00599604 0.707081" mass="0.385" diaginertia="0.001743 0.00151729 0.000514712"/>
          <joint name="Right_Hip_Roll" pos="0 0 0" axis="1 0 0" range="-1.57 0.2" actuatorfrcrange="-30 30"/>
          <geom class="visual" material="gray" mesh="Hip_Roll_Right"/>
          <geom size="0.05 0.08" pos="0 0 -0.08" type="capsule" class="collision" name="right_thigh"/>
          <body name="Hip_Yaw_Right" pos="0 0 -0.081854">
            <inertial pos="-0.007191 -0.000149 -0.08922" quat="0.714468 -0.0315638 -0.0336391 0.698146" mass="2.17" diaginertia="0.0257623 0.0253298 0.00259389"/>
            <joint name="Right_Hip_Yaw" pos="0 0 0" axis="0 0 1" range="-1 1" actuatorfrcrange="-30 30"/>
            <geom class="visual" material="gray" mesh="Hip_Yaw_Right"/>
            <body name="Shank_Right" pos="-0.014 0 -0.134">
              <inertial pos="-0.005741 -0.000541 -0.122602" quat="0.99926 -0.000580963 -0.023461 -0.0304754" mass="1.79" diaginertia="0.0351717 0.0349574 0.00196589"/>
              <joint name="Right_Knee_Pitch" pos="0 0 0" axis="0 1 0" range="0 2.34" actuatorfrcrange="-60 60"/>
              <geom class="visual" material="gray" mesh="Shank_Right"/>
              <geom size="0.05 0.075" pos="0 0 -0.12" type="capsule" class="collision" name="right_calf"/>
              <body name="Ankle_Cross_Right" pos="0 0 -0.28">
                <inertial pos="-0.003722 0 -0.007981" quat="0.443136 0.551027 0.551027 0.443136" mass="0.073" diaginertia="2.9e-05 2.56589e-05 1.13411e-05"/>
                <joint name="Right_Ankle_Pitch" pos="0 0 0" axis="0 1 0" range="-0.87 0.35" actuatorfrcrange="-20 20"/>
                <geom class="visual" material="gray" mesh="Ankle_Cross_Right"/>
                <body name="right_foot_link" pos="0 -0.00025 -0.012">
                  <inertial pos="-0.000248 0 -0.00914" quat="0 0.679927 0 0.733279" mass="0.685" diaginertia="0.00268212 0.002385 0.000726885"/>
                  <joint name="Right_Ankle_Roll" pos="0 0 0" axis="1 0 0" range="-0.44 0.44" actuatorfrcrange="-15 15"/>
                  <geom class="visual" material="gray" mesh="right_foot_link"/>
                  <geom size="0.02 0.0915" pos="0.01 0.035 -0.01"  quat="0.707105 0 0.707108 0" type="capsule" class="collision" name="right_foot_1"/>
                  <geom size="0.02 0.0915" pos="0.01 -0.035 -0.01"  quat="0.707105 0 0.707108 0" type="capsule" class="collision" name="right_foot_2"/>
                </body>
              </body>
            </body>
          </body>
        </body>
      </body>
    </body>
    </body>
  </worldbody>

  <actuator>
    <motor name="AAHead_yaw" joint="AAHead_yaw" ctrllimited="true" ctrlrange="-7 7" gear="1" />
    <motor name="Head_pitch" joint="Head_pitch" ctrllimited="true" ctrlrange="-7 7" gear="1" />
    <motor name="Left_Shoulder_Pitch" joint="Left_Shoulder_Pitch" ctrllimited="true" ctrlrange="-18 18" gear="1" />
    <motor name="Left_Shoulder_Roll" joint="Left_Shoulder_Roll" ctrllimited="true" ctrlrange="-18 18" gear="1" />
    <motor name="Left_Elbow_Pitch" joint="Left_Elbow_Pitch" ctrllimited="true" ctrlrange="-18 18" gear="1" />
    <motor name="Left_Elbow_Yaw" joint="Left_Elbow_Yaw" ctrllimited="true" ctrlrange="-18 18" gear="1" />
    <motor name="Right_Shoulder_Pitch" joint="Right_Shoulder_Pitch" ctrllimited="true" ctrlrange="-18 18" gear="1" />
    <motor name="Right_Shoulder_Roll" joint="Right_Shoulder_Roll" ctrllimited="true" ctrlrange="-18 18" gear="1" />
    <motor name="Right_Elbow_Pitch" joint="Right_Elbow_Pitch" ctrllimited="true" ctrlrange="-18 18" gear="1" />
    <motor name="Right_Elbow_Yaw" joint="Right_Elbow_Yaw" ctrllimited="true" ctrlrange="-18 18" gear="1" />
    <motor name="Waist" joint="Waist" ctrllimited="true" ctrlrange="-30 30" gear="1" />
    <motor name="Left_Hip_Pitch" joint="Left_Hip_Pitch" ctrllimited="true" ctrlrange="-45 45" gear="1" />
    <motor name="Left_Hip_Roll" joint="Left_Hip_Roll" ctrllimited="true" ctrlrange="-30 30" gear="1" />
    <motor name="Left_Hip_Yaw" joint="Left_Hip_Yaw" ctrllimited="true" ctrlrange="-30 30" gear="1" />
    <motor name="Left_Knee_Pitch" joint="Left_Knee_Pitch" ctrllimited="true" ctrlrange="-60 60" gear="1" />
    <motor name="Left_Ankle_Pitch" joint="Left_Ankle_Pitch" ctrllimited="true" ctrlrange="-20 20" gear="1" />
    <motor name="Left_Ankle_Roll" joint="Left_Ankle_Roll" ctrllimited="true" ctrlrange="-15 15" gear="1" />
    <motor name="Right_Hip_Pitch" joint="Right_Hip_Pitch" ctrllimited="true" ctrlrange="-45 45" gear="1" />
    <motor name="Right_Hip_Roll" joint="Right_Hip_Roll" ctrllimited="true" ctrlrange="-30 30" gear="1" />
    <motor name="Right_Hip_Yaw" joint="Right_Hip_Yaw" ctrllimited="true" ctrlrange="-30 30" gear="1" />
    <motor name="Right_Knee_Pitch" joint="Right_Knee_Pitch" ctrllimited="true" ctrlrange="-60 60" gear="1" />
    <motor name="Right_Ankle_Pitch" joint="Right_Ankle_Pitch" ctrllimited="true" ctrlrange="-20 20" gear="1" />
    <motor name="Right_Ankle_Roll" joint="Right_Ankle_Roll" ctrllimited="true" ctrlrange="-15 15" gear="1" />
  </actuator>



  <!-- setup scene -->
  <statistic center="1.0 0.7 1.0" extent="0.8"/>
  <visual>
      <headlight diffuse="0.6 0.6 0.6" ambient="0.1 0.1 0.1" specular="0.9 0.9 0.9"/>
      <rgba haze="0.15 0.25 0.35 1"/>
      <global azimuth="-140" elevation="-20" offwidth="2080" offheight="1170"/>
  </visual>
  <asset>
       <texture type="skybox" builtin="gradient" rgb1="1 1 1" rgb2="1 1 1" width="800" height="800"/>
  <texture type="2d" name="groundplane" builtin="checker" mark="edge" rgb1="1 1 1" rgb2="1 1 1" markrgb="0 0 0"
    width="300" height="300"/>
  <material name="groundplane" texture="groundplane" texuniform="true" texrepeat="5 5" reflectance="0"/>
      <texture type="skybox" builtin="gradient" rgb1=".4 .5 .6" rgb2="0 0 0" width="100" height="100"/>
      <texture builtin="flat" height="1278" mark="cross" markrgb="1 1 1" name="texgeom" random="0.01" rgb1="0.8 0.6 0.4" rgb2="0.8 0.6 0.4" type="cube" width="127"/>
      <texture name="texplane" builtin="checker" height="512" width="512" rgb1=".2 .3 .4" rgb2=".1 .15 .2" type="2d" />
      <material name="MatPlane" reflectance="0.5" shininess="0.01" specular="0.1" texrepeat="1 1" texture="texplane" texuniform="true" />
      <material name="geom" texture="texgeom" texuniform="true"/>
  </asset>
  <worldbody>
      <geom name="floor" size="0 0 0.01" type="plane" material="groundplane" contype="1" conaffinity="0" priority="1"
    friction="0.6" condim="3"/>
    <!-- <light diffuse=".5 .5 .5" pos="0 0 5" dir="0 0 -1" castshadow="true"/> -->

        <light diffuse=".5 .5 .5" pos="-3 -3 5" dir="3 3 -5" castshadow="true"/>


  </worldbody>

</mujoco>
