<?xml version="1.0" encoding="utf-8"?>
<!-- This URDF was automatically created by SolidWorks to URDF Exporter! Originally created by Stephen Brawner (brawner@gmail.com) 
     Commit Version: 1.6.0-4-g7f85cfe  Build Version: 1.6.7995.38578
     For more information, please see http://wiki.ros.org/sw_urdf_exporter -->
<robot
  name="r1_pro_with_gripper">
  <link
    name="base_link">
    <inertial>
      <origin
        xyz="-0.049262 -8.8054E-05 0.18255"
        rpy="0 0 0" />
      <mass
        value="47.63" />
      <inertia
        ixx="1.5812"
        ixy="-1.0625E-05"
        ixz="0.053601"
        iyy="1.4648"
        iyz="5.7054E-06"
        izz="2.835" />
    </inertial>
    <visual>
      <origin
        xyz="0 0 0"
        rpy="0 0 0" />
      <geometry>
        <mesh
          filename="meshes/base_link.obj" />
      </geometry>
    </visual>
    <collision>
      <origin
        xyz="0 0 0"
        rpy="0 0 0" />
      <geometry>
        <mesh
          filename="meshes/base_link.obj" />
      </geometry>
    </collision>
  </link>
  <link
    name="steer_motor_link1">
    <inertial>
      <origin
        xyz="7.7174E-06 -0.004623 -0.049428"
        rpy="0 0 0" />
      <mass
        value="1.5" />
      <inertia
        ixx="0.00022164"
        ixy="-3.529E-09"
        ixz="3.4267E-09"
        iyy="0.00032908"
        iyz="-7.5872E-08"
        izz="0.00015872" />
    </inertial>
    <visual>
      <origin
        xyz="0 0 0"
        rpy="0 0 0" />
      <geometry>
        <mesh
          filename="meshes/steer_motor_link1.obj" />
      </geometry>
    </visual>
    <collision>
      <origin
        xyz="0 0 0"
        rpy="0 0 0" />
      <geometry>
        <mesh
          filename="meshes/steer_motor_link1.obj" />
      </geometry>
    </collision>
  </link>
  <joint
    name="steer_motor_joint1"
    type="revolute">
    <origin
      xyz="0.16897 0.28 0.15765"
      rpy="0 0 0" />
    <parent
      link="base_link" />
    <child
      link="steer_motor_link1" />
    <axis
      xyz="0 0 1" />
    <limit
      lower="-3.1416"
      upper="3.1416"
      effort="50"
      velocity="20" />
  </joint>
  <link
    name="wheel_motor_link1">
    <inertial>
      <origin
        xyz="1.6481E-10 -1.6203E-10 -9.455E-10"
        rpy="0 0 0" />
      <mass
        value="1.5" />
      <inertia
        ixx="0.0012628"
        ixy="1.0701E-10"
        ixz="5.7971E-09"
        iyy="0.0020893"
        iyz="1.2406E-09"
        izz="0.0012628" />
    </inertial>
    <visual>
      <origin
        xyz="0 0 0"
        rpy="0 0 0" />
      <geometry>
        <mesh
          filename="meshes/wheel_motor_link1.obj" />
      </geometry>
    </visual>
    <collision>
      <origin
        xyz="0 0 0"
        rpy="0 0 0" />
      <geometry>
        <mesh
          filename="meshes/wheel_motor_link1.obj" />
      </geometry>
    </collision>
  </link>
  <joint
    name="wheel_motor_joint1"
    type="continuous">
    <origin
      xyz="0 0 -0.08765"
      rpy="0 0 0" />
    <parent
      link="steer_motor_link1" />
    <child
      link="wheel_motor_link1" />
    <axis
      xyz="0 1 0" />
  </joint>
  <link
    name="steer_motor_link2">
    <inertial>
      <origin
        xyz="6.044E-06 0.00010023 -0.052223"
        rpy="0 0 0" />
      <mass
        value="1.5" />
      <inertia
        ixx="0.0002535"
        ixy="-4.9113E-09"
        ixz="5.8918E-09"
        iyy="0.00037037"
        iyz="-2.9177E-07"
        izz="0.000163" />
    </inertial>
    <visual>
      <origin
        xyz="0 0 0"
        rpy="0 0 0" />
      <geometry>
        <mesh
          filename="meshes/steer_motor_link2.obj" />
      </geometry>
    </visual>
    <collision>
      <origin
        xyz="0 0 0"
        rpy="0 0 0" />
      <geometry>
        <mesh
          filename="meshes/steer_motor_link2.obj" />
      </geometry>
    </collision>
  </link>
  <joint
    name="steer_motor_joint2"
    type="revolute">
    <origin
      xyz="0.16897 -0.28 0.15765"
      rpy="0 0 0" />
    <parent
      link="base_link" />
    <child
      link="steer_motor_link2" />
    <axis
      xyz="0 0 1" />
    <limit
      lower="-3.1416"
      upper="3.1416"
      effort="50"
      velocity="20" />
  </joint>
  <link
    name="wheel_motor_link2">
    <inertial>
      <origin
        xyz="1.6448E-10 -1.616E-10 -9.4549E-10"
        rpy="0 0 0" />
      <mass
        value="1.5" />
      <inertia
        ixx="0.0012628"
        ixy="1.0701E-10"
        ixz="5.7971E-09"
        iyy="0.0020893"
        iyz="1.2406E-09"
        izz="0.0012628" />
    </inertial>
    <visual>
      <origin
        xyz="0 0 0"
        rpy="0 0 0" />
      <geometry>
        <mesh
          filename="meshes/wheel_motor_link2.obj" />
      </geometry>
    </visual>
    <collision>
      <origin
        xyz="0 0 0"
        rpy="0 0 0" />
      <geometry>
        <mesh
          filename="meshes/wheel_motor_link2.obj" />
      </geometry>
    </collision>
  </link>
  <joint
    name="wheel_motor_joint2"
    type="continuous">
    <origin
      xyz="0 0 -0.08765"
      rpy="0 0 0" />
    <parent
      link="steer_motor_link2" />
    <child
      link="wheel_motor_link2" />
    <axis
      xyz="0 1 0" />
  </joint>
  <link
    name="steer_motor_link3">
    <inertial>
      <origin
        xyz="-6.029E-06 -0.00010167 -0.052221"
        rpy="0 0 0" />
      <mass
        value="1.5" />
      <inertia
        ixx="0.0002535"
        ixy="-4.6767E-09"
        ixz="-3.5903E-09"
        iyy="0.00037036"
        iyz="2.9246E-07"
        izz="0.000163" />
    </inertial>
    <visual>
      <origin
        xyz="0 0 0"
        rpy="0 0 0" />
      <geometry>
        <mesh
          filename="meshes/steer_motor_link3.obj" />
      </geometry>
    </visual>
    <collision>
      <origin
        xyz="0 0 0"
        rpy="0 0 0" />
      <geometry>
        <mesh
          filename="meshes/steer_motor_link3.obj" />
      </geometry>
    </collision>
  </link>
  <joint
    name="steer_motor_joint3"
    type="revolute">
    <origin
      xyz="-0.32703 0 0.15765"
      rpy="0 0 0" />
    <parent
      link="base_link" />
    <child
      link="steer_motor_link3" />
    <axis
      xyz="0 0 1" />
    <limit
      lower="-3.1416"
      upper="3.1416"
      effort="50"
      velocity="20" />
  </joint>
  <link
    name="wheel_motor_link3">
    <inertial>
      <origin
        xyz="-2.443E-09 1.4779E-12 5.1754E-12"
        rpy="0 0 0" />
      <mass
        value="1.5" />
      <inertia
        ixx="0.0012628"
        ixy="1.1439E-10"
        ixz="5.7894E-09"
        iyy="0.0020893"
        iyz="1.2052E-09"
        izz="0.0012628" />
    </inertial>
    <visual>
      <origin
        xyz="0 0 0"
        rpy="0 0 0" />
      <geometry>
        <mesh
          filename="meshes/wheel_motor_link3.obj" />
      </geometry>
    </visual>
    <collision>
      <origin
        xyz="0 0 0"
        rpy="0 0 0" />
      <geometry>
        <mesh
          filename="meshes/wheel_motor_link3.obj" />
      </geometry>
    </collision>
  </link>
  <joint
    name="wheel_motor_joint3"
    type="continuous">
    <origin
      xyz="0 0 -0.08765"
      rpy="0 0 0" />
    <parent
      link="steer_motor_link3" />
    <child
      link="wheel_motor_link3" />
    <axis
      xyz="0 1 0" />
  </joint>
  <link
    name="torso_link1">
    <inertial>
      <origin
        xyz="0.00065636 0.0032244 0.23142"
        rpy="0 0 0" />
      <mass
        value="5.72" />
      <inertia
        ixx="0.10931"
        ixy="7.7894E-06"
        ixz="-0.00017473"
        iyy="0.10736"
        iyz="0.00013778"
        izz="0.0081222" />
    </inertial>
    <visual>
      <origin
        xyz="0 0 0"
        rpy="0 0 0" />
      <geometry>
        <mesh
          filename="meshes/torso_link1.obj" />
      </geometry>
    </visual>
    <collision>
      <origin
        xyz="0 0 0"
        rpy="0 0 0" />
      <geometry>
        <mesh
          filename="meshes/torso_link1.obj" />
      </geometry>
    </collision>
  </link>
  <joint
    name="torso_joint1"
    type="revolute">
    <origin
      xyz="-0.079032 0 0.34265"
      rpy="0 0 0" />
    <parent
      link="base_link" />
    <child
      link="torso_link1" />
    <axis
      xyz="0 1 0" />
    <limit
      lower="-1.1345"
      upper="1.8326"
      effort="100"
      velocity="2.5" />
  </joint>
  <link
    name="torso_link2">
    <inertial>
      <origin
        xyz="0.0052517 0.014411 0.15711"
        rpy="0 0 0" />
      <mass
        value="3.5" />
      <inertia
        ixx="0.026081"
        ixy="-3.3436E-07"
        ixz="0.00024541"
        iyy="0.027574"
        iyz="4.2283E-07"
        izz="0.0018515" />
    </inertial>
    <visual>
      <origin
        xyz="0 0 0"
        rpy="0 0 0" />
      <geometry>
        <mesh
          filename="meshes/torso_link2.obj" />
      </geometry>
    </visual>
    <collision>
      <origin
        xyz="0 0 0"
        rpy="0 0 0" />
      <geometry>
        <mesh
          filename="meshes/torso_link2.obj" />
      </geometry>
    </collision>
  </link>
  <joint
    name="torso_joint2"
    type="revolute">
    <origin
      xyz="0 0 0.4"
      rpy="0 0 0" />
    <parent
      link="torso_link1" />
    <child
      link="torso_link2" />
    <axis
      xyz="0 1 0" />
    <limit
      lower="-2.7925"
      upper="2.5307"
      effort="100"
      velocity="2.5" />
  </joint>
  <link
    name="torso_link3">
    <inertial>
      <origin
        xyz="-9.8337E-07 -0.0055146 0.020182"
        rpy="0 0 0" />
      <mass
        value="3.4" />
      <inertia
        ixx="0.0016099"
        ixy="3.5899E-07"
        ixz="2.5497E-07"
        iyy="0.0023011"
        iyz="1.367E-05"
        izz="0.0017027" />
    </inertial>
    <visual>
      <origin
        xyz="0 0 0"
        rpy="0 0 0" />
      <geometry>
        <mesh
          filename="meshes/torso_link3.obj" />
      </geometry>
    </visual>
    <collision>
      <origin
        xyz="0 0 0"
        rpy="0 0 0" />
      <geometry>
        <mesh
          filename="meshes/torso_link3.obj" />
      </geometry>
    </collision>
  </link>
  <joint
    name="torso_joint3"
    type="revolute">
    <origin
      xyz="0 0.0001005 0.3"
      rpy="0 0 0" />
    <parent
      link="torso_link2" />
    <child
      link="torso_link3" />
    <axis
      xyz="0 -1 0" />
    <limit
      lower="-1.8326"
      upper="1.5708"
      effort="100"
      velocity="2.5" />
  </joint>
  <link
    name="torso_link4">
    <inertial>
      <origin
        xyz="0.0049601 -1.2497E-05 0.21237"
        rpy="0 0 0" />
      <mass
        value="5" />
      <inertia
        ixx="0.026836"
        ixy="1.3048E-05"
        ixz="-0.00014074"
        iyy="0.013023"
        iyz="4.6641E-07"
        izz="0.021541" />
    </inertial>
    <visual>
      <origin
        xyz="0 0 0"
        rpy="0 0 0" />
      <geometry>
        <mesh
          filename="meshes/torso_link4.obj" />
      </geometry>
    </visual>
    <collision>
      <origin
        xyz="0 0 0"
        rpy="0 0 0" />
      <geometry>
        <mesh
          filename="meshes/torso_link4.obj" />
      </geometry>
    </collision>
  </link>
  <joint
    name="torso_joint4"
    type="revolute">
    <origin
      xyz="0 -0.00010015 0.09962"
      rpy="0 0 0" />
    <parent
      link="torso_link3" />
    <child
      link="torso_link4" />
    <axis
      xyz="0 0 1" />
    <limit
      lower="-3.0543"
      upper="3.0543"
      effort="100"
      velocity="2.5" />
  </joint>
  <link
    name="zed_link">
    <inertial>
      <origin
        xyz="0.060004 0.015906 -0.068413"
        rpy="0 0 0" />
      <mass
        value="2.05" />
      <inertia
        ixx="0.010375"
        ixy="1.8965E-07"
        ixz="1.3342E-08"
        iyy="0.014618"
        iyz="0.00028961"
        izz="0.012229" />
    </inertial>
    <visual>
      <origin
        xyz="0 0 0"
        rpy="0 0 0" />
      <geometry>
        <mesh
          filename="meshes/zed_link.obj" />
      </geometry>
    </visual>
    <collision>
      <origin
        xyz="0 0 0"
        rpy="0 0 0" />
      <geometry>
        <mesh
          filename="meshes/zed_link.obj" />
      </geometry>
    </collision>
  </link>
  <joint
    name="zed_joint"
    type="fixed">
    <origin
      xyz="0.065511 0.060003 0.47598"
      rpy="-1.9199 0 -1.5708" />
    <parent
      link="torso_link4" />
    <child
      link="zed_link" />
    <axis
      xyz="0 0 0" />
  </joint>
  <link
    name="left_arm_base_link">
    <inertial>
      <origin
        xyz="0.00026981 0.034587 1.3734E-08"
        rpy="0 0 0" />
      <mass
        value="1.48" />
      <inertia
        ixx="0.0010298"
        ixy="5.2194E-06"
        ixz="-1.2182E-07"
        iyy="0.0014076"
        iyz="-3.9334E-09"
        izz="0.0010201" />
    </inertial>
    <visual>
      <origin
        xyz="0 0 0"
        rpy="0 0 0" />
      <geometry>
        <mesh
          filename="meshes/left_arm_base_link.obj" />
      </geometry>
    </visual>
    <collision>
      <origin
        xyz="0 0 0"
        rpy="0 0 0" />
      <geometry>
        <mesh
          filename="meshes/left_arm_base_link.obj" />
      </geometry>
    </collision>
  </link>
  <joint
    name="left_arm_base_joint"
    type="fixed">
    <origin
      xyz="-0.00048618 0.097234 0.30302"
      rpy="0 0 0" />
    <parent
      link="torso_link4" />
    <child
      link="left_arm_base_link" />
    <axis
      xyz="0 0 0" />
  </joint>
  <link
    name="left_arm_link1">
    <inertial>
      <origin
        xyz="0.00042258 0.074131 7.9156E-05"
        rpy="0 0 0" />
      <mass
        value="1.135" />
      <inertia
        ixx="0.00061603"
        ixy="-1.1635E-06"
        ixz="-6.9725E-07"
        iyy="0.00030259"
        iyz="-6.2894E-07"
        izz="0.00047136" />
    </inertial>
    <visual>
      <origin
        xyz="0 0 0"
        rpy="0 0 0" />
      <geometry>
        <mesh
          filename="meshes/left_arm_link1.obj" />
      </geometry>
    </visual>
    <collision>
      <origin
        xyz="0 0 0"
        rpy="0 0 0" />
      <geometry>
        <mesh
          filename="meshes/left_arm_link1.obj" />
      </geometry>
    </collision>
  </link>
  <joint
    name="left_arm_joint1"
    type="revolute">
    <origin
      xyz="0 0.0735 0"
      rpy="0 0 0" />
    <parent
      link="left_arm_base_link" />
    <child
      link="left_arm_link1" />
    <axis
      xyz="0 1 0" />
    <limit
      lower="-4.4506"
      upper="1.3090"
      effort="55"
      velocity="7.1209" />
  </joint>
  <link
    name="left_arm_link2">
    <inertial>
      <origin
        xyz="-0.026826 -0.0040392 -0.031835"
        rpy="0 0 0" />
      <mass
        value="0.92" />
      <inertia
        ixx="0.00037378"
        ixy="-7.5909E-07"
        ixz="2.9042E-06"
        iyy="0.00033872"
        iyz="1.2166E-05"
        izz="0.00032361" />
    </inertial>
    <visual>
      <origin
        xyz="0 0 0"
        rpy="0 0 0" />
      <geometry>
        <mesh
          filename="meshes/left_arm_link2.obj" />
      </geometry>
    </visual>
    <collision>
      <origin
        xyz="0 0 0"
        rpy="0 0 0" />
      <geometry>
        <mesh
          filename="meshes/left_arm_link2.obj" />
      </geometry>
    </collision>
  </link>
  <joint
    name="left_arm_joint2"
    type="revolute">
    <origin
      xyz="0.025012 0.081265 0"
      rpy="0 0 0" />
    <parent
      link="left_arm_link1" />
    <child
      link="left_arm_link2" />
    <axis
      xyz="1 0 0" />
    <limit
      lower="-0.1745"
      upper="3.1416"
      effort="55"
      velocity="7.1209" />
  </joint>
  <link
    name="left_arm_link3">
    <inertial>
      <origin
        xyz="0.0053849 -0.00086892 -0.1126"
        rpy="0 0 0" />
      <mass
        value="1.245" />
      <inertia
        ixx="0.00072339"
        ixy="-3.3477E-06"
        ixz="-0.00012824"
        iyy="0.00073856"
        iyz="-8.3574E-06"
        izz="0.00037352" />
    </inertial>
    <visual>
      <origin
        xyz="0 0 0"
        rpy="0 0 0" />
      <geometry>
        <mesh
          filename="meshes/left_arm_link3.obj" />
      </geometry>
    </visual>
    <collision>
      <origin
        xyz="0 0 0"
        rpy="0 0 0" />
      <geometry>
        <mesh
          filename="meshes/left_arm_link3.obj" />
      </geometry>
    </collision>
  </link>
  <joint
    name="left_arm_joint3"
    type="revolute">
    <origin
      xyz="-0.025012 0 -0.1155"
      rpy="0 0 0" />
    <parent
      link="left_arm_link2" />
    <child
      link="left_arm_link3" />
    <axis
      xyz="0 0 1" />
    <limit
      lower="-2.356196"
      upper="2.356196"
      effort="25"
      velocity="8.3776" />
  </joint>
  <link
    name="left_arm_link4">
    <inertial>
      <origin
        xyz="-0.0011018 -0.036243 -0.042164"
        rpy="0 0 0" />
      <mass
        value="0.827" />
      <inertia
        ixx="0.00013884"
        ixy="7.8394E-08"
        ixz="3.5926E-06"
        iyy="0.00019751"
        iyz="1.4227E-06"
        izz="0.00010229" />
    </inertial>
    <visual>
      <origin
        xyz="0 0 0"
        rpy="0 0 0" />
      <geometry>
        <mesh
          filename="meshes/left_arm_link4.obj" />
      </geometry>
    </visual>
    <collision>
      <origin
        xyz="0 0 0"
        rpy="0 0 0" />
      <geometry>
        <mesh
          filename="meshes/left_arm_link4.obj" />
      </geometry>
    </collision>
  </link>
  <joint
    name="left_arm_joint4"
    type="revolute">
    <origin
      xyz="0 0.035065 -0.1945"
      rpy="0 0 0" />
    <parent
      link="left_arm_link3" />
    <child
      link="left_arm_link4" />
    <axis
      xyz="0 1 0" />
    <limit
      lower="-2.0944"
      upper="0.3491"
      effort="25"
      velocity="8.3776" />
  </joint>
  <link
    name="left_arm_link5">
    <inertial>
      <origin
        xyz="3.7881E-07 -0.0028035 -0.062981"
        rpy="0 0 0" />
      <mass
        value="0.939" />
      <inertia
        ixx="0.00070496"
        ixy="1.4329E-08"
        ixz="-2.9036E-09"
        iyy="0.00067006"
        iyz="-5.1951E-05"
        izz="0.00032998" />
    </inertial>
    <visual>
      <origin
        xyz="0 0 0"
        rpy="0 0 0" />
      <geometry>
        <mesh
          filename="meshes/left_arm_link5.obj" />
      </geometry>
    </visual>
    <collision>
      <origin
        xyz="0 0 0"
        rpy="0 0 0" />
      <geometry>
        <mesh
          filename="meshes/left_arm_link5.obj" />
      </geometry>
    </collision>
  </link>
  <joint
    name="left_arm_joint5"
    type="revolute">
    <origin
      xyz="0 -0.035065 -0.095"
      rpy="0 0 0" />
    <parent
      link="left_arm_link4" />
    <child
      link="left_arm_link5" />
    <axis
      xyz="0 0 1" />
    <limit
      lower="-2.356196"
      upper="2.356196"
      effort="18"
      velocity="10.4720" />
  </joint>
  <link
    name="left_arm_link6">
    <inertial>
      <origin
        xyz="0.0017919 0.027487 0.00025471"
        rpy="0 0 0" />
      <mass
        value="0.527" />
      <inertia
        ixx="8.5442E-05"
        ixy="-1.5351E-07"
        ixz="8.3797E-07"
        iyy="8.1186E-05"
        iyz="-2.1972E-08"
        izz="8.2736E-05" />
    </inertial>
    <visual>
      <origin
        xyz="0 0 0"
        rpy="0 0 0" />
      <geometry>
        <mesh
          filename="meshes/left_arm_link6.obj" />
      </geometry>
    </visual>
    <collision>
      <origin
        xyz="0 0 0"
        rpy="0 0 0" />
      <geometry>
        <mesh
          filename="meshes/left_arm_link6.obj" />
      </geometry>
    </collision>
  </link>
  <joint
    name="left_arm_joint6"
    type="revolute">
    <origin
      xyz="0 -0.028 -0.16305"
      rpy="0 0 0" />
    <parent
      link="left_arm_link5" />
    <child
      link="left_arm_link6" />
    <axis
      xyz="0 1 0" />
    <limit
      lower="-1.047198"
      upper="1.047198"
      effort="18"
      velocity="10.4720" />
  </joint>
  <link
    name="left_arm_link7">
    <inertial>
      <origin
        xyz="-0.022945 8.4007E-07 -0.056525"
        rpy="0 0 0" />
      <mass
        value="0.185" />
      <inertia
        ixx="4.2564E-05"
        ixy="-2.1577E-09"
        ixz="-6.9368E-06"
        iyy="4.5515E-05"
        iyz="-1.9389E-09"
        izz="4.7946E-05" />
    </inertial>
    <visual>
      <origin
        xyz="0 0 0"
        rpy="0 0 0" />
      <geometry>
        <mesh
          filename="meshes/left_arm_link7.obj" />
      </geometry>
    </visual>
    <collision>
      <origin
        xyz="0 0 0"
        rpy="0 0 0" />
      <geometry>
        <mesh
          filename="meshes/left_arm_link7.obj" />
      </geometry>
    </collision>
  </link>
  <joint
    name="left_arm_joint7"
    type="revolute">
    <origin
      xyz="0.0295 0.028 0"
      rpy="0 0 0" />
    <parent
      link="left_arm_link6" />
    <child
      link="left_arm_link7" />
    <axis
      xyz="1 0 0" />
    <limit
      lower="-1.5708"
      upper="1.5708"
      effort="18"
      velocity="10.4720" />
  </joint>
  <link
    name="left_gripper_link">
    <inertial>
      <origin
        xyz="-2.2589E-07 -5.2175E-08 0.031107"
        rpy="0 0 0" />
      <mass
        value="0.24625" />
      <inertia
        ixx="0.00016511"
        ixy="9.5318E-07"
        ixz="5.0942E-10"
        iyy="9.8651E-05"
        iyz="-1.8604E-10"
        izz="0.00017588" />
    </inertial>
    <visual>
      <origin
        xyz="0 0 0"
        rpy="0 0 0" />
      <geometry>
        <mesh
          filename="meshes/left_gripper_link.obj" />
      </geometry>
    </visual>
    <collision>
      <origin
        xyz="0 0 0"
        rpy="0 0 0" />
      <geometry>
        <mesh
          filename="meshes/left_gripper_link.obj" />
      </geometry>
    </collision>
  </link>
  <joint
    name="left_gripper_joint"
    type="fixed">
    <origin
      xyz="-0.0295 0 -0.16065"
      rpy="0 0 0" />
    <parent
      link="left_arm_link7" />
    <child
      link="left_gripper_link" />
    <axis
      xyz="0 0 0" />
  </joint>
  <link
    name="left_realsense_link">
    <inertial>
      <origin
        xyz="0.0058264 -0.02222 -0.017353"
        rpy="0 0 0" />
      <mass
        value="0.175" />
      <inertia
        ixx="2.3234E-05"
        ixy="-2.801E-06"
        ixz="-1.4377E-06"
        iyy="7.0119E-06"
        iyz="-1.2674E-06"
        izz="2.5513E-05" />
    </inertial>
    <visual>
      <origin
        xyz="0 0 0"
        rpy="0 0 0" />
      <geometry>
        <mesh
          filename="meshes/left_realsense_link.obj" />
      </geometry>
    </visual>
    <collision>
      <origin
        xyz="0 0 0"
        rpy="0 0 0" />
      <geometry>
        <mesh
          filename="meshes/left_realsense_link.obj" />
      </geometry>
    </collision>
  </link>
  <joint
    name="left_realsense_joint"
    type="fixed">
    <origin
      xyz="0.05051 0.0028934 0.0051317"
      rpy="-3.1376 -0.43631 3.1399" />
    <parent
      link="left_gripper_link" />
    <child
      link="left_realsense_link" />
    <axis
      xyz="0 0 0" />
  </joint>
  <link
    name="left_gripper_finger_link1">
    <inertial>
      <origin
        xyz="0.0056571 -0.015027 0.01959"
        rpy="0 0 0" />
      <mass
        value="0.020196" />
      <inertia
        ixx="6.4827E-06"
        ixy="7.3969E-08"
        ixz="-4.4977E-08"
        iyy="5.7129E-06"
        iyz="-3.9973E-07"
        izz="2.4057E-06" />
    </inertial>
    <visual>
      <origin
        xyz="0 0 0"
        rpy="0 0 0" />
      <geometry>
        <mesh
          filename="meshes/left_gripper_finger_link1.obj" />
      </geometry>
    </visual>
    <collision>
      <origin
        xyz="0 0 0"
        rpy="0 0 0" />
      <geometry>
        <mesh
          filename="meshes/left_gripper_finger_link1.obj" />
      </geometry>
    </collision>
  </link>
  <joint
    name="left_gripper_finger_joint1"
    type="prismatic">
    <origin
      xyz="-8.8709E-05 0.013453 -0.03689"
      rpy="0 0 0" />
    <parent
      link="left_gripper_link" />
    <child
      link="left_gripper_finger_link1" />
    <axis
      xyz="0 1 0" />
    <limit
      lower="0"
      upper="0.05"
      effort="100"
      velocity="0.25" />
  </joint>
  <link
    name="left_gripper_finger_link2">
    <inertial>
      <origin
        xyz="-0.0056573 0.015027 0.01959"
        rpy="0 0 0" />
      <mass
        value="0.020196" />
      <inertia
        ixx="6.4827E-06"
        ixy="7.3965E-08"
        ixz="4.5014E-08"
        iyy="5.7129E-06"
        iyz="3.9974E-07"
        izz="2.4057E-06" />
    </inertial>
    <visual>
      <origin
        xyz="0 0 0"
        rpy="0 0 0" />
      <geometry>
        <mesh
          filename="meshes/left_gripper_finger_link2.obj" />
      </geometry>
    </visual>
    <collision>
      <origin
        xyz="0 0 0"
        rpy="0 0 0" />
      <geometry>
        <mesh
          filename="meshes/left_gripper_finger_link2.obj" />
      </geometry>
    </collision>
  </link>
  <joint
    name="left_gripper_finger_joint2"
    type="prismatic">
    <origin
      xyz="8.9046E-05 -0.013453 -0.03689"
      rpy="0 0 0" />
    <parent
      link="left_gripper_link" />
    <child
      link="left_gripper_finger_link2" />
    <axis
      xyz="0 1 0" />
    <limit
      lower="-0.05"
      upper="0"
      effort="100"
      velocity="0.25" />
  </joint>
  <link
    name="right_arm_base_link">
    <inertial>
      <origin
        xyz="-0.00026981 -0.034587 -3.669E-08"
        rpy="0 0 0" />
      <mass
        value="1.48" />
      <inertia
        ixx="0.0010298"
        ixy="5.2194E-06"
        ixz="1.2188E-07"
        iyy="0.0014076"
        iyz="5.1015E-09"
        izz="0.0010201" />
    </inertial>
    <visual>
      <origin
        xyz="0 0 0"
        rpy="0 0 0" />
      <geometry>
        <mesh
          filename="meshes/right_arm_base_link.obj" />
      </geometry>
    </visual>
    <collision>
      <origin
        xyz="0 0 0"
        rpy="0 0 0" />
      <geometry>
        <mesh
          filename="meshes/right_arm_base_link.obj" />
      </geometry>
    </collision>
  </link>
  <joint
    name="right_arm_base_joint"
    type="fixed">
    <origin
      xyz="-0.00048706 -0.097236 0.30302"
      rpy="0 0 0" />
    <parent
      link="torso_link4" />
    <child
      link="right_arm_base_link" />
    <axis
      xyz="0 0 0" />
  </joint>
  <link
    name="right_arm_link1">
    <inertial>
      <origin
        xyz="-0.00042261 -0.074132 7.8365E-05"
        rpy="0 0 0" />
      <mass
        value="1.135" />
      <inertia
        ixx="0.00061603"
        ixy="-1.1635E-06"
        ixz="6.9785E-07"
        iyy="0.00030259"
        iyz="6.2359E-07"
        izz="0.00047135" />
    </inertial>
    <visual>
      <origin
        xyz="0 0 0"
        rpy="0 0 0" />
      <geometry>
        <mesh
          filename="meshes/right_arm_link1.obj" />
      </geometry>
    </visual>
    <collision>
      <origin
        xyz="0 0 0"
        rpy="0 0 0" />
      <geometry>
        <mesh
          filename="meshes/right_arm_link1.obj" />
      </geometry>
    </collision>
  </link>
  <joint
    name="right_arm_joint1"
    type="revolute">
    <origin
      xyz="0 -0.0735 0"
      rpy="0 0 0" />
    <parent
      link="right_arm_base_link" />
    <child
      link="right_arm_link1" />
    <axis
      xyz="0 1 0" />
    <limit
      lower="-4.4506"
      upper="1.3090"
      effort="55"
      velocity="7.1209" />
  </joint>
  <link
    name="right_arm_link2">
    <inertial>
      <origin
        xyz="-0.022361 0.0049527 -0.032732"
        rpy="0 0 0" />
      <mass
        value="0.92" />
      <inertia
        ixx="0.00038179"
        ixy="2.6532E-07"
        ixz="-3.6367E-06"
        iyy="0.00034188"
        iyz="-8.4407E-06"
        izz="0.00032895" />
    </inertial>
    <visual>
      <origin
        xyz="0 0 0"
        rpy="0 0 0" />
      <geometry>
        <mesh
          filename="meshes/right_arm_link2.obj" />
      </geometry>
    </visual>
    <collision>
      <origin
        xyz="0 0 0"
        rpy="0 0 0" />
      <geometry>
        <mesh
          filename="meshes/right_arm_link2.obj" />
      </geometry>
    </collision>
  </link>
  <joint
    name="right_arm_joint2"
    type="revolute">
    <origin
      xyz="0.023988 -0.081265 0"
      rpy="0 0 0" />
    <parent
      link="right_arm_link1" />
    <child
      link="right_arm_link2" />
    <axis
      xyz="1 0 0" />
    <limit
      lower="-3.1416"
      upper="0.1745"
      effort="55"
      velocity="7.1209" />
  </joint>
  <link
    name="right_arm_link3">
    <inertial>
      <origin
        xyz="0.0053839 -0.00087109 -0.11261"
        rpy="0 0 0" />
      <mass
        value="1.245" />
      <inertia
        ixx="0.00072336"
        ixy="-3.3628E-06"
        ixz="-0.00012821"
        iyy="0.00073854"
        iyz="-8.3749E-06"
        izz="0.00037348" />
    </inertial>
    <visual>
      <origin
        xyz="0 0 0"
        rpy="0 0 0" />
      <geometry>
        <mesh
          filename="meshes/right_arm_link3.obj" />
      </geometry>
    </visual>
    <collision>
      <origin
        xyz="0 0 0"
        rpy="0 0 0" />
      <geometry>
        <mesh
          filename="meshes/right_arm_link3.obj" />
      </geometry>
    </collision>
  </link>
  <joint
    name="right_arm_joint3"
    type="revolute">
    <origin
      xyz="-0.023988 0 -0.1155"
      rpy="0 0 0" />
    <parent
      link="right_arm_link2" />
    <child
      link="right_arm_link3" />
    <axis
      xyz="0 0 1" />
    <limit
      lower="-2.356196"
      upper="2.356196"
      effort="25"
      velocity="8.3776" />
  </joint>
  <link
    name="right_arm_link4">
    <inertial>
      <origin
        xyz="-0.00058877 -0.035687 -0.057422"
        rpy="0 0 0" />
      <mass
        value="0.827" />
      <inertia
        ixx="0.00016157"
        ixy="7.8184E-08"
        ixz="3.5925E-06"
        iyy="0.00022024"
        iyz="1.4211E-06"
        izz="0.00012683" />
    </inertial>
    <visual>
      <origin
        xyz="0 0 0"
        rpy="0 0 0" />
      <geometry>
        <mesh
          filename="meshes/right_arm_link4.obj" />
      </geometry>
    </visual>
    <collision>
      <origin
        xyz="0 0 0"
        rpy="0 0 0" />
      <geometry>
        <mesh
          filename="meshes/right_arm_link4.obj" />
      </geometry>
    </collision>
  </link>
  <joint
    name="right_arm_joint4"
    type="revolute">
    <origin
      xyz="0 0.035058 -0.1945"
      rpy="0 0 0" />
    <parent
      link="right_arm_link3" />
    <child
      link="right_arm_link4" />
    <axis
      xyz="0 1 0" />
    <limit
      lower="-2.0944"
      upper="0.3491"
      effort="25"
      velocity="8.3776" />
  </joint>
  <link
    name="right_arm_link5">
    <inertial>
      <origin
        xyz="-2.2815E-07 0.0031762 -0.07334"
        rpy="0 0 0" />
      <mass
        value="0.63" />
      <inertia
        ixx="0.00069134"
        ixy="1.4191E-08"
        ixz="3.837E-09"
        iyy="0.00065644"
        iyz="5.1952E-05"
        izz="0.00031157" />
    </inertial>
    <visual>
      <origin
        xyz="0 0 0"
        rpy="0 0 0" />
      <geometry>
        <mesh
          filename="meshes/right_arm_link5.obj" />
      </geometry>
    </visual>
    <collision>
      <origin
        xyz="0 0 0"
        rpy="0 0 0" />
      <geometry>
        <mesh
          filename="meshes/right_arm_link5.obj" />
      </geometry>
    </collision>
  </link>
  <joint
    name="right_arm_joint5"
    type="revolute">
    <origin
      xyz="0 -0.035058 -0.095"
      rpy="0 0 0" />
    <parent
      link="right_arm_link4" />
    <child
      link="right_arm_link5" />
    <axis
      xyz="0 0 1" />
    <limit
      lower="-2.356196"
      upper="2.356196"
      effort="18"
      velocity="10.4720" />
  </joint>
  <link
    name="right_arm_link6">
    <inertial>
      <origin
        xyz="0.0017914 -0.027486 0.00025485"
        rpy="0 0 0" />
      <mass
        value="0.527" />
      <inertia
        ixx="8.5442E-05"
        ixy="1.5357E-07"
        ixz="8.3693E-07"
        iyy="8.1185E-05"
        iyz="2.2221E-08"
        izz="8.2736E-05" />
    </inertial>
    <visual>
      <origin
        xyz="0 0 0"
        rpy="0 0 0" />
      <geometry>
        <mesh
          filename="meshes/right_arm_link6.obj" />
      </geometry>
    </visual>
    <collision>
      <origin
        xyz="0 0 0"
        rpy="0 0 0" />
      <geometry>
        <mesh
          filename="meshes/right_arm_link6.obj" />
      </geometry>
    </collision>
  </link>
  <joint
    name="right_arm_joint6"
    type="revolute">
    <origin
      xyz="0 0.028001 -0.16305"
      rpy="0 0 0" />
    <parent
      link="right_arm_link5" />
    <child
      link="right_arm_link6" />
    <axis
      xyz="0 1 0" />
    <limit
      lower="-1.047198"
      upper="1.047198"
      effort="18"
      velocity="10.4720" />
  </joint>
  <link
    name="right_arm_link7">
    <inertial>
      <origin
        xyz="-0.022945 2.2938E-07 -0.056523"
        rpy="0 0 0" />
      <mass
        value="0.185" />
      <inertia
        ixx="7.8535E-05"
        ixy="-9.5509E-10"
        ixz="-2.8712E-05"
        iyy="9.467E-05"
        iyz="9.104E-11"
        izz="6.1128E-05" />
    </inertial>
    <visual>
      <origin
        xyz="0 0 0"
        rpy="0 0 0" />
      <geometry>
        <mesh
          filename="meshes/right_arm_link7.obj" />
      </geometry>
    </visual>
    <collision>
      <origin
        xyz="0 0 0"
        rpy="0 0 0" />
      <geometry>
        <mesh
          filename="meshes/right_arm_link7.obj" />
      </geometry>
    </collision>
  </link>
  <joint
    name="right_arm_joint7"
    type="revolute">
    <origin
      xyz="0.0295 -0.028001 0"
      rpy="0 0 0" />
    <parent
      link="right_arm_link6" />
    <child
      link="right_arm_link7" />
    <axis
      xyz="1 0 0" />
    <limit
      lower="-1.5708"
      upper="1.5708"
      effort="18"
      velocity="10.4720" />
  </joint>
  <link
    name="right_gripper_link">
    <inertial>
      <origin
        xyz="-2.2589E-07 -5.2175E-08 0.031107"
        rpy="0 0 0" />
      <mass
        value="0.24625" />
      <inertia
        ixx="0.00016511"
        ixy="9.5318E-07"
        ixz="5.0942E-10"
        iyy="9.8651E-05"
        iyz="-1.8604E-10"
        izz="0.00017588" />
    </inertial>
    <visual>
      <origin
        xyz="0 0 0"
        rpy="0 0 0" />
      <geometry>
        <mesh
          filename="meshes/right_gripper_link.obj" />
      </geometry>
    </visual>
    <collision>
      <origin
        xyz="0 0 0"
        rpy="0 0 0" />
      <geometry>
        <mesh
          filename="meshes/right_gripper_link.obj" />
      </geometry>
    </collision>
  </link>
  <joint
    name="right_gripper_joint"
    type="fixed">
    <origin
      xyz="-0.0295 0 -0.16065"
      rpy="0 0 0" />
    <parent
      link="right_arm_link7" />
    <child
      link="right_gripper_link" />
    <axis
      xyz="0 0 0" />
  </joint>
  <link
    name="right_realsense_link">
    <inertial>
      <origin
        xyz="0.0058264 -0.02222 -0.017353"
        rpy="0 0 0" />
      <mass
        value="0.175" />
      <inertia
        ixx="2.3234E-05"
        ixy="-2.801E-06"
        ixz="-1.4377E-06"
        iyy="7.0119E-06"
        iyz="-1.2674E-06"
        izz="2.5513E-05" />
    </inertial>
    <visual>
      <origin
        xyz="0 0 0"
        rpy="0 0 0" />
      <geometry>
        <mesh
          filename="meshes/right_realsense_link.obj" />
      </geometry>
    </visual>
    <collision>
      <origin
        xyz="0 0 0"
        rpy="0 0 0" />
      <geometry>
        <mesh
          filename="meshes/right_realsense_link.obj" />
      </geometry>
    </collision>
  </link>
  <joint
    name="right_realsense_joint"
    type="fixed">
    <origin
      xyz="0.05051 0.0028934 0.0051317"
      rpy="-3.1376 -0.43631 3.1399" />
    <parent
      link="right_gripper_link" />
    <child
      link="right_realsense_link" />
    <axis
      xyz="0 0 0" />
  </joint>
  <link
    name="right_gripper_finger_link1">
    <inertial>
      <origin
        xyz="0.0056571 -0.015027 0.01959"
        rpy="0 0 0" />
      <mass
        value="0.027" />
      <inertia
        ixx="6.4827E-06"
        ixy="7.3969E-08"
        ixz="-4.4977E-08"
        iyy="5.7129E-06"
        iyz="-3.9973E-07"
        izz="2.4057E-06" />
    </inertial>
    <visual>
      <origin
        xyz="0 0 0"
        rpy="0 0 0" />
      <geometry>
        <mesh
          filename="meshes/right_gripper_finger_link1.obj" />
      </geometry>
    </visual>
    <collision>
      <origin
        xyz="0 0 0"
        rpy="0 0 0" />
      <geometry>
        <mesh
          filename="meshes/right_gripper_finger_link1.obj" />
      </geometry>
    </collision>
  </link>
  <joint
    name="right_gripper_finger_joint1"
    type="prismatic">
    <origin
      xyz="-8.8709E-05 0.013453 -0.03689"
      rpy="0 0 0" />
    <parent
      link="right_gripper_link" />
    <child
      link="right_gripper_finger_link1" />
    <axis
      xyz="0 1 0" />
    <limit
      lower="0"
      upper="0.05"
      effort="100"
      velocity="0.25" />
  </joint>
  <link
    name="right_gripper_finger_link2">
    <inertial>
      <origin
        xyz="-0.0056573 0.015027 0.01959"
        rpy="0 0 0" />
      <mass
        value="0.027" />
      <inertia
        ixx="6.4827E-06"
        ixy="7.3965E-08"
        ixz="4.5014E-08"
        iyy="5.7129E-06"
        iyz="3.9974E-07"
        izz="2.4057E-06" />
    </inertial>
    <visual>
      <origin
        xyz="0 0 0"
        rpy="0 0 0" />
      <geometry>
        <mesh
          filename="meshes/right_gripper_finger_link2.obj" />
      </geometry>
    </visual>
    <collision>
      <origin
        xyz="0 0 0"
        rpy="0 0 0" />
      <geometry>
        <mesh
          filename="meshes/right_gripper_finger_link2.obj" />
      </geometry>
    </collision>
  </link>
  <joint
    name="right_gripper_finger_joint2"
    type="prismatic">
    <origin
      xyz="8.9046E-05 -0.013453 -0.03689"
      rpy="0 0 0" />
    <parent
      link="right_gripper_link" />
    <child
      link="right_gripper_finger_link2" />
    <axis
      xyz="0 1 0" />
    <limit
      lower="-0.05"
      upper="0"
      effort="100"
      velocity="0.25" />
  </joint>
</robot>