<mujoco model="r1_pro_with_gripper">
  <compiler angle="radian"/>


  <default>
    <default class="arm">
      <general biastype="affine" ctrlrange="-6.28319 6.28319"/>
    </default>
  </default>

  <default>
    <default class="base_link">
      <geom contype="0" conaffinity="0"/>
    </default>
  </default>

  <default>
    <default class="galaxea_base">
      <geom material="Material008"/>
    </default>
  </default>


  <default>
    <default class="left_hand">
      <joint damping="0.05" armature="0.0002" frictionloss="0.01"/>
    </default>
    <default class="right_hand">
      <joint damping="0.05" armature="0.0002" frictionloss="0.01"/>
    </default>
    <default class="finger">
      <!-- <joint damping="0.03"/> -->
      <joint damping="0.5" armature="0.0001" frictionloss="0.05"/>
    </default>
    <default class="hand_col">
      <geom friction="1.0 0.005 0.0001" solimp="0.3 0.99 0.001" solref="0.0005 10" priority="2" condim="3" contype="1" conaffinity="1" rgba="1 0 1 0.5" group="3"/>
    </default>
    <default class="hand_visual">
      <geom contype="0" conaffinity="0"/>
    </default>
    <default class="thumb">
      <!-- <joint damping="0.05"/> -->
      <joint damping="1.0" armature="0.0001" frictionloss="0.05"/>
    </default>
  </default>

  <default>
    <default class="base_servo">
      <joint pos="0 0 0" axis="0 0 -1" range="-1.66 1.66" damping="2"/>
      <position ctrlrange="-1.66 1.66" kp="10" kv="1"/>
    </default>
    <default class="base_wheel">
      <velocity ctrlrange="-15 15" kv="1"/>
    </default>
  </default>

  <asset>
    <mesh name="base_link" file="meshes/base_link.obj"/>
    <mesh name="steer_motor_link1" file="meshes/steer_motor_link1.obj"/>
    <mesh name="wheel_motor_link1" file="meshes/wheel_motor_link1.obj"/>
    <mesh name="steer_motor_link2" file="meshes/steer_motor_link2.obj"/>
    <mesh name="wheel_motor_link2" file="meshes/wheel_motor_link2.obj"/>
    <mesh name="steer_motor_link3" file="meshes/steer_motor_link3.obj"/>
    <mesh name="wheel_motor_link3" file="meshes/wheel_motor_link3.obj"/>
    <mesh name="torso_link1" file="meshes/torso_link1.obj"/>
    <mesh name="torso_link2" file="meshes/torso_link2.obj"/>
    <mesh name="torso_link3" file="meshes/torso_link3.obj"/>
    <mesh name="torso_link4" file="meshes/torso_link4.obj"/>
    <mesh name="zed_link" file="meshes/zed_link.obj"/>
    <mesh name="left_arm_base_link" file="meshes/left_arm_base_link.obj"/>
    <mesh name="left_arm_link1" file="meshes/left_arm_link1.obj"/>
    <mesh name="left_arm_link2" file="meshes/left_arm_link2.obj"/>
    <mesh name="left_arm_link3" file="meshes/left_arm_link3.obj"/>
    <mesh name="left_arm_link4" file="meshes/left_arm_link4.obj"/>
    <mesh name="left_arm_link5" file="meshes/left_arm_link5.obj"/>
    <mesh name="left_arm_link6" file="meshes/left_arm_link6.obj"/>
    <mesh name="left_arm_link7" file="meshes/left_arm_link7.obj"/>
    <mesh name="left_gripper_link" file="meshes/left_gripper_link.obj"/>
    <mesh name="left_realsense_link" file="meshes/left_realsense_link.obj"/>
    <mesh name="left_gripper_finger_link1" file="meshes/left_gripper_finger_link1.obj"/>
    <mesh name="left_gripper_finger_link2" file="meshes/left_gripper_finger_link2.obj"/>
    <mesh name="right_arm_base_link" file="meshes/right_arm_base_link.obj"/>
    <mesh name="right_arm_link1" file="meshes/right_arm_link1.obj"/>
    <mesh name="right_arm_link2" file="meshes/right_arm_link2.obj"/>
    <mesh name="right_arm_link3" file="meshes/right_arm_link3.obj"/>
    <mesh name="right_arm_link4" file="meshes/right_arm_link4.obj"/>
    <mesh name="right_arm_link5" file="meshes/right_arm_link5.obj"/>
    <mesh name="right_arm_link6" file="meshes/right_arm_link6.obj"/>
    <mesh name="right_arm_link7" file="meshes/right_arm_link7.obj"/>
    <mesh name="right_gripper_link" file="meshes/right_gripper_link.obj"/>
    <mesh name="right_realsense_link" file="meshes/right_realsense_link.obj"/>
    <mesh name="right_gripper_finger_link1" file="meshes/right_gripper_finger_link1.obj"/>
    <mesh name="right_gripper_finger_link2" file="meshes/right_gripper_finger_link2.obj"/>
    <texture name="Material008_tex" type="2d" file="meshes/output.png"/>
    <material name="Material008" texture="Material008_tex" specular="0.5" shininess="0.25" emission="0"/>

  </asset>

  <worldbody>
  <body name="base_link" childclass="galaxea_base" gravcomp="1">
    <!-- <freejoint name="base_joint"/> -->
      <joint name="base_x" type="slide" axis="1 0 0"/>
    <joint name="base_y" type="slide" axis="0 1 0"/>
    <joint name="base_yaw" type="hinge" axis="0 0 1"/>
    <geom type="mesh" mesh="base_link"/>
    <body name="steer_motor_link1" pos="0.16897 0.28 0.15765" >
      <inertial pos="7.7174e-06 -0.004623 -0.049428" quat="0.707095 -0.000176703 0.000138216 0.707118" mass="50" diaginertia="0.00032908 0.00022164 0.00015872"/>
      <joint name="steer_motor_joint1" pos="0 0 0" axis="0 0 1" range="-3.1416 3.1416" actuatorfrcrange="-50 50"/>
      <geom type="mesh" mesh="steer_motor_link1"/>
      <body name="wheel_motor_link1" pos="0 0 -0.08765">
        <inertial pos="1.6481e-10 -1.6203e-10 -9.455e-10" quat="0.270598 0.653281 0.653281 0.270598" mass="50" diaginertia="0.0020893 0.00126281 0.00126279"/>
        <joint name="wheel_motor_joint1" pos="0 0 0" axis="0 1 0"/>
        <geom type="mesh" mesh="wheel_motor_link1" />
      </body>
    </body>
    <body name="steer_motor_link2" pos="0.16897 -0.28 0.15765" >
      <inertial pos="6.044e-06 0.00010023 -0.052223" quat="0.707092 -0.000520429 0.00047447 0.707122" mass="50" diaginertia="0.00037037 0.0002535 0.000163"/>
      <joint name="steer_motor_joint2" pos="0 0 0" axis="0 0 1" range="-3.1416 3.1416" actuatorfrcrange="-50 50"/>
      <geom type="mesh" mesh="steer_motor_link2"/>
      <body name="wheel_motor_link2" pos="0 0 -0.08765">
        <inertial pos="1.6448e-10 -1.616e-10 -9.4549e-10" quat="0.270598 0.653281 0.653281 0.270598" mass="50" diaginertia="0.0020893 0.00126281 0.00126279"/>
        <joint name="wheel_motor_joint2" pos="0 0 0" axis="0 1 0"/>
        <geom type="mesh" mesh="wheel_motor_link2" />
      </body>
    </body>
    <body name="steer_motor_link3" pos="-0.32703 0 0.15765" >
      <inertial pos="-6.029e-06 -0.00010167 -0.052221" quat="0.707092 0.000512639 -0.000484659 0.707121" mass="50" diaginertia="0.00037036 0.0002535 0.000163"/>
      <joint name="steer_motor_joint3" pos="0 0 0" axis="0 0 1" range="-3.1416 3.1416" actuatorfrcrange="-50 50"/>
      <geom type="mesh" mesh="steer_motor_link3"/>
      <body name="wheel_motor_link3" pos="0 0 -0.08765">
        <inertial pos="-2.443e-09 1.4779e-12 5.1754e-12" quat="0.270598 0.653281 0.653281 0.270598" mass="50" diaginertia="0.0020893 0.00126281 0.00126279"/>
        <joint name="wheel_motor_joint3" pos="0 0 0" axis="0 1 0"/>
        <geom type="mesh" mesh="wheel_motor_link3" />
      </body>
    </body>
    <body name="torso_link1" pos="-0.079032 0 0.34265" gravcomp="1">
      <inertial pos="0.00065636 0.0032244 0.23142" quat="0.999998 0.000695924 0.000862045 0.00193552" mass="5.72" diaginertia="0.10931 0.10736 0.00812171"/>
      <joint name="torso_joint1" pos="0 0 0" axis="0 1 0" range="-1.1345 1.8326" actuatorfrcrange="-500 500" stiffness="50" damping="20" armature="10" frictionloss="50"/>
      <geom type="mesh" mesh="torso_link1" />
      <body name="torso_link2" pos="0 0 0.4" gravcomp="1">
        <inertial pos="0.0052517 0.014411 0.15711" quat="0.707019 -0.00357502 -0.00358594 0.707176" mass="3.5" diaginertia="0.027574 0.0260835 0.00184901"/>
        <joint name="torso_joint2" pos="0 0 0" axis="0 1 0" range="-2.7925 2.5307" actuatorfrcrange="-300 300" stiffness="50" damping="20" armature="10" frictionloss="50"/>
        <geom type="mesh" mesh="torso_link2" />
        <body name="torso_link3" pos="0 0.0001005 0.3" gravcomp="1">
          <inertial pos="-9.8337e-07 -0.0055146 0.020182" quat="0.493716 0.506467 0.494804 0.504882" mass="3.4" diaginertia="0.00230141 0.00170239 0.0016099"/>
          <joint name="torso_joint3" pos="0 0 0" axis="0 -1 0" range="-1.8326 1.5708" actuatorfrcrange="-300 300" stiffness="50" damping="20" armature="10" frictionloss="50"/>
          <geom type="mesh" mesh="torso_link3" />
          <body name="torso_link4" pos="0 -0.00010015 0.09962" gravcomp="1">
            <inertial pos="0.00147021 -6.6903e-06 0.294893" quat="0.999829 -9.15166e-07 -0.0184644 -0.000615691" mass="10.01" diaginertia="0.2007 0.134246 0.0895291"/>
            <joint name="torso_joint4" pos="0 0 0" axis="0 0 1" range="-3.0543 3.0543" actuatorfrcrange="-300 300" stiffness="50" damping="20" armature="10" frictionloss="50"/>
            <geom type="mesh" mesh="torso_link4" />
            <geom pos="0.065511 0.060003 0.47598" quat="0.405568 -0.579235 0.579237 -0.40557" type="mesh" mesh="zed_link"/>
            <geom pos="-0.00048618 0.097234 0.30302" quat="1 0 0 0" type="mesh" mesh="left_arm_base_link" />
            <geom pos="-0.00048706 -0.097236 0.30302" quat="1 0 0 0" type="mesh" mesh="right_arm_base_link" />
            <body name="left_arm_link1" pos="-0.00048618 0.170734 0.30302" gravcomp="1">
              <inertial pos="0.00042258 0.074131 7.9156e-05" quat="0.705776 0.708428 0.000383566 -0.00300782" mass="1.135" diaginertia="0.000616038 0.000471359 0.000302583"/>
              <joint name="left_arm_joint1" pos="0 0 0" axis="0 1 0" range="-4.4506 1.309" actuatorfrcrange="-550 550" armature="0.1" damping="5"/>
              <geom type="mesh" mesh="left_arm_link1" />
              <body name="left_arm_link2" pos="0.025012 0.081265 0" gravcomp="1">
                <inertial pos="-0.026826 -0.0040392 -0.031835" quat="0.967826 0.24999 -0.0279104 0.00629583" mass="0.92" diaginertia="0.000373948 0.000345466 0.000316696"/>
                <joint name="left_arm_joint2" pos="0 0 0" axis="1 0 0" range="-0.1745 3.1416" actuatorfrcrange="-550 550" damping="10"/>
                <geom type="mesh" mesh="left_arm_link2" />
                <body name="left_arm_link3" pos="-0.025012 0 -0.1155" gravcomp="1">
                  <inertial pos="0.0053849 -0.00086892 -0.1126" quat="0.987419 -0.0126124 0.157363 -0.00905809" mass="1.245" diaginertia="0.000765373 0.000738745 0.000331352"/>
                  <joint name="left_arm_joint3" pos="0 0 0" axis="0 0 1" range="-2.3562 2.3562" actuatorfrcrange="-250 250" damping="5"/>
                  <geom type="mesh" mesh="left_arm_link3" />
                  <body name="left_arm_link4" pos="0 0.035065 -0.1945" gravcomp="1">
                    <inertial pos="-0.0011018 -0.036243 -0.042164" quat="0.70731 -0.0289938 -0.0395261 0.705202" mass="0.827" diaginertia="0.000197532 0.000139189 0.000101919"/>
                    <joint name="left_arm_joint4" pos="0 0 0" axis="0 1 0" range="-2.0944 0.3491" actuatorfrcrange="-250 250" damping="5"/>
                    <geom type="mesh" mesh="left_arm_link4" />
                    <body name="left_arm_link5" pos="0 -0.035065 -0.095" gravcomp="1">
                      <inertial pos="3.7881e-07 -0.0028035 -0.062981" quat="0.997254 -0.074061 2.09046e-05 0.000268168" mass="0.939" diaginertia="0.00070496 0.000677819 0.000322221"/>
                      <joint name="left_arm_joint5" pos="0 0 0" axis="0 0 1" range="-2.3562 2.3562" actuatorfrcrange="-180 180" damping="1"/>
                      <geom type="mesh" mesh="left_arm_link5" />
                      <body name="left_arm_link6" pos="0 -0.028 -0.16305" gravcomp="1">
                        <inertial pos="0.0017919 0.027487 0.00025471" quat="0.704102 0.696344 -0.110248 0.0847966" mass="0.527" diaginertia="8.56857e-05 8.24979e-05 8.11804e-05"/>
                        <joint name="left_arm_joint6" pos="0 0 0" axis="0 1 0" range="-1.0472 1.0472" actuatorfrcrange="-180 180" damping="0.5"/>
                        <geom type="mesh" mesh="left_arm_link6" />
                        <body name="left_arm_link7" pos="0.0295 0.028 0" gravcomp="1">
                          <inertial pos="-0.0123271 -0.00555954 -0.109485" quat="0.829618 -0.181097 -0.11049 0.516459" mass="0.60625" diaginertia="0.00127785 0.00106218 0.000514758"/>
                          <joint name="left_arm_joint7" pos="0 0 0" axis="1 0 0" range="-1.5708 1.5708" actuatorfrcrange="-180 180" damping="2" armature="0.1"/>
                          <geom type="mesh" mesh="left_arm_link7" />
                          <geom pos="-0.0295 0 -0.16065" quat="1 0 0 0" type="mesh" mesh="left_gripper_link"/>
                          <geom pos="0.02101 0.0028934 -0.155518" quat="0.21643 -0.000394204 -0.976296 0.00176584" type="mesh" mesh="left_realsense_link"/>
                          <!-- <body name="left_gripper_finger_link1" pos="-0.0295887 0.013453 -0.19754" gravcomp="1">
                            <inertial pos="0.0056571 -0.015027 0.01959" quat="0.996815 -0.0588415 0.00751429 0.0532934" mass="0.020196" diaginertia="6.4915e-06 5.75204e-06 2.35776e-06"/>
                            <joint name="left_gripper_finger_joint1" pos="0 0 0" axis="0 1 0" type="slide" range="0 0.05" actuatorfrcrange="-100 100"/>
                            <geom type="mesh" mesh="left_gripper_finger_link1"/>
                          </body>
                          <body name="left_gripper_finger_link2" pos="-0.029411 -0.013453 -0.19754" gravcomp="1">
                            <inertial pos="-0.0056573 0.015027 0.01959" quat="0.996815 0.0588425 -0.00751885 0.0532936" mass="0.020196" diaginertia="6.4915e-06 5.75204e-06 2.35776e-06"/>
                            <joint name="left_gripper_finger_joint2" pos="0 0 0" axis="0 1 0" type="slide" range="-0.05 0" actuatorfrcrange="-100 100"/>
                            <geom type="mesh" mesh="left_gripper_finger_link2"/>
                          </body> -->
                        </body>
                      </body>
                    </body>
                  </body>
                </body>
              </body>
            </body>
            <body name="right_arm_link1" pos="-0.00048706 -0.170736 0.30302" gravcomp="1">
              <inertial pos="-0.00042261 -0.074132 7.8365e-05" quat="0.708417 0.705787 -0.00300924 0.000384982" mass="1.135" diaginertia="0.000616038 0.000471349 0.000302583"/>
              <joint name="right_arm_joint1" pos="0 0 0" axis="0 1 0" range="-4.4506 1.309" actuatorfrcrange="-550 550" armature="0.1" damping="5"/>
              <geom type="mesh" mesh="right_arm_link1" />
              <body name="right_arm_link2" pos="0.023988 -0.081265 0" gravcomp="1">
                <inertial pos="-0.022361 0.0049527 -0.032732" quat="0.973837 -0.224135 0.0325444 0.0186079" mass="0.92" diaginertia="0.000382057 0.000345953 0.00032461"/>
                <joint name="right_arm_joint2" pos="0 0 0" axis="1 0 0" range="-3.1416 0.1745" actuatorfrcrange="-550 550" damping="10"/>
                <geom type="mesh" mesh="right_arm_link2" />
                <body name="right_arm_link3" pos="-0.023988 0 -0.1155" gravcomp="1">
                  <inertial pos="0.0053839 -0.00087109 -0.11261" quat="0.987422 -0.0126678 0.15733 -0.00924199" mass="1.245" diaginertia="0.000765324 0.000738726 0.00033133"/>
                  <joint name="right_arm_joint3" pos="0 0 0" axis="0 0 1" range="-2.3562 2.3562" actuatorfrcrange="-250 250" damping="5"/>
                  <geom type="mesh" mesh="right_arm_link3"/>
                  <body name="right_arm_link4" pos="0 0.035058 -0.1945" gravcomp="1">
                    <inertial pos="-0.00058877 -0.035687 -0.057422" quat="0.707245 -0.0306329 -0.0413532 0.705093" mass="0.827" diaginertia="0.000220262 0.000161937 0.000126441"/>
                    <joint name="right_arm_joint4" pos="0 0 0" axis="0 1 0" range="-2.0944 0.3491" actuatorfrcrange="-250 250" damping="5"/>
                    <geom type="mesh" mesh="right_arm_link4"/>
                    <body name="right_arm_link5" pos="0 -0.035058 -0.095" gravcomp="1">
                      <inertial pos="-2.2815e-07 0.0031762 -0.07334" quat="0.997325 0.0730935 -2.18067e-05 0.000267049" mass="0.63" diaginertia="0.00069134 0.000664096 0.000303914"/>
                      <joint name="right_arm_joint5" pos="0 0 0" axis="0 0 1" range="-2.3562 2.3562" actuatorfrcrange="-180 180" damping="5"/>
                      <geom type="mesh" mesh="right_arm_link5"/>
                      <body name="right_arm_link6" pos="0 0.028001 -0.16305" gravcomp="1">
                        <inertial pos="0.0017914 -0.027486 0.00025485" quat="0.696434 0.70404 -0.0847037 0.110151" mass="0.527" diaginertia="8.56852e-05 8.24984e-05 8.11794e-05"/>
                        <joint name="right_arm_joint6" pos="0 0 0" axis="0 1 0" range="-1.0472 1.0472" actuatorfrcrange="-180 180" damping="0.5"/>
                        <geom type="mesh" mesh="right_arm_link6"/>
                        <body name="right_arm_link7" pos="0.0295 -0.028001 0" gravcomp="1">
                          <inertial pos="-0.0123271 -0.00555972 -0.109485" quat="0.824628 -0.167542 -0.093075 0.532218" mass="0.60625" diaginertia="0.00132489 0.00108229 0.000545999"/>
                          <joint name="right_arm_joint7" pos="0 0 0" axis="1 0 0" range="-1.5708 1.5708" actuatorfrcrange="-180 180" damping="2" armature="0.1"/>
                          <geom type="mesh" mesh="right_arm_link7"/>
                          <geom pos="-0.0295 0 -0.16065" quat="1 0 0 0" type="mesh" mesh="right_gripper_link"/>
                          <geom pos="0.02101 0.0028934 -0.155518" quat="0.21643 -0.000394204 -0.976296 0.00176584" type="mesh" mesh="right_realsense_link"/>
                          <!-- <body name="right_gripper_finger_link1" pos="-0.0295887 0.013453 -0.19754">
                            <inertial pos="0.0056571 -0.015027 0.01959" quat="0.996815 -0.0588415 0.00751429 0.0532934" mass="0.027" diaginertia="6.4915e-06 5.75204e-06 2.35776e-06"/>
                            <joint name="right_gripper_finger_joint1" pos="0 0 0" axis="0 1 0" type="slide" range="0 0.05" actuatorfrcrange="-100 100"/>
                            <geom type="mesh" mesh="right_gripper_finger_link1"/>
                          </body>
                          <body name="right_gripper_finger_link2" pos="-0.029411 -0.013453 -0.19754">
                            <inertial pos="-0.0056573 0.015027 0.01959" quat="0.996815 0.0588425 -0.00751885 0.0532936" mass="0.027" diaginertia="6.4915e-06 5.75204e-06 2.35776e-06"/>
                            <joint name="right_gripper_finger_joint2" pos="0 0 0" axis="0 1 0" type="slide" range="-0.05 0" actuatorfrcrange="-100 100"/>
                            <geom type="mesh" mesh="right_gripper_finger_link2"/>
                          </body> -->
                        </body>
                      </body>
                    </body>
                  </body>
                </body>
              </body>
            </body>
          </body>
        </body>
      </body>
    </body>
  </body>
  </worldbody>



  <contact>
    <exclude body1="torso_link4" body2="left_arm_link1"/>
    <exclude body1="left_arm_link1" body2="left_arm_link2"/>
    <exclude body1="torso_link4" body2="right_arm_link1"/>
    <exclude body1="right_arm_link1" body2="right_arm_link2"/>
    <exclude body1="left_arm_link2" body2="left_arm_link3" />
    <exclude body1="left_arm_link3" body2="left_arm_link4" />
    <exclude body1="left_arm_link3" body2="left_arm_link5" />
    <exclude body1="left_arm_link4" body2="left_arm_link5" />
    <exclude body1="left_arm_link5" body2="left_arm_link6" />
    <exclude body1="left_arm_link6" body2="left_arm_link7" />
    <exclude body1="left_arm_link5" body2="left_arm_link7" />
    <exclude body1="right_arm_link2" body2="right_arm_link3" />
    <exclude body1="right_arm_link3" body2="right_arm_link4" />
    <exclude body1="right_arm_link3" body2="right_arm_link5" />
    <exclude body1="right_arm_link4" body2="right_arm_link5" />
    <exclude body1="right_arm_link5" body2="right_arm_link6" />
    <exclude body1="right_arm_link6" body2="right_arm_link7" />
    <exclude body1="right_arm_link5" body2="right_arm_link7" />
    <exclude body1="base_link" body2="torso_link1" />
    <exclude body1="torso_link1" body2="torso_link2" />
    <exclude body1="torso_link2" body2="torso_link3" />
    <exclude body1="torso_link3" body2="torso_link4" />
    <exclude body1="base_link" body2="steer_motor_link1" />
    <exclude body1="base_link" body2="steer_motor_link2" />
    <exclude body1="base_link" body2="steer_motor_link3" />
    <exclude body1="wheel_motor_link1" body2="steer_motor_link1" />
    <exclude body1="wheel_motor_link1" body2="base_link" />
    <exclude body1="wheel_motor_link2" body2="base_link" />
    <exclude body1="wheel_motor_link3" body2="base_link" />
    <exclude body1="steer_motor_link1" body2="torso_link1" />
    <exclude body1="steer_motor_link2" body2="torso_link1" />
    <exclude body1="steer_motor_link3" body2="torso_link1" />
  </contact>



  <actuator>
    <position name="steer_motor_link1" joint="steer_motor_joint1" class="base_servo"/>
    <position name="steer_motor_link2" joint="steer_motor_joint2" class="base_servo"/>
    <position name="steer_motor_link3" joint="steer_motor_joint3" class="base_servo"/>
    <velocity name="wheel_motor_link1" joint="wheel_motor_joint1" class="base_wheel"/>
    <velocity name="wheel_motor_link2" joint="wheel_motor_joint2" class="base_wheel"/>
    <velocity name="wheel_motor_link3" joint="wheel_motor_joint3" class="base_wheel"/>
    <position class="arm" name="l_actuator_1" joint="left_arm_joint1" ctrlrange="-4.4506 1.309" kp="300" kv="40" />
    <position class="arm" name="l_actuator_2" joint="left_arm_joint2" ctrlrange="-0.1745 3.1416" kp="300" kv="20" />
    <position class="arm" name="l_actuator_3" joint="left_arm_joint3" ctrlrange="-2.3562 2.3562" kp="200" kv="5" />
    <position class="arm" name="l_actuator_4" joint="left_arm_joint4" ctrlrange="-1.7453 0.3491" kp="150" kv="10" />
    <position class="arm" name="l_actuator_5" joint="left_arm_joint5" ctrlrange="-2.3562 2.3562" kp="60" kv="1" />
    <position class="arm" name="l_actuator_6" joint="left_arm_joint6" ctrlrange="-1.0472 1.0472" kp="10" kv="0.4" />
    <position class="arm" name="l_actuator_7" joint="left_arm_joint7" ctrlrange="-1.5708 1.5708" kp="5" kv="0.2" />
    <position class="arm" name="r_actuator_1" joint="right_arm_joint1" ctrlrange="-4.4506 1.309" kp="300" kv="40" />
    <position class="arm" name="r_actuator_2" joint="right_arm_joint2" ctrlrange="-3.1416 0.1745" kp="300" kv="20" />
    <position class="arm" name="r_actuator_3" joint="right_arm_joint3" ctrlrange="-2.3562 2.3562" kp="200" kv="5" />
    <position class="arm" name="r_actuator_4" joint="right_arm_joint4" ctrlrange="-2.0944 0.3491" kp="150" kv="10" />
    <position class="arm" name="r_actuator_5" joint="right_arm_joint5" ctrlrange="-2.3562 2.3562" kp="60" kv="1" />
    <position class="arm" name="r_actuator_6" joint="right_arm_joint6" ctrlrange="-1.0472 1.0472" kp="10" kv="0.4" />
    <position class="arm" name="r_actuator_7" joint="right_arm_joint7" ctrlrange="-1.5708 1.5708" kp="5" kv="0.2" />
    <position name="torso_actuator_1" joint="torso_joint1" ctrlrange="-0.1745 3.1416" kp="5000" kv="800" />
    <position name="torso_actuator_2" joint="torso_joint2" ctrlrange="-0.1745 3.1416" kp="5000" kv="500" />
    <position name="torso_actuator_3" joint="torso_joint3" ctrlrange="-0.1745 3.1416" kp="5000" kv="500" />
    <position name="torso_actuator_4" joint="torso_joint4" ctrlrange="-0.1745 3.1416" kp="5000" kv="500" />
  </actuator>

  <!-- setup scene -->
  <statistic center="1.0 0.7 1.0" extent="0.8"/>
  <visual>
    <headlight diffuse="0.6 0.6 0.6" ambient="0.1 0.1 0.1" specular="0.9 0.9 0.9"/>
    <rgba haze="0.15 0.25 0.35 1"/>
    <global azimuth="-140" elevation="-20" offwidth="2080" offheight="1170"/>
  </visual>
  <asset>
     <texture type="skybox" builtin="gradient" rgb1="1 1 1" rgb2="1 1 1" width="800" height="800"/>
    <texture type="2d" name="groundplane" builtin="checker" mark="edge" rgb1="1 1 1" rgb2="1 1 1" markrgb="0 0 0"
      width="300" height="300"/>
    <material name="groundplane" texture="groundplane" texuniform="true" texrepeat="5 5" reflectance="0"/>
    <texture type="skybox" builtin="gradient" rgb1=".4 .5 .6" rgb2="0 0 0" width="100" height="100"/>
    <texture builtin="flat" height="1278" mark="cross" markrgb="1 1 1" name="texgeom" random="0.01" rgb1="0.8 0.6 0.4" rgb2="0.8 0.6 0.4" type="cube" width="127"/>
    <texture name="texplane" builtin="checker" height="512" width="512" rgb1=".2 .3 .4" rgb2=".1 .15 .2" type="2d" />
    <material name="MatPlane" reflectance="0.5" shininess="0.01" specular="0.1" texrepeat="1 1" texture="texplane" texuniform="true" />
    <material name="geom" texture="texgeom" texuniform="true"/>
  </asset>
   <worldbody>
    <geom name="floor" size="0 0 0.01" type="plane" material="groundplane" contype="1" conaffinity="0" priority="1"
      friction="0.6" condim="3"/>

        <light diffuse=".5 .5 .5" pos="-3 -3 5" dir="3 3 -5" castshadow="true"/>

  </worldbody>

</mujoco>
