<?xml version="1.0" ?>
<robot name="sysID_2XC430">
  <link name="2xc430">
    <visual>
      <origin xyz="0 0 0" rpy="0 -0 0"/>
      <geometry>
        <mesh filename="package:///meshes/2xc430_visual.stl"/>
      </geometry>
      <material name="2xc430_material">
        <color rgba="0.5377843339532841771 0.52643579701664233728 0.51553771127182368428 1.0"/>
      </material>
    </visual>
    <collision>
      <origin xyz="0 0 0" rpy="0 -0 0"/>
      <geometry>
        <mesh filename="package:///meshes/2xc430_collision.stl"/>
      </geometry>
    </collision>
    <inertial>
      <origin xyz="0.075524953696132240966 0.017886243519076062969 0.0056748822304184690438" rpy="0 0 0"/>
      <mass value="0.13164999999836238254"/>
      <inertia ixx="4.5973499788565142952e-05" ixy="-6.3707692171101783292e-06" ixz="-6.4106848464462851079e-07" iyy="4.4966269289965505717e-05" iyz="-1.4151876066262552453e-07" izz="5.894200547616510697e-05"/>
    </inertial>
  </link>

  <link name="arm_430">
    <visual>
      <origin xyz="0 0 0" rpy="0 -0 0"/>
      <geometry>
        <mesh filename="package:///meshes/arm_430_visual.stl"/>
      </geometry>
      <material name="arm_430_material">
        <color rgba="0.63059283987567626983 0.65298952457695413898 0.67418901807298270423 1.0"/>
      </material>
    </visual>
    <collision>
      <origin xyz="0 0 0" rpy="0 -0 0"/>
      <geometry>
        <mesh filename="package:///meshes/arm_430_collision.stl"/>
      </geometry>
    </collision>
    <inertial>
      <origin xyz="-0.077790387031996685585 -1.3637865612687661678e-05 -0.019000000000000103612" rpy="0 0 0"/>
      <mass value="0.25549999999999994937"/>
      <inertia ixx="0.00024426144376379259684" ixy="9.4015858830726081364e-08" ixz="-8.2803592903272644658e-19" iyy="0.00041073874164068111545" iyz="1.4667330776453234728e-16" izz="0.00022084196523238869498"/>
    </inertial>
  </link>

  <joint name="joint_0" type="revolute">
    <origin xyz="0.096000000152447806379 0.032699858643998935825 0.0062193960984139899303" rpy="-1.5707963267948961139 1.0547118733939117296e-15 -1.5707963267948950037"/>
    <parent link="2xc430"/>
    <child link="arm_430"/>
    <axis xyz="0 0 1"/>
    <limit effort="1" velocity="20" lower="-1.570796326794896558" upper="1.570796326794896558"/>
    <joint_properties friction="0.0"/>
  </joint>


</robot>