<?xml version="1.0" ?><robot name="left_leg_reorder">  
  <link name="2xc430">    
    <visual>      
      <origin xyz="0 0 0" rpy="0 -0 0"/>      
      <geometry>        
        <mesh filename="package:///meshes/left_2xc430_visual.stl"/>        
      </geometry>      
      <material name="2xc430_material">        
        <color rgba="0.51698661238356047321 0.50347815951093488618 0.49050589017722012741 1.0"/>        
      </material>      
    </visual>    
    <collision>      
      <origin xyz="0 0 0" rpy="0 -0 0"/>      
      <geometry>        
        <mesh filename="package:///meshes/left_2xc430_collision.stl"/>        
      </geometry>      
    </collision>    
    <inertial>      
      <origin xyz="-0.012000151133967865147 0.00049588831386336226781 0.018504019244503618763" rpy="0 0 0"/>      
      <mass value="0.11059999999836234164"/>      
      <inertia ixx="2.2818802599021433919e-05" ixy="4.6888548259072258494e-08" ixz="4.6520143289445516196e-08" iyy="3.0871666424472358657e-05" iyz="-5.7477343899722563502e-07" izz="3.0871632082341921239e-05"/>      
    </inertial>    
  </link>  

  <link name="hip_yaw_link">    
    <visual>      
      <origin xyz="0 0 0" rpy="0 -0 0"/>      
      <geometry>        
        <mesh filename="package:///meshes/left_hip_yaw_link_visual.stl"/>        
      </geometry>      
      <material name="hip_yaw_link_material">        
        <color rgba="0.61568627450980395466 0.81176470588235283277 0.92941176470588238168 1.0"/>        
      </material>      
    </visual>    
    <collision>      
      <origin xyz="0 0 0" rpy="0 -0 0"/>      
      <geometry>        
        <mesh filename="package:///meshes/left_hip_yaw_link_collision.stl"/>        
      </geometry>      
    </collision>    
    <inertial>      
      <origin xyz="-2.6529777091804280315e-18 -0.015800610849654266737 -0.019005670096647751116" rpy="0 0 0"/>      
      <mass value="0.013199999999999994724"/>      
      <inertia ixx="5.7894615975174157252e-06" ixy="-4.5096954887673693913e-35" ixz="-4.6860781276867837534e-35" iyy="5.0110144042848759377e-06" iyz="1.1826010760651800808e-09" izz="2.7344876354814335894e-06"/>      
    </inertial>    
  </link>  

  <link name="spur_gear_21_teeth">    
    <visual>      
      <origin xyz="0 0 0" rpy="0 -0 0"/>      
      <geometry>        
        <mesh filename="package:///meshes/left_spur_gear_21_teeth_visual.stl"/>        
      </geometry>      
      <material name="spur_gear_21_teeth_material">        
        <color rgba="0.61568627450980395466 0.81176470588235294379 0.9294117647058824927 1.0"/>        
      </material>      
    </visual>    
    <collision>      
      <origin xyz="0 0 0" rpy="0 -0 0"/>      
      <geometry>        
        <mesh filename="package:///meshes/left_spur_gear_21_teeth_collision.stl"/>        
      </geometry>      
    </collision>    
    <inertial>      
      <origin xyz="-4.5505289275732625397e-11 -1.6782160465261941845e-11 -0.00249241020062506086" rpy="0 0 0"/>      
      <mass value="0.0022000000000000001325"/>      
      <inertia ixx="7.0162310059594196881e-08" ixy="3.8801235249534522434e-48" ixz="2.812550158047784253e-36" iyy="7.016231005804746178e-08" iyz="3.6086829965958625889e-39" izz="1.3125544198538289306e-07"/>      
    </inertial>    
  </link>  

  <link name="left_hip_pitch_link">    
    <visual>      
      <origin xyz="0 0 0" rpy="0 -0 0"/>      
      <geometry>        
        <mesh filename="package:///meshes/left_hip_pitch_link_visual.stl"/>        
      </geometry>      
      <material name="left_hip_pitch_link_material">        
        <color rgba="0.79618318075804139777 0.72120748766550990538 0.38540937988910844991 1.0"/>        
      </material>      
    </visual>    
    <collision>      
      <origin xyz="0 0 0" rpy="0 -0 0"/>      
      <geometry>        
        <mesh filename="package:///meshes/left_hip_pitch_link_collision.stl"/>        
      </geometry>      
    </collision>    
    <inertial>      
      <origin xyz="-0.0092773123251564133113 -0.0054583150498874076148 0.03951473811674113823" rpy="0 0 0"/>      
      <mass value="0.15848965119785962674"/>      
      <inertia ixx="8.2188788742760970928e-05" ixy="-1.3373705321924678437e-06" ixz="-9.0917451363903152822e-06" iyy="9.9396334685477745453e-05" iyz="1.298937899441436632e-06" izz="4.5892431466748451869e-05"/>      
    </inertial>    
  </link>  

  <link name="spur_gear_18_teeth">    
    <visual>      
      <origin xyz="0 0 0" rpy="0 -0 0"/>      
      <geometry>        
        <mesh filename="package:///meshes/left_spur_gear_18_teeth_visual.stl"/>        
      </geometry>      
      <material name="spur_gear_18_teeth_material">        
        <color rgba="0.61568627450980395466 0.81176470588235294379 0.92941176470588238168 1.0"/>        
      </material>      
    </visual>    
    <collision>      
      <origin xyz="0 0 0" rpy="0 -0 0"/>      
      <geometry>        
        <mesh filename="package:///meshes/left_spur_gear_18_teeth_collision.stl"/>        
      </geometry>      
    </collision>    
    <inertial>      
      <origin xyz="-7.7520300317166844125e-14 -3.6849386393036389205e-13 0.0017500000000010135486" rpy="0 0 0"/>      
      <mass value="0.0011999999999999998949"/>      
      <inertia ixx="2.9367899810799911435e-08" ixy="7.02382161729363821e-19" ixz="-3.9642189780159722141e-36" iyy="2.9367899814659476616e-08" iyz="7.4779432983140607212e-37" izz="5.6306346207859568346e-08"/>      
    </inertial>    
  </link>  

  <joint name="left_hip_yaw_drive" type="revolute">    
    <origin xyz="-0.019199999999993125344 0.00020000000000295475866 -3.3514857555871913064e-14" rpy="-3.1415926535896550043 -5.0131548558082056583e-13 4.8264233360682142308e-13"/>    
    <parent link="left_hip_pitch_link"/>    
    <child link="spur_gear_18_teeth"/>    
    <axis xyz="0 0 1"/>    
    <limit effort="1" velocity="20" lower="-1.8325957145940461324" upper="1.8325957145940461324"/>    
    <joint_properties friction="0.0"/>    
  </joint>  

  <link name="left_calf_link">    
    <visual>      
      <origin xyz="0 0 0" rpy="0 -0 0"/>      
      <geometry>        
        <mesh filename="package:///meshes/left_calf_link_visual.stl"/>        
      </geometry>      
      <material name="left_calf_link_material">        
        <color rgba="0.61568627450980395466 0.81176470588235283277 0.92941176470588238168 1.0"/>        
      </material>      
    </visual>    
    <collision>      
      <origin xyz="0 0 0" rpy="0 -0 0"/>      
      <geometry>        
        <mesh filename="package:///meshes/left_calf_link_collision.stl"/>        
      </geometry>      
    </collision>    
    <inertial>      
      <origin xyz="-0.0043450054391248908378 0.040752982165250292712 0.0087116093515538506331" rpy="0 0 0"/>      
      <mass value="0.030999999999999996309"/>      
      <inertia ixx="3.3069388685110848712e-05" ixy="-1.3783307153200011406e-06" ixz="-1.2742534026335853803e-07" iyy="7.7316525337312940424e-06" iyz="-7.3356500593809455715e-08" izz="2.8031377753986189355e-05"/>      
    </inertial>    
  </link>  

  <link name="bearing_683">    
    <visual>      
      <origin xyz="0 0 0" rpy="0 -0 0"/>      
      <geometry>        
        <mesh filename="package:///meshes/left_bearing_683_visual.stl"/>        
      </geometry>      
      <material name="bearing_683_material">        
        <color rgba="0.64705882352941179736 0.64705882352941179736 0.64705882352941179736 1.0"/>        
      </material>      
    </visual>    
    <collision>      
      <origin xyz="0 0 0" rpy="0 -0 0"/>      
      <geometry>        
        <mesh filename="package:///meshes/left_bearing_683_collision.stl"/>        
      </geometry>      
    </collision>    
    <inertial>      
      <origin xyz="2.7862896558581284628e-17 -2.4186774283159373987e-19 -0.0015499999999999934403" rpy="0 0 0"/>      
      <mass value="0.00048694686130641793437"/>      
      <inertia ixx="2.1551456503319887385e-09" ixy="1.1914621380619801841e-28" ixz="1.5101308346925888839e-38" iyy="2.1551456503319891521e-09" iyz="1.9510753379696893624e-38" izz="3.5303647444715305817e-09"/>      
    </inertial>    
  </link>  

  <joint name="left_knee_front_rev_2" type="revolute">    
    <origin xyz="-0.0057402514854759043028 -0.013858192987668382923 0.026199999999997631434" rpy="-3.141592653589793116 5.8119982868751027369e-16 -1.5702375052298918057"/>    
    <parent link="left_calf_link"/>    
    <child link="bearing_683"/>    
    <axis xyz="0 0 1"/>    
    <limit effort="1" velocity="20"/>    
    <joint_properties friction="0.0"/>    
  </joint>  

  <link name="bearing_683_2">    
    <visual>      
      <origin xyz="0 0 0" rpy="0 -0 0"/>      
      <geometry>        
        <mesh filename="package:///meshes/left_bearing_683_2_visual.stl"/>        
      </geometry>      
      <material name="bearing_683_2_material">        
        <color rgba="0.64705882352941179736 0.64705882352941179736 0.64705882352941179736 1.0"/>        
      </material>      
    </visual>    
    <collision>      
      <origin xyz="0 0 0" rpy="0 -0 0"/>      
      <geometry>        
        <mesh filename="package:///meshes/left_bearing_683_2_collision.stl"/>        
      </geometry>      
    </collision>    
    <inertial>      
      <origin xyz="-2.7648254672676526986e-17 -2.4186774283159783248e-19 -0.0015500000000000003792" rpy="0 0 0"/>      
      <mass value="0.00048694686130641793437"/>      
      <inertia ixx="2.1551456503319887385e-09" ixy="-7.8866825289820444564e-28" ixz="-2.3651432074089930782e-38" iyy="2.1551456503319883249e-09" iyz="-6.4744944073117677257e-39" izz="3.5303647444715305817e-09"/>      
    </inertial>    
  </link>  

  <joint name="left_knee_back_rev_2" type="revolute">    
    <origin xyz="0.005740251485475959814 0.013858192987669604168 0.026199999999998637573" rpy="3.141592653589793116 1.5424497757392420363e-15 -1.5720025997049917876"/>    
    <parent link="left_calf_link"/>    
    <child link="bearing_683_2"/>    
    <axis xyz="0 0 1"/>    
    <limit effort="1" velocity="20"/>    
    <joint_properties friction="0.0"/>    
  </joint>  

  <link name="left_ank_pitch_link">    
    <visual>      
      <origin xyz="0 0 0" rpy="0 -0 0"/>      
      <geometry>        
        <mesh filename="package:///meshes/left_ank_pitch_link_visual.stl"/>        
      </geometry>      
      <material name="left_ank_pitch_link_material">        
        <color rgba="0.70321688500203327621 0.64514870846184446673 0.40484735422826279017 1.0"/>        
      </material>      
    </visual>    
    <collision>      
      <origin xyz="0 0 0" rpy="0 -0 0"/>      
      <geometry>        
        <mesh filename="package:///meshes/left_ank_pitch_link_collision.stl"/>        
      </geometry>      
    </collision>    
    <inertial>      
      <origin xyz="0.01777024189140121585 0.012301334508572171061 0.018813528244421770519" rpy="0 0 0"/>      
      <mass value="0.17676376695067899658"/>      
      <inertia ixx="4.7283316680251603133e-05" ixy="-1.3380598598440868841e-06" ixz="-5.5304058905135221963e-07" iyy="0.00010706456048089208876" iyz="-5.3225137839476522468e-08" izz="0.00012185522397136354139"/>      
    </inertial>    
  </link>  

  <link name="ank_roll_link">    
    <visual>      
      <origin xyz="0 0 0" rpy="0 -0 0"/>      
      <geometry>        
        <mesh filename="package:///meshes/left_ank_roll_link_visual.stl"/>        
      </geometry>      
      <material name="ank_roll_link_material">        
        <color rgba="0.61568627450980395466 0.81176470588235294379 0.92941176470588238168 1.0"/>        
      </material>      
    </visual>    
    <collision>      
      <origin xyz="0 0 0" rpy="0 -0 0"/>      
      <geometry>        
        <mesh filename="package:///meshes/left_ank_roll_link_collision.stl"/>        
      </geometry>      
    </collision>    
    <inertial>      
      <origin xyz="-0.027003066516822105125 -2.005727129968961316e-12 0.033764011359896435593" rpy="0 0 0"/>      
      <mass value="0.042599999999999998979"/>      
      <inertia ixx="3.7284397827464328061e-05" ixy="-5.5173297572831528906e-16" ixz="2.3929183768080734033e-06" iyy="3.7589276943350436312e-05" iyz="5.093485532365750308e-12" izz="1.0090430906786797971e-05"/>      
    </inertial>    
  </link>  

  <joint name="left_ank_roll" type="revolute">    
    <origin xyz="0.022749999999985347915 -7.7438055967604668695e-15 0.019000000000000561579" rpy="-1.5707963267949487385 6.9598897929083939361e-14 1.5707963267951468023"/>    
    <parent link="left_ank_pitch_link"/>    
    <child link="ank_roll_link"/>    
    <axis xyz="0 0 1"/>    
    <limit effort="1" velocity="20" lower="-1.570796326794896558" upper="1.570796326794896558"/>    
    <joint_properties friction="0.0"/>    
  </joint>  

  <joint name="left_ank_pitch" type="revolute">    
    <origin xyz="-1.5860271119798389095e-15 0.099999999999998423483 0.027750000000001679573" rpy="-3.141592653589793116 2.6670249114811232296e-16 -3.8252904387067536217e-14"/>    
    <parent link="left_calf_link"/>    
    <child link="left_ank_pitch_link"/>    
    <axis xyz="0 0 1"/>    
    <limit effort="1" velocity="20" lower="-1.7453292519943295336" upper="0.785398163397448279"/>    
    <joint_properties friction="0.0"/>    
  </joint>  

  <joint name="left_knee" type="revolute">    
    <origin xyz="-9.150119726040088374e-16 -0.0087499999999997267464 0.085949999999997653277" rpy="1.5707963267948872321 4.8975632202997979707e-15 3.141592653589793116"/>    
    <parent link="left_hip_pitch_link"/>    
    <child link="left_calf_link"/>    
    <axis xyz="0 0 1"/>    
    <limit effort="1" velocity="20" lower="-2.0943951023931952626" upper="0"/>    
    <joint_properties friction="0.0"/>    
  </joint>  

  <link name="xm430_plate">    
    <visual>      
      <origin xyz="0 0 0" rpy="0 -0 0"/>      
      <geometry>        
        <mesh filename="package:///meshes/left_xm430_plate_visual.stl"/>        
      </geometry>      
      <material name="xm430_plate_material">        
        <color rgba="0.61568627450980395466 0.81176470588235294379 0.92941176470588227065 1.0"/>        
      </material>      
    </visual>    
    <collision>      
      <origin xyz="0 0 0" rpy="0 -0 0"/>      
      <geometry>        
        <mesh filename="package:///meshes/left_xm430_plate_collision.stl"/>        
      </geometry>      
    </collision>    
    <inertial>      
      <origin xyz="1.2574180636021760909e-18 -2.454297176641402282e-18 0.002527851391958388285" rpy="0 0 0"/>      
      <mass value="0.0027000000000000001429"/>      
      <inertia ixx="1.2887178787151829982e-07" ixy="5.873956255630364624e-08" ixz="1.8999776467072272227e-37" iyy="2.4635091298412544671e-07" iyz="3.1227251026058173467e-36" izz="3.6467998413810321832e-07"/>      
    </inertial>    
  </link>  

  <link name="knee_rod">    
    <visual>      
      <origin xyz="0 0 0" rpy="0 -0 0"/>      
      <geometry>        
        <mesh filename="package:///meshes/left_knee_rod_visual.stl"/>        
      </geometry>      
      <material name="knee_rod_material">        
        <color rgba="0.62051618944235198416 0.78640765248647581664 0.88594253031295022716 1.0"/>        
      </material>      
    </visual>    
    <collision>      
      <origin xyz="0 0 0" rpy="0 -0 0"/>      
      <geometry>        
        <mesh filename="package:///meshes/left_knee_rod_collision.stl"/>        
      </geometry>      
    </collision>    
    <inertial>      
      <origin xyz="0.017534307439465060541 1.9597103348831170378e-05 -0.0015987301647619339435" rpy="0 0 0"/>      
      <mass value="0.0031629468613064179276"/>      
      <inertia ixx="2.4224450180623724587e-08" ixy="-1.9777338984408308296e-10" ixz="4.9178338762830809582e-10" iyy="8.1758888028360200094e-07" iyz="5.4963846751764537446e-13" izz="8.3704884992894945209e-07"/>      
    </inertial>    
  </link>  

  <joint name="left_knee_front_rev_1" type="revolute">    
    <origin xyz="0.013858192987669312735 -0.0057402514854763440552 0.004999999999999997502" rpy="-3.1415926535897784611 -7.4622057945515895608e-15 -3.1410338320247936927"/>    
    <parent link="xm430_plate"/>    
    <child link="knee_rod"/>    
    <axis xyz="0 0 1"/>    
    <limit effort="1" velocity="20"/>    
    <joint_properties friction="0.0"/>    
  </joint>  

  <link name="knee_rod_2">    
    <visual>      
      <origin xyz="0 0 0" rpy="0 -0 0"/>      
      <geometry>        
        <mesh filename="package:///meshes/left_knee_rod_2_visual.stl"/>        
      </geometry>      
      <material name="knee_rod_2_material">        
        <color rgba="0.62051618944235198416 0.78640765248647581664 0.88594253031295022716 1.0"/>        
      </material>      
    </visual>    
    <collision>      
      <origin xyz="0 0 0" rpy="0 -0 0"/>      
      <geometry>        
        <mesh filename="package:///meshes/left_knee_rod_2_collision.stl"/>        
      </geometry>      
    </collision>    
    <inertial>      
      <origin xyz="0.017534287401029989562 -4.2302323075187753124e-05 -0.0015987301647627436257" rpy="0 0 0"/>      
      <mass value="0.0031629468613064179276"/>      
      <inertia ixx="2.4225259089666954163e-08" ixy="4.2691331074777808525e-10" ixz="4.9178282561869325727e-10" iyy="8.1758847582921511072e-07" iyz="-1.1864500396169323768e-12" izz="8.370492543836071811e-07"/>      
    </inertial>    
  </link>  

  <joint name="left_knee_back_rev_1" type="revolute">    
    <origin xyz="-0.013858192987669298857 0.0057402514854763457899 0.0050000000000000044409" rpy="-3.1415926535897775729 -9.0463447639716938948e-15 3.1403863806796916691"/>    
    <parent link="xm430_plate"/>    
    <child link="knee_rod_2"/>    
    <axis xyz="0 0 1"/>    
    <limit effort="1" velocity="20"/>    
    <joint_properties friction="0.0"/>    
  </joint>  

  <joint name="left_knee_act" type="revolute">    
    <origin xyz="-7.4872906434390518473e-16 0.012449999999999808442 0.044499999999998832156" rpy="-1.5707963267948819031 1.5707963267948761299 0"/>    
    <parent link="left_hip_pitch_link"/>    
    <child link="xm430_plate"/>    
    <axis xyz="0 0 1"/>    
    <limit effort="1" velocity="20" lower="-2.0943951023931952626" upper="0"/>    
    <joint_properties friction="0.0"/>    
  </joint>  

  <joint name="left_hip_yaw_driven" type="revolute">    
    <origin xyz="6.1229146868660582384e-18 3.4694469519536141888e-18 -0.0050000000000000044409" rpy="3.1415926535897837901 1.1763977000879646623e-14 2.7749339408464486521e-29"/>    
    <parent link="spur_gear_21_teeth"/>    
    <child link="left_hip_pitch_link"/>    
    <axis xyz="0 0 1"/>    
    <limit effort="1" velocity="20" lower="-1.570796326794896558" upper="1.570796326794896558"/>    
    <joint_properties friction="0.0"/>    
  </joint>  

  <joint name="left_hip_yaw_fixed" type="fixed">    
    <origin xyz="-3.4694469519536141888e-18 -0.027999999999999986705 -0.018999999999999999528" rpy="-1.5707963267948950037 1.570796326794896336 0"/>    
    <parent link="hip_yaw_link"/>    
    <child link="spur_gear_21_teeth"/>    
    <axis xyz="0 0 1"/>    
    <limit effort="1" velocity="20"/>    
    <joint_properties friction="0.0"/>    
  </joint>  

  <joint name="left_hip_roll" type="revolute">    
    <origin xyz="-0.024000000716154074043 0.019000000152474230686 0.019000000152447748397" rpy="-1.5707963267952167463 -1.5707963267948206187 0"/>    
    <parent link="2xc430"/>    
    <child link="hip_yaw_link"/>    
    <axis xyz="0 0 1"/>    
    <limit effort="1" velocity="20" lower="-0.785398163397448279" upper="0.785398163397448279"/>    
    <joint_properties friction="0.0"/>    
  </joint>  


</robot>