<?xml version='1.0' encoding='utf-8'?>
<mujoco model="body_arm">
    
    <body name = "left-base-link" pos = "-0.03779 0 0.3421" euler = "1.5707963 0 0">
        <body name = "left-arm-link1" pos = "0 0 -0.191" euler = "0 0 -1.5707963">
            <inertial pos = "-0.002330 0.008782 0.032870" mass = "0.276944"
                    fullinertia = "0.000595 0.000381 0.000542 -0.000006 -0.000002 0.000053" />
            <joint name = "idx13_left_arm_joint1" type = "hinge" axis = "0 0 1" range = "-2.967 2.967" limited = "true" damping = "10"/>
            <geom type = "mesh" mesh = "left-arm-link1" material = "metalic black"/>

            <body name = "left-arm-link2" pos = "0 0 0" euler = "1.5707963 0 0">
                <inertial pos = "-0.000451 -0.051682 -0.001084" mass = "2.852114"
                        fullinertia = "0.011984 0.002880 0.011709 0.000039 0.000003 0.000140" />
                <joint name = "idx14_left_arm_joint2" type = "hinge" axis = "0 0 1" range = "-0.523598767 1.658062761 " limited = "true" damping = "10"/>
                <geom type = "mesh" mesh = "left-arm-link2" material = "metalic silver"/>

                <body name = "left-arm-link3" pos = "0 -0.154 0" euler = "1.5707963 0 0">
                    <inertial pos = "-0.000673 0.001065 0.079222" mass = "1.310295"
                            fullinertia = "0.002030 0.002186 0.001189 -0.000008 0.000005 0.000018" />
                    <joint name = "idx15_left_arm_joint3" type = "hinge" axis = "0 0 1" range = "-2.967 2.967" limited = "true" damping = "10"/>
                    <geom type = "mesh" mesh = "left-arm-link3" material = "metalic silver"/>

                    <body name = "left-arm-link4" pos = "0 0 0.093" euler = "-1.5707963 0 1.5707963">
                        <inertial pos = "0.000273 -0.066853 -0.007408" mass = "0.677343"
                            fullinertia = "0.000893 0.000508 0.000767 -0.000001 -0.000002 0.000238" />
                        <joint name = "idx16_left_arm_joint4" type = "hinge" axis = "0 0 1" range = "-2.094395067 0" limited = "true" damping = "10"/>
                        <geom type = "mesh" mesh = "left-arm-link4" material = "metalic black"/>

                        <body name = "left-arm-link5" pos = "0  -0.103 0.0" euler = "1.5707963 0 0">
                            <inertial pos = "-0.001962 -0.000002 0.071786" mass = "0.260886"
                                    fullinertia = "0.000638 0.000618 0.000229 0.000000 0.000015 0.000000" />
                            <joint name = "idx17_left_arm_joint5" type = "hinge" axis = "0 0 1" range = "-2.87979 2.87979" limited = "true" damping = "10"/>
                            <geom type = "mesh" mesh = "left-arm-link5" material = "metalic silver"/>


                            <body name = "left_wrist_motor_A" pos = "0.005 0.02245 0.0245" euler = "0 -3.126778944 0">
                                <inertial pos = "0.00013884 0.00055850 -0.05078467" mass = "0.22783320" 
                                    fullinertia = "0.00013539 0.00013685 0.00002895 0 0 0" />
                                <joint name = "idx18_01_left_wrist_motor_A_ball" type = "ball" axis = "0 0 1" limited = "false" damping = "0.5"/>
                                <geom type = "mesh" mesh = "left-wrist-motor-A" material = "metalic black"/>

                                <body name = "left_wrist_rod_A" pos = "0 0.00055 -0.135" euler = "0 3.1415926 0">
                                    <inertial pos = "-0.00000638 0.00010875 -0.00108426" mass = "0.01468271" 
                                        fullinertia = "0.00000055 0.00000092 0.00000049 0.00000002 0.00000000 0.00000000" />
                                    <joint name = "idx18_01_left_wrist_rod_A_joint" type = "slide" axis = "0 0 1" range = "-0.01199 0.01204" limited = "true" damping = "0.5"/>
                                    <geom type = "mesh" mesh = "left-wrist-rod-A" material = "metalic black"/>
                                </body>
                            </body>

                            <body name = "left_wrist_motor_B" pos = "0.005 -0.02245 0.0245" euler = "0 -3.126778944 0">
                                <inertial pos = "0.00013884 0.00055850 -0.05078467" mass = "0.22783320" 
                                    fullinertia = "0.00013539 0.00013685 0.00002895 0 0 0" />
                                <joint name = "idx19_01_left_wrist_motor_B_ball" type = "ball" axis = "0 0 1" limited = "false" damping = "0.5"/>
                                <geom type = "mesh" mesh = "left-wrist-motor-B" material = "metalic black"/>

                                <body name = "left_wrist_rod_B" pos = "0 0.00055 -0.135" euler = "0 3.1415926 0">
                                    <inertial pos = "-0.00000638 0.00010875 -0.00108426" mass = "0.01468271" 
                                        fullinertia = "0.00000055 0.00000092 0.00000049 0.00000002 0.00000000 0.00000000" />
                                    <joint name = "idx19_01_left_wrist_rod_B_joint" type = "slide" axis = "0 0 1" range = "-0.01199 0.01204" limited = "true" damping = "0.5"/>
                                    <geom type = "mesh" mesh = "left-wrist-rod-B" material = "metalic black" />
                                </body>
                            </body>

                            <body name = "left-arm-link6" pos = "-0.01 0 0.1595" euler = "-1.5707963 1.5707963 0">
                                <inertial pos = "0.00018011 -0.00021701 0.00000000" mass = "0.02504627"
                                        fullinertia = "0.00000197 0.00000173 0.00000071 0 0 0" />
                                <joint name = "idx18_left_arm_joint6" type = "hinge" axis = "0 0 1" range = "-0.7854 0.7854" limited = "true" damping = "0.5"/>
                                <geom type = "mesh" mesh = "left-arm-link6" material = "metalic black"/>

                                <body name = "left-arm-link7" pos = "0 0 0" euler = "1.5707963 0 0">
                                    <inertial pos = "-0.01211757 -0.00009712 0.00886324" mass = "0.05050219" 
                                        fullinertia = "0.00000828 0.00001140 0.00001294 0.00000006 -0.00000179 0.00000004" />
                                    <joint name = "idx19_left_arm_joint7" type = "hinge" axis = "0 0 1" range = "-0.5236 0.5236" limited = "true" damping = "0.5"/>
                                    <geom type = "mesh" mesh = "left-arm-link7" material = "metalic black"/>
                                
                                    <include file = "hand_left.xml" />
                                </body>
                            </body>
                        </body>
                    </body>
                </body>
            </body>
        </body>
    </body>

    <body name = "right-base-link" pos = "-0.03779 0 0.3421" euler = "1.5707963 0 0">   
        <body name = "right-arm-link1" pos = "-0.0 0.0 0.191" euler = "0   0  -1.5707963">
            <inertial pos = "-0.002330 0.008782 -0.032870" mass = "0.276944"
                    fullinertia = "0.000595 0.000381 0.000542 -0.000006 0.000002 -0.000053" />
            <joint name = "idx20_right_arm_joint1" type = "hinge" axis = "0 0 1" range = "-2.967 2.967" limited = "true" damping = "10"/>
            <geom type = "mesh" mesh = "right-arm-link1" material = "metalic black"/>

            <body name = "right-arm-link2" pos = "0 0 0.0" euler = "1.5707963 0 0">
                <inertial pos = "-0.000451 0.051682 -0.001084" mass = "2.852114"
                        fullinertia = "0.011984 0.002880 0.011709 -0.000039 0.000003 -0.000140" />
                <joint name = "idx21_right_arm_joint2" type = "hinge" axis = "0 0 1" range = "-1.658062761 0.523598767 " limited = "true" damping = "10"/>
                <geom type = "mesh" mesh = "right-arm-link2" material = "metalic silver"/>

                <body name = "right-arm-link3" pos = "0 0.154  0" euler = "1.5707963 0 0">
                    <inertial pos = "-0.000673 0.001065 -0.079222" mass = "1.310295"
                            fullinertia = "0.002030 0.002186 0.001189 -0.000008 -0.000005 -0.000018" />
                    <joint name = "idx22_right_arm_joint3" type = "hinge" axis = "0 0 1" range = "-2.967 2.967" limited = "true" damping = "10"/>
                    <geom type = "mesh" mesh = "right-arm-link3" material = "metalic silver"/>

                    <body name = "right-arm-link4" pos = "0 0 -0.093" euler = "-1.5707963 0 1.5707963">
                        <inertial pos = "0.000273 0.066853 -0.007408" mass = "0.677343"
                            fullinertia = "0.000893 0.000508 0.000767 0.000001 -0.000002 -0.000238" />
                        <joint name = "idx23_right_arm_joint4" type = "hinge" axis = "0 0 1" range = "0 2.094395067" limited = "true" damping = "10"/>
                        <geom type = "mesh" mesh = "right-arm-link4" material = "metalic black"/>

                        <body name = "right-arm-link5" pos = "0  0.103 0.0" euler = "1.5707963 0 0">
                            <inertial pos = "-0.001962 -0.000002 -0.071786" mass = "0.260886"
                                    fullinertia = "0.000638 0.000618 0.000229 0.000000 -0.000015 -0.000000" />
                            <joint name = "idx24_right_arm_joint5" type = "hinge" axis = "0 0 1" range = "-2.87979 2.87979" limited = "true" damping = "10"/>
                            <geom type = "mesh" mesh = "right-arm-link5" material = "metalic silver"/>

                            <body name = "right_wrist_motor_A" pos = "0.005 0.02245 -0.0245" euler = "0 -0.01481371 0">
                                <inertial pos = "0.00013884 0.00055850 -0.05078467" mass = "0.22783320" 
                                    fullinertia = "0.00013539 0.00013685 0.00002895 0 0 0" />
                                <joint name = "idx25_01_right_wrist_motor_A_ball" type = "ball" axis = "0 0 1" limited = "false" damping = "0.5"/>
                                <geom type = "mesh" mesh = "right-wrist-motor-A" material = "metalic black"/>

                                <body name = "right_wrist_rod_A" pos = "0 0.00055 -0.135" euler = "0 3.1415926 0">
                                    <inertial pos = "-0.00000638 0.00010875 -0.00108426" mass = "0.01468271" 
                                        fullinertia = "0.00000055 0.00000092 0.00000049 0.00000002 0.00000000 0.00000000" />
                                    <joint name = "idx25_01_right_wrist_rod_A_joint" type = "slide" axis = "0 0 1" range = "-0.01199 0.01204" limited = "true" damping = "0.5"/>
                                    <geom type = "mesh" mesh = "right-wrist-rod-A" material = "metalic black" />
                                </body>
                            </body>

                            <body name = "right_wrist_motor_B" pos = "0.005 -0.02245 -0.0245" euler = "0 -0.01481371 0">
                                <inertial pos = "0.00013884 0.00055850 -0.05078467" mass = "0.22783320" 
                                    fullinertia = "0.00013539 0.00013685 0.00002895 0 0 0" />
                                <joint name = "idx26_01_right_wrist_motor_B_ball" type = "ball" axis = "0 0 1" limited = "false" damping = "0.5"/>
                                <geom type = "mesh" mesh = "right-wrist-motor-B" material = "metalic black"/>

                                <body name = "right_wrist_rod_B" pos = "0 0.00055 -0.135" euler = "0 3.1415926 0">
                                    <inertial pos = "-0.00000638 0.00010875 -0.00108426" mass = "0.01468271" 
                                        fullinertia = "0.00000055 0.00000092 0.00000049 0.00000002 0.00000000 0.00000000" />
                                    <joint name = "idx26_01_right_wrist_rod_B_joint" type = "slide" axis = "0 0 1" range = "-0.01199 0.01204" limited = "true" damping = "0.5"/>
                                    <geom type = "mesh" mesh = "right-wrist-rod-B" material = "metalic black"/>
                                </body>
                            </body>

                            <body name = "right-arm-link6" pos = "-0.01 0 -0.1595" euler = "-1.5707963 1.5707963 0">
                                <inertial pos = "-0.00018011 -0.00021701 0.00000000" mass = "0.02504627"
                                        fullinertia = "0.00000197 0.00000173 0.00000071 0 0 0" />
                                <joint name = "idx25_right_arm_joint6" type = "hinge" axis = "0 0 1" range = "-0.7854 0.7854" limited = "true" damping = "0.5"/>
                                <geom type = "mesh" mesh = "right-arm-link6" material = "metalic black"/>

                                <body name = "right-arm-link7" pos = "0 0 0" euler = "1.5707963 0 0">
                                    <inertial pos = "0.01211757 -0.00009712 0.00886324" mass = "0.05050219" 
                                        fullinertia = "0.00000828 0.00001140 0.00001294 -0.00000006 0.00000179 0.00000004" />
                                    <joint name = "idx26_right_arm_joint7" type = "hinge" axis = "0 0 1" range = "-0.5236 0.5236" limited = "true" damping = "0.5"/>
                                    <geom type = "mesh" mesh = "right-arm-link7" material = "metalic black"/>
                                
                                    <include file = "hand_right.xml" />
                                
                                </body>
                            </body>
                        </body>
                    </body>
                </body>
            </body>
        </body>
    </body>
</mujoco>