<?xml version='1.0' encoding='utf-8'?>
<mujoco model="body_head">
    <body name = "head_yaw" pos = "-0.03779 0 0.4101" euler = "0 0 0">
        <inertial pos = "-0.00154008 0.00649494 0.11627791" mass = "1.39889495"
                    fullinertia = "0.00378192 0.00393150 0.00152438 -0.00000282 0.00029671 -0.00021616" />
        <joint name = "idx27_head_joint1" type = 'hinge' pos = "0 0 0" axis = "0 0 1" damping = '1' limited = "true" range = "-2.2 2.2" />
        <geom type = 'mesh' mesh = 'head-yaw' pos = '0 0 0' euler = '-0 0 -0' material = "metalic black" />
            
        <body name = "head_pitch" pos = "-0.00501 0 0.16059" euler = "1.5708 0 0">
            <inertial pos = "0.03256533 0.02834041 0.00009476" mass = "0.65606942"
                    fullinertia = "0.00350189 0.00369636 0.00360950 0.00039729 -0.00000150 0.00000231" />
            <joint name = "idx28_head_joint2" type = 'hinge' pos = "0 0 0" axis = "0 0 1" damping = '1' limited = "true" range = "-0.5 0.5" />
            <geom type = 'mesh' mesh = 'head-pitch' pos = '0 0 0' euler = '-0 0 -0' material = "metalic black" />
        </body>
    </body>
</mujoco>