<?xml version='1.0' encoding='utf-8'?>
<mujoco model="body_leg">
    <body name = "left_hip_roll" pos = "-0.0808 0.105 -0.0652" euler = "0.7854 0 1.5707963">
        <inertial pos = "0.00011252 0.02130615 -0.07465143" mass = "2.39059365"
                fullinertia = "0.00381223 0.00368166 0.00334373 -0.00000253 0.00000433 0.00019809" />
        <joint name = "idx01_left_hip_roll" type = 'hinge' pos = "0 0 0" axis = "0 0 1" damping = '1' limited = "true" range = "-0.698 0.698" />
        <geom type = 'mesh' mesh = 'left-hip-roll' pos = '0 0 0' euler = '-0 0 -0' material = "metalic black" />
            
        <body name = "left_hip_yaw" pos = "0 -0.017 -0.0682" euler = "1.5707963 -1.5707963 0">
            <inertial pos = "-0.00012288 0.01576460 0.1082870" mass = "3.79911511" 
                    fullinertia = "0.00941292 0.01442888 0.00698406 0.00000766 0.00000238 -0.00055185" />
            <joint name = "idx02_left_hip_yaw" type = 'hinge' pos = "0 0 0" axis = "0 0 1" damping = '1' limited = "true" range = "-1.5707963 1.5707963" />
            <geom type = 'mesh' mesh = 'left-hip-yaw' pos = '0 0 0' euler = '-0 0 -0' material = "metalic black" />

            <body name = "left_hip_pitch" pos = "0 -0.020 0.1205" euler = "1.5707963 0.7854 0">
                <inertial pos = "-0.06943423 0.00469099 0.02228242" mass = "5.92461880"
                        fullinertia = "0.01406779 0.08875802 0.09356940 0.00370132 -0.00808512 0.00067639" />
                <joint name = "idx03_left_hip_pitch" type = 'hinge' pos = "0 0 0" axis = "0 0 1" damping = '1' limited = "true" range = "-1.919862144 0.78539815" />
                <geom type = 'mesh' mesh = 'left-hip-pitch' pos = '0 0 0' euler = '-0 0 -0' material = "metalic silver" />

                <body name = "left_tarsus" pos = "-0.34 0 0" euler = "0 0 0">
                    <inertial pos = "-0.17711952 0.00417209 0.00013325" mass = "3.02166726"
                            fullinertia = "0.00286094 0.02537518 0.02674320 -0.00112212 0.00004708 0.00001928" />
                    <joint name = "idx04_left_tarsus" type = 'hinge' pos = "0 0 0" axis = "0 0 1" damping = '1' limited = "true" range = "-0.087266461 2.443460911" />
                    <geom type = 'mesh' mesh = 'left-knee' pos = '0 0 0' euler = '-0 0 -0' material = "metalic silver" />

                    <body name = "left_toe_A" pos = "-0.138 0 -0.0315" euler = "0 0 -1.5707963">
                        <inertial pos = "0.00009121 -0.01877013 -0.00172194" mass = "0.06362578" 
                                fullinertia = "0.00004436 0.00001212 0.00005103 -0.00000004 -0.00000004 -0.00000800" />
                        <joint name = "idx05_01_left_toe_motorA" type = 'hinge' pos = "0 0 0" axis = "0 0 1" damping = '1' limited = "true" range = "-1.0 1.0" />
                        <geom type = 'mesh' mesh = 'left-toe-A' pos = '0 0 0' euler = '0 0 0' material = "metalic black" />
                        
                        <body name = 'left_toe_A_rod' pos = '0.063 0 0' euler = '-3.1415926535 0 1.5707963'>
                            <inertial pos = "-0.11950000 0.0 -0.00001491" mass = "0.08203113"
                             fullinertia = "0.00000228 0.00078598 0.00078738 0 0 0" />
                            <joint name = 'idx05_01_left_toe_motorA_ball' type = 'ball' axis = '0 0 1' damping = '1' limited = 'false' />
                            <geom type = 'mesh' mesh = 'left-toe-A-rod' pos = '0 0 0' euler = '-0 0 -0' material = "metalic black" />
                        </body>
                    </body>
                    
                    <body name = "left_toe_B" pos = "-0.232 0 0.0315" euler = "0 0 -1.5707963">
                        <inertial pos = "-0.00009121 -0.01877013 0.00172194" mass = "0.06362578" 
                                fullinertia = "0.00004436 0.00001212 0.00005103 0.00000004 -0.00000004 0.000008" />
                        <joint name = "idx06_01_left_toe_motorB" type = 'hinge' pos = "0 0 0" axis = "0 0 1" damping = '1' limited = "true" range = "-1.0 1.0" />
                        <geom type = 'mesh' mesh = 'left-toe-B' pos = '0 0 0' euler = '0 0 0' material = "metalic black" />
                        
                        <body name = 'left_toe_B_rod' pos = '0.063 0 0' euler = '-3.1415926535 0 1.5707963'>
                            <inertial pos = "-0.07250000 0.00000653 -0.00002437" mass = "0.08225550" 
                                fullinertia = "0.00000274 0.00031414 0.00031573 0 0 -0.00000046" />
                            <joint name = 'idx06_01_left_toe_motorB_ball' type = 'ball' axis = '0 0 1' damping = '1' limited = 'false' />
                            <geom type = 'mesh' mesh = 'left-toe-B-rod' pos = '0 0 0' euler = '0 0 0' material = "metalic black" />
                        </body>
                    </body>


                    <body name = "left_toe_pitch" pos = "-0.377 0 0" euler = "0 0 0">
                        <inertial pos = "0 0 0" mass = "0.08772028"
                                fullinertia = "0.00001572 0.00001128 0.00001148 0.0 0.0 0.0" />
                        <joint name = "idx05_left_toe_pitch" type = 'hinge' pos = "0 0 0" axis = "0 0 1" damping = '1' limited = "true" range = "-1.047197533 0.523598767" />
                        <geom type = 'mesh' mesh = 'left-toe-pitch' pos = '0 0 0' euler = '-0 0 -0' material = "metalic black" />

                        <body name = "left_toe_roll" pos = "0 0 0" euler = "-1.5707963 0 0">
                            <inertial pos = "-0.03898340 0.00002335 0.03167314" mass = "1.21058213"
                                    fullinertia = "0.00701152 0.00653210 0.00112114 0.00000021 0.00015476 -0.00000270" />
                            <joint name = "idx06_left_toe_roll" type = 'hinge' pos = "0 0 0" axis = "0 0 1" damping = '1' limited = "true" range = "-0.488692182 0.488692182" />
                            <geom type = 'mesh' mesh = 'left-toe-roll' pos = '0 0 0' euler = '-0 0 -0' material = "metalic black" />
                            <geom type = "sphere" size = "0.002" pos = "-0.059 0 0.175" class = "collision"  />
                            <geom type = "sphere" size = "0.002" pos = "-0.059 0 -0.095" class = "collision"  />
                            <geom type = "sphere" size = "0.002" pos = "-0.059 0.05 0.12" class = "collision"  />
                            <geom type = "sphere" size = "0.002" pos = "-0.059 -0.05 0.12" class = "collision"  />
                            <geom type = "sphere" size = "0.002" pos = "-0.059 0.05 -0.07" class = "collision"  />
                            <geom type = "sphere" size = "0.002" pos = "-0.059 -0.05 -0.07" class = "collision"  />
                            <site name = "left-foot-hl-site" size = "0.002" pos = "-0.059 0.05 0.11" />
                            <site name = "left-foot-hr-site" size = "0.002" pos = "-0.059 -0.05 0.11" />
                            <site name = "left-foot-rl-site" size = "0.002" pos = "-0.059 0.05 -0.048" />
                            <site name = "left-foot-rr-site" size = "0.002" pos = "-0.059 -0.05 -0.048" />
                        </body>
                    </body>
                </body>
            </body>
        </body>
    </body>


    <body name = "right_hip_roll" pos = "-0.0808 -0.105 -0.0652" euler = "0.7854 0 1.5707963">
        <inertial pos = "-0.00011252 0.02130615 -0.07465143" mass = "2.39059365"
                fullinertia = "0.00381223 0.00368166 0.00334373 0.00000253 -0.00000433 0.00019809" />
        <joint name = "idx07_right_hip_roll" type = 'hinge' pos = "0 0 0" axis = "0 0 1" damping = '1' limited = "true" range = "-0.698 0.698" />
        <geom type = 'mesh' mesh = 'right-hip-roll' pos = '0 0 0' euler = '-0 0 -0' material = "metalic black" />

        <body name = "right_hip_yaw" pos = "0 -0.017 -0.0682" euler = "1.5707963 -1.5707963 0">
            <inertial pos = "-0.00012288 -0.01576460 0.10828703" mass = "3.79911511"
                    fullinertia = "0.00941292 0.01442888 0.00698406 -0.00000766 0.00000238 0.00055185" />
            <joint name = "idx08_right_hip_yaw" type = 'hinge' pos = "0 0 0" axis = "0 0 1" damping = '1' limited = "true" range = "-1.5707963 1.5707963" />
            <geom type = 'mesh' mesh = 'right-hip-yaw' pos = '0 0 0' euler = '-0 0 -0' material = "metalic black" />
            
            <body name = "right_hip_pitch" pos = "0 0.020 0.1205" euler = "1.5707963 0.7854 0">
                <inertial pos = "-0.06943423 0.00469099 -0.02228242" mass = "5.92461880"
                        fullinertia = "0.01406779 0.08875802 0.09356940 0.00370132 0.00808512 -0.00067639" />
                <joint name = "idx09_right_hip_pitch" type = 'hinge' pos = "0 0 0" axis = "0 0 1" damping = '1' limited = "true" range = "-1.919862144 0.78539815" />
                <geom type = 'mesh' mesh = 'right-hip-pitch' pos = '0 0 0' euler = '-0 0 -0' material = "metalic silver"/>

                <body name = "right_tarsus" pos = "-0.34 0 0" euler = "0 0 0">
                    <inertial pos = "-0.17711952 0.00417209 -0.00013325" mass = "3.02166726"
                            fullinertia = "0.00286094 0.02537518 0.02674320 -0.00112212 -0.00004708 -0.00001928" />
                    <joint name = "idx10_right_tarsus" type = 'hinge' pos = "0 0 0" axis = "0 0 1" damping = '1' limited = "true" range = "-0.087266461 2.443460911" />
                    <geom type = 'mesh' mesh = 'right-knee' pos = '0 0 0' euler = '-0 0 -0' material = "metalic silver" />

                    <body name = "right_toe_A" pos = "-0.138 0 0.0315" euler = "0 0 -1.5707963">
                        <inertial pos = "-0.00009121 -0.01877013 0.00172194" mass = "0.06362578" 
                                fullinertia = "0.00004436 0.00001212 0.00005103 0.00000004 -0.00000004 0.000008" />
                        <joint name = "idx11_01_right_toe_motorA" type = 'hinge' pos = "0 0 0" axis = "0 0 1" damping = '1' limited = "true" range = "-1.0 1.0" />
                        <geom type = 'mesh' mesh = 'right-toe-A' pos = '0 0 0' euler = '0 0 0' material = "metalic black" />
                        
                        <body name = 'right_toe_A_rod' pos = '0.063 0 0' euler = '-3.1415926535 0 1.5707963'>
                            <inertial pos = "-0.11950000 0.0 0.00001491" mass = "0.08203113"
                             fullinertia = "0.00000228 0.00078598 0.00078738 0 0 0" />
                            <joint name = 'idx11_01_right_toe_motorA_ball' type = 'ball' axis = '0 0 1' damping = '1' limited = 'false' />
                            <geom type = 'mesh' mesh = 'right-toe-A-rod' pos = '0 0 0' euler = '0 0 0' material = "metalic black" />
                        </body>
                    </body>
                    
                    <body name = "right_toe_B" pos = "-0.232 0 -0.0315" euler = "0 0 -1.5707963">
                        <inertial pos = "0.00009121 -0.01877013 -0.00172194" mass = "0.06362578" 
                                fullinertia = "0.00004436 0.00001212 0.00005103 -0.00000004 -0.00000004 -0.00000800" />
                        <joint name = "idx12_01_right_toe_motorB" type = 'hinge' pos = "0 0 0" axis = "0 0 1" damping = '1' limited = "true" range = "-1.0 1.0" />
                        <geom type = 'mesh' mesh = 'right-toe-B' pos = '0 0 0' euler = '0 0 0' material = "metalic black" />

                        <body name = 'right_toe_B_rod' pos = '0.063 0 0' euler = '3.1415926535 0 1.5707963'>
                            <inertial pos = "-0.07250000 0.00000653 0.00002437" mass = "0.08225550" 
                                fullinertia = "0.00000274 0.00031414 0.00031573 0 0 0.00000046" />
                            <joint name = 'idx12_01_right_toe_motorB_ball' type = 'ball' axis = '0 0 1' damping = '1' limited = 'false' />
                            <geom type = 'mesh' mesh = 'right-toe-B-rod' pos = '0 0 0' euler = '0 0 0' material = "metalic black" />
                        </body>
                    </body>

                    <body name = "right_toe_pitch" pos = "-0.377 0 0" euler = "0 0 0">
                        <inertial pos = "0 0 0" mass = "0.08772028"
                                fullinertia = "0.00001572 0.00001128 0.00001148 0.0 0.0 0.0" />
                        <joint name = "idx11_right_toe_pitch" type = 'hinge' pos = "0 0 0" axis = "0 0 1" damping = '1' limited = "true" range = "-1.047197533 0.523598767" />
                        <geom type = 'mesh' mesh = 'right-toe-pitch' pos = '0 0 0' euler = '-0 0 -0' material = "metalic black" />

                        <body name = "right_toe_roll" pos = "0 0 0" euler = "-1.5707963 0 0">
                            <inertial pos = "-0.03898340 -0.00002335 0.03167314" mass = "1.21058213"
                                    fullinertia = "0.00701152 0.00653210 0.00112114 -0.00000021 0.00015476 0.00000270" />
                            <joint name = "idx12_right_toe_roll" type = 'hinge' pos = "0 0 0" axis = "0 0 1" damping = '1' limited = "true" range = "-0.488692182 0.488692182" />
                            <geom type = 'mesh' mesh = 'right-toe-roll' pos = '0 0 0' euler = '-0 0 -0' material = "metalic black" />
                            <geom type = "sphere" size = "0.002" pos = "-0.059 0 0.175" class = "collision"  />
                            <geom type = "sphere" size = "0.002" pos = "-0.059 0 -0.095" class = "collision"  />
                            <geom type = "sphere" size = "0.002" pos = "-0.059 0.05 0.12" class = "collision"  />
                            <geom type = "sphere" size = "0.002" pos = "-0.059 -0.05 0.12" class = "collision"  />
                            <geom type = "sphere" size = "0.002" pos = "-0.059 0.05 -0.07" class = "collision"  />
                            <geom type = "sphere" size = "0.002" pos = "-0.059 -0.05 -0.07" class = "collision"  />
                            <site name = "right-foot-hl-site" size = "0.002" pos = "-0.059 0.05 0.11" />
                            <site name = "right-foot-hr-site" size = "0.002" pos = "-0.059 -0.05 0.11" />
                            <site name = "right-foot-rl-site" size = "0.002" pos = "-0.059 0.05 -0.048" />
                            <site name = "right-foot-rr-site" size = "0.002" pos = "-0.059 -0.05 -0.048" />                          
                        </body>
                    </body>
                </body>
            </body>
        </body>
    </body>
</mujoco>