<mujoco model="hi_25dof_250708">
  <compiler angle="radian" meshdir="meshes/"/>

  <asset>
    <mesh name="base_link" file="base_link.STL"/>
    <mesh name="waist_link" file="waist_link.STL"/>
    <mesh name="l_hip_pitch_link" file="l_hip_pitch_link.STL"/>
    <mesh name="l_hip_roll_link" file="l_hip_roll_link.STL"/>
    <mesh name="l_thigh_link" file="l_thigh_link.STL"/>
    <mesh name="l_calf_link" file="l_calf_link.STL"/>
    <mesh name="l_ankle_pitch_link" file="l_ankle_pitch_link.STL"/>
    <mesh name="l_ankle_roll_link" file="l_ankle_roll_link.STL"/>
    <mesh name="r_hip_pitch_link" file="r_hip_pitch_link.STL"/>
    <mesh name="r_hip_roll_link" file="r_hip_roll_link.STL"/>
    <mesh name="r_thigh_link" file="r_thigh_link.STL"/>
    <mesh name="r_calf_link" file="r_calf_link.STL"/>
    <mesh name="r_ankle_pitch_link" file="r_ankle_pitch_link.STL"/>
    <mesh name="r_ankle_roll_link" file="r_ankle_roll_link.STL"/>
    <mesh name="l_shoulder_pitch_link" file="l_shoulder_pitch_link.STL"/>
    <mesh name="l_shoulder_roll_link" file="l_shoulder_roll_link.STL"/>
    <mesh name="l_upper_arm_link" file="l_upper_arm_link.STL"/>
    <mesh name="l_elbow_link" file="l_elbow_link.STL"/>
    <mesh name="l_wrist_link" file="l_wrist_link.STL"/>
    <mesh name="r_shoulder_pitch_link" file="r_shoulder_pitch_link.STL"/>
    <mesh name="r_shoulder_roll_link" file="r_shoulder_roll_link.STL"/>
    <mesh name="r_upper_arm_link" file="r_upper_arm_link.STL"/>
    <mesh name="r_elbow_link" file="r_elbow_link.STL"/>
    <mesh name="r_wrist_link" file="r_wrist_link.STL"/>
    <mesh name="head_yaw_link" file="head_yaw_link.STL"/>
    <mesh name="head_pitch_link" file="head_pitch_link.STL"/>
  </asset>

  <worldbody>
    <body name="base_link" pos="0 0 0.688">
      <site name="imu" size="0.01" pos="-0.0 -0.0 0.0" />

      <inertial pos="0.007306 0 -0.048481" quat="0.999992 2.41514e-05 -0.00402332 -8.39315e-05" mass="4.80787" diaginertia="0.0458926 0.0316408 0.0186378"/>
      <joint name="floating_base_joint" type="free" limited="false" actuatorfrclimited="false"/>
      <geom type="mesh" contype="0" conaffinity="0" group="1" density="0" rgba="1 1 1 1" mesh="base_link"/>
      <geom type="mesh" rgba="1 1 1 1" mesh="base_link"/>
      <body name="waist_link" pos="0.009 0 -0.2126">
        <inertial pos="0 0 -0.0391895" quat="0.707107 0.707107 0 0" mass="1.35043" diaginertia="0.0022104 0.0019106 0.0010637"/>
        <joint name="waist_joint" pos="0 0 0" axis="0 0 1" range="-3.14 3.14" actuatorfrcrange="-21 21"/>
        <geom type="mesh" contype="0" conaffinity="0" group="1" density="0" rgba="0.79216 0.81961 0.93333 1" mesh="waist_link"/>
        <geom type="mesh" rgba="0.79216 0.81961 0.93333 1" mesh="waist_link"/>
        <body name="l_hip_pitch_link" pos="0 0.0575 -0.04">
          <inertial pos="-0.000511 0.039927 0" quat="0.707082 0.707082 0.005874 0.005874" mass="0.66609" diaginertia="0.00046911 0.0004671 0.00043299"/>
          <joint name="l_hip_pitch_joint" pos="0 0 0" axis="0 1 0" range="-3.14 3.14" actuatorfrcrange="-21 21"/>
          <geom type="mesh" contype="0" conaffinity="0" group="1" density="0" rgba="0.89804 0.91765 0.92941 1" mesh="l_hip_pitch_link"/>
          <geom type="mesh" rgba="0.89804 0.91765 0.92941 1" mesh="l_hip_pitch_link"/>
          <body name="l_hip_roll_link" pos="0.02725 0.042 0">
            <inertial pos="-0.026857 0 -0.075365" quat="0.706985 0.0130968 0.0130968 0.706985" mass="0.7909" diaginertia="0.0015217 0.00131357 0.000681333"/>
            <joint name="l_hip_roll_joint" pos="0 0 0" axis="1 0 0" range="-3.14 3.14" actuatorfrcrange="-21 21"/>
            <geom type="mesh" contype="0" conaffinity="0" group="1" density="0" rgba="0.79216 0.81961 0.93333 1" mesh="l_hip_roll_link"/>
            <geom type="mesh" rgba="0.79216 0.81961 0.93333 1" mesh="l_hip_roll_link"/>
            <body name="l_thigh_link" pos="-0.02725 0 -0.123">
              <inertial pos="0 -0.0018181 -0.032514" quat="0.491506 0.870874 0 0" mass="0.25619" diaginertia="0.0004162 0.000287924 0.000249276"/>
              <joint name="l_thigh_joint" pos="0 0 0" axis="0 0 1" range="-3.14 3.14" actuatorfrcrange="-21 21"/>
              <geom type="mesh" contype="0" conaffinity="0" group="1" density="0" rgba="0.89804 0.91765 0.92941 1" mesh="l_thigh_link"/>
              <geom type="mesh" rgba="0.89804 0.91765 0.92941 1" mesh="l_thigh_link"/>
              <body name="l_calf_link" pos="0 0.03175 -0.069">
                <inertial pos="0.0010782 -0.031083 -0.064513" quat="0.70511 -0.0111865 0.00266066 0.709005" mass="1.6402" diaginertia="0.00650394 0.00644571 0.000895843"/>
                <joint name="l_calf_joint" pos="0 0 0" axis="0 1 0" range="-3.14 3.14" actuatorfrcrange="-21 21"/>
                <geom type="mesh" contype="0" conaffinity="0" group="1" density="0" rgba="1 1 1 1" mesh="l_calf_link"/>
                <geom type="mesh" rgba="1 1 1 1" mesh="l_calf_link"/>
                <body name="l_ankle_pitch_link" pos="0 -0.03175 -0.19945">
                  <inertial pos="-0.0009911 0 0" quat="0.5 0.5 0.5 0.5" mass="0.013231" diaginertia="2.8e-06 2.3e-06 9e-07"/>
                  <joint name="l_ankle_pitch_joint" pos="0 0 0" axis="0 1 0" range="-3.14 3.14" actuatorfrcrange="-21 21"/>
                  <geom type="mesh" contype="0" conaffinity="0" group="1" density="0" rgba="0.89804 0.91765 0.92941 1" mesh="l_ankle_pitch_link"/>
                  <geom type="mesh" rgba="0.89804 0.91765 0.92941 1" mesh="l_ankle_pitch_link"/>
                  <body name="l_ankle_roll_link" pos="0.0215 0 0">
                    <inertial pos="-0.012597 0 -0.028754" quat="0 0.741267 0 0.67121" mass="0.40357" diaginertia="0.000775295 0.000774 0.000142605"/>
                    <joint name="l_ankle_roll_joint" pos="0 0 0" axis="1 0 0" range="-3.14 3.14" actuatorfrcrange="-21 21"/>
                    <geom type="mesh" contype="0" conaffinity="0" group="1" density="0" rgba="0.89804 0.91765 0.92941 1" mesh="l_ankle_roll_link"/>
                    <geom type="mesh" rgba="0.89804 0.91765 0.92941 1" mesh="l_ankle_roll_link"/>
                  </body>
                </body>
              </body>
            </body>
          </body>
        </body>
        <body name="r_hip_pitch_link" pos="0 -0.0575 -0.04">
          <inertial pos="-0.000511 -0.039927 0" quat="0.707082 0.707082 -0.005874 -0.005874" mass="0.66609" diaginertia="0.00046911 0.0004671 0.00043299"/>
          <joint name="r_hip_pitch_joint" pos="0 0 0" axis="0 1 0" range="-3.14 3.14" actuatorfrcrange="-21 21"/>
          <geom type="mesh" contype="0" conaffinity="0" group="1" density="0" rgba="0.89804 0.91765 0.92941 1" mesh="r_hip_pitch_link"/>
          <geom type="mesh" rgba="0.89804 0.91765 0.92941 1" mesh="r_hip_pitch_link"/>
          <body name="r_hip_roll_link" pos="0.02725 -0.042 0">
            <inertial pos="-0.0268572 0 -0.0753647" quat="0.706985 0.0130968 0.0130968 0.706985" mass="0.790903" diaginertia="0.0015217 0.00131357 0.000681333"/>
            <joint name="r_hip_roll_joint" pos="0 0 0" axis="1 0 0" range="-3.14 3.14" actuatorfrcrange="-21 21"/>
            <geom type="mesh" contype="0" conaffinity="0" group="1" density="0" rgba="0.89804 0.91765 0.92941 1" mesh="r_hip_roll_link"/>
            <geom type="mesh" rgba="0.89804 0.91765 0.92941 1" mesh="r_hip_roll_link"/>
            <body name="r_thigh_link" pos="-0.02725 0 -0.123">
              <inertial pos="0 0.0018181 -0.032514" quat="0.870874 0.491506 0 0" mass="0.25619" diaginertia="0.0004162 0.000287924 0.000249276"/>
              <joint name="r_thigh_joint" pos="0 0 0" axis="0 0 1" range="-3.14 3.14" actuatorfrcrange="-21 21"/>
              <geom type="mesh" contype="0" conaffinity="0" group="1" density="0" rgba="0.89804 0.91765 0.92941 1" mesh="r_thigh_link"/>
              <geom type="mesh" rgba="0.89804 0.91765 0.92941 1" mesh="r_thigh_link"/>
              <body name="r_calf_link" pos="0 -0.03175 -0.069">
                <inertial pos="0.0010785 0.0310814 -0.0645143" quat="0.708845 0.00253783 -0.0110549 0.705273" mass="1.64019" diaginertia="0.00650377 0.00644541 0.000895623"/>
                <joint name="r_calf_joint" pos="0 0 0" axis="0 1 0" range="-3.14 3.14" actuatorfrcrange="-21 21"/>
                <geom type="mesh" contype="0" conaffinity="0" group="1" density="0" rgba="1 1 1 1" mesh="r_calf_link"/>
                <geom type="mesh" rgba="1 1 1 1" mesh="r_calf_link"/>
                <body name="r_ankle_pitch_link" pos="0 0.03175 -0.19945">
                  <inertial pos="-0.0009911 0 0" quat="0.5 0.5 0.5 0.5" mass="0.013231" diaginertia="2.8e-06 2.3e-06 9e-07"/>
                  <joint name="r_ankle_pitch_joint" pos="0 0 0" axis="0 1 0" range="-3.14 3.14" actuatorfrcrange="-21 21"/>
                  <geom type="mesh" contype="0" conaffinity="0" group="1" density="0" rgba="0.89804 0.91765 0.92941 1" mesh="r_ankle_pitch_link"/>
                  <geom type="mesh" rgba="0.89804 0.91765 0.92941 1" mesh="r_ankle_pitch_link"/>
                  <body name="r_ankle_roll_link" pos="0.0215 0 0">
                    <inertial pos="-0.012597 0 -0.028754" quat="0 0.741267 0 0.67121" mass="0.40357" diaginertia="0.000775295 0.000774 0.000142605"/>
                    <joint name="r_ankle_roll_joint" pos="0 0 0" axis="1 0 0" range="-3.14 3.14" actuatorfrcrange="-21 21"/>
                    <geom type="mesh" contype="0" conaffinity="0" group="1" density="0" rgba="0.89804 0.91765 0.92941 1" mesh="r_ankle_roll_link"/>
                    <geom type="mesh" rgba="0.89804 0.91765 0.92941 1" mesh="r_ankle_roll_link"/>
                  </body>
                </body>
              </body>
            </body>
          </body>
        </body>
      </body>
      <body name="l_shoulder_pitch_link" pos="0.009 0.11945 0.020657">
        <inertial pos="-0.0007568 0.030935 0" quat="0.48479 0.514761 -0.48479 0.514761" mass="0.39963" diaginertia="0.0002098 0.00019906 0.00018234"/>
        <joint name="l_shoulder_pitch_joint" pos="0 0 0" axis="0 1 0" range="-3.14 3.14" actuatorfrcrange="-21 21"/>
        <geom type="mesh" contype="0" conaffinity="0" group="1" density="0" rgba="0.89804 0.91765 0.92941 1" mesh="l_shoulder_pitch_link"/>
        <geom type="mesh" rgba="0.89804 0.91765 0.92941 1" mesh="l_shoulder_pitch_link"/>
        <body name="l_shoulder_roll_link" pos="0.02335 0.034 0">
          <inertial pos="-0.02515 0 -0.060623" quat="0.702311 -0.0822171 -0.0822171 0.702311" mass="0.45112" diaginertia="0.0004383 0.000383444 0.000240156"/>
          <joint name="l_shoulder_roll_joint" pos="0 0 0" axis="1 0 0" range="-3.14 3.14" actuatorfrcrange="-21 21"/>
          <geom type="mesh" contype="0" conaffinity="0" group="1" density="0" rgba="0.89804 0.91765 0.92941 1" mesh="l_shoulder_roll_link"/>
          <geom type="mesh" rgba="0.89804 0.91765 0.92941 1" mesh="l_shoulder_roll_link"/>
          <body name="l_upper_arm_link" pos="-0.0236 0 -0.0977">
            <inertial pos="0 -0.0007568 -0.030935" quat="0.999551 -0.0299715 0 0" mass="0.39963" diaginertia="0.0002098 0.00019906 0.00018234"/>
            <joint name="l_upper_arm_joint" pos="0 0 0" axis="0 0 1" range="-3.14 3.14" actuatorfrcrange="-21 21"/>
            <geom type="mesh" contype="0" conaffinity="0" group="1" density="0" rgba="0.89804 0.91765 0.92941 1" mesh="l_upper_arm_link"/>
            <geom type="mesh" rgba="0.89804 0.91765 0.92941 1" mesh="l_upper_arm_link"/>
            <body name="l_elbow_link" pos="0 0.02335 -0.034">
              <inertial pos="0 -0.026131 -0.051717" quat="0.989237 0.146325 0 0" mass="0.27632" diaginertia="0.0002914 0.000237433 0.000143967"/>
              <joint name="l_elbow_joint" pos="0 0 0" axis="0 1 0" range="-3.14 3.14" actuatorfrcrange="-21 21"/>
              <geom type="mesh" contype="0" conaffinity="0" group="1" density="0" rgba="0.79216 0.81961 0.93333 1" mesh="l_elbow_link"/>
              <geom type="mesh" rgba="0.79216 0.81961 0.93333 1" mesh="l_elbow_link"/>
              <body name="l_wrist_link" pos="0 -0.0236 -0.0884">
                <inertial pos="0 0 -0.0390078" mass="0.2921" diaginertia="0.0001388 0.0001388 2.21e-05"/>
                <joint name="l_wrist_joint" pos="0 0 0" axis="0 0 1" range="-3.14 3.14" actuatorfrcrange="-21 21"/>
                <geom type="mesh" contype="0" conaffinity="0" group="1" density="0" rgba="0.50196 0.50196 0.50196 1" mesh="l_wrist_link"/>
                <geom type="mesh" rgba="0.50196 0.50196 0.50196 1" mesh="l_wrist_link"/>
              </body>
            </body>
          </body>
        </body>
      </body>
      <body name="r_shoulder_pitch_link" pos="0.009 -0.11945 0.020657">
        <inertial pos="-0.0007568 -0.030935 0" quat="0.514761 0.48479 -0.514761 0.48479" mass="0.39963" diaginertia="0.0002098 0.00019906 0.00018234"/>
        <joint name="r_shoulder_pitch_joint" pos="0 0 0" axis="0 1 0" range="-3.14 3.14" actuatorfrcrange="-21 21"/>
        <geom type="mesh" contype="0" conaffinity="0" group="1" density="0" rgba="0.89804 0.91765 0.92941 1" mesh="r_shoulder_pitch_link"/>
        <geom type="mesh" rgba="0.89804 0.91765 0.92941 1" mesh="r_shoulder_pitch_link"/>
        <body name="r_shoulder_roll_link" pos="0.02335 -0.034 0">
          <inertial pos="-0.02515 0 -0.060623" quat="0.702311 -0.0822171 -0.0822171 0.702311" mass="0.45112" diaginertia="0.0004383 0.000383444 0.000240156"/>
          <joint name="r_shoulder_roll_joint" pos="0 0 0" axis="1 0 0" range="-3.14 3.14" actuatorfrcrange="-21 21"/>
          <geom type="mesh" contype="0" conaffinity="0" group="1" density="0" rgba="0.89804 0.91765 0.92941 1" mesh="r_shoulder_roll_link"/>
          <geom type="mesh" rgba="0.89804 0.91765 0.92941 1" mesh="r_shoulder_roll_link"/>
          <body name="r_upper_arm_link" pos="-0.0236 0 -0.0977">
            <inertial pos="0 0.0007568 -0.030935" quat="0.999551 0.0299715 0 0" mass="0.39963" diaginertia="0.0002098 0.00019906 0.00018234"/>
            <joint name="r_upper_arm_joint" pos="0 0 0" axis="0 0 1" range="-3.14 3.14" actuatorfrcrange="-21 21"/>
            <geom type="mesh" contype="0" conaffinity="0" group="1" density="0" rgba="0.89804 0.91765 0.92941 1" mesh="r_upper_arm_link"/>
            <geom type="mesh" rgba="0.89804 0.91765 0.92941 1" mesh="r_upper_arm_link"/>
            <body name="r_elbow_link" pos="0 -0.02335 -0.034">
              <inertial pos="0 0.026131 -0.051717" quat="0.989237 -0.146325 0 0" mass="0.27632" diaginertia="0.0002914 0.000237433 0.000143967"/>
              <joint name="r_elbow_joint" pos="0 0 0" axis="0 1 0" range="-3.14 3.14" actuatorfrcrange="-21 21"/>
              <geom type="mesh" contype="0" conaffinity="0" group="1" density="0" rgba="0.89804 0.91765 0.92941 1" mesh="r_elbow_link"/>
              <geom type="mesh" rgba="0.89804 0.91765 0.92941 1" mesh="r_elbow_link"/>
              <body name="r_wrist_link" pos="0 0.0236 -0.0884">
                <inertial pos="0 0 -0.0390078" mass="0.2921" diaginertia="0.0001388 0.0001388 2.21e-05"/>
                <joint name="r_wrist_joint" pos="0 0 0" axis="0 0 1" range="-3.14 3.14" actuatorfrcrange="-21 21"/>
                <geom type="mesh" contype="0" conaffinity="0" group="1" density="0" rgba="0.50196 0.50196 0.50196 1" mesh="r_wrist_link"/>
                <geom type="mesh" rgba="0.50196 0.50196 0.50196 1" mesh="r_wrist_link"/>
              </body>
            </body>
          </body>
        </body>
      </body>
      <body name="head_yaw_link" pos="0.009 0 0.1175">
        <inertial pos="2e-05 -0.0015717 0.022694" quat="0.972018 -0.234907 0 0" mass="0.17851" diaginertia="2.2e-05 1.90806e-05 1.34194e-05"/>
        <joint name="head_yaw_joint" pos="0 0 0" axis="0 0 1" range="-3.14 3.14" actuatorfrcrange="-21 21"/>
        <geom type="mesh" contype="0" conaffinity="0" group="1" density="0" rgba="1 1 1 1" mesh="head_yaw_link"/>
        <geom type="mesh" rgba="1 1 1 1" mesh="head_yaw_link"/>
        <body name="head_pitch_link" pos="0 0.0151 0.0255">
          <inertial pos="0.02294 -0.013625 0.031517" quat="0.506593 0.501887 -0.495024 0.496413" mass="0.25396" diaginertia="0.000834371 0.000664755 0.000261174"/>
          <joint name="head_pitch_joint" pos="0 0 0" axis="0 1 0" range="-3.14 3.14" actuatorfrcrange="-21 21"/>
          <geom type="mesh" contype="0" conaffinity="0" group="1" density="0" rgba="0.89804 0.91765 0.92941 1" mesh="head_pitch_link"/>
          <geom type="mesh" rgba="0.89804 0.91765 0.92941 1" mesh="head_pitch_link"/>
        </body>
      </body>
    </body>
  </worldbody>
  <actuator>
      <motor name="l_shoulder_pitch_joint" joint="l_shoulder_pitch_joint" gear="1" ctrllimited="true" ctrlrange="-30 30" />
      <motor name="l_shoulder_roll_joint" joint="l_shoulder_roll_joint" gear="1" ctrllimited="true" ctrlrange="-30 30" />
      <motor name="l_upper_arm_joint" joint="l_upper_arm_joint" gear="1" ctrllimited="true" ctrlrange="-30 30" />
      <motor name="l_elbow_joint" joint="l_elbow_joint" gear="1" ctrllimited="true" ctrlrange="-30 30" />
      <motor name="r_shoulder_pitch_joint" joint="r_shoulder_pitch_joint" gear="1" ctrllimited="true" ctrlrange="-30 30" />
      <motor name="r_shoulder_roll_joint" joint="r_shoulder_roll_joint" gear="1" ctrllimited="true" ctrlrange="-30 30" />
      <motor name="r_upper_arm_joint" joint="r_upper_arm_joint" gear="1" ctrllimited="true" ctrlrange="-30 30" />
      <motor name="r_elbow_joint" joint="r_elbow_joint" gear="1" ctrllimited="true" ctrlrange="-30 30" />
      <motor name="waist_joint" joint="waist_joint" gear="1" ctrllimited="true" ctrlrange="-30 30" />
      <motor name="l_hip_pitch_joint" joint="l_hip_pitch_joint" gear="1" ctrllimited="true" ctrlrange="-30 30" />
      <motor name="l_hip_roll_joint" joint="l_hip_roll_joint" gear="1" ctrllimited="true" ctrlrange="-30 30" />
      <motor name="l_thigh_joint" joint="l_thigh_joint" gear="1" ctrllimited="true" ctrlrange="-30 30" />
      <motor name="l_calf_joint" joint="l_calf_joint" gear="1" ctrllimited="true" ctrlrange="-30 30" />
      <motor name="l_ankle_pitch_joint" joint="l_ankle_pitch_joint" gear="1" ctrllimited="true" ctrlrange="-30 30" />
      <motor name="l_ankle_roll_joint" joint="l_ankle_roll_joint" gear="1" ctrllimited="true" ctrlrange="-30 30" />
      <motor name="r_hip_pitch_joint" joint="r_hip_pitch_joint" gear="1" ctrllimited="true" ctrlrange="-30 30" />
      <motor name="r_hip_roll_joint" joint="r_hip_roll_joint" gear="1" ctrllimited="true" ctrlrange="-30 30" />
      <motor name="r_thigh_joint" joint="r_thigh_joint" gear="1" ctrllimited="true" ctrlrange="-30 30" />
      <motor name="r_calf_joint" joint="r_calf_joint" gear="1" ctrllimited="true" ctrlrange="-30 30" />
      <motor name="r_ankle_pitch_joint" joint="r_ankle_pitch_joint" gear="1" ctrllimited="true" ctrlrange="-30 30" />
      <motor name="r_ankle_roll_joint" joint="r_ankle_roll_joint" gear="1" ctrllimited="true" ctrlrange="-30 30" />
      
      
   </actuator>
   <sensor>
   <!-- Position sensors -->
    <actuatorpos name="l_shoulder_pitch_joint_p" actuator="l_shoulder_pitch_joint" user="13"/>
    <actuatorpos name="l_shoulder_roll_joint_p" actuator="l_shoulder_roll_joint" user="13"/>
    <actuatorpos name="l_upper_arm_joint_p" actuator="l_upper_arm_joint" user="13"/>
    <actuatorpos name="l_elbow_joint_p" actuator="l_elbow_joint" user="13"/>
    <actuatorpos name="r_shoulder_pitch_joint_p" actuator="r_shoulder_pitch_joint" user="13"/>
    <actuatorpos name="r_shoulder_roll_joint_p" actuator="r_shoulder_roll_joint" user="13"/>
    <actuatorpos name="r_upper_arm_joint_p" actuator="r_upper_arm_joint" user="13"/>
    <actuatorpos name="r_elbow_joint_p" actuator="r_elbow_joint" user="13"/>
    <actuatorpos name="waist_joint_p" actuator="waist_joint" user="13"/>
    <actuatorpos name="l_hip_pitch_joint_p" actuator="l_hip_pitch_joint" user="13"/>
    <actuatorpos name="l_hip_roll_joint_p" actuator="l_hip_roll_joint" user="13"/>
    <actuatorpos name="l_thigh_joint_p" actuator="l_thigh_joint" user="13"/>
    <actuatorpos name="l_calf_joint_p" actuator="l_calf_joint" user="13"/>
    <actuatorpos name="l_ankle_pitch_joint_p" actuator="l_ankle_pitch_joint" user="13"/>
    <actuatorpos name="l_ankle_roll_joint_p" actuator="l_ankle_roll_joint" user="13"/>
    
    <actuatorpos name="r_hip_pitch_joint_p" actuator="r_hip_pitch_joint" user="13"/>
    <actuatorpos name="r_hip_roll_joint_p" actuator="r_hip_roll_joint" user="13"/>
    <actuatorpos name="r_thigh_joint_p" actuator="r_thigh_joint" user="13"/>
    <actuatorpos name="r_calf_joint_p" actuator="r_calf_joint" user="13"/>
    <actuatorpos name="r_ankle_pitch_joint_p" actuator="r_ankle_pitch_joint" user="13"/>
    <actuatorpos name="r_ankle_roll_joint_p" actuator="r_ankle_roll_joint" user="13"/>
    
  
    <!-- Velocity sensors -->
    <actuatorvel name="l_shoulder_pitch_joint_v" actuator="l_shoulder_pitch_joint" user="13" noise="1e-3"/>
    <actuatorvel name="l_shoulder_roll_joint_v" actuator="l_shoulder_roll_joint" user="13" noise="1e-3"/>
    <actuatorvel name="l_upper_arm_joint_v" actuator="l_upper_arm_joint" user="13" noise="1e-3"/>
    <actuatorvel name="l_elbow_joint_v" actuator="l_elbow_joint" user="13" noise="1e-3"/>
    <actuatorvel name="r_shoulder_pitch_joint_v" actuator="r_shoulder_pitch_joint" user="13" noise="1e-3"/>
    <actuatorvel name="r_shoulder_roll_joint_v" actuator="r_shoulder_roll_joint" user="13" noise="1e-3"/>
    <actuatorvel name="r_upper_arm_joint_v" actuator="r_upper_arm_joint" user="13" noise="1e-3"/>
    <actuatorvel name="r_elbow_joint_v" actuator="r_elbow_joint" user="13" noise="1e-3"/>
    <actuatorvel name="waist_joint_v" actuator="waist_joint" user="13" noise="1e-3"/>
    <actuatorvel name="l_hip_pitch_joint_v" actuator="l_hip_pitch_joint" user="13" noise="1e-3"/>
    <actuatorvel name="l_hip_roll_joint_v" actuator="l_hip_roll_joint" user="13" noise="1e-3"/>
    <actuatorvel name="l_thigh_joint_v" actuator="l_thigh_joint" user="13" noise="1e-3"/>
    <actuatorvel name="l_calf_joint_v" actuator="l_calf_joint" user="13" noise="1e-3"/>
    <actuatorvel name="l_ankle_pitch_joint_v" actuator="l_ankle_pitch_joint" user="13" noise="1e-3"/>
    <actuatorvel name="l_ankle_roll_joint_v" actuator="l_ankle_roll_joint" user="13" noise="1e-3"/>
    
    
    <actuatorvel name="r_hip_pitch_joint_v" actuator="r_hip_pitch_joint" user="13" noise="1e-3"/>
    <actuatorvel name="r_hip_roll_joint_v" actuator="r_hip_roll_joint" user="13" noise="1e-3"/>
    <actuatorvel name="r_thigh_joint_v" actuator="r_thigh_joint" user="13" noise="1e-3"/>
    <actuatorvel name="r_calf_joint_v" actuator="r_calf_joint" user="13" noise="1e-3"/>
    <actuatorvel name="r_ankle_pitch_joint_v" actuator="r_ankle_pitch_joint" user="13" noise="1e-3"/>
    <actuatorvel name="r_ankle_roll_joint_v" actuator="r_ankle_roll_joint" user="13" noise="1e-3"/>
    

    <!-- Force sensors -->
    <actuatorfrc name="l_shoulder_pitch_joint_f" actuator="l_shoulder_pitch_joint" user="13" noise="1e-3"/>
    <actuatorfrc name="l_shoulder_roll_joint_f" actuator="l_shoulder_roll_joint" user="13" noise="1e-3"/>
    <actuatorfrc name="l_upper_arm_joint_f" actuator="l_upper_arm_joint" user="13" noise="1e-3"/>
    <actuatorfrc name="l_elbow_joint_f" actuator="l_elbow_joint" user="13" noise="1e-3"/>
    <actuatorfrc name="r_shoulder_pitch_joint_f" actuator="r_shoulder_pitch_joint" user="13" noise="1e-3"/>
    <actuatorfrc name="r_shoulder_roll_joint_f" actuator="r_shoulder_roll_joint" user="13" noise="1e-3"/>
    <actuatorfrc name="r_upper_arm_joint_f" actuator="r_upper_arm_joint" user="13" noise="1e-3"/>
    <actuatorfrc name="r_elbow_joint_f" actuator="r_elbow_joint" user="13" noise="1e-3"/>
    <actuatorfrc name="waist_joint_f" actuator="waist_joint" user="13" noise="1e-3"/>
    <actuatorfrc name="l_hip_pitch_joint_f" actuator="l_hip_pitch_joint" user="13" noise="1e-3"/>
    <actuatorfrc name="l_hip_roll_joint_f" actuator="l_hip_roll_joint" user="13" noise="1e-3"/>
    <actuatorfrc name="l_thigh_joint_f" actuator="l_thigh_joint" user="13" noise="1e-3"/>
    <actuatorfrc name="l_calf_joint_f" actuator="l_calf_joint" user="13" noise="1e-3"/>
    <actuatorfrc name="l_ankle_pitch_joint_f" actuator="l_ankle_pitch_joint" user="13" noise="1e-3"/>
    <actuatorfrc name="l_ankle_roll_joint_f" actuator="l_ankle_roll_joint" user="13" noise="1e-3"/>
    
    
    <actuatorfrc name="r_hip_pitch_joint_f" actuator="r_hip_pitch_joint" user="13" noise="1e-3"/>
    <actuatorfrc name="r_hip_roll_joint_f" actuator="r_hip_roll_joint" user="13" noise="1e-3"/>
    <actuatorfrc name="r_thigh_joint_f" actuator="r_thigh_joint" user="13" noise="1e-3"/>
    <actuatorfrc name="r_calf_joint_f" actuator="r_calf_joint" user="13" noise="1e-3"/>
    <actuatorfrc name="r_ankle_pitch_joint_f" actuator="r_ankle_pitch_joint" user="13" noise="1e-3"/>
    <actuatorfrc name="r_ankle_roll_joint_f" actuator="r_ankle_roll_joint" user="13" noise="1e-3"/>
    

    <framequat name='orientation' objtype='site' noise='0.001' objname='imu'/>
    <framepos name='position' objtype='site' noise='0.001' objname='imu'/>
    <gyro name='angular-velocity' site='imu' noise='0.005' cutoff='34.9'/>
    <velocimeter name='linear-velocity' site='imu' noise='0.001' cutoff='30'/>
    <accelerometer name='linear-acceleration' site='imu' noise='0.005' cutoff='157'/>
    <magnetometer name='magnetometer' site='imu'/>

  </sensor>
    <!-- setup scene -->
  !-- setup scene -->
    <statistic center="1.0 0.7 1.0" extent="0.8"/>
    <visual>
        <headlight diffuse="0.6 0.6 0.6" ambient="0.1 0.1 0.1" specular="0.9 0.9 0.9"/>
        <rgba haze="0.15 0.25 0.35 1"/>
        <global azimuth="-140" elevation="-20" offwidth="2080" offheight="1170"/>
    </visual>
    <asset>
         <texture type="skybox" builtin="gradient" rgb1="1 1 1" rgb2="1 1 1" width="800" height="800"/>
    <texture type="2d" name="groundplane" builtin="checker" mark="edge" rgb1="1 1 1" rgb2="1 1 1" markrgb="0 0 0"
      width="300" height="300"/>
    <material name="groundplane" texture="groundplane" texuniform="true" texrepeat="5 5" reflectance="0"/>
        <texture type="skybox" builtin="gradient" rgb1=".4 .5 .6" rgb2="0 0 0" width="100" height="100"/>
        <texture builtin="flat" height="1278" mark="cross" markrgb="1 1 1" name="texgeom" random="0.01" rgb1="0.8 0.6 0.4" rgb2="0.8 0.6 0.4" type="cube" width="127"/>
        <texture name="texplane" builtin="checker" height="512" width="512" rgb1=".2 .3 .4" rgb2=".1 .15 .2" type="2d" />
        <material name="MatPlane" reflectance="0.5" shininess="0.01" specular="0.1" texrepeat="1 1" texture="texplane" texuniform="true" />
        <material name="geom" texture="texgeom" texuniform="true"/>
    </asset>
    <worldbody>
        <geom name="floor" size="0 0 0.01" type="plane" material="groundplane" contype="1" conaffinity="0" priority="1"
      friction="0.6" condim="3"/>
      <!-- <light diffuse=".5 .5 .5" pos="0 0 5" dir="0 0 -1" castshadow="true"/> -->

          <light diffuse=".5 .5 .5" pos="-3 -3 5" dir="3 3 -5" castshadow="true"/>


    </worldbody>
</mujoco>
