<?xml version="1.0" encoding="utf-8"?>
<!-- This URDF was automatically created by SolidWorks to URDF Exporter! Originally created by Stephen Brawner (brawner@gmail.com) 
     Commit Version: 1.6.0-4-g7f85cfe  Build Version: 1.6.7995.38578
     For more information, please see http://wiki.ros.org/sw_urdf_exporter -->
<robot
  name="hi_25dof_250708">
  <mujoco>
		<compiler meshdir="meshes/" balanceinertia="true" discardvisual="false" />
	</mujoco>
  <link name="world"></link>
  <joint name="floating_base_joint" type="floating">
    <parent link="world" />
    <child link="base_link" />
  </joint>
  <link
    name="base_link">
    <inertial>
      <origin
        xyz="0.007306 0 -0.048481"
        rpy="0 0 0" />
      <mass
        value="4.8078654" />
      <inertia
        ixx="0.0458908"
        ixy="-2.4E-06"
        ixz="0.0002193"
        iyy="0.0316408"
        iyz="6E-07"
        izz="0.0186396" />
    </inertial>
    <visual>
      <origin
        xyz="0 0 0"
        rpy="0 0 0" />
      <geometry>
        <mesh
          filename="meshes/base_link.STL" />
      </geometry>
      <material
        name="">
        <color
          rgba="1 1 1 1" />
      </material>
    </visual>
    <collision>
      <origin
        xyz="0 0 0"
        rpy="0 0 0" />
      <geometry>
        <mesh
          filename="meshes/base_link.STL" />
      </geometry>
    </collision>
  </link>
  <link
    name="waist_link">
    <inertial>
      <origin
        xyz="0 0 -0.0391895"
        rpy="0 0 0" />
      <mass
        value="1.3504342" />
      <inertia
        ixx="0.0022104"
        ixy="0"
        ixz="0"
        iyy="0.0010637"
        iyz="0"
        izz="0.0019106" />
    </inertial>
    <visual>
      <origin
        xyz="0 0 0"
        rpy="0 0 0" />
      <geometry>
        <mesh
          filename="meshes/waist_link.STL" />
      </geometry>
      <material
        name="">
        <color
          rgba="0.79216 0.81961 0.93333 1" />
      </material>
    </visual>
    <collision>
      <origin
        xyz="0 0 0"
        rpy="0 0 0" />
      <geometry>
        <mesh
          filename="meshes/waist_link.STL" />
      </geometry>
    </collision>
  </link>
  <joint
    name="waist_joint"
    type="revolute">
    <origin
      xyz="0.009 0 -0.2126"
      rpy="0 0 0" />
    <parent
      link="base_link" />
    <child
      link="waist_link" />
    <axis
      xyz="0 0 1" />
    <limit
      lower="-3.14"
      upper="3.14"
      effort="21"
      velocity="21" />
  </joint>
  <link
    name="l_hip_pitch_link">
    <inertial>
      <origin
        xyz="-0.000511 0.039927 0"
        rpy="0 0 0" />
      <mass
        value="0.66609" />
      <inertia
        ixx="0.0004691"
        ixy="6E-07"
        ixz="0"
        iyy="0.000433"
        iyz="0"
        izz="0.0004671" />
    </inertial>
    <visual>
      <origin
        xyz="0 0 0"
        rpy="0 0 0" />
      <geometry>
        <mesh
          filename="meshes/l_hip_pitch_link.STL" />
      </geometry>
      <material
        name="">
        <color
          rgba="0.89804 0.91765 0.92941 1" />
      </material>
    </visual>
    <collision>
      <origin
        xyz="0 0 0"
        rpy="0 0 0" />
      <geometry>
        <mesh
          filename="meshes/l_hip_pitch_link.STL" />
      </geometry>
    </collision>
  </link>
  <joint
    name="l_hip_pitch_joint"
    type="revolute">
    <origin
      xyz="0 0.0575 -0.04"
      rpy="0 0 0" />
    <parent
      link="waist_link" />
    <child
      link="l_hip_pitch_link" />
    <axis
      xyz="0 1 0" />
    <limit
      lower="-3.14"
      upper="3.14"
      effort="21"
      velocity="21" />
  </joint>
  <link
    name="l_hip_roll_link">
    <inertial>
      <origin
        xyz="-0.026857 0 -0.075365"
        rpy="0 0 0" />
      <mass
        value="0.7909" />
      <inertia
        ixx="0.0013127"
        ixy="0"
        ixz="-2.34E-05"
        iyy="0.0015217"
        iyz="0"
        izz="0.0006822" />
    </inertial>
    <visual>
      <origin
        xyz="0 0 0"
        rpy="0 0 0" />
      <geometry>
        <mesh
          filename="meshes/l_hip_roll_link.STL" />
      </geometry>
      <material
        name="">
        <color
          rgba="0.79216 0.81961 0.93333 1" />
      </material>
    </visual>
    <collision>
      <origin
        xyz="0 0 0"
        rpy="0 0 0" />
      <geometry>
        <mesh
          filename="meshes/l_hip_roll_link.STL" />
      </geometry>
    </collision>
  </link>
  <joint
    name="l_hip_roll_joint"
    type="revolute">
    <origin
      xyz="0.02725 0.042 0"
      rpy="0 0 0" />
    <parent
      link="l_hip_pitch_link" />
    <child
      link="l_hip_roll_link" />
    <axis
      xyz="1 0 0" />
    <limit
      lower="-3.14"
      upper="3.14"
      effort="21"
      velocity="21" />
  </joint>
  <link
    name="l_thigh_link">
    <inertial>
      <origin
        xyz="0 -0.0018181 -0.032514"
        rpy="0 0 0" />
      <mass
        value="0.25619" />
      <inertia
        ixx="0.0004162"
        ixy="0"
        ixz="0"
        iyy="0.0002596"
        iyz="-1.71E-05"
        izz="0.0002776" />
    </inertial>
    <visual>
      <origin
        xyz="0 0 0"
        rpy="0 0 0" />
      <geometry>
        <mesh
          filename="meshes/l_thigh_link.STL" />
      </geometry>
      <material
        name="">
        <color
          rgba="0.89804 0.91765 0.92941 1" />
      </material>
    </visual>
    <collision>
      <origin
        xyz="0 0 0"
        rpy="0 0 0" />
      <geometry>
        <mesh
          filename="meshes/l_thigh_link.STL" />
      </geometry>
    </collision>
  </link>
  <joint
    name="l_thigh_joint"
    type="revolute">
    <origin
      xyz="-0.02725 0 -0.123"
      rpy="0 0 0" />
    <parent
      link="l_hip_roll_link" />
    <child
      link="l_thigh_link" />
    <axis
      xyz="0 0 1" />
    <limit
      lower="-3.14"
      upper="3.14"
      effort="21"
      velocity="21" />
  </joint>
  <link
    name="l_calf_link">
    <inertial>
      <origin
        xyz="0.0010782 -0.031083 -0.064513"
        rpy="0 0 0" />
      <mass
        value="1.6402" />
      <inertia
        ixx="0.0064449"
        ixy="1E-06"
        ixz="6.72E-05"
        iyy="0.0065018"
        iyz="-0.0001096"
        izz="0.0008988" />
    </inertial>
    <visual>
      <origin
        xyz="0 0 0"
        rpy="0 0 0" />
      <geometry>
        <mesh
          filename="meshes/l_calf_link.STL" />
      </geometry>
      <material
        name="">
        <color
          rgba="1 1 1 1" />
      </material>
    </visual>
    <collision>
      <origin
        xyz="0 0 0"
        rpy="0 0 0" />
      <geometry>
        <mesh
          filename="meshes/l_calf_link.STL" />
      </geometry>
    </collision>
  </link>
  <joint
    name="l_calf_joint"
    type="revolute">
    <origin
      xyz="0 0.03175 -0.069"
      rpy="0 0 0" />
    <parent
      link="l_thigh_link" />
    <child
      link="l_calf_link" />
    <axis
      xyz="0 1 0" />
    <limit
      lower="-3.14"
      upper="3.14"
      effort="21"
      velocity="21" />
  </joint>
  <link
    name="l_ankle_pitch_link">
    <inertial>
      <origin
        xyz="-0.0009911 0 0"
        rpy="0 0 0" />
      <mass
        value="0.013231" />
      <inertia
        ixx="9E-07"
        ixy="0"
        ixz="0"
        iyy="2.8E-06"
        iyz="0"
        izz="2.3E-06" />
    </inertial>
    <visual>
      <origin
        xyz="0 0 0"
        rpy="0 0 0" />
      <geometry>
        <mesh
          filename="meshes/l_ankle_pitch_link.STL" />
      </geometry>
      <material
        name="">
        <color
          rgba="0.89804 0.91765 0.92941 1" />
      </material>
    </visual>
    <collision>
      <origin
        xyz="0 0 0"
        rpy="0 0 0" />
      <geometry>
        <mesh
          filename="meshes/l_ankle_pitch_link.STL" />
      </geometry>
    </collision>
  </link>
  <joint
    name="l_ankle_pitch_joint"
    type="revolute">
    <origin
      xyz="0 -0.03175 -0.19945"
      rpy="0 0 0" />
    <parent
      link="l_calf_link" />
    <child
      link="l_ankle_pitch_link" />
    <axis
      xyz="0 1 0" />
    <limit
      lower="-3.14"
      upper="3.14"
      effort="21"
      velocity="21" />
  </joint>
  <link
    name="l_ankle_roll_link">
    <inertial>
      <origin
        xyz="-0.012597 0 -0.028754"
        rpy="0 0 0" />
      <mass
        value="0.40357" />
      <inertia
        ixx="0.0001488"
        ixy="0"
        ixz="6.23E-05"
        iyy="0.000774"
        iyz="0"
        izz="0.0007691" />
    </inertial>
    <visual>
      <origin
        xyz="0 0 0"
        rpy="0 0 0" />
      <geometry>
        <mesh
          filename="meshes/l_ankle_roll_link.STL" />
      </geometry>
      <material
        name="">
        <color
          rgba="0.89804 0.91765 0.92941 1" />
      </material>
    </visual>
    <collision>
      <origin
        xyz="0 0 0"
        rpy="0 0 0" />
      <geometry>
        <mesh
          filename="meshes/l_ankle_roll_link.STL" />
      </geometry>
    </collision>
  </link>
  <joint
    name="l_ankle_roll_joint"
    type="revolute">
    <origin
      xyz="0.0215 0 0"
      rpy="0 0 0" />
    <parent
      link="l_ankle_pitch_link" />
    <child
      link="l_ankle_roll_link" />
    <axis
      xyz="1 0 0" />
    <limit
      lower="-3.14"
      upper="3.14"
      effort="21"
      velocity="21" />
  </joint>
  <link
    name="r_hip_pitch_link">
    <inertial>
      <origin
        xyz="-0.000511 -0.039927 0"
        rpy="0 0 0" />
      <mass
        value="0.66609" />
      <inertia
        ixx="0.0004691"
        ixy="-6E-07"
        ixz="0"
        iyy="0.000433"
        iyz="0"
        izz="0.0004671" />
    </inertial>
    <visual>
      <origin
        xyz="0 0 0"
        rpy="0 0 0" />
      <geometry>
        <mesh
          filename="meshes/r_hip_pitch_link.STL" />
      </geometry>
      <material
        name="">
        <color
          rgba="0.89804 0.91765 0.92941 1" />
      </material>
    </visual>
    <collision>
      <origin
        xyz="0 0 0"
        rpy="0 0 0" />
      <geometry>
        <mesh
          filename="meshes/r_hip_pitch_link.STL" />
      </geometry>
    </collision>
  </link>
  <joint
    name="r_hip_pitch_joint"
    type="revolute">
    <origin
      xyz="0 -0.0575 -0.04"
      rpy="0 0 0" />
    <parent
      link="waist_link" />
    <child
      link="r_hip_pitch_link" />
    <axis
      xyz="0 1 0" />
    <limit
      lower="-3.14"
      upper="3.14"
      effort="21"
      velocity="21" />
  </joint>
  <link
    name="r_hip_roll_link">
    <inertial>
      <origin
        xyz="-0.0268572 0 -0.0753647"
        rpy="0 0 0" />
      <mass
        value="0.7909034" />
      <inertia
        ixx="0.0013127"
        ixy="0"
        ixz="-2.34E-05"
        iyy="0.0015217"
        iyz="0"
        izz="0.0006822" />
    </inertial>
    <visual>
      <origin
        xyz="0 0 0"
        rpy="0 0 0" />
      <geometry>
        <mesh
          filename="meshes/r_hip_roll_link.STL" />
      </geometry>
      <material
        name="">
        <color
          rgba="0.89804 0.91765 0.92941 1" />
      </material>
    </visual>
    <collision>
      <origin
        xyz="0 0 0"
        rpy="0 0 0" />
      <geometry>
        <mesh
          filename="meshes/r_hip_roll_link.STL" />
      </geometry>
    </collision>
  </link>
  <joint
    name="r_hip_roll_joint"
    type="revolute">
    <origin
      xyz="0.02725 -0.042 0"
      rpy="0 0 0" />
    <parent
      link="r_hip_pitch_link" />
    <child
      link="r_hip_roll_link" />
    <axis
      xyz="1 0 0" />
    <limit
      lower="-3.14"
      upper="3.14"
      effort="21"
      velocity="21" />
  </joint>
  <link
    name="r_thigh_link">
    <inertial>
      <origin
        xyz="0 0.0018181 -0.032514"
        rpy="0 0 0" />
      <mass
        value="0.25619" />
      <inertia
        ixx="0.0004162"
        ixy="0"
        ixz="0"
        iyy="0.0002596"
        iyz="1.71E-05"
        izz="0.0002776" />
    </inertial>
    <visual>
      <origin
        xyz="0 0 0"
        rpy="0 0 0" />
      <geometry>
        <mesh
          filename="meshes/r_thigh_link.STL" />
      </geometry>
      <material
        name="">
        <color
          rgba="0.89804 0.91765 0.92941 1" />
      </material>
    </visual>
    <collision>
      <origin
        xyz="0 0 0"
        rpy="0 0 0" />
      <geometry>
        <mesh
          filename="meshes/r_thigh_link.STL" />
      </geometry>
    </collision>
  </link>
  <joint
    name="r_thigh_joint"
    type="revolute">
    <origin
      xyz="-0.02725 0 -0.123"
      rpy="0 0 0" />
    <parent
      link="r_hip_roll_link" />
    <child
      link="r_thigh_link" />
    <axis
      xyz="0 0 1" />
    <limit
      lower="-3.14"
      upper="3.14"
      effort="21"
      velocity="21" />
  </joint>
  <link
    name="r_calf_link">
    <inertial>
      <origin
        xyz="0.0010785 0.0310814 -0.0645143"
        rpy="0 0 0" />
      <mass
        value="1.6401929" />
      <inertia
        ixx="0.0064446"
        ixy="-1E-06"
        ixz="6.71E-05"
        iyy="0.0065017"
        iyz="0.0001076"
        izz="0.0008985" />
    </inertial>
    <visual>
      <origin
        xyz="0 0 0"
        rpy="0 0 0" />
      <geometry>
        <mesh
          filename="meshes/r_calf_link.STL" />
      </geometry>
      <material
        name="">
        <color
          rgba="1 1 1 1" />
      </material>
    </visual>
    <collision>
      <origin
        xyz="0 0 0"
        rpy="0 0 0" />
      <geometry>
        <mesh
          filename="meshes/r_calf_link.STL" />
      </geometry>
    </collision>
  </link>
  <joint
    name="r_calf_joint"
    type="revolute">
    <origin
      xyz="0 -0.03175 -0.069"
      rpy="0 0 0" />
    <parent
      link="r_thigh_link" />
    <child
      link="r_calf_link" />
    <axis
      xyz="0 1 0" />
    <limit
      lower="-3.14"
      upper="3.14"
      effort="21"
      velocity="21" />
  </joint>
  <link
    name="r_ankle_pitch_link">
    <inertial>
      <origin
        xyz="-0.0009911 0 0"
        rpy="0 0 0" />
      <mass
        value="0.013231" />
      <inertia
        ixx="9E-07"
        ixy="0"
        ixz="0"
        iyy="2.8E-06"
        iyz="0"
        izz="2.3E-06" />
    </inertial>
    <visual>
      <origin
        xyz="0 0 0"
        rpy="0 0 0" />
      <geometry>
        <mesh
          filename="meshes/r_ankle_pitch_link.STL" />
      </geometry>
      <material
        name="">
        <color
          rgba="0.89804 0.91765 0.92941 1" />
      </material>
    </visual>
    <collision>
      <origin
        xyz="0 0 0"
        rpy="0 0 0" />
      <geometry>
        <mesh
          filename="meshes/r_ankle_pitch_link.STL" />
      </geometry>
    </collision>
  </link>
  <joint
    name="r_ankle_pitch_joint"
    type="revolute">
    <origin
      xyz="0 0.03175 -0.19945"
      rpy="0 0 0" />
    <parent
      link="r_calf_link" />
    <child
      link="r_ankle_pitch_link" />
    <axis
      xyz="0 1 0" />
    <limit
      lower="-3.14"
      upper="3.14"
      effort="21"
      velocity="21" />
  </joint>
  <link
    name="r_ankle_roll_link">
    <inertial>
      <origin
        xyz="-0.012597 0 -0.028754"
        rpy="0 0 0" />
      <mass
        value="0.40357" />
      <inertia
        ixx="0.0001488"
        ixy="0"
        ixz="6.23E-05"
        iyy="0.000774"
        iyz="0"
        izz="0.0007691" />
    </inertial>
    <visual>
      <origin
        xyz="0 0 0"
        rpy="0 0 0" />
      <geometry>
        <mesh
          filename="meshes/r_ankle_roll_link.STL" />
      </geometry>
      <material
        name="">
        <color
          rgba="0.89804 0.91765 0.92941 1" />
      </material>
    </visual>
    <collision>
      <origin
        xyz="0 0 0"
        rpy="0 0 0" />
      <geometry>
        <mesh
          filename="meshes/r_ankle_roll_link.STL" />
      </geometry>
    </collision>
  </link>
  <joint
    name="r_ankle_roll_joint"
    type="revolute">
    <origin
      xyz="0.0215 0 0"
      rpy="0 0 0" />
    <parent
      link="r_ankle_pitch_link" />
    <child
      link="r_ankle_roll_link" />
    <axis
      xyz="1 0 0" />
    <limit
      lower="-3.14"
      upper="3.14"
      effort="21"
      velocity="21" />
  </joint>
  <link
    name="l_shoulder_pitch_link">
    <inertial>
      <origin
        xyz="-0.0007568 0.030935 0"
        rpy="0 0 0" />
      <mass
        value="0.39963" />
      <inertia
        ixx="0.000199"
        ixy="1E-06"
        ixz="0"
        iyy="0.0001824"
        iyz="0"
        izz="0.0002098" />
    </inertial>
    <visual>
      <origin
        xyz="0 0 0"
        rpy="0 0 0" />
      <geometry>
        <mesh
          filename="meshes/l_shoulder_pitch_link.STL" />
      </geometry>
      <material
        name="">
        <color
          rgba="0.89804 0.91765 0.92941 1" />
      </material>
    </visual>
    <collision>
      <origin
        xyz="0 0 0"
        rpy="0 0 0" />
      <geometry>
        <mesh
          filename="meshes/l_shoulder_pitch_link.STL" />
      </geometry>
    </collision>
  </link>
  <joint
    name="l_shoulder_pitch_joint"
    type="revolute">
    <origin
      xyz="0.009 0.11945 0.020657"
      rpy="0 0 0" />
    <parent
      link="base_link" />
    <child
      link="l_shoulder_pitch_link" />
    <axis
      xyz="0 1 0" />
    <limit
      lower="-3.14"
      upper="3.14"
      effort="21"
      velocity="21" />
  </joint>
  <link
    name="l_shoulder_roll_link">
    <inertial>
      <origin
        xyz="-0.02515 0 -0.060623"
        rpy="0 0 0" />
      <mass
        value="0.45112" />
      <inertia
        ixx="0.0003758"
        ixy="0"
        ixz="3.22E-05"
        iyy="0.0004383"
        iyz="0"
        izz="0.0002478" />
    </inertial>
    <visual>
      <origin
        xyz="0 0 0"
        rpy="0 0 0" />
      <geometry>
        <mesh
          filename="meshes/l_shoulder_roll_link.STL" />
      </geometry>
      <material
        name="">
        <color
          rgba="0.89804 0.91765 0.92941 1" />
      </material>
    </visual>
    <collision>
      <origin
        xyz="0 0 0"
        rpy="0 0 0" />
      <geometry>
        <mesh
          filename="meshes/l_shoulder_roll_link.STL" />
      </geometry>
    </collision>
  </link>
  <joint
    name="l_shoulder_roll_joint"
    type="revolute">
    <origin
      xyz="0.02335 0.034 0"
      rpy="0 0 0" />
    <parent
      link="l_shoulder_pitch_link" />
    <child
      link="l_shoulder_roll_link" />
    <axis
      xyz="1 0 0" />
    <limit
      lower="-3.14"
      upper="3.14"
      effort="21"
      velocity="21" />
  </joint>
  <link
    name="l_upper_arm_link">
    <inertial>
      <origin
        xyz="0 -0.0007568 -0.030935"
        rpy="0 0 0" />
      <mass
        value="0.39963" />
      <inertia
        ixx="0.0002098"
        ixy="0"
        ixz="0"
        iyy="0.000199"
        iyz="-1E-06"
        izz="0.0001824" />
    </inertial>
    <visual>
      <origin
        xyz="0 0 0"
        rpy="0 0 0" />
      <geometry>
        <mesh
          filename="meshes/l_upper_arm_link.STL" />
      </geometry>
      <material
        name="">
        <color
          rgba="0.89804 0.91765 0.92941 1" />
      </material>
    </visual>
    <collision>
      <origin
        xyz="0 0 0"
        rpy="0 0 0" />
      <geometry>
        <mesh
          filename="meshes/l_upper_arm_link.STL" />
      </geometry>
    </collision>
  </link>
  <joint
    name="l_upper_arm_joint"
    type="revolute">
    <origin
      xyz="-0.0236 0 -0.0977"
      rpy="0 0 0" />
    <parent
      link="l_shoulder_roll_link" />
    <child
      link="l_upper_arm_link" />
    <axis
      xyz="0 0 1" />
    <limit
      lower="-3.14"
      upper="3.14"
      effort="21"
      velocity="21" />
  </joint>
  <link
    name="l_elbow_link">
    <inertial>
      <origin
        xyz="0 -0.026131 -0.051717"
        rpy="0 0 0" />
      <mass
        value="0.27632" />
      <inertia
        ixx="0.0002914"
        ixy="0"
        ixz="0"
        iyy="0.0002296"
        iyz="2.59E-05"
        izz="0.0001518" />
    </inertial>
    <visual>
      <origin
        xyz="0 0 0"
        rpy="0 0 0" />
      <geometry>
        <mesh
          filename="meshes/l_elbow_link.STL" />
      </geometry>
      <material
        name="">
        <color
          rgba="0.79216 0.81961 0.93333 1" />
      </material>
    </visual>
    <collision>
      <origin
        xyz="0 0 0"
        rpy="0 0 0" />
      <geometry>
        <mesh
          filename="meshes/l_elbow_link.STL" />
      </geometry>
    </collision>
  </link>
  <joint
    name="l_elbow_joint"
    type="revolute">
    <origin
      xyz="0 0.02335 -0.034"
      rpy="0 0 0" />
    <parent
      link="l_upper_arm_link" />
    <child
      link="l_elbow_link" />
    <axis
      xyz="0 1 0" />
    <limit
      lower="-3.14"
      upper="3.14"
      effort="21"
      velocity="21" />
  </joint>
  <link
    name="l_wrist_link">
    <inertial>
      <origin
        xyz="0 0 -0.0390078"
        rpy="0 0 0" />
      <mass
        value="0.2921" />
      <inertia
        ixx="0.0001388"
        ixy="0"
        ixz="0"
        iyy="0.0001388"
        iyz="0"
        izz="2.21E-05" />
    </inertial>
    <visual>
      <origin
        xyz="0 0 0"
        rpy="0 0 0" />
      <geometry>
        <mesh
          filename="meshes/l_wrist_link.STL" />
      </geometry>
      <material
        name="">
        <color
          rgba="0.50196 0.50196 0.50196 1" />
      </material>
    </visual>
    <collision>
      <origin
        xyz="0 0 0"
        rpy="0 0 0" />
      <geometry>
        <mesh
          filename="meshes/l_wrist_link.STL" />
      </geometry>
    </collision>
  </link>
  <joint
    name="l_wrist_joint"
    type="revolute">
    <origin
      xyz="0 -0.0236 -0.0884"
      rpy="0 0 0" />
    <parent
      link="l_elbow_link" />
    <child
      link="l_wrist_link" />
    <axis
      xyz="0 0 1" />
    <limit
      lower="-3.14"
      upper="3.14"
      effort="21"
      velocity="21" />
  </joint>
  <link
    name="r_shoulder_pitch_link">
    <inertial>
      <origin
        xyz="-0.0007568 -0.030935 0"
        rpy="0 0 0" />
      <mass
        value="0.39963" />
      <inertia
        ixx="0.000199"
        ixy="-1E-06"
        ixz="0"
        iyy="0.0001824"
        iyz="0"
        izz="0.0002098" />
    </inertial>
    <visual>
      <origin
        xyz="0 0 0"
        rpy="0 0 0" />
      <geometry>
        <mesh
          filename="meshes/r_shoulder_pitch_link.STL" />
      </geometry>
      <material
        name="">
        <color
          rgba="0.89804 0.91765 0.92941 1" />
      </material>
    </visual>
    <collision>
      <origin
        xyz="0 0 0"
        rpy="0 0 0" />
      <geometry>
        <mesh
          filename="meshes/r_shoulder_pitch_link.STL" />
      </geometry>
    </collision>
  </link>
  <joint
    name="r_shoulder_pitch_joint"
    type="revolute">
    <origin
      xyz="0.009 -0.11945 0.020657"
      rpy="0 0 0" />
    <parent
      link="base_link" />
    <child
      link="r_shoulder_pitch_link" />
    <axis
      xyz="0 1 0" />
    <limit
      lower="-3.14"
      upper="3.14"
      effort="21"
      velocity="21" />
  </joint>
  <link
    name="r_shoulder_roll_link">
    <inertial>
      <origin
        xyz="-0.02515 0 -0.060623"
        rpy="0 0 0" />
      <mass
        value="0.45112" />
      <inertia
        ixx="0.0003758"
        ixy="0"
        ixz="3.22E-05"
        iyy="0.0004383"
        iyz="0"
        izz="0.0002478" />
    </inertial>
    <visual>
      <origin
        xyz="0 0 0"
        rpy="0 0 0" />
      <geometry>
        <mesh
          filename="meshes/r_shoulder_roll_link.STL" />
      </geometry>
      <material
        name="">
        <color
          rgba="0.89804 0.91765 0.92941 1" />
      </material>
    </visual>
    <collision>
      <origin
        xyz="0 0 0"
        rpy="0 0 0" />
      <geometry>
        <mesh
          filename="meshes/r_shoulder_roll_link.STL" />
      </geometry>
    </collision>
  </link>
  <joint
    name="r_shoulder_roll_joint"
    type="revolute">
    <origin
      xyz="0.02335 -0.034 0"
      rpy="0 0 0" />
    <parent
      link="r_shoulder_pitch_link" />
    <child
      link="r_shoulder_roll_link" />
    <axis
      xyz="1 0 0" />
    <limit
      lower="-3.14"
      upper="3.14"
      effort="21"
      velocity="21" />
  </joint>
  <link
    name="r_upper_arm_link">
    <inertial>
      <origin
        xyz="0 0.0007568 -0.030935"
        rpy="0 0 0" />
      <mass
        value="0.39963" />
      <inertia
        ixx="0.0002098"
        ixy="0"
        ixz="0"
        iyy="0.000199"
        iyz="1E-06"
        izz="0.0001824" />
    </inertial>
    <visual>
      <origin
        xyz="0 0 0"
        rpy="0 0 0" />
      <geometry>
        <mesh
          filename="meshes/r_upper_arm_link.STL" />
      </geometry>
      <material
        name="">
        <color
          rgba="0.89804 0.91765 0.92941 1" />
      </material>
    </visual>
    <collision>
      <origin
        xyz="0 0 0"
        rpy="0 0 0" />
      <geometry>
        <mesh
          filename="meshes/r_upper_arm_link.STL" />
      </geometry>
    </collision>
  </link>
  <joint
    name="r_upper_arm_joint"
    type="revolute">
    <origin
      xyz="-0.0236 0 -0.0977"
      rpy="0 0 0" />
    <parent
      link="r_shoulder_roll_link" />
    <child
      link="r_upper_arm_link" />
    <axis
      xyz="0 0 1" />
    <limit
      lower="-3.14"
      upper="3.14"
      effort="21"
      velocity="21" />
  </joint>
  <link
    name="r_elbow_link">
    <inertial>
      <origin
        xyz="0 0.026131 -0.051717"
        rpy="0 0 0" />
      <mass
        value="0.27632" />
      <inertia
        ixx="0.0002914"
        ixy="0"
        ixz="0"
        iyy="0.0002296"
        iyz="-2.59E-05"
        izz="0.0001518" />
    </inertial>
    <visual>
      <origin
        xyz="0 0 0"
        rpy="0 0 0" />
      <geometry>
        <mesh
          filename="meshes/r_elbow_link.STL" />
      </geometry>
      <material
        name="">
        <color
          rgba="0.89804 0.91765 0.92941 1" />
      </material>
    </visual>
    <collision>
      <origin
        xyz="0 0 0"
        rpy="0 0 0" />
      <geometry>
        <mesh
          filename="meshes/r_elbow_link.STL" />
      </geometry>
    </collision>
  </link>
  <joint
    name="r_elbow_joint"
    type="revolute">
    <origin
      xyz="0 -0.02335 -0.034"
      rpy="0 0 0" />
    <parent
      link="r_upper_arm_link" />
    <child
      link="r_elbow_link" />
    <axis
      xyz="0 1 0" />
    <limit
      lower="-3.14"
      upper="3.14"
      effort="21"
      velocity="21" />
  </joint>
  <link
    name="r_wrist_link">
    <inertial>
      <origin
        xyz="0 0 -0.0390078"
        rpy="0 0 0" />
      <mass
        value="0.2921" />
      <inertia
        ixx="0.0001388"
        ixy="0"
        ixz="0"
        iyy="0.0001388"
        iyz="0"
        izz="2.21E-05" />
    </inertial>
    <visual>
      <origin
        xyz="0 0 0"
        rpy="0 0 0" />
      <geometry>
        <mesh
          filename="meshes/r_wrist_link.STL" />
      </geometry>
      <material
        name="">
        <color
          rgba="0.50196 0.50196 0.50196 1" />
      </material>
    </visual>
    <collision>
      <origin
        xyz="0 0 0"
        rpy="0 0 0" />
      <geometry>
        <mesh
          filename="meshes/r_wrist_link.STL" />
      </geometry>
    </collision>
  </link>
  <joint
    name="r_wrist_joint"
    type="revolute">
    <origin
      xyz="0 0.0236 -0.0884"
      rpy="0 0 0" />
    <parent
      link="r_elbow_link" />
    <child
      link="r_wrist_link" />
    <axis
      xyz="0 0 1" />
    <limit
      lower="-3.14"
      upper="3.14"
      effort="21"
      velocity="21" />
  </joint>
  <link
    name="head_yaw_link">
    <inertial>
      <origin
        xyz="2E-05 -0.0015717 0.022694"
        rpy="0 0 0" />
      <mass
        value="0.17851" />
      <inertia
        ixx="2.2E-05"
        ixy="0"
        ixz="0"
        iyy="1.79E-05"
        iyz="-2.3E-06"
        izz="1.46E-05" />
    </inertial>
    <visual>
      <origin
        xyz="0 0 0"
        rpy="0 0 0" />
      <geometry>
        <mesh
          filename="meshes/head_yaw_link.STL" />
      </geometry>
      <material
        name="">
        <color
          rgba="1 1 1 1" />
      </material>
    </visual>
    <collision>
      <origin
        xyz="0 0 0"
        rpy="0 0 0" />
      <geometry>
        <mesh
          filename="meshes/head_yaw_link.STL" />
      </geometry>
    </collision>
  </link>
  <joint
    name="head_yaw_joint"
    type="revolute">
    <origin
      xyz="0.009 0 0.1175"
      rpy="0 0 0" />
    <parent
      link="base_link" />
    <child
      link="head_yaw_link" />
    <axis
      xyz="0 0 1" />
    <limit
      lower="-3.14"
      upper="3.14"
      effort="21"
      velocity="21" />
  </joint>
  <link
    name="head_pitch_link">
    <inertial>
      <origin
        xyz="0.02294 -0.013625 0.031517"
        rpy="0 0 0" />
      <mass
        value="0.25396" />
      <inertia
        ixx="0.0006648"
        ixy="-1.3E-06"
        ixz="2.9E-06"
        iyy="0.0002612"
        iyz="3.5E-06"
        izz="0.0008343" />
    </inertial>
    <visual>
      <origin
        xyz="0 0 0"
        rpy="0 0 0" />
      <geometry>
        <mesh
          filename="meshes/head_pitch_link.STL" />
      </geometry>
      <material
        name="">
        <color
          rgba="0.89804 0.91765 0.92941 1" />
      </material>
    </visual>
    <collision>
      <origin
        xyz="0 0 0"
        rpy="0 0 0" />
      <geometry>
        <mesh
          filename="meshes/head_pitch_link.STL" />
      </geometry>
    </collision>
  </link>
  <joint
    name="head_pitch_joint"
    type="revolute">
    <origin
      xyz="0 0.0151 0.0255"
      rpy="0 0 0" />
    <parent
      link="head_yaw_link" />
    <child
      link="head_pitch_link" />
    <axis
      xyz="0 1 0" />
    <limit
      lower="-3.14"
      upper="3.14"
      effort="21"
      velocity="21" />
  </joint>
</robot>