<?xml version="1.0" ?><robot name="left_leg_active">  
  <link name="2xc430">    
    <visual>      
      <origin xyz="0 0 0" rpy="0 -0 0"/>      
      <geometry>        
        <mesh filename="package:///meshes/left_2xc430_visual.stl"/>        
      </geometry>      
      <material name="2xc430_material">        
        <color rgba="0.51698661238356058423 0.5034781595109349972 0.49050589017722023844 1.0"/>        
      </material>      
    </visual>    
    <collision>      
      <origin xyz="0 0 0" rpy="0 -0 0"/>      
      <geometry>        
        <mesh filename="package:///meshes/left_2xc430_collision.stl"/>        
      </geometry>      
    </collision>    
    <inertial>      
      <origin xyz="-0.012000151133967866882 0.00049588831386336313517 0.018504019244503622232" rpy="0 0 0"/>      
      <mass value="0.11059999999836231388"/>      
      <inertia ixx="2.2818802599021430531e-05" ixy="4.6888548259071808508e-08" ixz="4.6520143289445622075e-08" iyy="3.0871666424472358657e-05" iyz="-5.747734389972252115e-07" izz="3.0871632082341921239e-05"/>      
    </inertial>    
  </link>  

  <link name="hip_yaw_link">    
    <visual>      
      <origin xyz="0 0 0" rpy="0 -0 0"/>      
      <geometry>        
        <mesh filename="package:///meshes/left_hip_yaw_link_visual.stl"/>        
      </geometry>      
      <material name="hip_yaw_link_material">        
        <color rgba="0.61568627450980395466 0.81176470588235294379 0.92941176470588238168 1.0"/>        
      </material>      
    </visual>    
    <collision>      
      <origin xyz="0 0 0" rpy="0 -0 0"/>      
      <geometry>        
        <mesh filename="package:///meshes/left_hip_yaw_link_collision.stl"/>        
      </geometry>      
    </collision>    
    <inertial>      
      <origin xyz="-2.6788828011921458333e-18 -0.015800610849654263268 -0.019005670096647751116" rpy="0 0 0"/>      
      <mass value="0.013199999999999998193"/>      
      <inertia ixx="5.7894615975174182663e-06" ixy="-4.5096954887673704604e-35" ixz="-4.6860781276867853571e-35" iyy="5.0110144042848776317e-06" iyz="1.1826010760652090322e-09" izz="2.7344876354814340129e-06"/>      
    </inertial>    
  </link>  

  <link name="spur_gear_21_teeth">    
    <visual>      
      <origin xyz="0 0 0" rpy="0 -0 0"/>      
      <geometry>        
        <mesh filename="package:///meshes/left_spur_gear_21_teeth_visual.stl"/>        
      </geometry>      
      <material name="spur_gear_21_teeth_material">        
        <color rgba="0.61568627450980395466 0.81176470588235294379 0.9294117647058824927 1.0"/>        
      </material>      
    </visual>    
    <collision>      
      <origin xyz="0 0 0" rpy="0 -0 0"/>      
      <geometry>        
        <mesh filename="package:///meshes/left_spur_gear_21_teeth_collision.stl"/>        
      </geometry>      
    </collision>    
    <inertial>      
      <origin xyz="-4.5505288721570903318e-11 -1.678216019244386562e-11 -0.00249241020062506086" rpy="0 0 0"/>      
      <mass value="0.0022000000000000001325"/>      
      <inertia ixx="7.0162310059594183647e-08" ixy="3.8801235249534522434e-48" ixz="2.8125501580477835848e-36" iyy="7.0162310058047448545e-08" iyz="3.6086829965958632414e-39" izz="1.3125544198538289306e-07"/>      
    </inertial>    
  </link>  

  <link name="left_hip_pitch_link">    
    <visual>      
      <origin xyz="0 0 0" rpy="0 -0 0"/>      
      <geometry>        
        <mesh filename="package:///meshes/left_hip_pitch_link_visual.stl"/>        
      </geometry>      
      <material name="left_hip_pitch_link_material">        
        <color rgba="0.79618318075804161982 0.72120748766551001641 0.38540937988910828338 1.0"/>        
      </material>      
    </visual>    
    <collision>      
      <origin xyz="0 0 0" rpy="0 -0 0"/>      
      <geometry>        
        <mesh filename="package:///meshes/left_hip_pitch_link_collision.stl"/>        
      </geometry>      
    </collision>    
    <inertial>      
      <origin xyz="-0.0092773123251564115765 -0.0054583150498874076148 0.03951473811674113823" rpy="0 0 0"/>      
      <mass value="0.15848965119785968225"/>      
      <inertia ixx="8.2188788742760984481e-05" ixy="-1.3373705321924665731e-06" ixz="-9.0917451363903152822e-06" iyy="9.9396334685477759005e-05" iyz="1.2989378994414343027e-06" izz="4.5892431466748451869e-05"/>      
    </inertial>    
  </link>  

  <link name="spur_gear_18_teeth">    
    <visual>      
      <origin xyz="0 0 0" rpy="0 -0 0"/>      
      <geometry>        
        <mesh filename="package:///meshes/left_spur_gear_18_teeth_visual.stl"/>        
      </geometry>      
      <material name="spur_gear_18_teeth_material">        
        <color rgba="0.61568627450980395466 0.81176470588235294379 0.92941176470588238168 1.0"/>        
      </material>      
    </visual>    
    <collision>      
      <origin xyz="0 0 0" rpy="0 -0 0"/>      
      <geometry>        
        <mesh filename="package:///meshes/left_spur_gear_18_teeth_collision.stl"/>        
      </geometry>      
    </collision>    
    <inertial>      
      <origin xyz="-7.752038183041959484e-14 -3.6849389759155399626e-13 0.0017500000000010135486" rpy="0 0 0"/>      
      <mass value="0.0011999999999999998949"/>      
      <inertia ixx="2.9367899810799921361e-08" ixy="7.0238050736813871495e-19" ixz="-3.9642189780159722141e-36" iyy="2.9367899814659476616e-08" iyz="7.4779432983140590507e-37" izz="5.6306346207859581581e-08"/>      
    </inertial>    
  </link>  

  <joint name="left_hip_yaw_drive" type="fixed">    
    <origin xyz="-0.019199999999993125344 0.00020000000000295475866 -3.3514857555871913064e-14" rpy="-3.1415926535896550043 -5.0131548558082056583e-13 4.8264233360682142308e-13"/>    
    <parent link="left_hip_pitch_link"/>    
    <child link="spur_gear_18_teeth"/>    
    <axis xyz="0 0 1"/>    
    <limit effort="1" velocity="20"/>    
    <joint_properties friction="0.0"/>    
  </joint>  

  <link name="left_calf_link">    
    <visual>      
      <origin xyz="0 0 0" rpy="0 -0 0"/>      
      <geometry>        
        <mesh filename="package:///meshes/left_calf_link_visual.stl"/>        
      </geometry>      
      <material name="left_calf_link_material">        
        <color rgba="0.61568627450980395466 0.81176470588235294379 0.92941176470588238168 1.0"/>        
      </material>      
    </visual>    
    <collision>      
      <origin xyz="0 0 0" rpy="0 -0 0"/>      
      <geometry>        
        <mesh filename="package:///meshes/left_calf_link_collision.stl"/>        
      </geometry>      
    </collision>    
    <inertial>      
      <origin xyz="-0.0043450054391248908378 0.040752982165250292712 0.0087116093515538488984" rpy="0 0 0"/>      
      <mass value="0.031000000000000003247"/>      
      <inertia ixx="3.3069388685110862264e-05" ixy="-1.3783307153200015641e-06" ixz="-1.274253402633582998e-07" iyy="7.7316525337312923483e-06" iyz="-7.3356500593809879232e-08" izz="2.803137775398619952e-05"/>      
    </inertial>    
  </link>  

  <link name="left_ank_pitch_link">    
    <visual>      
      <origin xyz="0 0 0" rpy="0 -0 0"/>      
      <geometry>        
        <mesh filename="package:///meshes/left_ank_pitch_link_visual.stl"/>        
      </geometry>      
      <material name="left_ank_pitch_link_material">        
        <color rgba="0.70321688500203349825 0.64514870846184446673 0.40484735422826273465 1.0"/>        
      </material>      
    </visual>    
    <collision>      
      <origin xyz="0 0 0" rpy="0 -0 0"/>      
      <geometry>        
        <mesh filename="package:///meshes/left_ank_pitch_link_collision.stl"/>        
      </geometry>      
    </collision>    
    <inertial>      
      <origin xyz="0.017770241891401212381 0.012301334508572169327 0.018813528244421767049" rpy="0 0 0"/>      
      <mass value="0.17676376695067907985"/>      
      <inertia ixx="4.7283316680251609909e-05" ixy="-1.3380598598440940839e-06" ixz="-5.5304058905135761946e-07" iyy="0.00010706456048089211587" iyz="-5.3225137839476575408e-08" izz="0.00012185522397136355495"/>      
    </inertial>    
  </link>  

  <link name="ank_roll_link">    
    <visual>      
      <origin xyz="0 0 0" rpy="0 -0 0"/>      
      <geometry>        
        <mesh filename="package:///meshes/left_ank_roll_link_visual.stl"/>        
      </geometry>      
      <material name="ank_roll_link_material">        
        <color rgba="0.61568627450980384364 0.81176470588235283277 0.92941176470588227065 1.0"/>        
      </material>      
    </visual>    
    <collision>      
      <origin xyz="0 0 0" rpy="0 -0 0"/>      
      <geometry>        
        <mesh filename="package:///meshes/left_ank_roll_link_collision.stl"/>        
      </geometry>      
    </collision>    
    <inertial>      
      <origin xyz="-0.027003066516822105125 -2.0057285780772465402e-12 0.033764011359896435593" rpy="0 0 0"/>      
      <mass value="0.042600000000000012856"/>      
      <inertia ixx="3.7284397827464328061e-05" ixy="-5.5173241969370399862e-16" ixz="2.3929183768080750974e-06" iyy="3.7589276943350436312e-05" iyz="5.0934855318400778365e-12" izz="1.0090430906786797971e-05"/>      
    </inertial>    
  </link>  

  <joint name="left_ank_roll" type="revolute">    
    <origin xyz="0.022749999999985347915 -7.7438055967604668695e-15 0.019000000000000561579" rpy="-1.5707963267949487385 6.9598897929083939361e-14 1.5707963267951468023"/>    
    <parent link="left_ank_pitch_link"/>    
    <child link="ank_roll_link"/>    
    <axis xyz="0 0 1"/>    
    <limit effort="1" velocity="20" lower="-1.570796326794896558" upper="1.570796326794896558"/>    
    <joint_properties friction="0.0"/>    
  </joint>  

  <joint name="left_ank_pitch" type="revolute">    
    <origin xyz="-1.5860271119798389095e-15 0.099999999999998423483 0.027750000000001679573" rpy="-3.141592653589793116 2.6670249114811232296e-16 -3.8252904387067536217e-14"/>    
    <parent link="left_calf_link"/>    
    <child link="left_ank_pitch_link"/>    
    <axis xyz="0 0 1"/>    
    <limit effort="1" velocity="20" lower="-1.7453292519943295336" upper="0.785398163397448279"/>    
    <joint_properties friction="0.0"/>    
  </joint>  

  <joint name="left_knee" type="revolute">    
    <origin xyz="-9.150119726040088374e-16 -0.0087499999999997267464 0.085949999999997653277" rpy="1.5707963267948872321 4.8975632202997979707e-15 3.141592653589793116"/>    
    <parent link="left_hip_pitch_link"/>    
    <child link="left_calf_link"/>    
    <axis xyz="0 0 1"/>    
    <limit effort="1" velocity="20" lower="-2.0943951023931952626" upper="0"/>    
    <joint_properties friction="0.0"/>    
  </joint>  

  <link name="xm430_plate">    
    <visual>      
      <origin xyz="0 0 0" rpy="0 -0 0"/>      
      <geometry>        
        <mesh filename="package:///meshes/left_xm430_plate_visual.stl"/>        
      </geometry>      
      <material name="xm430_plate_material">        
        <color rgba="0.61568627450980395466 0.81176470588235294379 0.9294117647058824927 1.0"/>        
      </material>      
    </visual>    
    <collision>      
      <origin xyz="0 0 0" rpy="0 -0 0"/>      
      <geometry>        
        <mesh filename="package:///meshes/left_xm430_plate_collision.stl"/>        
      </geometry>      
    </collision>    
    <inertial>      
      <origin xyz="1.5284898498035939143e-17 -2.6039897774112988365e-18 0.0025278513919583887187" rpy="0 0 0"/>      
      <mass value="0.0026999999999999992756"/>      
      <inertia ixx="1.2887178787151822041e-07" ixy="5.8739562556303606535e-08" ixz="-9.9980146054615768914e-37" iyy="2.4635091298412528789e-07" iyz="-3.0618892391105573999e-36" izz="3.646799841381030595e-07"/>      
    </inertial>    
  </link>  

  <joint name="left_knee_act" type="fixed">    
    <origin xyz="-7.4872906434390518473e-16 0.012449999999999808442 0.044499999999998859912" rpy="-1.5707963267948827912 1.5707963267948863439 0"/>    
    <parent link="left_hip_pitch_link"/>    
    <child link="xm430_plate"/>    
    <axis xyz="0 0 1"/>    
    <limit effort="1" velocity="20"/>    
    <joint_properties friction="0.0"/>    
  </joint>  

  <joint name="left_hip_yaw" type="revolute">    
    <origin xyz="6.1229146868660582384e-18 3.4694469519536141888e-18 -0.0050000000000000044409" rpy="3.1415926535897837901 1.1763977000879646623e-14 2.7749339408464486521e-29"/>    
    <parent link="spur_gear_21_teeth"/>    
    <child link="left_hip_pitch_link"/>    
    <axis xyz="0 0 1"/>    
    <limit effort="1" velocity="20" lower="-1.570796326794896558" upper="1.570796326794896558"/>    
    <joint_properties friction="0.0"/>    
  </joint>  

  <joint name="left_hip_yaw_fixed" type="fixed">    
    <origin xyz="-3.4694469519536141888e-18 -0.027999999999999986705 -0.018999999999999999528" rpy="-1.5707963267948950037 1.570796326794896336 0"/>    
    <parent link="hip_yaw_link"/>    
    <child link="spur_gear_21_teeth"/>    
    <axis xyz="0 0 1"/>    
    <limit effort="1" velocity="20"/>    
    <joint_properties friction="0.0"/>    
  </joint>  

  <joint name="left_hip_roll" type="revolute">    
    <origin xyz="-0.024000000716154074043 0.019000000152474230686 0.019000000152447748397" rpy="-1.5707963267952167463 -1.5707963267948206187 0"/>    
    <parent link="2xc430"/>    
    <child link="hip_yaw_link"/>    
    <axis xyz="0 0 1"/>    
    <limit effort="1" velocity="20" lower="-0.785398163397448279" upper="0.785398163397448279"/>    
    <joint_properties friction="0.0"/>    
  </joint>  


</robot>