<?xml version="1.0" ?>
<!-- Generated using onshape-to-robot -->
<!-- Onshape document_id: 8eacf058d85ce70fa4dc9355 -->
<robot name="berkeley-humanoid-lite">
  <!-- Link base -->
  <link name="base">
    <inertial>
      <origin xyz="-0.0030965 0.000264765 0.675059" rpy="0 0 0"/>
      <mass value="4.44401"/>
      <inertia ixx="0.0667167" ixy="1.21504e-06" ixz="-0.00131643" iyy="0.0447686" iyz="2.88151e-05" izz="0.0318661"/>
    </inertial>
    <!-- Part base_parts -->
    <collision>
      <origin xyz="-6.93889e-18 7.53521e-18 0.71" rpy="-2.26485e-14 -9.65001e-16 -1.5708"/>
      <geometry>
        <box size="0.15 0.14 0.23"/>
      </geometry>
    </collision>
    <visual>
      <origin xyz="-0.0030965 0.000264765 0.675059" rpy="0 -0 0"/>
      <geometry>
        <mesh filename="./assets/merged/base_visual.stl"/>
      </geometry>
      <material name="base_parts_material">
        <color rgba="0.378685 0.40631 0.372653 1.0"/>
      </material>
    </visual>
  </link>
  <!-- Link imu_2 -->
  <link name="imu_2">
    <inertial>
      <origin xyz="3.52366e-18 9.75464e-19 0.0025" rpy="0 0 0"/>
      <mass value="0.00197704"/>
      <inertia ixx="1.11441e-07" ixy="1.34895e-38" ixz="0" iyy="4.06118e-08" iyz="0" izz="1.43815e-07"/>
    </inertial>
    <!-- Part imu_2_parts -->
    <visual>
      <origin xyz="6.93889e-18 9.75464e-19 0.0025" rpy="6.12323e-17 -2.26485e-14 2.65724e-15"/>
      <geometry>
        <mesh filename="./assets/merged/imu_2_visual.stl"/>
      </geometry>
      <material name="imu_2_parts_material">
        <color rgba="0.141176 0.694118 0.65098 1.0"/>
      </material>
    </visual>
  </link>
  <!-- Frame imu (dummy link + fixed joint) -->
  <link name="imu">
    <origin xyz="0 0 0" rpy="0 -0 0"/>
    <inertial>
      <origin xyz="0 0 0" rpy="0 0 0"/>
      <mass value="1e-9"/>
      <inertia ixx="0" ixy="0" ixz="0" iyy="0" iyz="0" izz="0"/>
    </inertial>
  </link>
  <joint name="imu_frame" type="fixed">
    <origin xyz="0 -6.33816e-19 0.005" rpy="0 -0 -1.90898e-31"/>
    <parent link="imu_2"/>
    <child link="imu"/>
    <axis xyz="0 0 0"/>
  </joint>
  <!-- Joint from base to imu_2 -->
  <joint name="imu" type="fixed">
    <origin xyz="0.061722 -1.49319e-16 0.68" rpy="-6.12323e-17 2.26485e-14 -2.65724e-15"/>
    <parent link="base"/>
    <child link="imu_2"/>
    <axis xyz="0 0 1"/>
    <limit effort="20" velocity="15"/>
    <joint_properties friction="0.1"/>
  </joint>
  <!-- Link arm_left_shoulder_pitch -->
  <link name="arm_left_shoulder_pitch">
    <inertial>
      <origin xyz="-0.00661228 -8.80749e-05 0.0396144" rpy="0 0 0"/>
      <mass value="0.342876"/>
      <inertia ixx="0.000218285" ixy="-1.17021e-06" ixz="1.05191e-05" iyy="0.000260325" iyz="-4.52438e-07" izz="0.00022463"/>
    </inertial>
    <!-- Part arm_left_shoulder_pitch_parts -->
    <visual>
      <origin xyz="-0.00661228 -8.80749e-05 0.0396144" rpy="1.5708 -7.66952e-17 -2.36686e-13"/>
      <geometry>
        <mesh filename="./assets/merged/arm_left_shoulder_pitch_visual.stl"/>
      </geometry>
      <material name="arm_left_shoulder_pitch_parts_material">
        <color rgba="0.441363 0.482355 0.421528 1.0"/>
      </material>
    </visual>
  </link>
  <!-- Link arm_left_shoulder_roll -->
  <link name="arm_left_shoulder_roll">
    <inertial>
      <origin xyz="-4.00762e-05 0.0737019 -0.0277329" rpy="0 0 0"/>
      <mass value="0.443945"/>
      <inertia ixx="0.000698118" ixy="-4.07105e-07" ixz="-1.31045e-07" iyy="0.000365437" iyz="-1.56428e-05" izz="0.000568315"/>
    </inertial>
    <!-- Part arm_left_shoulder_roll_parts -->
    <visual>
      <origin xyz="-4.00762e-05 0.0737019 -0.0277329" rpy="1.309 -1.5708 0"/>
      <geometry>
        <mesh filename="./assets/merged/arm_left_shoulder_roll_visual.stl"/>
      </geometry>
      <material name="arm_left_shoulder_roll_parts_material">
        <color rgba="0.553366 0.585026 0.538047 1.0"/>
      </material>
    </visual>
  </link>
  <!-- Link arm_left_shoulder_yaw -->
  <link name="arm_left_shoulder_yaw">
    <inertial>
      <origin xyz="-0.00781722 -9.17114e-05 0.0409759" rpy="0 0 0"/>
      <mass value="0.329199"/>
      <inertia ixx="0.000196136" ixy="-1.164e-06" ixz="8.20811e-06" iyy="0.000241556" iyz="-4.93374e-07" izz="0.000214842"/>
    </inertial>
    <!-- Part arm_left_shoulder_yaw_parts -->
    <collision>
      <origin xyz="5.26142e-15 -3.0972e-15 -0.035" rpy="-3.14159 1.50982e-13 3.14159"/>
      <geometry>
        <cylinder length="0.15" radius="0.04"/>
      </geometry>
    </collision>
    <visual>
      <origin xyz="-0.00781722 -9.17114e-05 0.0409759" rpy="2.87979 1.09732e-13 -1.5708"/>
      <geometry>
        <mesh filename="./assets/merged/arm_left_shoulder_yaw_visual.stl"/>
      </geometry>
      <material name="arm_left_shoulder_yaw_parts_material">
        <color rgba="0.420907 0.463607 0.40026 1.0"/>
      </material>
    </visual>
  </link>
  <!-- Link arm_left_elbow_pitch -->
  <link name="arm_left_elbow_pitch">
    <inertial>
      <origin xyz="-4.00762e-05 0.0737019 -0.0277329" rpy="0 0 0"/>
      <mass value="0.443945"/>
      <inertia ixx="0.000698118" ixy="-4.07105e-07" ixz="-1.31045e-07" iyy="0.000365437" iyz="-1.56428e-05" izz="0.000568315"/>
    </inertial>
    <!-- Part arm_left_elbow_pitch_parts -->
    <visual>
      <origin xyz="-4.00762e-05 0.0737019 -0.0277329" rpy="-1.8326 4.33938e-13 3.14159"/>
      <geometry>
        <mesh filename="./assets/merged/arm_left_elbow_pitch_visual.stl"/>
      </geometry>
      <material name="arm_left_elbow_pitch_parts_material">
        <color rgba="0.553366 0.585026 0.538047 1.0"/>
      </material>
    </visual>
  </link>
  <!-- Link arm_left_elbow_roll -->
  <link name="arm_left_elbow_roll">
    <inertial>
      <origin xyz="-6.0299e-19 -2.28764e-17 0.005" rpy="0 0 0"/>
      <mass value="0.000826239"/>
      <inertia ixx="1.20493e-08" ixy="-1.61704e-36" ixz="6.37804e-38" iyy="1.20493e-08" iyz="-2.09406e-25" izz="1.0328e-08"/>
    </inertial>
    <!-- Part arm_left_elbow_roll_parts -->
    <collision>
      <origin xyz="-6.74047e-19 -4.04359e-17 -0.01" rpy="3.14159 2.74243e-29 -7.13294e-29"/>
      <geometry>
        <cylinder length="0.12" radius="0.03"/>
      </geometry>
    </collision>
    <visual>
      <origin xyz="-6.0299e-19 0 0.005" rpy="2.87979 -4.15404e-13 3.14159"/>
      <geometry>
        <mesh filename="./assets/merged/arm_left_elbow_roll_visual.stl"/>
      </geometry>
      <material name="arm_left_elbow_roll_parts_material">
        <color rgba="0.917647 0.917647 0.917647 1.0"/>
      </material>
    </visual>
  </link>
  <!-- Link arm_left_hand_link -->
  <link name="arm_left_hand_link">
    <inertial>
      <origin xyz="-0.00248666 0.0134979 -0.0541316" rpy="0 0 0"/>
      <mass value="0.291741"/>
      <inertia ixx="0.000556491" ixy="3.82363e-06" ixz="-2.67254e-06" iyy="0.000494025" iyz="-0.000102102" izz="0.000161723"/>
    </inertial>
    <!-- Part arm_left_hand_link_parts -->
    <visual>
      <origin xyz="-0.00248666 0.0134979 -0.0541316" rpy="-0.261799 4.15391e-13 1.5708"/>
      <geometry>
        <mesh filename="./assets/merged/arm_left_hand_link_visual.stl"/>
      </geometry>
      <material name="arm_left_hand_link_parts_material">
        <color rgba="0.309962 0.309962 0.309962 1.0"/>
      </material>
    </visual>
  </link>
  <!-- Joint from arm_left_elbow_roll to arm_left_hand_link -->
  <joint name="arm_left_hand_l" type="fixed">
    <origin xyz="-6.31089e-30 -5.55112e-17 5.55112e-17" rpy="3.14159 2.68666e-14 -1.5708"/>
    <parent link="arm_left_elbow_roll"/>
    <child link="arm_left_hand_link"/>
    <axis xyz="0 0 1"/>
    <limit effort="20" velocity="15"/>
    <joint_properties friction="0.1"/>
  </joint>
  <!-- Joint from arm_left_elbow_pitch to arm_left_elbow_roll -->
  <joint name="arm_left_elbow_roll_joint" type="revolute">
    <origin xyz="-3.16213e-14 0.123 -0.0255" rpy="-1.5708 1.75811e-13 2.18496e-13"/>
    <parent link="arm_left_elbow_pitch"/>
    <child link="arm_left_elbow_roll"/>
    <axis xyz="0 0 1"/>
    <limit effort="20" velocity="15" lower="-0.785398" upper="0.785398"/>
    <joint_properties friction="0.1"/>
  </joint>
  <!-- Joint from arm_left_shoulder_yaw to arm_left_elbow_pitch -->
  <joint name="arm_left_elbow_pitch_joint" type="revolute">
    <origin xyz="0.0245 6.0295e-17 0.043" rpy="1.5708 -3.0664e-13 1.5708"/>
    <parent link="arm_left_shoulder_yaw"/>
    <child link="arm_left_elbow_pitch"/>
    <axis xyz="0 0 1"/>
    <limit effort="20" velocity="15" lower="-6.16396e-13" upper="1.5708"/>
    <joint_properties friction="0.1"/>
  </joint>
  <!-- Joint from arm_left_shoulder_roll to arm_left_shoulder_yaw -->
  <joint name="arm_left_shoulder_yaw_joint" type="revolute">
    <origin xyz="2.77001e-14 0.123 -0.0255" rpy="-1.5708 5.43678e-13 5.82627e-14"/>
    <parent link="arm_left_shoulder_roll"/>
    <child link="arm_left_shoulder_yaw"/>
    <axis xyz="0 0 1"/>
    <limit effort="20" velocity="15" lower="-0.785398" upper="0.785398"/>
    <joint_properties friction="0.1"/>
  </joint>
  <!-- Joint from arm_left_shoulder_pitch to arm_left_shoulder_roll -->
  <joint name="arm_left_shoulder_roll_joint" type="revolute">
    <origin xyz="0.0255 -1.44329e-15 0.043" rpy="1.5708 1.309 1.5708"/>
    <parent link="arm_left_shoulder_pitch"/>
    <child link="arm_left_shoulder_roll"/>
    <axis xyz="0 0 1"/>
    <limit effort="20" velocity="15" lower="-0.261799" upper="1.309"/>
    <joint_properties friction="0.1"/>
  </joint>
  <!-- Joint from base to arm_left_shoulder_pitch -->
  <joint name="arm_left_shoulder_pitch_joint" type="revolute">
    <origin xyz="8.30342e-16 0.133 0.764028" rpy="-1.5708 2.36686e-13 -7.66952e-17"/>
    <parent link="base"/>
    <child link="arm_left_shoulder_pitch"/>
    <axis xyz="0 0 1"/>
    <limit effort="20" velocity="15" lower="-1.5708" upper="0.785398"/>
    <joint_properties friction="0.1"/>
  </joint>
  <!-- Link arm_right_shoulder_pitch -->
  <link name="arm_right_shoulder_pitch">
    <inertial>
      <origin xyz="0.00661228 -1.57066e-05 0.0397088" rpy="0 0 0"/>
      <mass value="0.342876"/>
      <inertia ixx="0.000218503" ixy="2.55599e-07" ixz="-1.17928e-05" iyy="0.000260541" iyz="5.72405e-07" izz="0.000224632"/>
    </inertial>
    <!-- Part arm_right_shoulder_pitch_parts -->
    <visual>
      <origin xyz="0.00661228 -1.57066e-05 0.0397088" rpy="-1.5708 -3.33067e-15 -3.14159"/>
      <geometry>
        <mesh filename="./assets/merged/arm_right_shoulder_pitch_visual.stl"/>
      </geometry>
      <material name="arm_right_shoulder_pitch_parts_material">
        <color rgba="0.441363 0.482355 0.421528 1.0"/>
      </material>
    </visual>
  </link>
  <!-- Link arm_right_shoulder_roll -->
  <link name="arm_right_shoulder_roll">
    <inertial>
      <origin xyz="-4.00762e-05 0.0737019 -0.0277329" rpy="0 0 0"/>
      <mass value="0.443945"/>
      <inertia ixx="0.000698118" ixy="-4.07105e-07" ixz="-1.31045e-07" iyy="0.000365437" iyz="-1.56428e-05" izz="0.000568315"/>
    </inertial>
    <!-- Part arm_right_shoulder_roll_parts -->
    <visual>
      <origin xyz="-4.00762e-05 0.0737019 -0.0277329" rpy="1.8326 -1.5708 0"/>
      <geometry>
        <mesh filename="./assets/merged/arm_right_shoulder_roll_visual.stl"/>
      </geometry>
      <material name="arm_right_shoulder_roll_parts_material">
        <color rgba="0.553366 0.585026 0.538047 1.0"/>
      </material>
    </visual>
  </link>
  <!-- Link arm_right_shoulder_yaw -->
  <link name="arm_right_shoulder_yaw">
    <inertial>
      <origin xyz="-0.00781722 -1.63693e-05 0.0404875" rpy="0 0 0"/>
      <mass value="0.329199"/>
      <inertia ixx="0.000195409" ixy="-2.54474e-07" ixz="1.84257e-06" iyy="0.000240827" iyz="-5.40945e-07" izz="0.000214844"/>
    </inertial>
    <!-- Part arm_right_shoulder_yaw_parts -->
    <collision>
      <origin xyz="-2.1684e-16 -1.93193e-15 -0.035" rpy="3.14159 6.61281e-15 6.78624e-14"/>
      <geometry>
        <cylinder length="0.15" radius="0.04"/>
      </geometry>
    </collision>
    <visual>
      <origin xyz="-0.00781722 -1.63693e-05 0.0404875" rpy="-2.87979 -1.70523e-14 1.5708"/>
      <geometry>
        <mesh filename="./assets/merged/arm_right_shoulder_yaw_visual.stl"/>
      </geometry>
      <material name="arm_right_shoulder_yaw_parts_material">
        <color rgba="0.420907 0.463607 0.40026 1.0"/>
      </material>
    </visual>
  </link>
  <!-- Link arm_right_elbow_pitch -->
  <link name="arm_right_elbow_pitch">
    <inertial>
      <origin xyz="-4.00762e-05 0.0737019 -0.0277329" rpy="0 0 0"/>
      <mass value="0.443945"/>
      <inertia ixx="0.000698118" ixy="-4.07105e-07" ixz="-1.31045e-07" iyy="0.000365437" iyz="-1.56428e-05" izz="0.000568315"/>
    </inertial>
    <!-- Part arm_right_elbow_pitch_parts -->
    <visual>
      <origin xyz="-4.00762e-05 0.0737019 -0.0277329" rpy="1.8326 -1.1101e-13 2.90323e-14"/>
      <geometry>
        <mesh filename="./assets/merged/arm_right_elbow_pitch_visual.stl"/>
      </geometry>
      <material name="arm_right_elbow_pitch_parts_material">
        <color rgba="0.553366 0.585026 0.538047 1.0"/>
      </material>
    </visual>
  </link>
  <!-- Link arm_right_elbow_roll -->
  <link name="arm_right_elbow_roll">
    <inertial>
      <origin xyz="-6.0299e-19 2.4885e-17 0.005" rpy="0 0 0"/>
      <mass value="0.000826239"/>
      <inertia ixx="1.20493e-08" ixy="-4.56561e-37" ixz="1.0276e-37" iyy="1.20493e-08" iyz="9.90656e-25" izz="1.0328e-08"/>
    </inertial>
    <!-- Part arm_right_elbow_roll_parts -->
    <collision>
      <origin xyz="-6.74047e-19 3.15807e-17 -0.01" rpy="-3.14159 1.4828e-30 -1.64446e-29"/>
      <geometry>
        <cylinder length="0.12" radius="0.03"/>
      </geometry>
    </collision>
    <visual>
      <origin xyz="-6.0299e-19 5.55112e-17 0.005" rpy="-2.87979 7.47769e-15 3.14159"/>
      <geometry>
        <mesh filename="./assets/merged/arm_right_elbow_roll_visual.stl"/>
      </geometry>
      <material name="arm_right_elbow_roll_parts_material">
        <color rgba="0.917647 0.917647 0.917647 1.0"/>
      </material>
    </visual>
  </link>
  <!-- Link arm_right_hand_link -->
  <link name="arm_right_hand_link">
    <inertial>
      <origin xyz="-0.00248666 0.0134979 -0.0541316" rpy="0 0 0"/>
      <mass value="0.291741"/>
      <inertia ixx="0.000556491" ixy="3.82363e-06" ixz="-2.67254e-06" iyy="0.000494025" iyz="-0.000102102" izz="0.000161723"/>
    </inertial>
    <!-- Part arm_right_hand_link_parts -->
    <visual>
      <origin xyz="-0.00248666 0.0134979 -0.0541316" rpy="0.261799 2.73809e-15 1.5708"/>
      <geometry>
        <mesh filename="./assets/merged/arm_right_hand_link_visual.stl"/>
      </geometry>
      <material name="arm_right_hand_link_parts_material">
        <color rgba="0.309962 0.309962 0.309962 1.0"/>
      </material>
    </visual>
  </link>
  <!-- Joint from arm_right_elbow_roll to arm_right_hand_link -->
  <joint name="arm_hand_r" type="fixed">
    <origin xyz="-6.74047e-19 5.55112e-17 0" rpy="-3.14159 -9.75587e-15 -1.5708"/>
    <parent link="arm_right_elbow_roll"/>
    <child link="arm_right_hand_link"/>
    <axis xyz="0 0 1"/>
    <limit effort="20" velocity="15"/>
    <joint_properties friction="0.1"/>
  </joint>
  <!-- Joint from arm_right_elbow_pitch to arm_right_elbow_roll -->
  <joint name="arm_right_elbow_roll_joint" type="revolute">
    <origin xyz="3.07195e-14 0.123 -0.0255" rpy="1.5708 3.84599e-15 -3.14159"/>
    <parent link="arm_right_elbow_pitch"/>
    <child link="arm_right_elbow_roll"/>
    <axis xyz="0 0 1"/>
    <limit effort="20" velocity="15" lower="-0.785398" upper="0.785398"/>
    <joint_properties friction="0.1"/>
  </joint>
  <!-- Joint from arm_right_shoulder_yaw to arm_right_elbow_pitch -->
  <joint name="arm_right_elbow_pitch_joint" type="revolute">
    <origin xyz="0.0245 6.99949e-15 0.043" rpy="1.5708 1.198e-14 1.5708"/>
    <parent link="arm_right_shoulder_yaw"/>
    <child link="arm_right_elbow_pitch"/>
    <axis xyz="0 0 1"/>
    <limit effort="20" velocity="15" lower="-1.5708" upper="-0"/>
    <joint_properties friction="0.1"/>
  </joint>
  <!-- Joint from arm_right_shoulder_roll to arm_right_shoulder_yaw -->
  <joint name="arm_right_shoulder_yaw_joint" type="revolute">
    <origin xyz="8.10463e-15 0.123 -0.0255" rpy="1.5708 -1.73988e-13 3.14159"/>
    <parent link="arm_right_shoulder_roll"/>
    <child link="arm_right_shoulder_yaw"/>
    <axis xyz="0 0 1"/>
    <limit effort="20" velocity="15" lower="-0.785398" upper="0.785398"/>
    <joint_properties friction="0.1"/>
  </joint>
  <!-- Joint from arm_right_shoulder_pitch to arm_right_shoulder_roll -->
  <joint name="arm_right_shoulder_roll_joint" type="revolute">
    <origin xyz="-0.0255 3.21965e-15 0.043" rpy="1.5708 -1.309 -1.5708"/>
    <parent link="arm_right_shoulder_pitch"/>
    <child link="arm_right_shoulder_roll"/>
    <axis xyz="0 0 1"/>
    <limit effort="20" velocity="15" lower="-1.309" upper="0.261799"/>
    <joint_properties friction="0.1"/>
  </joint>
  <!-- Joint from base to arm_right_shoulder_pitch -->
  <joint name="arm_right_shoulder_pitch_joint" type="revolute">
    <origin xyz="1.14127e-16 -0.133 0.764028" rpy="-1.5708 -5.46706e-15 -3.14159"/>
    <parent link="base"/>
    <child link="arm_right_shoulder_pitch"/>
    <axis xyz="0 0 1"/>
    <limit effort="20" velocity="15" lower="-0.785398" upper="1.5708"/>
    <joint_properties friction="0.1"/>
  </joint>
  <!-- Link leg_left_hip_roll -->
  <link name="leg_left_hip_roll">
    <inertial>
      <origin xyz="-0.00410941 -0.000112596 -0.0464623" rpy="0 0 0"/>
      <mass value="0.83786"/>
      <inertia ixx="0.000979918" ixy="6.45954e-06" ixz="-1.63173e-05" iyy="0.000896043" iyz="-5.43389e-06" izz="0.000727678"/>
    </inertial>
    <!-- Part leg_left_hip_roll_parts -->
    <visual>
      <origin xyz="-0.00410941 -0.000112596 -0.0464623" rpy="-9.35706e-15 -0.785398 1.19419e-14"/>
      <geometry>
        <mesh filename="./assets/merged/leg_left_hip_roll_visual.stl"/>
      </geometry>
      <material name="leg_left_hip_roll_parts_material">
        <color rgba="0.514202 0.546917 0.498371 1.0"/>
      </material>
    </visual>
  </link>
  <!-- Link leg_left_hip_yaw -->
  <link name="leg_left_hip_yaw">
    <inertial>
      <origin xyz="-0.00411632 -8.63203e-05 0.0463382" rpy="0 0 0"/>
      <mass value="0.837683"/>
      <inertia ixx="0.000979031" ixy="-1.13217e-06" ixz="1.96352e-05" iyy="0.000898166" iyz="-5.91541e-06" izz="0.000724287"/>
    </inertial>
    <!-- Part leg_left_hip_yaw_parts -->
    <visual>
      <origin xyz="-0.00411632 -8.63203e-05 0.0463382" rpy="-3.14159 -0.785398 -1.5708"/>
      <geometry>
        <mesh filename="./assets/merged/leg_left_hip_yaw_visual.stl"/>
      </geometry>
      <material name="leg_left_hip_yaw_parts_material">
        <color rgba="0.514113 0.546836 0.49828 1.0"/>
      </material>
    </visual>
  </link>
  <!-- Link leg_left_hip_pitch -->
  <link name="leg_left_hip_pitch">
    <inertial>
      <origin xyz="0.0030405 0.120388 0.0210924" rpy="0 0 0"/>
      <mass value="0.947974"/>
      <inertia ixx="0.00286449" ixy="0.00012235" ixz="-2.15676e-05" iyy="0.00102465" iyz="0.000265775" izz="0.00259958"/>
    </inertial>
    <!-- Part leg_left_hip_pitch_parts -->
    <collision>
      <origin xyz="0.00597627 0.039 0.0295" rpy="1.5708 1.5708 0"/>
      <geometry>
        <cylinder length="0.13" radius="0.05"/>
      </geometry>
    </collision>
    <visual>
      <origin xyz="0.0030405 0.120388 0.0210924" rpy="1.5708 -7.461e-15 -3.10862e-15"/>
      <geometry>
        <mesh filename="./assets/merged/leg_left_hip_pitch_visual.stl"/>
      </geometry>
      <material name="leg_left_hip_pitch_parts_material">
        <color rgba="0.562885 0.5918 0.548895 1.0"/>
      </material>
    </visual>
  </link>
  <!-- Link leg_left_knee_pitch -->
  <link name="leg_left_knee_pitch">
    <inertial>
      <origin xyz="-4.14041e-05 -0.112249 0.0257397" rpy="0 0 0"/>
      <mass value="0.653864"/>
      <inertia ixx="0.00230126" ixy="-4.24923e-07" ixz="1.36589e-06" iyy="0.000559753" iyz="3.7889e-05" izz="0.00203727"/>
    </inertial>
    <!-- Part leg_left_knee_pitch_parts -->
    <collision>
      <origin xyz="-5.41812e-15 -0.115 0.022" rpy="-1.5708 1.5708 0"/>
      <geometry>
        <cylinder length="0.15" radius="0.04"/>
      </geometry>
    </collision>
    <visual>
      <origin xyz="-4.14041e-05 -0.112249 0.0257397" rpy="1.5708 -7.28874e-15 3.14159"/>
      <geometry>
        <mesh filename="./assets/merged/leg_left_knee_pitch_visual.stl"/>
      </geometry>
      <material name="leg_left_knee_pitch_parts_material">
        <color rgba="0.664553 0.686049 0.654152 1.0"/>
      </material>
    </visual>
  </link>
  <!-- Link leg_left_ankle_pitch -->
  <link name="leg_left_ankle_pitch">
    <inertial>
      <origin xyz="0.0131065 0.0273743 0.0274153" rpy="0 0 0"/>
      <mass value="0.106196"/>
      <inertia ixx="0.000188241" ixy="-2.50802e-05" ixz="-7.26755e-06" iyy="0.000142962" iyz="-7.72963e-06" izz="8.17202e-05"/>
    </inertial>
    <!-- Part leg_left_ankle_pitch_parts -->
    <visual>
      <origin xyz="0.0131065 0.0273743 0.0274153" rpy="1.5708 5.92291e-15 -2.07873e-13"/>
      <geometry>
        <mesh filename="./assets/merged/leg_left_ankle_pitch_visual.stl"/>
      </geometry>
      <material name="leg_left_ankle_pitch_parts_material">
        <color rgba="0.866867 0.866867 0.866867 1.0"/>
      </material>
    </visual>
  </link>
  <!-- Link leg_left_ankle_roll -->
  <link name="leg_left_ankle_roll">
    <inertial>
      <origin xyz="2.29341e-05 0.0226611 0.0197836" rpy="0 0 0"/>
      <mass value="0.706476"/>
      <inertia ixx="0.00198705" ixy="5.37011e-07" ixz="-8.3949e-07" iyy="0.00190341" iyz="0.000143151" izz="0.000619673"/>
    </inertial>
    <!-- Part leg_left_ankle_roll_parts -->
    <collision>
      <origin xyz="1.4526e-14 0.03 0.006" rpy="1.5708 -1.57874e-13 -6.89359e-14"/>
      <geometry>
        <box size="0.072 0.22 0.04"/>
      </geometry>
    </collision>
    <visual>
      <origin xyz="2.29341e-05 0.0226611 0.0197836" rpy="1.5708 -1.5708 0"/>
      <geometry>
        <mesh filename="./assets/merged/leg_left_ankle_roll_visual.stl"/>
      </geometry>
      <material name="leg_left_ankle_roll_parts_material">
        <color rgba="0.694564 0.714459 0.684938 1.0"/>
      </material>
    </visual>
  </link>
  <!-- Joint from leg_left_ankle_pitch to leg_left_ankle_roll -->
  <joint name="leg_left_ankle_roll_joint" type="revolute">
    <origin xyz="0.03 0.05 0.025" rpy="-6.80837e-17 1.5708 0"/>
    <parent link="leg_left_ankle_pitch"/>
    <child link="leg_left_ankle_roll"/>
    <axis xyz="0 0 1"/>
    <limit effort="20" velocity="15" lower="-0.261799" upper="0.261799"/>
    <joint_properties friction="0.1"/>
  </joint>
  <!-- Joint from leg_left_knee_pitch to leg_left_ankle_pitch -->
  <joint name="leg_left_ankle_pitch_joint" type="revolute">
    <origin xyz="-2.44769e-15 -0.16 -0.003" rpy="1.34337e-14 -1.32117e-14 -3.14159"/>
    <parent link="leg_left_knee_pitch"/>
    <child link="leg_left_ankle_pitch"/>
    <axis xyz="0 0 1"/>
    <limit effort="20" velocity="15" lower="-0.785398" upper="0.785398"/>
    <joint_properties friction="0.1"/>
  </joint>
  <!-- Joint from leg_left_hip_pitch to leg_left_knee_pitch -->
  <joint name="leg_left_knee_pitch_joint" type="revolute">
    <origin xyz="4.04191e-16 0.15 -0.018" rpy="1.40516e-29 1.72255e-16 -3.14159"/>
    <parent link="leg_left_hip_pitch"/>
    <child link="leg_left_knee_pitch"/>
    <axis xyz="0 0 1"/>
    <limit effort="20" velocity="15" lower="-3.16192e-13" upper="2.44346"/>
    <joint_properties friction="0.1"/>
  </joint>
  <!-- Joint from leg_left_hip_yaw to leg_left_hip_pitch -->
  <joint name="leg_left_hip_pitch_joint" type="revolute">
    <origin xyz="0.027 -1.11022e-16 0.052" rpy="1.5708 -0.785398 -1.5708"/>
    <parent link="leg_left_hip_yaw"/>
    <child link="leg_left_hip_pitch"/>
    <axis xyz="0 0 1"/>
    <limit effort="20" velocity="15" lower="-1.89805" upper="0.981748"/>
    <joint_properties friction="0.1"/>
  </joint>
  <!-- Joint from leg_left_hip_roll to leg_left_hip_yaw -->
  <joint name="leg_left_hip_yaw_joint" type="revolute">
    <origin xyz="0.027 0 -0.052" rpy="-1.5708 -1.63347e-15 -1.5708"/>
    <parent link="leg_left_hip_roll"/>
    <child link="leg_left_hip_yaw"/>
    <axis xyz="0 0 1"/>
    <limit effort="20" velocity="15" lower="-0.981748" upper="0.589049"/>
    <joint_properties friction="0.1"/>
  </joint>
  <!-- Joint from base to leg_left_hip_roll -->
  <joint name="leg_left_hip_roll_joint" type="revolute">
    <origin xyz="-0.0290919 0.08 0.542631" rpy="2.21613e-15 0.785398 -7.34556e-15"/>
    <parent link="base"/>
    <child link="leg_left_hip_roll"/>
    <axis xyz="0 0 1"/>
    <limit effort="20" velocity="15" lower="-0.174533" upper="1.5708"/>
    <joint_properties friction="0.1"/>
  </joint>
  <!-- Link leg_right_hip_roll -->
  <link name="leg_right_hip_roll">
    <inertial>
      <origin xyz="0.00410941 -0.00018505 -0.0464478" rpy="0 0 0"/>
      <mass value="0.83786"/>
      <inertia ixx="0.000979766" ixy="-3.69135e-06" ixz="1.57667e-05" iyy="0.000896334" iyz="-4.74708e-06" izz="0.000727235"/>
    </inertial>
    <!-- Part leg_right_hip_roll_parts -->
    <visual>
      <origin xyz="0.00410941 -0.00018505 -0.0464478" rpy="-9.76523e-15 -0.785398 -3.14159"/>
      <geometry>
        <mesh filename="./assets/merged/leg_right_hip_roll_visual.stl"/>
      </geometry>
      <material name="leg_right_hip_roll_parts_material">
        <color rgba="0.514202 0.546917 0.498371 1.0"/>
      </material>
    </visual>
  </link>
  <!-- Link leg_right_hip_yaw -->
  <link name="leg_right_hip_yaw">
    <inertial>
      <origin xyz="0.00411632 -1.3851e-05 0.0463238" rpy="0 0 0"/>
      <mass value="0.837683"/>
      <inertia ixx="0.000978901" ixy="-1.63559e-06" ixz="-1.90847e-05" iyy="0.000898454" iyz="-5.23378e-06" izz="0.000723868"/>
    </inertial>
    <!-- Part leg_right_hip_yaw_parts -->
    <visual>
      <origin xyz="0.00411632 -1.3851e-05 0.0463238" rpy="-3.14159 -0.785398 -1.5708"/>
      <geometry>
        <mesh filename="./assets/merged/leg_right_hip_yaw_visual.stl"/>
      </geometry>
      <material name="leg_right_hip_yaw_parts_material">
        <color rgba="0.514113 0.546836 0.49828 1.0"/>
      </material>
    </visual>
  </link>
  <!-- Link leg_right_hip_pitch -->
  <link name="leg_right_hip_pitch">
    <inertial>
      <origin xyz="0.00319928 0.120388 -0.0210924" rpy="0 0 0"/>
      <mass value="0.947974"/>
      <inertia ixx="0.00286448" ixy="0.000117078" ixz="2.6845e-05" iyy="0.00102371" iyz="-0.000265774" izz="0.00259864"/>
    </inertial>
    <!-- Part leg_right_hip_pitch_parts -->
    <collision>
      <origin xyz="0.00597627 0.039 -0.0295" rpy="1.5708 1.5708 0"/>
      <geometry>
        <cylinder length="0.13" radius="0.05"/>
      </geometry>
    </collision>
    <visual>
      <origin xyz="0.00319928 0.120388 -0.0210924" rpy="1.5708 -6.71544e-15 -2.48065e-15"/>
      <geometry>
        <mesh filename="./assets/merged/leg_right_hip_pitch_visual.stl"/>
      </geometry>
      <material name="leg_right_hip_pitch_parts_material">
        <color rgba="0.562885 0.5918 0.548895 1.0"/>
      </material>
    </visual>
  </link>
  <!-- Link leg_right_knee_pitch -->
  <link name="leg_right_knee_pitch">
    <inertial>
      <origin xyz="-5.09429e-05 0.112249 -0.0257397" rpy="0 0 0"/>
      <mass value="0.653864"/>
      <inertia ixx="0.00230126" ixy="1.34936e-06" ixz="-1.17826e-06" iyy="0.000559752" iyz="3.7889e-05" izz="0.00203727"/>
    </inertial>
    <!-- Part leg_right_knee_pitch_parts -->
    <collision>
      <origin xyz="1.15514e-14 0.115 -0.022" rpy="1.5708 1.5708 0"/>
      <geometry>
        <cylinder length="0.15" radius="0.04"/>
      </geometry>
    </collision>
    <visual>
      <origin xyz="-5.09429e-05 0.112249 -0.0257397" rpy="1.5708 -6.95618e-15 -2.56528e-15"/>
      <geometry>
        <mesh filename="./assets/merged/leg_right_knee_pitch_visual.stl"/>
      </geometry>
      <material name="leg_right_knee_pitch_parts_material">
        <color rgba="0.664553 0.686049 0.654152 1.0"/>
      </material>
    </visual>
  </link>
  <!-- Link leg_right_ankle_pitch -->
  <link name="leg_right_ankle_pitch">
    <inertial>
      <origin xyz="0.0131065 0.0273743 -0.0274153" rpy="0 0 0"/>
      <mass value="0.106196"/>
      <inertia ixx="0.000188241" ixy="-2.50802e-05" ixz="7.26754e-06" iyy="0.000142962" iyz="7.72962e-06" izz="8.17203e-05"/>
    </inertial>
    <!-- Part leg_right_ankle_pitch_parts -->
    <visual>
      <origin xyz="0.0131065 0.0273743 -0.0274153" rpy="1.5708 -6.79537e-15 1.09692e-13"/>
      <geometry>
        <mesh filename="./assets/merged/leg_right_ankle_pitch_visual.stl"/>
      </geometry>
      <material name="leg_right_ankle_pitch_parts_material">
        <color rgba="0.866867 0.866867 0.866867 1.0"/>
      </material>
    </visual>
  </link>
  <!-- Link leg_right_ankle_roll -->
  <link name="leg_right_ankle_roll">
    <inertial>
      <origin xyz="2.29341e-05 0.0226611 0.0197836" rpy="0 0 0"/>
      <mass value="0.706476"/>
      <inertia ixx="0.00198705" ixy="5.37011e-07" ixz="-8.3949e-07" iyy="0.00190341" iyz="0.000143151" izz="0.000619673"/>
    </inertial>
    <!-- Part leg_right_ankle_roll_parts -->
    <collision>
      <origin xyz="6.38304e-15 0.03 0.006" rpy="1.5708 4.48974e-13 -2.11051e-13"/>
      <geometry>
        <box size="0.072 0.22 0.04"/>
      </geometry>
    </collision>
    <visual>
      <origin xyz="2.29341e-05 0.0226611 0.0197836" rpy="1.5708 -1.5708 0"/>
      <geometry>
        <mesh filename="./assets/merged/leg_right_ankle_roll_visual.stl"/>
      </geometry>
      <material name="leg_right_ankle_roll_parts_material">
        <color rgba="0.694564 0.714459 0.684938 1.0"/>
      </material>
    </visual>
  </link>
  <!-- Joint from leg_right_ankle_pitch to leg_right_ankle_roll -->
  <joint name="leg_right_ankle_roll_joint" type="revolute">
    <origin xyz="0.03 0.05 -0.025" rpy="-6.80837e-17 1.5708 0"/>
    <parent link="leg_right_ankle_pitch"/>
    <child link="leg_right_ankle_roll"/>
    <axis xyz="0 0 1"/>
    <limit effort="20" velocity="15" lower="-0.261799" upper="0.261799"/>
    <joint_properties friction="0.1"/>
  </joint>
  <!-- Joint from leg_right_knee_pitch to leg_right_ankle_pitch -->
  <joint name="leg_right_ankle_pitch_joint" type="revolute">
    <origin xyz="1.42421e-15 0.16 0.003" rpy="-2.22045e-16 -1.60812e-16 -1.12257e-13"/>
    <parent link="leg_right_knee_pitch"/>
    <child link="leg_right_ankle_pitch"/>
    <axis xyz="0 0 1"/>
    <limit effort="20" velocity="15" lower="-0.785398" upper="0.785398"/>
    <joint_properties friction="0.1"/>
  </joint>
  <!-- Joint from leg_right_hip_pitch to leg_right_knee_pitch -->
  <joint name="leg_right_knee_pitch_joint" type="revolute">
    <origin xyz="0 0.15 0.018" rpy="3.21091e-16 2.40745e-16 8.46265e-17"/>
    <parent link="leg_right_hip_pitch"/>
    <child link="leg_right_knee_pitch"/>
    <axis xyz="0 0 1"/>
    <limit effort="20" velocity="15" lower="-1.08358e-13" upper="2.44346"/>
    <joint_properties friction="0.1"/>
  </joint>
  <!-- Joint from leg_right_hip_yaw to leg_right_hip_pitch -->
  <joint name="leg_right_hip_pitch_joint" type="revolute">
    <origin xyz="-0.027 -2.22045e-16 0.052" rpy="1.5708 -0.785398 -1.5708"/>
    <parent link="leg_right_hip_yaw"/>
    <child link="leg_right_hip_pitch"/>
    <axis xyz="0 0 1"/>
    <limit effort="20" velocity="15" lower="-1.89805" upper="0.981748"/>
    <joint_properties friction="0.1"/>
  </joint>
  <!-- Joint from leg_right_hip_roll to leg_right_hip_yaw -->
  <joint name="leg_right_hip_yaw_joint" type="revolute">
    <origin xyz="-0.027 -1.38778e-17 -0.052" rpy="-1.5708 4.7846e-16 1.5708"/>
    <parent link="leg_right_hip_roll"/>
    <child link="leg_right_hip_yaw"/>
    <axis xyz="0 0 1"/>
    <limit effort="20" velocity="15" lower="-0.589049" upper="0.981748"/>
    <joint_properties friction="0.1"/>
  </joint>
  <!-- Joint from base to leg_right_hip_roll -->
  <joint name="leg_right_hip_roll_joint" type="revolute">
    <origin xyz="-0.0290919 -0.08 0.542631" rpy="-1.75261e-15 -0.785398 3.14159"/>
    <parent link="base"/>
    <child link="leg_right_hip_roll"/>
    <axis xyz="0 0 1"/>
    <limit effort="20" velocity="15" lower="-1.5708" upper="0.174533"/>
    <joint_properties friction="0.1"/>
  </joint>
</robot>
