<?xml version="1.0" ?>
<robot name="sysID_XC430">
  <link name="xc430">
    <visual>
      <origin xyz="0 0 0" rpy="0 -0 0"/>
      <geometry>
        <mesh filename="package:///meshes/xc430_visual.stl"/>
      </geometry>
      <material name="xc430_material">
        <color rgba="0.44786462886842598463 0.53733448957467955243 0.69800988116095863401 1.0"/>
      </material>
    </visual>
    <collision>
      <origin xyz="0 0 0" rpy="0 -0 0"/>
      <geometry>
        <mesh filename="package:///meshes/xc430_collision.stl"/>
      </geometry>
    </collision>
    <inertial>
      <origin xyz="0.0709224439626469777 0.016712412139443660886 0.005543011911192575851" rpy="0 0 0"/>
      <mass value="0.086449999993020193445"/>
      <inertia ixx="2.7835937895289603625e-05" ixy="-5.7442278246997916427e-06" ixz="-3.9581376465514811914e-08" iyy="2.9061697096171224734e-05" iyz="-5.0973493978072746798e-08" izz="4.324213417779756573e-05"/>
    </inertial>
  </link>

  <link name="arm_430">
    <visual>
      <origin xyz="0 0 0" rpy="0 -0 0"/>
      <geometry>
        <mesh filename="package:///meshes/arm_430_visual.stl"/>
      </geometry>
      <material name="arm_430_material">
        <color rgba="0.63059283987567626983 0.65298952457695413898 0.67418901807298270423 1.0"/>
      </material>
    </visual>
    <collision>
      <origin xyz="0 0 0" rpy="0 -0 0"/>
      <geometry>
        <mesh filename="package:///meshes/arm_430_collision.stl"/>
      </geometry>
    </collision>
    <inertial>
      <origin xyz="-0.077790387031996310885 1.3637865612734206139e-05 -0.018999999999999978711" rpy="0 0 0"/>
      <mass value="0.25549999999999994937"/>
      <inertia ixx="0.00024426144376378929003" ixy="-9.401585883161292486e-08" ixz="5.3560758525686012555e-20" iyy="0.00041073874164067591128" iyz="1.4659063207649052332e-16" izz="0.00022084196523238823419"/>
    </inertial>
  </link>

  <joint name="joint_0" type="revolute">
    <origin xyz="0.054999999999999681088 0.032699857927858962114 0.0055693959459660142761" rpy="1.57079632679489678 -5.5511151231258061214e-17 -1.5707963267948972241"/>
    <parent link="xc430"/>
    <child link="arm_430"/>
    <axis xyz="0 0 1"/>
    <limit effort="1" velocity="20" lower="-1.570796326794896558" upper="1.570796326794896558"/>
    <joint_properties friction="0.0"/>
  </joint>


</robot>