<?xml version="1.0" ?><robot name="toddlerbot">  
  <link name="torso">    
    <visual>      
      <origin xyz="0 0 0" rpy="0 -0 0"/>      
      <geometry>        
        <mesh filename="package:///meshes/torso_visual.stl"/>        
      </geometry>      
      <material name="torso_material">        
        <color rgba="0.63761324738265878764 0.79140018897832431488 0.89744804913511877498 1.0"/>        
      </material>      
    </visual>    
    <collision>      
      <origin xyz="0 0 0" rpy="0 -0 0"/>      
      <geometry>        
        <mesh filename="package:///meshes/torso_collision.stl"/>        
      </geometry>      
    </collision>    
    <inertial>      
      <origin xyz="-0.0045319089141771552731 -0.0033046849194455856467 0.065594108502290693341" rpy="0 0 0"/>      
      <mass value="1.1369659631012025702"/>      
      <inertia ixx="0.0029825917743578666055" ixy="8.1730614288441110122e-05" ixz="2.1951370741857685305e-05" iyy="0.0023969506399989372152" iyz="-2.9575017351927617657e-05" izz="0.0025126356523908575241"/>      
    </inertial>    
  </link>  

  <link name="spur_1m_20t">    
    <visual>      
      <origin xyz="0 0 0" rpy="0 -0 0"/>      
      <geometry>        
        <mesh filename="package:///meshes/spur_1m_20t_visual.stl"/>        
      </geometry>      
      <material name="spur_1m_20t_material">        
        <color rgba="0.64705882352941179736 0.64705882352941179736 0.64705882352941179736 1.0"/>        
      </material>      
    </visual>    
    <collision>      
      <origin xyz="0 0 0" rpy="0 -0 0"/>      
      <geometry>        
        <mesh filename="package:///meshes/spur_1m_20t_collision.stl"/>        
      </geometry>      
    </collision>    
    <inertial>      
      <origin xyz="-2.9273600019542193503e-19 -8.407168954226882874e-18 0.003384232105434467619" rpy="0 0 0"/>      
      <mass value="0.0015778025963745997712"/>      
      <inertia ixx="4.5874424196602084909e-08" ixy="3.9290914639085633501e-24" ixz="-7.1097175513400442172e-39" iyy="4.5874424196602058439e-08" iyz="7.8419015231486113446e-38" izz="8.1737050837173876176e-08"/>      
    </inertial>    
  </link>  

  <joint name="neck_yaw_drive" type="revolute">    
    <origin xyz="-0.0049999999999995221878 3.1860588521011854095e-18 0.12148651076281755112" rpy="1.1607298201443905188e-14 1.6509758832059179101e-15 -5.3832337592600790636e-15"/>    
    <parent link="torso"/>    
    <child link="spur_1m_20t"/>    
    <axis xyz="0 0 1"/>    
    <limit effort="1" velocity="20" lower="-2.8797932657906435416" upper="2.8797932657906435416"/>    
    <joint_properties friction="0.0"/>    
  </joint>  

  <link name="neck_yaw_link_v2">    
    <visual>      
      <origin xyz="0 0 0" rpy="0 -0 0"/>      
      <geometry>        
        <mesh filename="package:///meshes/neck_yaw_link_v2_visual.stl"/>        
      </geometry>      
      <material name="neck_yaw_link_v2_material">        
        <color rgba="0.2313725490196078538 0.38039215686274507888 0.70588235294117662733 1.0"/>        
      </material>      
    </visual>    
    <collision>      
      <origin xyz="0 0 0" rpy="0 -0 0"/>      
      <geometry>        
        <mesh filename="package:///meshes/neck_yaw_link_v2_collision.stl"/>        
      </geometry>      
    </collision>    
    <inertial>      
      <origin xyz="-1.1403990895369493244e-06 -1.1841855614897924462e-10 0.0082571849701004972066" rpy="0 0 0"/>      
      <mass value="0.0067298837334394089049"/>      
      <inertia ixx="5.2266067624768086445e-07" ixy="-6.3046403327810586846e-15" ixz="1.1949403084466817268e-09" iyy="6.1218519979556588152e-07" iyz="-2.6012871962819705841e-15" izz="2.8062851709981924551e-07"/>      
    </inertial>    
  </link>  

  <link name="head">    
    <visual>      
      <origin xyz="0 0 0" rpy="0 -0 0"/>      
      <geometry>        
        <mesh filename="package:///meshes/head_visual.stl"/>        
      </geometry>      
      <material name="head_material">        
        <color rgba="0.62873939703496806164 0.79364291305093481732 0.87330110949792516539 1.0"/>        
      </material>      
    </visual>    
    <collision>      
      <origin xyz="0 0 0" rpy="0 -0 0"/>      
      <geometry>        
        <mesh filename="package:///meshes/head_collision.stl"/>        
      </geometry>      
    </collision>    
    <inertial>      
      <origin xyz="-0.045316002313821462932 -0.011276855645191824137 -0.0010251236602530945652" rpy="0 0 0"/>      
      <mass value="0.13722101760550831084"/>      
      <inertia ixx="0.000118808072940447212" ixy="1.1390016804751208719e-06" ixz="1.8378816154934639505e-06" iyy="0.00010489076115432989294" iyz="-9.2536559812160098181e-06" izz="9.1894624061612158465e-05"/>      
    </inertial>    
  </link>  

  <link name="motor_plate">    
    <visual>      
      <origin xyz="0 0 0" rpy="0 -0 0"/>      
      <geometry>        
        <mesh filename="package:///meshes/motor_plate_visual.stl"/>        
      </geometry>      
      <material name="motor_plate_material">        
        <color rgba="0.64705882352941179736 0.64705882352941179736 0.64705882352941179736 1.0"/>        
      </material>      
    </visual>    
    <collision>      
      <origin xyz="0 0 0" rpy="0 -0 0"/>      
      <geometry>        
        <mesh filename="package:///meshes/motor_plate_collision.stl"/>        
      </geometry>      
    </collision>    
    <inertial>      
      <origin xyz="-6.9388939039072283776e-18 -1.3877787807814456755e-17 -0.0028281768943845498818" rpy="0 0 0"/>      
      <mass value="0.0017000000000000001221"/>      
      <inertia ixx="4.805029073310371698e-08" ixy="1.0773753257370504076e-09" ixz="-3.1068233712543829119e-36" iyy="5.1782428339099010347e-08" iyz="8.7873943139860781386e-38" izz="9.2194729037862249329e-08"/>      
    </inertial>    
  </link>  

  <link name="bearing_683">    
    <visual>      
      <origin xyz="0 0 0" rpy="0 -0 0"/>      
      <geometry>        
        <mesh filename="package:///meshes/bearing_683_visual.stl"/>        
      </geometry>      
      <material name="bearing_683_material">        
        <color rgba="0.64705882352941179736 0.64705882352941179736 0.64705882352941179736 1.0"/>        
      </material>      
    </visual>    
    <collision>      
      <origin xyz="0 0 0" rpy="0 -0 0"/>      
      <geometry>        
        <mesh filename="package:///meshes/bearing_683_collision.stl"/>        
      </geometry>      
    </collision>    
    <inertial>      
      <origin xyz="1.3985108750766809383e-17 2.4186774283164997703e-19 -0.0015499999999999995118" rpy="0 0 0"/>      
      <mass value="0.00048694686130641793437"/>      
      <inertia ixx="2.1551456503319895657e-09" ixy="2.9047882901138312047e-26" ixz="-1.1228933808335255921e-37" iyy="2.1551456503319883249e-09" iyz="-1.3368752562953336429e-37" izz="3.5303647444715322361e-09"/>      
    </inertial>    
  </link>  

  <joint name="neck_pitch_front_rev_2" type="revolute">    
    <origin xyz="-0.0019411428382689055461 -0.0072444436971680192111 -0.0055000000000000005482" rpy="1.0718125710358602429e-14 -4.311384292830508141e-15 0.88076594287798393168"/>    
    <parent link="motor_plate"/>    
    <child link="bearing_683"/>    
    <axis xyz="0 0 1"/>    
    <limit effort="1" velocity="20" lower="-6.283185307179586232" upper="6.283185307179586232"/>    
    <joint_properties friction="0.0"/>    
  </joint>  

  <link name="bearing_683_2">    
    <visual>      
      <origin xyz="0 0 0" rpy="0 -0 0"/>      
      <geometry>        
        <mesh filename="package:///meshes/bearing_683_2_visual.stl"/>        
      </geometry>      
      <material name="bearing_683_2_material">        
        <color rgba="0.64705882352941179736 0.64705882352941179736 0.64705882352941179736 1.0"/>        
      </material>      
    </visual>    
    <collision>      
      <origin xyz="0 0 0" rpy="0 -0 0"/>      
      <geometry>        
        <mesh filename="package:///meshes/bearing_683_2_collision.stl"/>        
      </geometry>      
    </collision>    
    <inertial>      
      <origin xyz="1.3985108750766830954e-17 2.4186774283160303249e-19 -0.0015499999999999990782" rpy="0 0 0"/>      
      <mass value="0.00048694686130641793437"/>      
      <inertia ixx="2.1551456503319879113e-09" ixy="-2.1975945182776963045e-25" ixz="-2.7042340431588615727e-39" iyy="2.1551456503319883249e-09" iyz="2.2478231163415180367e-39" izz="3.5303647444715305817e-09"/>      
    </inertial>    
  </link>  

  <joint name="neck_pitch_back_rev_2" type="revolute">    
    <origin xyz="0.0019411428382688777905 0.007244443697168007068 -0.0055000000000000014155" rpy="-2.5111971789710972494e-13 -1.8026647498047445117e-13 0.87787101658584032471"/>    
    <parent link="motor_plate"/>    
    <child link="bearing_683_2"/>    
    <axis xyz="0 0 1"/>    
    <limit effort="1" velocity="20" lower="-6.283185307179586232" upper="6.283185307179586232"/>    
    <joint_properties friction="0.0"/>    
  </joint>  

  <joint name="neck_pitch_act" type="revolute">    
    <origin xyz="-0.032615697718560709983 -0.027000000000000058675 0.0024999999999998486974" rpy="-3.1415926535897655825 -3.1199051560142798919e-13 -3.141592653589449835"/>    
    <parent link="head"/>    
    <child link="motor_plate"/>    
    <axis xyz="0 0 1"/>    
    <limit effort="1" velocity="20" lower="-1.3962634015954635824" upper="0.61086523819801530344"/>    
    <joint_properties friction="0.0"/>    
  </joint>  

  <joint name="neck_pitch" type="revolute">    
    <origin xyz="-1.1796119636642288242e-16 0.0040000000000001215139 0.019400000000000056088" rpy="-1.5707963267904627713 1.5671692223466835436 -3.1415926535886637971"/>    
    <parent link="neck_yaw_link_v2"/>    
    <child link="head"/>    
    <axis xyz="0 0 1"/>    
    <limit effort="1" velocity="20" lower="-1.3962634015954635824" upper="0.61086523819801530344"/>    
    <joint_properties friction="0.0"/>    
  </joint>  

  <link name="neck_rod">    
    <visual>      
      <origin xyz="0 0 0" rpy="0 -0 0"/>      
      <geometry>        
        <mesh filename="package:///meshes/neck_rod_visual.stl"/>        
      </geometry>      
      <material name="neck_rod_material">        
        <color rgba="0.62051618944235187314 0.78640765248647570562 0.88594253031295011613 1.0"/>        
      </material>      
    </visual>    
    <collision>      
      <origin xyz="0 0 0" rpy="0 -0 0"/>      
      <geometry>        
        <mesh filename="package:///meshes/neck_rod_collision.stl"/>        
      </geometry>      
    </collision>    
    <inertial>      
      <origin xyz="0.017942953356019489264 -4.2302323070087306963e-05 -0.0016023848482628068844" rpy="0 0 0"/>      
      <mass value="0.0031629468613064174939"/>      
      <inertia ixx="1.6183187611801101548e-08" ixy="4.3686324090029618003e-10" ixz="5.4098718288322473511e-10" iyy="7.9430220338147421456e-07" iyz="-1.2754318974832872697e-12" izz="8.0573905690508686904e-07"/>      
    </inertial>    
  </link>  

  <joint name="neck_pitch_front_rev_1" type="revolute">    
    <origin xyz="-0.0072444436971684355447 -0.0040000000000001197792 0.017458857161731233809" rpy="1.5707963267946454256 -0.88439304732584833602 -3.1415926535894400651"/>    
    <parent link="neck_yaw_link_v2"/>    
    <child link="neck_rod"/>    
    <axis xyz="0 0 1"/>    
    <limit effort="1" velocity="20" lower="-6.283185307179586232" upper="6.283185307179586232"/>    
    <joint_properties friction="0.0"/>    
  </joint>  

  <link name="neck_rod_2">    
    <visual>      
      <origin xyz="0 0 0" rpy="0 -0 0"/>      
      <geometry>        
        <mesh filename="package:///meshes/neck_rod_2_visual.stl"/>        
      </geometry>      
      <material name="neck_rod_2_material">        
        <color rgba="0.62051618944235187314 0.78640765248647570562 0.88594253031295011613 1.0"/>        
      </material>      
    </visual>    
    <collision>      
      <origin xyz="0 0 0" rpy="0 -0 0"/>      
      <geometry>        
        <mesh filename="package:///meshes/neck_rod_2_collision.stl"/>        
      </geometry>      
    </collision>    
    <inertial>      
      <origin xyz="0.017901072327984525467 4.2302323074025779774e-05 -0.0016023848482717029801" rpy="0 0 0"/>      
      <mass value="0.0031629468613064174939"/>      
      <inertia ixx="1.6183187611802534225e-08" ixy="-4.3584354918256844597e-10" ixz="5.3972445329300678928e-10" iyy="7.9343818800628575981e-07" iyz="1.2754318717552505803e-12" izz="8.0487504152986580352e-07"/>      
    </inertial>    
  </link>  

  <joint name="neck_pitch_back_rev_1" type="revolute">    
    <origin xyz="0.0072444436971682013571 -0.0040000000000001362591 0.021341142838269100412" rpy="1.5707963267949220931 -0.8814981210337055062 3.1415926535897904515"/>    
    <parent link="neck_yaw_link_v2"/>    
    <child link="neck_rod_2"/>    
    <axis xyz="0 0 1"/>    
    <limit effort="1" velocity="20" lower="-6.283185307179586232" upper="6.283185307179586232"/>    
    <joint_properties friction="0.0"/>    
  </joint>  

  <joint name="neck_yaw_driven" type="revolute">    
    <origin xyz="0.016000000000000621364 3.9122381713629107253e-19 0.12248651076281739936" rpy="1.5470695466536949876e-14 -3.0902695541116811913e-15 -8.6007558735577539147e-16"/>    
    <parent link="torso"/>    
    <child link="neck_yaw_link_v2"/>    
    <axis xyz="0 0 1"/>    
    <limit effort="1" velocity="20" lower="-2.6179938779914944114" upper="2.6179938779914944114"/>    
    <joint_properties friction="0.0"/>    
  </joint>  

  <link name="waist_gears">    
    <visual>      
      <origin xyz="0 0 0" rpy="0 -0 0"/>      
      <geometry>        
        <mesh filename="package:///meshes/waist_gears_visual.stl"/>        
      </geometry>      
      <material name="waist_gears_material">        
        <color rgba="0.29673072126509869584 0.50090014891145351328 0.63316042503557934396 1.0"/>        
      </material>      
    </visual>    
    <collision>      
      <origin xyz="0 0 0" rpy="0 -0 0"/>      
      <geometry>        
        <mesh filename="package:///meshes/waist_gears_collision.stl"/>        
      </geometry>      
    </collision>    
    <inertial>      
      <origin xyz="-2.9089024309418600146e-07 5.5035553755051287407e-08 -0.012592985430860502774" rpy="0 0 0"/>      
      <mass value="0.026337180140419174518"/>      
      <inertia ixx="1.5367047941033374527e-06" ixy="1.8828487088222486339e-11" ixz="4.0600521957845183714e-10" iyy="7.302471227545066429e-06" iyz="3.2911737843456854381e-12" izz="6.9859065635059637868e-06"/>      
    </inertial>    
  </link>  

  <link name="waist_link">    
    <visual>      
      <origin xyz="0 0 0" rpy="0 -0 0"/>      
      <geometry>        
        <mesh filename="package:///meshes/waist_link_visual.stl"/>        
      </geometry>      
      <material name="waist_link_material">        
        <color rgba="0.64205964988973096563 0.77112878115803895618 0.80455743168009152821 1.0"/>        
      </material>      
    </visual>    
    <collision>      
      <origin xyz="0 0 0" rpy="0 -0 0"/>      
      <geometry>        
        <mesh filename="package:///meshes/waist_link_collision.stl"/>        
      </geometry>      
    </collision>    
    <inertial>      
      <origin xyz="-3.4876747961162537906e-18 -0.024647143936897920186 -0.024243097328499937232" rpy="0 0 0"/>      
      <mass value="0.10819999998618363979"/>      
      <inertia ixx="4.747970073566886237e-05" ixy="-9.3811587245404559892e-21" ixz="-5.6250747314438818848e-09" iyy="9.6352172992785340951e-05" iyz="1.5514215856083487346e-06" izz="6.7249246473027323736e-05"/>      
    </inertial>    
  </link>  

  <link name="spiral_bevel_1m_14t_30deg">    
    <visual>      
      <origin xyz="0 0 0" rpy="0 -0 0"/>      
      <geometry>        
        <mesh filename="package:///meshes/spiral_bevel_1m_14t_30deg_visual.stl"/>        
      </geometry>      
      <material name="spiral_bevel_1m_14t_30deg_material">        
        <color rgba="0.64705882352941179736 0.64705882352941179736 0.64705882352941179736 1.0"/>        
      </material>      
    </visual>    
    <collision>      
      <origin xyz="0 0 0" rpy="0 -0 0"/>      
      <geometry>        
        <mesh filename="package:///meshes/spiral_bevel_1m_14t_30deg_collision.stl"/>        
      </geometry>      
    </collision>    
    <inertial>      
      <origin xyz="7.4971447279470481499e-10 7.1802237593121532518e-10 0.006686895501897913846" rpy="0 0 0"/>      
      <mass value="0.00073261524436595492574"/>      
      <inertia ixx="1.3495056019478195011e-08" ixy="4.0596682073457136067e-17" ixz="8.5992550143797901999e-16" iyy="1.3495056150237195634e-08" iyz="-6.791300821815703182e-16" izz="1.4355986549816401791e-08"/>      
    </inertial>    
  </link>  

  <joint name="waist_act_1" type="revolute">    
    <origin xyz="-1.0950768566580540919e-18 -0.019600000000000002837 -0.012749999999999995712" rpy="1.570796326794896558 1.1603771602431690682e-14 -3.1415926535897926719"/>    
    <parent link="waist_link"/>    
    <child link="spiral_bevel_1m_14t_30deg"/>    
    <axis xyz="0 0 1"/>    
    <limit effort="1" velocity="20" lower="-4.6774823953448034786" upper="4.6774823953448034786"/>    
    <joint_properties friction="0.0"/>    
  </joint>  

  <link name="spiral_bevel_1m_14t_30deg_2">    
    <visual>      
      <origin xyz="0 0 0" rpy="0 -0 0"/>      
      <geometry>        
        <mesh filename="package:///meshes/spiral_bevel_1m_14t_30deg_2_visual.stl"/>        
      </geometry>      
      <material name="spiral_bevel_1m_14t_30deg_2_material">        
        <color rgba="0.64705882352941179736 0.64705882352941179736 0.64705882352941179736 1.0"/>        
      </material>      
    </visual>    
    <collision>      
      <origin xyz="0 0 0" rpy="0 -0 0"/>      
      <geometry>        
        <mesh filename="package:///meshes/spiral_bevel_1m_14t_30deg_2_collision.stl"/>        
      </geometry>      
    </collision>    
    <inertial>      
      <origin xyz="3.6393117165689492509e-10 -9.7220472384390577147e-10 -0.0066868955018979155808" rpy="0 0 0"/>      
      <mass value="0.00073261524436595492574"/>      
      <inertia ixx="1.3495056012354480834e-08" ixy="2.5804135905735602914e-17" ixz="-1.069429604882048706e-15" iyy="1.3495056157360909811e-08" iyz="-2.3876736936216327369e-16" izz="1.43559865498164051e-08"/>      
    </inertial>    
  </link>  

  <joint name="waist_act_2" type="revolute">    
    <origin xyz="1.3488415323837299524e-18 -0.019599999999999995898 -0.032750000000000001332" rpy="-1.570796326794896558 2.1438338568776302255e-14 -3.141592653589793116"/>    
    <parent link="waist_link"/>    
    <child link="spiral_bevel_1m_14t_30deg_2"/>    
    <axis xyz="0 0 1"/>    
    <limit effort="1" velocity="20" lower="-4.6774823953448034786" upper="4.6774823953448034786"/>    
    <joint_properties friction="0.0"/>    
  </joint>  

  <link name="left_leg_reorder">    
    <visual>      
      <origin xyz="0 0 0" rpy="0 -0 0"/>      
      <geometry>        
        <mesh filename="package:///meshes/left_leg_reorder_visual.stl"/>        
      </geometry>      
      <material name="left_leg_reorder_material">        
        <color rgba="0.67653026596252763269 0.66851610566566932459 0.5118046884622382553 1.0"/>        
      </material>      
    </visual>    
    <collision>      
      <origin xyz="0 0 0" rpy="0 -0 0"/>      
      <geometry>        
        <mesh filename="package:///meshes/left_leg_reorder_collision.stl"/>        
      </geometry>      
    </collision>    
    <inertial>      
      <origin xyz="-0.14003533244388222112 0.0074816434689661832219 0.017702532858624001749" rpy="0 0 0"/>      
      <mass value="0.546053205592126778"/>      
      <inertia ixx="0.00027861717898135978169" ixy="0.00013407375792838453874" ixz="4.2427014236359357198e-05" iyy="0.0047236295394518105009" iyz="3.3456180902162216475e-06" izz="0.0048793523265396572877"/>      
    </inertial>    
  </link>  

  <joint name="left_hip_pitch" type="revolute">    
    <origin xyz="0.056000000000000015044 -0.040099999999999996758 -0.022750000000000002859" rpy="-1.570796326794896558 -1.2750103475622600987e-14 1.5707963267948956698"/>    
    <parent link="waist_link"/>    
    <child link="left_leg_reorder"/>    
    <axis xyz="0 0 1"/>    
    <limit effort="1" velocity="20" lower="-1.570796326794896558" upper="2.356194490192344837"/>    
    <joint_properties friction="0.0"/>    
  </joint>  

  <link name="right_leg_reorder">    
    <visual>      
      <origin xyz="0 0 0" rpy="0 -0 0"/>      
      <geometry>        
        <mesh filename="package:///meshes/right_leg_reorder_visual.stl"/>        
      </geometry>      
      <material name="right_leg_reorder_material">        
        <color rgba="0.6780141176317181495 0.6650225861008666195 0.50162016666551234589 1.0"/>        
      </material>      
    </visual>    
    <collision>      
      <origin xyz="0 0 0" rpy="0 -0 0"/>      
      <geometry>        
        <mesh filename="package:///meshes/right_leg_reorder_collision.stl"/>        
      </geometry>      
    </collision>    
    <inertial>      
      <origin xyz="-0.14090597371372412527 -0.0074810456244053611524 0.017759864717390928118" rpy="0 0 0"/>      
      <mass value="0.53305320559212687748"/>      
      <inertia ixx="0.00027583337265989546884" ixy="-0.00014442015043751723702" ixz="4.1713196684263363818e-05" iyy="0.0046962475176855218023" iyz="-4.9410665672427896733e-06" izz="0.0048511997479009395795"/>      
    </inertial>    
  </link>  

  <joint name="right_hip_pitch" type="revolute">    
    <origin xyz="-0.056000000000000008105 -0.040100000000000010636 -0.022750000000000002859" rpy="1.570796326794896558 -4.6471944491513544759e-14 1.570796326794871689"/>    
    <parent link="waist_link"/>    
    <child link="right_leg_reorder"/>    
    <axis xyz="0 0 1"/>    
    <limit effort="1" velocity="20" lower="-2.356194490192344837" upper="1.570796326794896558"/>    
    <joint_properties friction="0.0"/>    
  </joint>  

  <joint name="waist_roll" type="revolute">    
    <origin xyz="-0.022707865260689970299 5.0992894772045551448e-17 -0.013999999999999354974" rpy="1.5707963267948972241 -1.2860661478503099299e-14 -1.570796326794896558"/>    
    <parent link="waist_gears"/>    
    <child link="waist_link"/>    
    <axis xyz="0 0 1"/>    
    <limit effort="1" velocity="20" lower="-0.52359877559829881566" upper="0.52359877559829881566"/>    
    <joint_properties friction="0.0"/>    
  </joint>  

  <joint name="waist_yaw" type="revolute">    
    <origin xyz="0 -5.3903211409646476972e-18 3.4694469519597032089e-18" rpy="-8.7262726250677497581e-16 -3.9724428353914665044e-15 -3.1415926535897766847"/>    
    <parent link="torso"/>    
    <child link="waist_gears"/>    
    <axis xyz="0 0 1"/>    
    <limit effort="1" velocity="20" lower="-1.570796326794896558" upper="1.570796326794896558"/>    
    <joint_properties friction="0.0"/>    
  </joint>  

  <link name="left_arm_gripper">    
    <visual>      
      <origin xyz="0 0 0" rpy="0 -0 0"/>      
      <geometry>        
        <mesh filename="package:///meshes/left_arm_gripper_visual.stl"/>        
      </geometry>      
      <material name="left_arm_gripper_material">        
        <color rgba="0.71478780303500455418 0.8179628718393714415 0.87230604980696380135 1.0"/>        
      </material>      
    </visual>    
    <collision>      
      <origin xyz="0 0 0" rpy="0 -0 0"/>      
      <geometry>        
        <mesh filename="package:///meshes/left_arm_gripper_collision.stl"/>        
      </geometry>      
    </collision>    
    <inertial>      
      <origin xyz="-0.0019746660314624358765 0.109617181394094515 0.033696051741592944473" rpy="0 0 0"/>      
      <mass value="0.52042116458808618251"/>      
      <inertia ixx="0.003209524082348431083" ixy="7.0016245872938289861e-05" ixz="5.0731735621282141087e-06" iyy="0.00025041152058739895225" iyz="0.00010641626953588181946" izz="0.0032523701154431095862"/>      
    </inertial>    
  </link>  

  <joint name="left_sho_pitch" type="revolute">    
    <origin xyz="-0.0035000000000004437284 0.067000000000001058709 0.104236510762817286" rpy="-1.5707963267949092145 -4.1522341120980961897e-14 3.464089692039239269e-14"/>    
    <parent link="torso"/>    
    <child link="left_arm_gripper"/>    
    <axis xyz="0 0 1"/>    
    <limit effort="1" velocity="20" lower="-3.141592653589793116" upper="1.570796326794896558"/>    
    <joint_properties friction="0.0"/>    
  </joint>  

  <link name="right_arm_gripper">    
    <visual>      
      <origin xyz="0 0 0" rpy="0 -0 0"/>      
      <geometry>        
        <mesh filename="package:///meshes/right_arm_gripper_visual.stl"/>        
      </geometry>      
      <material name="right_arm_gripper_material">        
        <color rgba="0.71479482658733595191 0.81796331111759057464 0.87230200259414103492 1.0"/>        
      </material>      
    </visual>    
    <collision>      
      <origin xyz="0 0 0" rpy="0 -0 0"/>      
      <geometry>        
        <mesh filename="package:///meshes/right_arm_gripper_collision.stl"/>        
      </geometry>      
    </collision>    
    <inertial>      
      <origin xyz="0.0017712351941345950285 0.10961044652576736047 0.033703365927060247031" rpy="0 0 0"/>      
      <mass value="0.52038428376188905489"/>      
      <inertia ixx="0.0032091551606731492582" ixy="-9.1112179043615116355e-05" ixz="-4.8462420630839258073e-06" iyy="0.00025075576470972888322" iyz="0.00010605698159843219164" izz="0.0032524112322552395371"/>      
    </inertial>    
  </link>  

  <joint name="right_sho_pitch" type="revolute">    
    <origin xyz="-0.0034999999999986777799 -0.067000000000001072586 0.10423651076281732764" rpy="-1.5707963267948872321 3.624878175401132949e-14 -3.1415926535897562566"/>    
    <parent link="torso"/>    
    <child link="right_arm_gripper"/>    
    <axis xyz="0 0 1"/>    
    <limit effort="1" velocity="20" lower="-1.570796326794896558" upper="3.141592653589793116"/>    
    <joint_properties friction="0.0"/>    
  </joint>  


</robot>