<?xml version="1.0" ?>
<robot name="sysID_XC330">
  <link name="xc330">
    <visual>
      <origin xyz="0 0 0" rpy="0 -0 0"/>
      <geometry>
        <mesh filename="package:///meshes/xc330_visual.stl"/>
      </geometry>
      <material name="xc330_material">
        <color rgba="0.66291664961446195026 0.70549986616795368199 0.66729895251604331996 1.0"/>
      </material>
    </visual>
    <collision>
      <origin xyz="0 0 0" rpy="0 -0 0"/>
      <geometry>
        <mesh filename="package:///meshes/xc330_collision.stl"/>
      </geometry>
    </collision>
    <inertial>
      <origin xyz="0.067523785979360526066 0.0091047662315145976714 0.0040548453010051110912" rpy="0 0 0"/>
      <mass value="0.037349999993091763384"/>
      <inertia ixx="7.1551666942363893246e-06" ixy="-4.4272140296375444478e-06" ixz="3.88600385203059254e-07" iyy="1.6392155116973046642e-05" iyz="3.364647266219376747e-07" izz="2.0987261801740487668e-05"/>
    </inertial>
  </link>

  <link name="arm_330">
    <visual>
      <origin xyz="0 0 0" rpy="0 -0 0"/>
      <geometry>
        <mesh filename="package:///meshes/arm_330_visual.stl"/>
      </geometry>
      <material name="arm_330_material">
        <color rgba="0.63059283987567626983 0.65298952457695413898 0.67418901807298270423 1.0"/>
      </material>
    </visual>
    <collision>
      <origin xyz="0 0 0" rpy="0 -0 0"/>
      <geometry>
        <mesh filename="package:///meshes/arm_330_collision.stl"/>
      </geometry>
    </collision>
    <inertial>
      <origin xyz="0.077771581880464596415 1.3637865613089529684e-05 -0.014499999999999879305" rpy="0 0 0"/>
      <mass value="0.25549999999999994937"/>
      <inertia ixx="0.00024322303213941348448" ixy="9.3950332757091710781e-08" ixz="5.9314470448743356968e-20" iyy="0.00041031606159673929875" iyz="3.8999390614646317898e-16" izz="0.00022144160734724412142"/>
    </inertial>
  </link>

  <joint name="joint_0" type="revolute">
    <origin xyz="0.089400000000000034994 0.021949857927858890116 0.0034193959459662072627" rpy="1.57079632679489678 -2.3592239273285399858e-16 1.5707963267948961139"/>
    <parent link="xc330"/>
    <child link="arm_330"/>
    <axis xyz="0 0 1"/>
    <limit effort="1" velocity="20" lower="-1.570796326794896558" upper="1.570796326794896558"/>
    <joint_properties friction="0.0"/>
  </joint>


</robot>