<?xml version="1.0" ?>
<robot name="sysID_XM430">
  <link name="xm430">
    <visual>
      <origin xyz="0 0 0" rpy="0 -0 0"/>
      <geometry>
        <mesh filename="package:///meshes/xm430_visual.stl"/>
      </geometry>
      <material name="xm430_material">
        <color rgba="0.91426034379578891009 0.70000842084638215113 0.13024790887542936346 1.0"/>
      </material>
    </visual>
    <collision>
      <origin xyz="0 0 0" rpy="0 -0 0"/>
      <geometry>
        <mesh filename="package:///meshes/xm430_collision.stl"/>
      </geometry>
    </collision>
    <inertial>
      <origin xyz="0.071958135955560123542 0.017445641259993493327 0.0055435138757473530202" rpy="0 0 0"/>
      <mass value="0.10345000000444960764"/>
      <inertia ixx="3.2324316568160294005e-05" ixy="-6.1940121394904672266e-06" ixz="-3.1148674256868344747e-08" iyy="3.2377737272392996743e-05" iyz="-4.6596185424280959135e-08" izz="4.8950379202494915772e-05"/>
    </inertial>
  </link>

  <link name="arm_430">
    <visual>
      <origin xyz="0 0 0" rpy="0 -0 0"/>
      <geometry>
        <mesh filename="package:///meshes/arm_430_visual.stl"/>
      </geometry>
      <material name="arm_430_material">
        <color rgba="0.63059283987567626983 0.65298952457695413898 0.67418901807298270423 1.0"/>
      </material>
    </visual>
    <collision>
      <origin xyz="0 0 0" rpy="0 -0 0"/>
      <geometry>
        <mesh filename="package:///meshes/arm_430_collision.stl"/>
      </geometry>
    </collision>
    <inertial>
      <origin xyz="-0.077790387031997254574 -1.3637865612588443627e-05 -0.019000000000000284023" rpy="0 0 0"/>
      <mass value="0.25549999999999994937"/>
      <inertia ixx="0.00024426144376379807207" ixy="9.4015858830096577065e-08" ixz="-1.3511144394429471329e-18" iyy="0.00041073874164068989749" iyz="1.4686499445886251816e-16" izz="0.00022084196523238972497"/>
    </inertial>
  </link>

  <joint name="joint_0" type="revolute">
    <origin xyz="0.093000000000000013212 0.032699857927858892725 0.0055693959459662215755" rpy="-1.570796326794896558 2.7547408798512016148e-15 -1.5707963267948912289"/>
    <parent link="xm430"/>
    <child link="arm_430"/>
    <axis xyz="0 0 1"/>
    <limit effort="1" velocity="20" lower="-1.570796326794896558" upper="1.570796326794896558"/>
    <joint_properties friction="0.0"/>
  </joint>


</robot>