<?xml version="1.0" ?><robot name="right_leg_OP3">  
  <link name="hip_yaw_link">    
    <visual>      
      <origin xyz="0 0 0" rpy="0 -0 0"/>      
      <geometry>        
        <mesh filename="package:///meshes/right_hip_yaw_link_visual.stl"/>        
      </geometry>      
      <material name="hip_yaw_link_material">        
        <color rgba="0.61568627450980395466 0.81176470588235294379 0.92941176470588238168 1.0"/>        
      </material>      
    </visual>    
    <collision>      
      <origin xyz="0 0 0" rpy="0 -0 0"/>      
      <geometry>        
        <mesh filename="package:///meshes/right_hip_yaw_link_collision.stl"/>        
      </geometry>      
    </collision>    
    <inertial>      
      <origin xyz="4.8887999145308863493e-19 6.4321318786322873916e-19 -0.0098919667346054427487" rpy="0 0 0"/>      
      <mass value="0.017999999999999988232"/>      
      <inertia ixx="2.6483505271519536081e-06" ixy="0" ixz="0" iyy="7.7055357996008217629e-06" iyz="0" izz="7.773668280680532449e-06"/>      
    </inertial>    
  </link>  

  <link name="hip_roll_link">    
    <visual>      
      <origin xyz="0 0 0" rpy="0 -0 0"/>      
      <geometry>        
        <mesh filename="package:///meshes/right_hip_roll_link_visual.stl"/>        
      </geometry>      
      <material name="hip_roll_link_material">        
        <color rgba="0.51698661238356058423 0.5034781595109349972 0.49050589017722023844 1.0"/>        
      </material>      
    </visual>    
    <collision>      
      <origin xyz="0 0 0" rpy="0 -0 0"/>      
      <geometry>        
        <mesh filename="package:///meshes/right_hip_roll_link_collision.stl"/>        
      </geometry>      
    </collision>    
    <inertial>      
      <origin xyz="-0.011999849582184064778 -0.00049598090794076004229 -0.018504111838597528394" rpy="0 0 0"/>      
      <mass value="0.11059999999836231388"/>      
      <inertia ixx="2.2818802599018418481e-05" ixy="-4.6520143285804068616e-08" ixz="-4.6888548259794506283e-08" iyy="3.0871632082338458568e-05" iyz="-5.7477343899718413041e-07" izz="3.0871666424468855328e-05"/>      
    </inertial>    
  </link>  

  <link name="right_hip_pitch_link_xm430">    
    <visual>      
      <origin xyz="0 0 0" rpy="0 -0 0"/>      
      <geometry>        
        <mesh filename="package:///meshes/right_hip_pitch_link_xm430_visual.stl"/>        
      </geometry>      
      <material name="right_hip_pitch_link_xm430_material">        
        <color rgba="0.87072221357329571134 0.72641010956094287376 0.24785169615220689621 1.0"/>        
      </material>      
    </visual>    
    <collision>      
      <origin xyz="0 0 0" rpy="0 -0 0"/>      
      <geometry>        
        <mesh filename="package:///meshes/right_hip_pitch_link_xm430_collision.stl"/>        
      </geometry>      
    </collision>    
    <inertial>      
      <origin xyz="0.00075715881371278158027 -0.050714784778880625526 -0.012656153620121986594" rpy="0 0 0"/>      
      <mass value="0.1148009013503056841"/>      
      <inertia ixx="6.6072786489385391473e-05" ixy="4.6010682906016093232e-07" ixz="1.8171597853316598418e-07" iyy="2.3633665181582008398e-05" iyz="1.4125296519935102633e-06" izz="6.2221763055418289235e-05"/>      
    </inertial>    
  </link>  

  <link name="right_calf_link">    
    <visual>      
      <origin xyz="0 0 0" rpy="0 -0 0"/>      
      <geometry>        
        <mesh filename="package:///meshes/right_calf_link_visual.stl"/>        
      </geometry>      
      <material name="right_calf_link_material">        
        <color rgba="0.522707147375079062 0.70740037950664136357 0.87533206831119547697 1.0"/>        
      </material>      
    </visual>    
    <collision>      
      <origin xyz="0 0 0" rpy="0 -0 0"/>      
      <geometry>        
        <mesh filename="package:///meshes/right_calf_link_collision.stl"/>        
      </geometry>      
    </collision>    
    <inertial>      
      <origin xyz="-0.0044344902671585514908 0.04088938884336386359 -0.0093892669849707597468" rpy="0 0 0"/>      
      <mass value="0.031000000000000003247"/>      
      <inertia ixx="3.2988539450830159979e-05" ixy="-1.5571453299274619951e-06" ixz="1.9732683818521195824e-07" iyy="7.7722801345028642319e-06" iyz="6.508648125695407498e-07" izz="2.7918707182365905571e-05"/>      
    </inertial>    
  </link>  

  <link name="bearing_683">    
    <visual>      
      <origin xyz="0 0 0" rpy="0 -0 0"/>      
      <geometry>        
        <mesh filename="package:///meshes/right_bearing_683_visual.stl"/>        
      </geometry>      
      <material name="bearing_683_material">        
        <color rgba="0.64705882352941179736 0.64705882352941179736 0.64705882352941179736 1.0"/>        
      </material>      
    </visual>    
    <collision>      
      <origin xyz="0 0 0" rpy="0 -0 0"/>      
      <geometry>        
        <mesh filename="package:///meshes/right_bearing_683_collision.stl"/>        
      </geometry>      
    </collision>    
    <inertial>      
      <origin xyz="9.7468268094077909387e-19 2.4186774283159932507e-19 -0.0015500000000000016803" rpy="0 0 0"/>      
      <mass value="0.00048694686130641793437"/>      
      <inertia ixx="2.1551456503319887385e-09" ixy="-1.008605192603736898e-27" ixz="-1.0935573393225559951e-38" iyy="2.1551456503319883249e-09" iyz="-4.9832977110102519673e-39" izz="3.5303647444715305817e-09"/>      
    </inertial>    
  </link>  

  <joint name="right_knee_front_rev_2" type="revolute">    
    <origin xyz="-0.0057402514854764195157 -0.013858192987669160079 -0.026200000000000063516" rpy="-5.1439183405559488125e-16 -2.9685331931264604348e-15 3.1359629690793391354"/>    
    <parent link="right_calf_link"/>    
    <child link="bearing_683"/>    
    <axis xyz="0 0 1"/>    
    <limit effort="1" velocity="20" lower="-6.283185307179586232" upper="6.283185307179586232"/>    
    <joint_properties friction="0.0"/>    
  </joint>  

  <link name="bearing_683_2">    
    <visual>      
      <origin xyz="0 0 0" rpy="0 -0 0"/>      
      <geometry>        
        <mesh filename="package:///meshes/right_bearing_683_2_visual.stl"/>        
      </geometry>      
      <material name="bearing_683_2_material">        
        <color rgba="0.64705882352941179736 0.64705882352941179736 0.64705882352941179736 1.0"/>        
      </material>      
    </visual>    
    <collision>      
      <origin xyz="0 0 0" rpy="0 -0 0"/>      
      <geometry>        
        <mesh filename="package:///meshes/right_bearing_683_2_collision.stl"/>        
      </geometry>      
    </collision>    
    <inertial>      
      <origin xyz="-7.6004079503603214129e-19 2.799744335846054081e-17 -0.0015499999999999982108" rpy="0 0 0"/>      
      <mass value="0.00048694686130641793437"/>      
      <inertia ixx="2.1551456503319887385e-09" ixy="-7.063165403686602894e-28" ixz="-7.8235602228308242713e-39" iyy="2.1551456503319874977e-09" iyz="3.988323221680714685e-38" izz="3.5303647444715305817e-09"/>      
    </inertial>    
  </link>  

  <joint name="right_knee_back_rev_2" type="revolute">    
    <origin xyz="0.0057402514854763960969 0.013858192987669354368 -0.026200000000000014944" rpy="2.0307557008913139329e-14 -1.7771544142448121049e-15 3.1358994637118597915"/>    
    <parent link="right_calf_link"/>    
    <child link="bearing_683_2"/>    
    <axis xyz="0 0 1"/>    
    <limit effort="1" velocity="20" lower="-6.283185307179586232" upper="6.283185307179586232"/>    
    <joint_properties friction="0.0"/>    
  </joint>  

  <link name="right_ank_pitch_link">    
    <visual>      
      <origin xyz="0 0 0" rpy="0 -0 0"/>      
      <geometry>        
        <mesh filename="package:///meshes/right_ank_pitch_link_visual.stl"/>        
      </geometry>      
      <material name="right_ank_pitch_link_material">        
        <color rgba="0.70321688500203327621 0.64514870846184457776 0.40484735422826279017 1.0"/>        
      </material>      
    </visual>    
    <collision>      
      <origin xyz="0 0 0" rpy="0 -0 0"/>      
      <geometry>        
        <mesh filename="package:///meshes/right_ank_pitch_link_collision.stl"/>        
      </geometry>      
    </collision>    
    <inertial>      
      <origin xyz="-0.017770241889542865571 0.012301334508571936874 0.018814514831173318604" rpy="0 0 0"/>      
      <mass value="0.17676376695067899658"/>      
      <inertia ixx="4.7283381546857274503e-05" ixy="1.3380598207226426526e-06" ixz="6.1532628607232562101e-07" iyy="0.00010706462535917273373" iyz="-5.1080086246313229535e-08" izz="0.00012185522398303844723"/>      
    </inertial>    
  </link>  

  <link name="ank_roll_link">    
    <visual>      
      <origin xyz="0 0 0" rpy="0 -0 0"/>      
      <geometry>        
        <mesh filename="package:///meshes/right_ank_roll_link_visual.stl"/>        
      </geometry>      
      <material name="ank_roll_link_material">        
        <color rgba="0.61568627450980395466 0.81176470588235294379 0.92941176470588215963 1.0"/>        
      </material>      
    </visual>    
    <collision>      
      <origin xyz="0 0 0" rpy="0 -0 0"/>      
      <geometry>        
        <mesh filename="package:///meshes/right_ank_roll_link_collision.stl"/>        
      </geometry>      
    </collision>    
    <inertial>      
      <origin xyz="-0.027003372529275586345 -2.0047344420266124326e-12 0.033758582145829468812" rpy="0 0 0"/>      
      <mass value="0.042599999999999998979"/>      
      <inertia ixx="3.7273661670606821517e-05" ixy="-5.5213265139054136481e-16" ixz="2.3913171754436051547e-06" iyy="3.758016044515443885e-05" iyz="5.0909543907035460515e-12" izz="1.0089086509198958482e-05"/>      
    </inertial>    
  </link>  

  <joint name="right_ank_roll" type="revolute">    
    <origin xyz="-0.022749999999997192607 1.6653345369377348106e-16 0.0189999999999991738" rpy="1.570796326794951403 -2.0579877843196441351e-14 1.5707963267948796826"/>    
    <parent link="right_ank_pitch_link"/>    
    <child link="ank_roll_link"/>    
    <axis xyz="0 0 1"/>    
    <limit effort="1" velocity="20" lower="-1.570796326794896558" upper="1.570796326794896558"/>    
    <joint_properties friction="0.0"/>    
  </joint>  

  <joint name="right_ank_pitch" type="revolute">    
    <origin xyz="0.00050000000000023441492 0.10000000000000039413 -0.029399999999999884559" rpy="-5.4667506414618354008e-16 -3.3588276253906543975e-15 -3.1415926535897877869"/>    
    <parent link="right_calf_link"/>    
    <child link="right_ank_pitch_link"/>    
    <axis xyz="0 0 1"/>    
    <limit effort="1" velocity="20" lower="-0.785398163397448279" upper="1.7453292519943295336"/>    
    <joint_properties friction="0.0"/>    
  </joint>  

  <joint name="right_knee" type="revolute">    
    <origin xyz="6.6012271456357184538e-18 -0.095999999999999877098 -0.009199999999999972089" rpy="-9.138977281102487298e-16 5.7742659530791861042e-17 3.141592653589793116"/>    
    <parent link="right_hip_pitch_link_xm430"/>    
    <child link="right_calf_link"/>    
    <axis xyz="0 0 1"/>    
    <limit effort="1" velocity="20" lower="-2.0943951023931952626" upper="0"/>    
    <joint_properties friction="0.0"/>    
  </joint>  

  <link name="xm430_plate">    
    <visual>      
      <origin xyz="0 0 0" rpy="0 -0 0"/>      
      <geometry>        
        <mesh filename="package:///meshes/right_xm430_plate_visual.stl"/>        
      </geometry>      
      <material name="xm430_plate_material">        
        <color rgba="0.61568627450980395466 0.81176470588235294379 0.92941176470588227065 1.0"/>        
      </material>      
    </visual>    
    <collision>      
      <origin xyz="0 0 0" rpy="0 -0 0"/>      
      <geometry>        
        <mesh filename="package:///meshes/right_xm430_plate_collision.stl"/>        
      </geometry>      
    </collision>    
    <inertial>      
      <origin xyz="8.5471520543368154117e-19 4.1198186879884584483e-18 -0.0024039046431217937771" rpy="0 0 0"/>      
      <mass value="0.0026999999999999997093"/>      
      <inertia ixx="2.6720434385876688324e-07" ixy="-6.8936588702566400709e-08" ixz="-2.5953127236483245287e-36" iyy="1.293311664536341083e-07" iyz="-2.0427625516522123035e-36" izz="3.8533537562751439267e-07"/>      
    </inertial>    
  </link>  

  <link name="knee_rod">    
    <visual>      
      <origin xyz="0 0 0" rpy="0 -0 0"/>      
      <geometry>        
        <mesh filename="package:///meshes/right_knee_rod_visual.stl"/>        
      </geometry>      
      <material name="knee_rod_material">        
        <color rgba="0.62051618944235198416 0.78640765248647581664 0.88594253031295022716 1.0"/>        
      </material>      
    </visual>    
    <collision>      
      <origin xyz="0 0 0" rpy="0 -0 0"/>      
      <geometry>        
        <mesh filename="package:///meshes/right_knee_rod_collision.stl"/>        
      </geometry>      
    </collision>    
    <inertial>      
      <origin xyz="0.014594553362682954542 3.7416799586905925216e-05 -0.0015996227373187303557" rpy="0 0 0"/>      
      <mass value="0.0031629468613064179276"/>      
      <inertia ixx="2.589592867711170848e-08" ixy="-3.1430030611629383791e-10" ixz="4.1682991868437332224e-10" iyy="6.0153261235254296022e-07" iyz="1.0686480871972266543e-12" izz="6.2266847675176384997e-07"/>      
    </inertial>    
  </link>  

  <joint name="right_knee_front_rev_1" type="revolute">    
    <origin xyz="-0.0057402514854763735455 -0.013858192987669271101 -0.0049999999999999992367" rpy="3.7594106814525390121e-15 -6.9096598398549006487e-16 1.5651666422844430215"/>    
    <parent link="xm430_plate"/>    
    <child link="knee_rod"/>    
    <axis xyz="0 0 1"/>    
    <limit effort="1" velocity="20" lower="-6.283185307179586232" upper="6.283185307179586232"/>    
    <joint_properties friction="0.0"/>    
  </joint>  

  <link name="knee_rod_2">    
    <visual>      
      <origin xyz="0 0 0" rpy="0 -0 0"/>      
      <geometry>        
        <mesh filename="package:///meshes/right_knee_rod_2_visual.stl"/>        
      </geometry>      
      <material name="knee_rod_2_material">        
        <color rgba="0.62051618944235198416 0.78640765248647581664 0.88594253031295022716 1.0"/>        
      </material>      
    </visual>    
    <collision>      
      <origin xyz="0 0 0" rpy="0 -0 0"/>      
      <geometry>        
        <mesh filename="package:///meshes/right_knee_rod_2_collision.stl"/>        
      </geometry>      
    </collision>    
    <inertial>      
      <origin xyz="0.014594550927656914363 3.9270448462004357089e-05 -0.0015996227373180191191" rpy="0 0 0"/>      
      <mass value="0.0031629468613064179276"/>      
      <inertia ixx="2.5896010493062238455e-08" ixy="-3.2987086147587118383e-10" ixz="4.1682984914096729936e-10" iyy="6.0153257144418870589e-07" iyz="1.1215895049805200854e-12" izz="6.2266851765936255091e-07"/>      
    </inertial>    
  </link>  

  <joint name="right_knee_back_rev_1" type="revolute">    
    <origin xyz="0.0057402514854763666066 0.01385819298766934049 -0.005000000000000016584" rpy="-5.9721322899995738745e-15 2.1763425120495147882e-14 1.5651031369169621232"/>    
    <parent link="xm430_plate"/>    
    <child link="knee_rod_2"/>    
    <axis xyz="0 0 1"/>    
    <limit effort="1" velocity="20" lower="-6.283185307179586232" upper="6.283185307179586232"/>    
    <joint_properties friction="0.0"/>    
  </joint>  

  <joint name="right_knee_act" type="revolute">    
    <origin xyz="0.00015000000000000958205 -0.061499999999999971356 -0.030399999999999996469" rpy="1.8480226030005917304e-16 2.0301725913858999669e-15 3.1415926535897922278"/>    
    <parent link="right_hip_pitch_link_xm430"/>    
    <child link="xm430_plate"/>    
    <axis xyz="0 0 1"/>    
    <limit effort="1" velocity="20" lower="-2.0943951023931952626" upper="0"/>    
    <joint_properties friction="0.0"/>    
  </joint>  

  <joint name="right_hip_pitch" type="revolute">    
    <origin xyz="-0.024000000716147704138 -0.019000000152441253592 -0.01900000015245582527" rpy="1.570796326795185216 1.5707963267947977481 0"/>    
    <parent link="hip_roll_link"/>    
    <child link="right_hip_pitch_link_xm430"/>    
    <axis xyz="0 0 1"/>    
    <limit effort="1" velocity="20" lower="-1.570796326794896558" upper="1.570796326794896558"/>    
    <joint_properties friction="0.0"/>    
  </joint>  

  <joint name="right_hip_roll" type="revolute">    
    <origin xyz="-0.018999999999999999528 -1.7604701631262654893e-16 -0.025999999999999919009" rpy="-2.8481848693987683332e-20 -1.5707963267948954478 0"/>    
    <parent link="hip_yaw_link"/>    
    <child link="hip_roll_link"/>    
    <axis xyz="0 0 1"/>    
    <limit effort="1" velocity="20" lower="-0.785398163397448279" upper="0.785398163397448279"/>    
    <joint_properties friction="0.0"/>    
  </joint>  


</robot>