<?xml version="1.0" ?><robot name="toddlerbot_legs">  
  <link name="torso">    
    <visual>      
      <origin xyz="0 0 0" rpy="0 -0 0"/>      
      <geometry>        
        <mesh filename="package:///meshes/torso_visual.stl"/>        
      </geometry>      
      <material name="torso_material">        
        <color rgba="0.58593977560074750333 0.73200332251165189934 0.84622153029708713223 1.0"/>        
      </material>      
    </visual>    
    <collision>      
      <origin xyz="0 0 0" rpy="0 -0 0"/>      
      <geometry>        
        <mesh filename="package:///meshes/torso_collision.stl"/>        
      </geometry>      
    </collision>    
    <inertial>      
      <origin xyz="-0.0075186748665465336777 0.0025090333219585044845 0.072270970201894393914" rpy="0 0 0"/>      
      <mass value="0.58475267652546314423"/>      
      <inertia ixx="0.0016182311860030490405" ixy="-1.4904703028685398913e-05" ixz="-2.0792700935848309104e-06" iyy="0.0013132464205886527821" iyz="2.3933304520818679713e-05" izz="0.0011865975677379551282"/>      
    </inertial>    
  </link>  

  <link name="waist_gears">    
    <visual>      
      <origin xyz="0 0 0" rpy="0 -0 0"/>      
      <geometry>        
        <mesh filename="package:///meshes/waist_gears_visual.stl"/>        
      </geometry>      
      <material name="waist_gears_material">        
        <color rgba="0.2632766275256509525 0.51746399844275270397 0.70128653634567084119 1.0"/>        
      </material>      
    </visual>    
    <collision>      
      <origin xyz="0 0 0" rpy="0 -0 0"/>      
      <geometry>        
        <mesh filename="package:///meshes/waist_gears_collision.stl"/>        
      </geometry>      
    </collision>    
    <inertial>      
      <origin xyz="-2.9688764928041068262e-07 5.6464343503266493767e-08 -0.012588230079602372169" rpy="0 0 0"/>      
      <mass value="0.025809950030454158199"/>      
      <inertia ixx="1.5121316248348308453e-06" ixy="1.8766601003449190681e-11" ixz="4.0584247096300465977e-10" iyy="7.254038670046187235e-06" iyz="3.1280091522235431051e-12" izz="6.9379699728506212154e-06"/>      
    </inertial>    
  </link>  

  <link name="waist_link">    
    <visual>      
      <origin xyz="0 0 0" rpy="0 -0 0"/>      
      <geometry>        
        <mesh filename="package:///meshes/waist_link_visual.stl"/>        
      </geometry>      
      <material name="waist_link_material">        
        <color rgba="0.63401200025306070351 0.68204699127249923674 0.6691019398503622595 1.0"/>        
      </material>      
    </visual>    
    <collision>      
      <origin xyz="0 0 0" rpy="0 -0 0"/>      
      <geometry>        
        <mesh filename="package:///meshes/waist_link_collision.stl"/>        
      </geometry>      
    </collision>    
    <inertial>      
      <origin xyz="-9.1086191328831884098e-07 0.026204483755308764087 -0.030190392008842690391" rpy="0 0 0"/>      
      <mass value="0.16631953490612461088"/>      
      <inertia ixx="6.8622997376115475059e-05" ixy="-6.1328048432543562216e-10" ixz="-3.6786792027265892827e-06" iyy="0.00020057117429216812874" iyz="-3.7255079147358228843e-06" izz="0.00015770127977213135168"/>      
    </inertial>    
  </link>  

  <link name="spiral_bevel_1m_14t_30deg">    
    <visual>      
      <origin xyz="0 0 0" rpy="0 -0 0"/>      
      <geometry>        
        <mesh filename="package:///meshes/spiral_bevel_1m_14t_30deg_visual.stl"/>        
      </geometry>      
      <material name="spiral_bevel_1m_14t_30deg_material">        
        <color rgba="0.64705882352941179736 0.64705882352941179736 0.64705882352941179736 1.0"/>        
      </material>      
    </visual>    
    <collision>      
      <origin xyz="0 0 0" rpy="0 -0 0"/>      
      <geometry>        
        <mesh filename="package:///meshes/spiral_bevel_1m_14t_30deg_collision.stl"/>        
      </geometry>      
    </collision>    
    <inertial>      
      <origin xyz="8.2641075233036431769e-10 3.4055789785436557278e-10 0.0068612577407481632752" rpy="0 0 0"/>      
      <mass value="0.00067997563436136235649"/>      
      <inertia ixx="1.2174575798018972184e-08" ixy="3.8216075412375150261e-18" ixz="4.7204547862376369162e-16" iyy="1.2174575801813739345e-08" iyz="-2.6184097722348798477e-16" izz="1.3178653206314319982e-08"/>      
    </inertial>    
  </link>  

  <joint name="waist_act_1" type="revolute">    
    <origin xyz="5.280785712277463867e-16 0.019600000000000086103 -0.012750000000000089387" rpy="1.5707963267949007768 1.5707963267948918951 0"/>    
    <parent link="waist_link"/>    
    <child link="spiral_bevel_1m_14t_30deg"/>    
    <axis xyz="0 0 1"/>    
    <limit effort="1" velocity="20" lower="-2.7825534678416246059" upper="2.7825534678416246059"/>    
    <joint_properties friction="0.0"/>    
  </joint>  

  <link name="spiral_bevel_1m_14t_30deg_2">    
    <visual>      
      <origin xyz="0 0 0" rpy="0 -0 0"/>      
      <geometry>        
        <mesh filename="package:///meshes/spiral_bevel_1m_14t_30deg_2_visual.stl"/>        
      </geometry>      
      <material name="spiral_bevel_1m_14t_30deg_2_material">        
        <color rgba="0.64705882352941179736 0.64705882352941179736 0.64705882352941179736 1.0"/>        
      </material>      
    </visual>    
    <collision>      
      <origin xyz="0 0 0" rpy="0 -0 0"/>      
      <geometry>        
        <mesh filename="package:///meshes/spiral_bevel_1m_14t_30deg_2_collision.stl"/>        
      </geometry>      
    </collision>    
    <inertial>      
      <origin xyz="7.299096500823498701e-10 5.1591309270179412606e-10 0.0068612577407481632752" rpy="0 0 0"/>      
      <mass value="0.00067997563436136235649"/>      
      <inertia ixx="1.2174575796548751289e-08" ixy="2.6199059649779442379e-18" ixz="5.1847541177444225726e-16" iyy="1.2174575803283980091e-08" iyz="-1.5023607647403962116e-16" izz="1.3178653206314316674e-08"/>      
    </inertial>    
  </link>  

  <joint name="waist_act_2" type="revolute">    
    <origin xyz="-2.7139481743289301149e-16 0.019599999999999884875 -0.032749999999999626632" rpy="1.5707963267948958919 1.3463968515392312764 -4.6112523179512435393e-14"/>    
    <parent link="waist_link"/>    
    <child link="spiral_bevel_1m_14t_30deg_2"/>    
    <axis xyz="0 0 1"/>    
    <limit effort="1" velocity="20" lower="-2.7825534678416246059" upper="2.7825534678416246059"/>    
    <joint_properties friction="0.0"/>    
  </joint>  

  <link name="spur_gear_19_teeth">    
    <visual>      
      <origin xyz="0 0 0" rpy="0 -0 0"/>      
      <geometry>        
        <mesh filename="package:///meshes/spur_gear_19_teeth_visual.stl"/>        
      </geometry>      
      <material name="spur_gear_19_teeth_material">        
        <color rgba="0.61568627450980395466 0.81176470588235294379 0.92941176470588238168 1.0"/>        
      </material>      
    </visual>    
    <collision>      
      <origin xyz="0 0 0" rpy="0 -0 0"/>      
      <geometry>        
        <mesh filename="package:///meshes/spur_gear_19_teeth_collision.stl"/>        
      </geometry>      
    </collision>    
    <inertial>      
      <origin xyz="-4.9968063132990057014e-09 -7.9242207278620244307e-11 0.0045295192537419945097" rpy="0 0 0"/>      
      <mass value="0.0010993711450650537481"/>      
      <inertia ixx="2.9215018435433075427e-08" ixy="2.5903313772733109345e-16" ixz="8.5599808504110491437e-15" iyy="2.9215021540034058468e-08" iyz="1.1526881392988152558e-16" izz="4.5709977027671368266e-08"/>      
    </inertial>    
  </link>  

  <joint name="left_hip_yaw_drive" type="revolute">    
    <origin xyz="-0.036999999999998180178 0.037100000000006128076 -0.039500000000001304901" rpy="-1.5707963267949545116 -4.7901784552298407448e-13 -3.592506663906207747e-13"/>    
    <parent link="waist_link"/>    
    <child link="spur_gear_19_teeth"/>    
    <axis xyz="0 0 1"/>    
    <limit effort="1" velocity="20" lower="-1.4211966766239538806" upper="1.4211966766239538806"/>    
    <joint_properties friction="0.0"/>    
  </joint>  

  <link name="spur_gear_21_teeth">    
    <visual>      
      <origin xyz="0 0 0" rpy="0 -0 0"/>      
      <geometry>        
        <mesh filename="package:///meshes/spur_gear_21_teeth_visual.stl"/>        
      </geometry>      
      <material name="spur_gear_21_teeth_material">        
        <color rgba="0.61568627450980395466 0.81176470588235294379 0.92941176470588238168 1.0"/>        
      </material>      
    </visual>    
    <collision>      
      <origin xyz="0 0 0" rpy="0 -0 0"/>      
      <geometry>        
        <mesh filename="package:///meshes/spur_gear_21_teeth_collision.stl"/>        
      </geometry>      
    </collision>    
    <inertial>      
      <origin xyz="-4.7814841746391350153e-10 -1.2610157619056981848e-12 0.0024944618616143296973" rpy="0 0 0"/>      
      <mass value="0.0010063046528317972673"/>      
      <inertia ixx="3.1842855421068488283e-08" ixy="-8.2234595750147931764e-39" ixz="0" iyy="3.1842855426953785697e-08" iyz="0" izz="5.9529380586728034749e-08"/>      
    </inertial>    
  </link>  

  <link name="left_leg_xm430">    
    <visual>      
      <origin xyz="0 0 0" rpy="0 -0 0"/>      
      <geometry>        
        <mesh filename="package:///meshes/left_leg_xm430_visual.stl"/>        
      </geometry>      
      <material name="left_leg_xm430_material">        
        <color rgba="0.61568627450980395466 0.81176470588235294379 0.92941176470588238168 1.0"/>        
      </material>      
    </visual>    
    <collision>      
      <origin xyz="0 0 0" rpy="0 -0 0"/>      
      <geometry>        
        <mesh filename="package:///meshes/left_leg_xm430_collision.stl"/>        
      </geometry>      
    </collision>    
    <inertial>      
      <origin xyz="7.1483402244533405971e-19 -6.4049127810723492124e-19 -0.0098390489054829034787" rpy="0 0 0"/>      
      <mass value="0.017999999999999995171"/>      
      <inertia ixx="2.638503389144253662e-06" ixy="2.2631754297690434276e-36" ixz="-2.9183059949877146772e-36" iyy="7.6596731957046890345e-06" iyz="3.2916879946902348384e-35" izz="7.7220708070894769837e-06"/>      
    </inertial>    
  </link>  

  <joint name="left_leg_fixed" type="fixed">    
    <origin xyz="0 0 0.004999999999999997502" rpy="3.1415926535897873428 -0 -1.7068474724759580563e-30"/>    
    <parent link="spur_gear_21_teeth"/>    
    <child link="left_leg_xm430"/>    
    <axis xyz="0 0 1"/>    
    <limit effort="1" velocity="20"/>    
    <joint_properties friction="0.0"/>    
  </joint>  

  <joint name="left_hip_yaw_driven" type="revolute">    
    <origin xyz="-0.036999999999999998168 0.041099999999999997646 -0.019499999999999968747" rpy="-1.5707963267949003328 -1.5707963267948956698 0"/>    
    <parent link="waist_link"/>    
    <child link="spur_gear_21_teeth"/>    
    <axis xyz="0 0 1"/>    
    <limit effort="1" velocity="20" lower="-1.570796326794896558" upper="1.570796326794896558"/>    
    <joint_properties friction="0.0"/>    
  </joint>  

  <link name="spur_gear_19_teeth_2">    
    <visual>      
      <origin xyz="0 0 0" rpy="0 -0 0"/>      
      <geometry>        
        <mesh filename="package:///meshes/spur_gear_19_teeth_2_visual.stl"/>        
      </geometry>      
      <material name="spur_gear_19_teeth_2_material">        
        <color rgba="0.61568627450980395466 0.81176470588235294379 0.92941176470588238168 1.0"/>        
      </material>      
    </visual>    
    <collision>      
      <origin xyz="0 0 0" rpy="0 -0 0"/>      
      <geometry>        
        <mesh filename="package:///meshes/spur_gear_19_teeth_2_collision.stl"/>        
      </geometry>      
    </collision>    
    <inertial>      
      <origin xyz="-4.9968063063601126247e-09 -7.924221074806719626e-11 0.0045295192537419875708" rpy="0 0 0"/>      
      <mass value="0.0010993711450650537481"/>      
      <inertia ixx="2.9215018435433082044e-08" ixy="2.5903313772733109345e-16" ixz="8.5599808504110491437e-15" iyy="2.9215021540034058468e-08" iyz="1.1526881392988152558e-16" izz="4.5709977027671368266e-08"/>      
    </inertial>    
  </link>  

  <joint name="right_hip_yaw_drive" type="revolute">    
    <origin xyz="0.037000000000001753708 0.03710000000000365783 -0.03950000000000099265" rpy="-1.5707963267949678343 -3.4916821824591171931e-13 -4.5331578110491156048e-13"/>    
    <parent link="waist_link"/>    
    <child link="spur_gear_19_teeth_2"/>    
    <axis xyz="0 0 1"/>    
    <limit effort="1" velocity="20" lower="-1.4211966766239538806" upper="1.4211966766239538806"/>    
    <joint_properties friction="0.0"/>    
  </joint>  

  <link name="spur_gear_21_teeth_2">    
    <visual>      
      <origin xyz="0 0 0" rpy="0 -0 0"/>      
      <geometry>        
        <mesh filename="package:///meshes/spur_gear_21_teeth_2_visual.stl"/>        
      </geometry>      
      <material name="spur_gear_21_teeth_2_material">        
        <color rgba="0.61568627450980395466 0.81176470588235294379 0.92941176470588238168 1.0"/>        
      </material>      
    </visual>    
    <collision>      
      <origin xyz="0 0 0" rpy="0 -0 0"/>      
      <geometry>        
        <mesh filename="package:///meshes/spur_gear_21_teeth_2_collision.stl"/>        
      </geometry>      
    </collision>    
    <inertial>      
      <origin xyz="-4.7814841746391350153e-10 1.2610157619056981848e-12 0.0025055381383856678047" rpy="0 0 0"/>      
      <mass value="0.0010063046528317972673"/>      
      <inertia ixx="3.1842855421068488283e-08" ixy="-2.1931238668045418773e-38" ixz="0" iyy="3.1842855426953785697e-08" iyz="0" izz="5.9529380586728034749e-08"/>      
    </inertial>    
  </link>  

  <link name="right_leg_xm430">    
    <visual>      
      <origin xyz="0 0 0" rpy="0 -0 0"/>      
      <geometry>        
        <mesh filename="package:///meshes/right_leg_xm430_visual.stl"/>        
      </geometry>      
      <material name="right_leg_xm430_material">        
        <color rgba="0.61568627450980395466 0.81176470588235294379 0.92941176470588238168 1.0"/>        
      </material>      
    </visual>    
    <collision>      
      <origin xyz="0 0 0" rpy="0 -0 0"/>      
      <geometry>        
        <mesh filename="package:///meshes/right_leg_xm430_collision.stl"/>        
      </geometry>      
    </collision>    
    <inertial>      
      <origin xyz="7.1483402244533251896e-19 -6.404912781072197064e-19 -0.0098390489054829104176" rpy="0 0 0"/>      
      <mass value="0.017999999999999995171"/>      
      <inertia ixx="2.638503389144253662e-06" ixy="3.5463491813255914207e-36" ixz="0" iyy="7.6596731957046890345e-06" iyz="0" izz="7.7220708070894769837e-06"/>      
    </inertial>    
  </link>  

  <joint name="right_leg_fixed" type="fixed">    
    <origin xyz="0 0 0.004999999999999997502" rpy="-3.141592653589793116 -0 -3.4436670920376892537e-31"/>    
    <parent link="spur_gear_21_teeth_2"/>    
    <child link="right_leg_xm430"/>    
    <axis xyz="0 0 1"/>    
    <limit effort="1" velocity="20"/>    
    <joint_properties friction="0.0"/>    
  </joint>  

  <joint name="right_hip_yaw_driven" type="revolute">    
    <origin xyz="0.037000000000000005107 0.041100000000000025402 -0.019499999999999965278" rpy="-1.5707963267949003328 -1.5707963267948956698 0"/>    
    <parent link="waist_link"/>    
    <child link="spur_gear_21_teeth_2"/>    
    <axis xyz="0 0 1"/>    
    <limit effort="1" velocity="20" lower="-1.570796326794896558" upper="1.570796326794896558"/>    
    <joint_properties friction="0.0"/>    
  </joint>  

  <joint name="waist_roll" type="revolute">    
    <origin xyz="-0.022707865260691555837 -1.3531682581278302231e-17 -0.01400000000000022754" rpy="-1.5707963267949187625 -1.8109711313713014789e-14 1.5707963267948794606"/>    
    <parent link="waist_gears"/>    
    <child link="waist_link"/>    
    <axis xyz="0 0 1"/>    
    <limit effort="1" velocity="20" lower="-0.52359877559829881566" upper="0.52359877559829881566"/>    
    <joint_properties friction="0.0"/>    
  </joint>  

  <joint name="waist_yaw" type="revolute">    
    <origin xyz="0 2.1696821152739187355e-18 7.7715611723760987412e-16" rpy="8.8888408709675104228e-15 1.5372781523506735431e-14 -3.1415926535897900074"/>    
    <parent link="torso"/>    
    <child link="waist_gears"/>    
    <axis xyz="0 0 1"/>    
    <limit effort="1" velocity="20" lower="-1.570796326794896558" upper="1.570796326794896558"/>    
    <joint_properties friction="0.0"/>    
  </joint>  


</robot>