<?xml version="1.0" ?><robot name="right_arm_active">  
  <link name="sho_pitch_link">    
    <visual>      
      <origin xyz="0 0 0" rpy="0 -0 0"/>      
      <geometry>        
        <mesh filename="package:///meshes/right_sho_pitch_link_visual.stl"/>        
      </geometry>      
      <material name="sho_pitch_link_material">        
        <color rgba="0.61568627450980395466 0.81176470588235294379 0.92941176470588227065 1.0"/>        
      </material>      
    </visual>    
    <collision>      
      <origin xyz="0 0 0" rpy="0 -0 0"/>      
      <geometry>        
        <mesh filename="package:///meshes/right_sho_pitch_link_collision.stl"/>        
      </geometry>      
    </collision>    
    <inertial>      
      <origin xyz="2.844942307502240611e-19 -2.0629817293647782366e-18 0.012913250798677606071" rpy="0 0 0"/>      
      <mass value="0.0085999999999999982708"/>      
      <inertia ixx="1.8365636406635808026e-06" ixy="2.7052466620977962537e-97" ixz="-6.0867229013657673323e-136" iyy="4.0110869076839143695e-06" iyz="-1.6935833339184750708e-44" izz="3.5160516450492489574e-06"/>      
    </inertial>    
  </link>  

  <link name="2xl430_gears">    
    <visual>      
      <origin xyz="0 0 0" rpy="0 -0 0"/>      
      <geometry>        
        <mesh filename="package:///meshes/right_2xl430_gears_visual.stl"/>        
      </geometry>      
      <material name="2xl430_gears_material">        
        <color rgba="0.7591476792056923717 0.85560384745670925444 0.90519468321360618823 1.0"/>        
      </material>      
    </visual>    
    <collision>      
      <origin xyz="0 0 0" rpy="0 -0 0"/>      
      <geometry>        
        <mesh filename="package:///meshes/right_2xl430_gears_collision.stl"/>        
      </geometry>      
    </collision>    
    <inertial>      
      <origin xyz="-0.01159290573797869435 -0.0024238553642522853854 -0.018551095523803726173" rpy="0 0 0"/>      
      <mass value="0.11800003674524907338"/>      
      <inertia ixx="2.7511021050424642629e-05" ixy="9.0043904315135393931e-07" ixz="-2.3349710123960794436e-08" iyy="3.2796197843346213958e-05" iyz="-6.5715119654693364971e-07" izz="3.5775739835740998952e-05"/>      
    </inertial>    
  </link>  

  <link name="spur_1m_24t_drive">    
    <visual>      
      <origin xyz="0 0 0" rpy="0 -0 0"/>      
      <geometry>        
        <mesh filename="package:///meshes/right_spur_1m_24t_drive_visual.stl"/>        
      </geometry>      
      <material name="spur_1m_24t_drive_material">        
        <color rgba="0.61568627450980395466 0.81176470588235294379 0.92941176470588238168 1.0"/>        
      </material>      
    </visual>    
    <collision>      
      <origin xyz="0 0 0" rpy="0 -0 0"/>      
      <geometry>        
        <mesh filename="package:///meshes/right_spur_1m_24t_drive_collision.stl"/>        
      </geometry>      
    </collision>    
    <inertial>      
      <origin xyz="3.0325499508169297121e-15 -3.3903525173049749467e-16 0.0048096451474093030592" rpy="0 0 0"/>      
      <mass value="0.003200000000000000587"/>      
      <inertia ixx="1.409759888701696132e-07" ixy="1.5562823134523607049e-15" ixz="3.9554371954665949126e-37" iyy="1.4097598803636001492e-07" iyz="-1.3068306635892905507e-36" izz="2.4107776386988840789e-07"/>      
    </inertial>    
  </link>  

  <joint name="right_sho_yaw_drive" type="fixed">    
    <origin xyz="-0.024000000716138267243 -0.019000000152445337132 -0.019000000152448424939" rpy="1.5707963267949289765 -7.4062049324254792929e-14 1.9645226351351914911e-14"/>    
    <parent link="2xl430_gears"/>    
    <child link="spur_1m_24t_drive"/>    
    <axis xyz="0 0 1"/>    
    <limit effort="1" velocity="20"/>    
    <joint_properties friction="0.0"/>    
  </joint>  

  <link name="spur_1m_24t_driven">    
    <visual>      
      <origin xyz="0 0 0" rpy="0 -0 0"/>      
      <geometry>        
        <mesh filename="package:///meshes/right_spur_1m_24t_driven_visual.stl"/>        
      </geometry>      
      <material name="spur_1m_24t_driven_material">        
        <color rgba="0.2313725490196078538 0.38039215686274507888 0.7058823529411765163 1.0"/>        
      </material>      
    </visual>    
    <collision>      
      <origin xyz="0 0 0" rpy="0 -0 0"/>      
      <geometry>        
        <mesh filename="package:///meshes/right_spur_1m_24t_driven_collision.stl"/>        
      </geometry>      
    </collision>    
    <inertial>      
      <origin xyz="-2.9213946397902766893e-18 -1.6882049367809071346e-15 -0.00097237500038395777158" rpy="0 0 0"/>      
      <mass value="0.0026999999999999992756"/>      
      <inertia ixx="1.2202334915684080498e-07" ixy="0" ixz="0" iyy="1.2202334915684064616e-07" iyz="-3.1611202962161956801e-37" izz="2.3180293204341252239e-07"/>      
    </inertial>    
  </link>  

  <link name="sho_yaw_link">    
    <visual>      
      <origin xyz="0 0 0" rpy="0 -0 0"/>      
      <geometry>        
        <mesh filename="package:///meshes/right_sho_yaw_link_visual.stl"/>        
      </geometry>      
      <material name="sho_yaw_link_material">        
        <color rgba="0.61568627450980395466 0.81176470588235294379 0.92941176470588227065 1.0"/>        
      </material>      
    </visual>    
    <collision>      
      <origin xyz="0 0 0" rpy="0 -0 0"/>      
      <geometry>        
        <mesh filename="package:///meshes/right_sho_yaw_link_collision.stl"/>        
      </geometry>      
    </collision>    
    <inertial>      
      <origin xyz="-1.286384586061391173e-18 3.5695430205025634479e-18 -0.024649285094360082193" rpy="0 0 0"/>      
      <mass value="0.014499999999999997266"/>      
      <inertia ixx="9.2365904614004456494e-06" ixy="3.5862833440692663253e-13" ixz="3.9137616104655003128e-44" iyy="5.8163826335078791714e-06" iyz="-5.7710285861749289932e-36" izz="4.5074356741562122031e-06"/>      
    </inertial>    
  </link>  

  <link name="2xl430_gears_2">    
    <visual>      
      <origin xyz="0 0 0" rpy="0 -0 0"/>      
      <geometry>        
        <mesh filename="package:///meshes/right_2xl430_gears_2_visual.stl"/>        
      </geometry>      
      <material name="2xl430_gears_2_material">        
        <color rgba="0.7591476792056923717 0.85560384745670925444 0.90519468321360618823 1.0"/>        
      </material>      
    </visual>    
    <collision>      
      <origin xyz="0 0 0" rpy="0 -0 0"/>      
      <geometry>        
        <mesh filename="package:///meshes/right_2xl430_gears_2_collision.stl"/>        
      </geometry>      
    </collision>    
    <inertial>      
      <origin xyz="-0.011592905737984601083 -0.0024238553642520564019 -0.018551095523805887638" rpy="0 0 0"/>      
      <mass value="0.11800003674524907338"/>      
      <inertia ixx="2.7511021050426052092e-05" ixy="9.0043904315050425938e-07" ixz="-2.3349710123665401621e-08" iyy="3.2796197843347216845e-05" iyz="-6.5715119654724493431e-07" izz="3.5775739835742259337e-05"/>      
    </inertial>    
  </link>  

  <link name="spur_1m_24t_drive_2">    
    <visual>      
      <origin xyz="0 0 0" rpy="0 -0 0"/>      
      <geometry>        
        <mesh filename="package:///meshes/right_spur_1m_24t_drive_2_visual.stl"/>        
      </geometry>      
      <material name="spur_1m_24t_drive_2_material">        
        <color rgba="0.61568627450980395466 0.81176470588235294379 0.92941176470588238168 1.0"/>        
      </material>      
    </visual>    
    <collision>      
      <origin xyz="0 0 0" rpy="0 -0 0"/>      
      <geometry>        
        <mesh filename="package:///meshes/right_spur_1m_24t_drive_2_collision.stl"/>        
      </geometry>      
    </collision>    
    <inertial>      
      <origin xyz="3.0256110569130224837e-15 -3.3903525175634688881e-16 0.0048096451474092995898" rpy="0 0 0"/>      
      <mass value="0.003200000000000000587"/>      
      <inertia ixx="1.409759888701696132e-07" ixy="1.5562823081290166788e-15" ixz="-2.834068160021242834e-36" iyy="1.4097598803635998845e-07" iyz="1.2526517803646003407e-36" izz="2.4107776386988840789e-07"/>      
    </inertial>    
  </link>  

  <joint name="right_elbow_yaw_drive" type="fixed">    
    <origin xyz="-0.024000000716147162905 -0.019000000152450874369 -0.019000000152450294971" rpy="1.5707963267950022512 -1.2151179192951298761e-14 -8.3478238015103697896e-15"/>    
    <parent link="2xl430_gears_2"/>    
    <child link="spur_1m_24t_drive_2"/>    
    <axis xyz="0 0 1"/>    
    <limit effort="1" velocity="20"/>    
    <joint_properties friction="0.0"/>    
  </joint>  

  <link name="spur_1m_24t_driven_2">    
    <visual>      
      <origin xyz="0 0 0" rpy="0 -0 0"/>      
      <geometry>        
        <mesh filename="package:///meshes/right_spur_1m_24t_driven_2_visual.stl"/>        
      </geometry>      
      <material name="spur_1m_24t_driven_2_material">        
        <color rgba="0.2313725490196078538 0.38039215686274507888 0.7058823529411765163 1.0"/>        
      </material>      
    </visual>    
    <collision>      
      <origin xyz="0 0 0" rpy="0 -0 0"/>      
      <geometry>        
        <mesh filename="package:///meshes/right_spur_1m_24t_driven_2_collision.stl"/>        
      </geometry>      
    </collision>    
    <inertial>      
      <origin xyz="-2.9213946397902766893e-18 -1.6882049367809083179e-15 -0.00097237500038396460205" rpy="0 0 0"/>      
      <mass value="0.0026999999999999992756"/>      
      <inertia ixx="1.2202334915684080498e-07" ixy="3.8503779869585959908e-37" ixz="1.8410192092776977521e-66" iyy="1.2202334915684064616e-07" iyz="1.7901380328147422279e-36" izz="2.3180293204341252239e-07"/>      
    </inertial>    
  </link>  

  <link name="elb_yaw_link">    
    <visual>      
      <origin xyz="0 0 0" rpy="0 -0 0"/>      
      <geometry>        
        <mesh filename="package:///meshes/right_elb_yaw_link_visual.stl"/>        
      </geometry>      
      <material name="elb_yaw_link_material">        
        <color rgba="0.61568627450980395466 0.81176470588235294379 0.92941176470588227065 1.0"/>        
      </material>      
    </visual>    
    <collision>      
      <origin xyz="0 0 0" rpy="0 -0 0"/>      
      <geometry>        
        <mesh filename="package:///meshes/right_elb_yaw_link_collision.stl"/>        
      </geometry>      
    </collision>    
    <inertial>      
      <origin xyz="5.3127688027528164616e-08 0.0019833638641961626875 -0.02341664355154993854" rpy="0 0 0"/>      
      <mass value="0.017500000000000005135"/>      
      <inertia ixx="1.4134344903109199776e-05" ixy="1.6945783921983924559e-12" ixz="-1.1286398721865470279e-11" iyy="6.6435900776211331934e-06" iyz="1.0545227077253053344e-06" izz="8.9925290757998976773e-06"/>      
    </inertial>    
  </link>  

  <link name="spur_1m_24t_driven_3">    
    <visual>      
      <origin xyz="0 0 0" rpy="0 -0 0"/>      
      <geometry>        
        <mesh filename="package:///meshes/right_spur_1m_24t_driven_3_visual.stl"/>        
      </geometry>      
      <material name="spur_1m_24t_driven_3_material">        
        <color rgba="0.2313725490196078538 0.38039215686274507888 0.7058823529411765163 1.0"/>        
      </material>      
    </visual>    
    <collision>      
      <origin xyz="0 0 0" rpy="0 -0 0"/>      
      <geometry>        
        <mesh filename="package:///meshes/right_spur_1m_24t_driven_3_collision.stl"/>        
      </geometry>      
    </collision>    
    <inertial>      
      <origin xyz="2.4834180975838778955e-17 -1.6882049367809035847e-15 -0.0025723750003839550293" rpy="0 0 0"/>      
      <mass value="0.0026999999999999992756"/>      
      <inertia ixx="1.2202334915684080498e-07" ixy="1.6801645595678856956e-36" ixz="1.4628821664372086897e-36" iyy="1.2202334915684064616e-07" iyz="0" izz="2.3180293204341252239e-07"/>      
    </inertial>    
  </link>  

  <link name="2xl430_gears_3">    
    <visual>      
      <origin xyz="0 0 0" rpy="0 -0 0"/>      
      <geometry>        
        <mesh filename="package:///meshes/right_2xl430_gears_3_visual.stl"/>        
      </geometry>      
      <material name="2xl430_gears_3_material">        
        <color rgba="0.7591476792056923717 0.85560384745670925444 0.90519468321360618823 1.0"/>        
      </material>      
    </visual>    
    <collision>      
      <origin xyz="0 0 0" rpy="0 -0 0"/>      
      <geometry>        
        <mesh filename="package:///meshes/right_2xl430_gears_3_collision.stl"/>        
      </geometry>      
    </collision>    
    <inertial>      
      <origin xyz="0.00044890447620015046237 0.011592905379911784894 -0.024576144788197192698" rpy="0 0 0"/>      
      <mass value="0.11800003674524907338"/>      
      <inertia ixx="3.5775739835742767557e-05" ixy="2.3349710123598919461e-08" ixz="6.5715119654677451339e-07" iyy="2.7511021050425879297e-05" iyz="9.0043904315183388935e-07" izz="3.2796197843346695073e-05"/>      
    </inertial>    
  </link>  

  <link name="spur_1m_24t_drive_3">    
    <visual>      
      <origin xyz="0 0 0" rpy="0 -0 0"/>      
      <geometry>        
        <mesh filename="package:///meshes/right_spur_1m_24t_drive_3_visual.stl"/>        
      </geometry>      
      <material name="spur_1m_24t_drive_3_material">        
        <color rgba="0.61568627450980395466 0.81176470588235294379 0.92941176470588238168 1.0"/>        
      </material>      
    </visual>    
    <collision>      
      <origin xyz="0 0 0" rpy="0 -0 0"/>      
      <geometry>        
        <mesh filename="package:///meshes/right_spur_1m_24t_drive_3_collision.stl"/>        
      </geometry>      
    </collision>    
    <inertial>      
      <origin xyz="3.0325499508169301065e-15 -3.3903525175634688881e-16 0.0048096451474093056613" rpy="0 0 0"/>      
      <mass value="0.003200000000000000587"/>      
      <inertia ixx="1.4097598887016963967e-07" ixy="1.5562823154952887796e-15" ixz="9.6598469821100867444e-37" iyy="1.4097598803636006786e-07" iyz="-1.7762240303079187312e-37" izz="2.4107776386988840789e-07"/>      
    </inertial>    
  </link>  

  <joint name="right_wrist_pitch_drive" type="fixed">    
    <origin xyz="-1.5244312511681577095e-10 0.024000000358071732487 -0.0080000000000008709977" rpy="1.2483159056318864267e-14 7.3485321852726251993e-14 -1.5707963267948599206"/>    
    <parent link="2xl430_gears_3"/>    
    <child link="spur_1m_24t_drive_3"/>    
    <axis xyz="0 0 1"/>    
    <limit effort="1" velocity="20"/>    
    <joint_properties friction="0.0"/>    
  </joint>  

  <link name="hand">    
    <visual>      
      <origin xyz="0 0 0" rpy="0 -0 0"/>      
      <geometry>        
        <mesh filename="package:///meshes/right_hand_visual.stl"/>        
      </geometry>      
      <material name="hand_material">        
        <color rgba="0.64149913129808888712 0.67624720774385704836 0.69709605361131810053 1.0"/>        
      </material>      
    </visual>    
    <collision>      
      <origin xyz="0 0 0" rpy="0 -0 0"/>      
      <geometry>        
        <mesh filename="package:///meshes/right_hand_collision.stl"/>        
      </geometry>      
    </collision>    
    <inertial>      
      <origin xyz="0.0037078693754091780581 -0.042127339671143418376 -0.019509671728381139388" rpy="0 0 0"/>      
      <mass value="0.039499999999999986511"/>      
      <inertia ixx="2.4635502047218993784e-05" ixy="6.2323015740443191139e-07" ixz="1.4391447736752212052e-08" iyy="2.5475207221933713524e-05" iyz="-4.0870433587618271501e-08" izz="1.3466679249845181932e-05"/>      
    </inertial>    
  </link>  

  <joint name="right_wrist_roll" type="revolute">    
    <origin xyz="0.019000000000002757738 -3.5806713150066116214e-10 -0.027000000152450184115" rpy="-1.0965151718337609193e-29 1.5707963267948208408 0"/>    
    <parent link="2xl430_gears_3"/>    
    <child link="hand"/>    
    <axis xyz="0 0 1"/>    
    <limit effort="1" velocity="20" lower="-1.3962634015954635824" upper="1.9198621771937625091"/>    
    <joint_properties friction="0.0"/>    
  </joint>  

  <link name="wrist_bearing_plate">    
    <visual>      
      <origin xyz="0 0 0" rpy="0 -0 0"/>      
      <geometry>        
        <mesh filename="package:///meshes/right_wrist_bearing_plate_visual.stl"/>        
      </geometry>      
      <material name="wrist_bearing_plate_material">        
        <color rgba="0.71932243125689065977 0.63128434304969727187 0.52422389360984933404 1.0"/>        
      </material>      
    </visual>    
    <collision>      
      <origin xyz="0 0 0" rpy="0 -0 0"/>      
      <geometry>        
        <mesh filename="package:///meshes/right_wrist_bearing_plate_collision.stl"/>        
      </geometry>      
    </collision>    
    <inertial>      
      <origin xyz="-0.007583558312149977533 -0.015499999999999982542 -0.0018386323705903335774" rpy="0 0 0"/>      
      <mass value="0.0049000367468305548388"/>      
      <inertia ixx="4.9707430109150129132e-07" ixy="1.1466335916912245224e-22" ixz="1.8100904820814035248e-08" iyy="7.1268523603538584823e-07" iyz="1.5467635767454412501e-23" izz="1.1919657811600111352e-06"/>      
    </inertial>    
  </link>  

  <joint name="right_wrist_pitch_fixed" type="fixed">    
    <origin xyz="0.015500000000003967202 4.5519144009631418157e-15 -0.045000000000003738398" rpy="-3.053113317715679127e-15 1.2051470932306202988e-13 -1.570796326794896558"/>    
    <parent link="2xl430_gears_3"/>    
    <child link="wrist_bearing_plate"/>    
    <axis xyz="0 0 1"/>    
    <limit effort="1" velocity="20"/>    
    <joint_properties friction="0.0"/>    
  </joint>  

  <joint name="right_wrist_pitch" type="revolute">    
    <origin xyz="2.7755575615628913511e-17 3.1554436208840472216e-30 -0.0015999999999999940051" rpy="-2.7183456742960519592e-16 6.3108872417680986472e-30 1.570796326794896558"/>    
    <parent link="spur_1m_24t_driven_3"/>    
    <child link="2xl430_gears_3"/>    
    <axis xyz="0 0 1"/>    
    <limit effort="1" velocity="20" lower="-1.9198621771937625091" upper="1.3962634015954635824"/>    
    <joint_properties friction="0.0"/>    
  </joint>  

  <joint name="right_wrist_roll_fixed" type="fixed">    
    <origin xyz="5.5220263365470826379e-30 -0.025299999999999999573 -0.051999999999999990674" rpy="1.570796326794896558 1.570796326794896558 0"/>    
    <parent link="elb_yaw_link"/>    
    <child link="spur_1m_24t_driven_3"/>    
    <axis xyz="0 0 1"/>    
    <limit effort="1" velocity="20"/>    
    <joint_properties friction="0.0"/>    
  </joint>  

  <joint name="right_elbow_yaw_fixed" type="fixed">    
    <origin xyz="-3.4694469519536141888e-18 7.8886090522101180541e-31 0.0015999999999999903189" rpy="3.141592653589793116 5.5511151240344814396e-17 -1.5707963267948970021"/>    
    <parent link="spur_1m_24t_driven_2"/>    
    <child link="elb_yaw_link"/>    
    <axis xyz="0 0 1"/>    
    <limit effort="1" velocity="20"/>    
    <joint_properties friction="0.0"/>    
  </joint>  

  <joint name="right_elbow_yaw" type="revolute">    
    <origin xyz="-3.5807255424624706563e-10 -0.027000000152453657032 -0.019000000000001768946" rpy="1.570796326794956066 3.0087043967523975425e-14 -4.0634162701317111644e-14"/>    
    <parent link="2xl430_gears_2"/>    
    <child link="spur_1m_24t_driven_2"/>    
    <axis xyz="0 0 1"/>    
    <limit effort="1" velocity="20" lower="-2.6179938779914944114" upper="2.6179938779914944114"/>    
    <joint_properties friction="0.0"/>    
  </joint>  

  <joint name="right_elbow_roll" type="revolute">    
    <origin xyz="-8.4654505627668186207e-16 -0.018999999999998996858 -0.05900000000000006628" rpy="1.570796326794896558 -7.4924624234411720275e-14 -2.6978419498846060156e-14"/>    
    <parent link="sho_yaw_link"/>    
    <child link="2xl430_gears_2"/>    
    <axis xyz="0 0 1"/>    
    <limit effort="1" velocity="20" lower="-1.9198621771937625091" upper="2.4434609527920612138"/>    
    <joint_properties friction="0.0"/>    
  </joint>  

  <joint name="right_sho_yaw_fixed" type="fixed">    
    <origin xyz="0 3.9443045261050590271e-31 0.0015999999999999972577" rpy="3.141592653589793116 -5.0487097934144755546e-29 -1.8301573001127473886e-28"/>    
    <parent link="spur_1m_24t_driven"/>    
    <child link="sho_yaw_link"/>    
    <axis xyz="0 0 1"/>    
    <limit effort="1" velocity="20"/>    
    <joint_properties friction="0.0"/>    
  </joint>  

  <joint name="right_sho_yaw" type="revolute">    
    <origin xyz="-3.5806816886529979627e-10 -0.027000000152446666096 -0.019000000000003354483" rpy="1.5707963267949260899 -2.2055090607973039157e-14 7.6050277186033683693e-15"/>    
    <parent link="2xl430_gears"/>    
    <child link="spur_1m_24t_driven"/>    
    <axis xyz="0 0 1"/>    
    <limit effort="1" velocity="20" lower="-2.6179938779914944114" upper="2.6179938779914944114"/>    
    <joint_properties friction="0.0"/>    
  </joint>  

  <joint name="right_sho_roll" type="revolute">    
    <origin xyz="-0.018999999999999999528 9.3241386833306442318e-18 0.027000000000000006634" rpy="3.141592653589793116 1.5707963267948952257 0"/>    
    <parent link="sho_pitch_link"/>    
    <child link="2xl430_gears"/>    
    <axis xyz="0 0 1"/>    
    <limit effort="1" velocity="20" lower="-1.570796326794896558" upper="0.34906585039886589561"/>    
    <joint_properties friction="0.0"/>    
  </joint>  


</robot>