<?xml version="1.0" ?><robot name="left_arm_gripper">  
  <link name="sho_pitch_link">    
    <visual>      
      <origin xyz="0 0 0" rpy="0 -0 0"/>      
      <geometry>        
        <mesh filename="package:///meshes/left_sho_pitch_link_visual.stl"/>        
      </geometry>      
      <material name="sho_pitch_link_material">        
        <color rgba="0.61568627450980395466 0.81176470588235294379 0.92941176470588227065 1.0"/>        
      </material>      
    </visual>    
    <collision>      
      <origin xyz="0 0 0" rpy="0 -0 0"/>      
      <geometry>        
        <mesh filename="package:///meshes/left_sho_pitch_link_collision.stl"/>        
      </geometry>      
    </collision>    
    <inertial>      
      <origin xyz="1.8449019812287164588e-18 -2.080223803955683775e-18 0.012913250798677554029" rpy="0 0 0"/>      
      <mass value="0.0085999999999999982708"/>      
      <inertia ixx="1.8365636406635691559e-06" ixy="1.0387514045979629962e-20" ixz="-1.6193093852519860617e-61" iyy="4.0110869076838864174e-06" iyz="-1.0800914119377960692e-46" izz="3.516051645049224817e-06"/>      
    </inertial>    
  </link>  

  <link name="2xl430_gears">    
    <visual>      
      <origin xyz="0 0 0" rpy="0 -0 0"/>      
      <geometry>        
        <mesh filename="package:///meshes/left_2xl430_gears_visual.stl"/>        
      </geometry>      
      <material name="2xl430_gears_material">        
        <color rgba="0.7591476792056923717 0.85560384745670914342 0.90519468321360618823 1.0"/>        
      </material>      
    </visual>    
    <collision>      
      <origin xyz="0 0 0" rpy="0 -0 0"/>      
      <geometry>        
        <mesh filename="package:///meshes/left_2xl430_gears_collision.stl"/>        
      </geometry>      
    </collision>    
    <inertial>      
      <origin xyz="-0.011592905737981450826 -0.002423855364253546963 -0.01855109552380399679" rpy="0 0 0"/>      
      <mass value="0.11800003674524908726"/>      
      <inertia ixx="2.7511021050426360412e-05" ixy="9.0043904315238054324e-07" ixz="-2.3349710124000869682e-08" iyy="3.2796197843347020334e-05" iyz="-6.5715119654760767617e-07" izz="3.5775739835743296106e-05"/>      
    </inertial>    
  </link>  

  <link name="spur_1m_24t_drive">    
    <visual>      
      <origin xyz="0 0 0" rpy="0 -0 0"/>      
      <geometry>        
        <mesh filename="package:///meshes/left_spur_1m_24t_drive_visual.stl"/>        
      </geometry>      
      <material name="spur_1m_24t_drive_material">        
        <color rgba="0.61568627450980406568 0.81176470588235294379 0.92941176470588238168 1.0"/>        
      </material>      
    </visual>    
    <collision>      
      <origin xyz="0 0 0" rpy="0 -0 0"/>      
      <geometry>        
        <mesh filename="package:///meshes/left_spur_1m_24t_drive_collision.stl"/>        
      </geometry>      
    </collision>    
    <inertial>      
      <origin xyz="3.0326539266682488924e-15 -3.3909557259597738952e-16 0.0048096451474093039266" rpy="0 0 0"/>      
      <mass value="0.0032000000000000001533"/>      
      <inertia ixx="1.409759888701696132e-07" ixy="1.5562823081573231774e-15" ixz="1.8909116097027644629e-36" iyy="1.4097598803635998845e-07" iyz="8.7196449218219347336e-37" izz="2.4107776386988835496e-07"/>      
    </inertial>    
  </link>  

  <joint name="left_sho_yaw_drive" type="revolute">    
    <origin xyz="-0.024000000716140296869 -0.019000000152454142588 -0.019000000152450579466" rpy="1.5707963267950031394 -3.1434454584096845964e-14 1.6688855498804727815e-13"/>    
    <parent link="2xl430_gears"/>    
    <child link="spur_1m_24t_drive"/>    
    <axis xyz="0 0 1"/>    
    <limit effort="1" velocity="20" lower="-2.6179938779914944114" upper="2.6179938779914944114"/>    
    <joint_properties friction="0.0"/>    
  </joint>  

  <link name="spur_1m_24t_driven">    
    <visual>      
      <origin xyz="0 0 0" rpy="0 -0 0"/>      
      <geometry>        
        <mesh filename="package:///meshes/left_spur_1m_24t_driven_visual.stl"/>        
      </geometry>      
      <material name="spur_1m_24t_driven_material">        
        <color rgba="0.23137254901960788156 0.38039215686274502337 0.7058823529411765163 1.0"/>        
      </material>      
    </visual>    
    <collision>      
      <origin xyz="0 0 0" rpy="0 -0 0"/>      
      <geometry>        
        <mesh filename="package:///meshes/left_spur_1m_24t_driven_collision.stl"/>        
      </geometry>      
    </collision>    
    <inertial>      
      <origin xyz="-6.3908415917439005078e-18 -1.6886349105605204739e-15 -0.00097237500038396124102" rpy="0 0 0"/>      
      <mass value="0.0026999999999999997093"/>      
      <inertia ixx="1.2202334915684083145e-07" ixy="4.2715130792968527767e-37" ixz="-7.4298475334020377518e-37" iyy="1.2202334915684064616e-07" iyz="3.4121884323812485808e-36" izz="2.3180293204341257533e-07"/>      
    </inertial>    
  </link>  

  <link name="sho_yaw_link">    
    <visual>      
      <origin xyz="0 0 0" rpy="0 -0 0"/>      
      <geometry>        
        <mesh filename="package:///meshes/left_sho_yaw_link_visual.stl"/>        
      </geometry>      
      <material name="sho_yaw_link_material">        
        <color rgba="0.61568627450980395466 0.81176470588235294379 0.92941176470588238168 1.0"/>        
      </material>      
    </visual>    
    <collision>      
      <origin xyz="0 0 0" rpy="0 -0 0"/>      
      <geometry>        
        <mesh filename="package:///meshes/left_sho_yaw_link_collision.stl"/>        
      </geometry>      
    </collision>    
    <inertial>      
      <origin xyz="-2.4352534325391168114e-18 2.8819643225844087237e-18 -0.024649285094360061377" rpy="0 0 0"/>      
      <mass value="0.014500000000000004205"/>      
      <inertia ixx="9.2365904614004439553e-06" ixy="3.5862833440690446869e-13" ixz="-1.2687936100387064119e-34" iyy="5.8163826335078791714e-06" iyz="-1.5023236319927603688e-35" izz="4.5074356741562113561e-06"/>      
    </inertial>    
  </link>  

  <link name="2xl430_gears_2">    
    <visual>      
      <origin xyz="0 0 0" rpy="0 -0 0"/>      
      <geometry>        
        <mesh filename="package:///meshes/left_2xl430_gears_2_visual.stl"/>        
      </geometry>      
      <material name="2xl430_gears_2_material">        
        <color rgba="0.7591476792056923717 0.85560384745670914342 0.90519468321360618823 1.0"/>        
      </material>      
    </visual>    
    <collision>      
      <origin xyz="0 0 0" rpy="0 -0 0"/>      
      <geometry>        
        <mesh filename="package:///meshes/left_2xl430_gears_2_collision.stl"/>        
      </geometry>      
    </collision>    
    <inertial>      
      <origin xyz="-0.01159290573798117327 -0.0024238553642602004949 -0.018551095523806161725" rpy="0 0 0"/>      
      <mass value="0.11800003674524908726"/>      
      <inertia ixx="2.7511021050432340465e-05" ixy="9.0043904315261866538e-07" ixz="-2.3349710124131547675e-08" iyy="3.2796197843347521777e-05" iyz="-6.5715119654698193058e-07" izz="3.5775739835749923291e-05"/>      
    </inertial>    
  </link>  

  <link name="spur_1m_24t_drive_2">    
    <visual>      
      <origin xyz="0 0 0" rpy="0 -0 0"/>      
      <geometry>        
        <mesh filename="package:///meshes/left_spur_1m_24t_drive_2_visual.stl"/>        
      </geometry>      
      <material name="spur_1m_24t_drive_2_material">        
        <color rgba="0.61568627450980406568 0.81176470588235294379 0.92941176470588238168 1.0"/>        
      </material>      
    </visual>    
    <collision>      
      <origin xyz="0 0 0" rpy="0 -0 0"/>      
      <geometry>        
        <mesh filename="package:///meshes/left_spur_1m_24t_drive_2_collision.stl"/>        
      </geometry>      
    </collision>    
    <inertial>      
      <origin xyz="3.0395928205721561208e-15 -3.3909557259597763604e-16 0.0048096451474092995898" rpy="0 0 0"/>      
      <mass value="0.0032000000000000001533"/>      
      <inertia ixx="1.409759888701696132e-07" ixy="1.5562823101719447534e-15" ixz="4.5205440903615987127e-36" iyy="1.4097598803636001492e-07" iyz="4.1303952486303564848e-36" izz="2.4107776386988835496e-07"/>      
    </inertial>    
  </link>  

  <joint name="left_elbow_yaw_drive" type="revolute">    
    <origin xyz="-0.024000000716141486889 -0.01900000015246021412 -0.019000000152444587731" rpy="1.5707963267946158936 -5.9566245242711314536e-14 1.228127009104490865e-13"/>    
    <parent link="2xl430_gears_2"/>    
    <child link="spur_1m_24t_drive_2"/>    
    <axis xyz="0 0 1"/>    
    <limit effort="1" velocity="20" lower="-2.6179938779914944114" upper="2.6179938779914944114"/>    
    <joint_properties friction="0.0"/>    
  </joint>  

  <link name="spur_1m_24t_driven_2">    
    <visual>      
      <origin xyz="0 0 0" rpy="0 -0 0"/>      
      <geometry>        
        <mesh filename="package:///meshes/left_spur_1m_24t_driven_2_visual.stl"/>        
      </geometry>      
      <material name="spur_1m_24t_driven_2_material">        
        <color rgba="0.23137254901960788156 0.38039215686274502337 0.7058823529411765163 1.0"/>        
      </material>      
    </visual>    
    <collision>      
      <origin xyz="0 0 0" rpy="0 -0 0"/>      
      <geometry>        
        <mesh filename="package:///meshes/left_spur_1m_24t_driven_2_collision.stl"/>        
      </geometry>      
    </collision>    
    <inertial>      
      <origin xyz="-2.9213946397902759189e-18 -1.6886349105605200794e-15 -0.00097237500038395430213" rpy="0 0 0"/>      
      <mass value="0.0026999999999999997093"/>      
      <inertia ixx="1.2202334915684083145e-07" ixy="0" ixz="0" iyy="1.2202334915684064616e-07" iyz="5.6884209303599264861e-37" izz="2.3180293204341257533e-07"/>      
    </inertial>    
  </link>  

  <link name="elb_yaw_link">    
    <visual>      
      <origin xyz="0 0 0" rpy="0 -0 0"/>      
      <geometry>        
        <mesh filename="package:///meshes/left_elb_yaw_link_visual.stl"/>        
      </geometry>      
      <material name="elb_yaw_link_material">        
        <color rgba="0.61568627450980395466 0.81176470588235294379 0.92941176470588227065 1.0"/>        
      </material>      
    </visual>    
    <collision>      
      <origin xyz="0 0 0" rpy="0 -0 0"/>      
      <geometry>        
        <mesh filename="package:///meshes/left_elb_yaw_link_collision.stl"/>        
      </geometry>      
    </collision>    
    <inertial>      
      <origin xyz="5.3127688027189133061e-08 0.0019833638641961665906 -0.023416643551549962826" rpy="0 0 0"/>      
      <mass value="0.017500000000000001665"/>      
      <inertia ixx="1.4134344903109196387e-05" ixy="1.6945783921929356084e-12" ixz="-1.1286398721892709078e-11" iyy="6.6435900776211340404e-06" iyz="1.0545227077253057579e-06" izz="8.9925290757998976773e-06"/>      
    </inertial>    
  </link>  

  <link name="spur_1m_24t_driven_3">    
    <visual>      
      <origin xyz="0 0 0" rpy="0 -0 0"/>      
      <geometry>        
        <mesh filename="package:///meshes/left_spur_1m_24t_driven_3_visual.stl"/>        
      </geometry>      
      <material name="spur_1m_24t_driven_3_material">        
        <color rgba="0.23137254901960788156 0.38039215686274502337 0.7058823529411765163 1.0"/>        
      </material>      
    </visual>    
    <collision>      
      <origin xyz="0 0 0" rpy="0 -0 0"/>      
      <geometry>        
        <mesh filename="package:///meshes/left_spur_1m_24t_driven_3_collision.stl"/>        
      </geometry>      
    </collision>    
    <inertial>      
      <origin xyz="-2.9213946397902759189e-18 -1.6886349105605200794e-15 -0.0025723750003839584988" rpy="0 0 0"/>      
      <mass value="0.0026999999999999997093"/>      
      <inertia ixx="1.2202334915684083145e-07" ixy="-3.9235082874827157071e-37" ixz="1.540151194783440735e-36" iyy="1.2202334915684064616e-07" iyz="1.0864894308623725195e-65" izz="2.3180293204341257533e-07"/>      
    </inertial>    
  </link>  

  <link name="2xl430_gears_3">    
    <visual>      
      <origin xyz="0 0 0" rpy="0 -0 0"/>      
      <geometry>        
        <mesh filename="package:///meshes/left_2xl430_gears_3_visual.stl"/>        
      </geometry>      
      <material name="2xl430_gears_3_material">        
        <color rgba="0.7591476792056923717 0.85560384745670914342 0.90519468321360618823 1.0"/>        
      </material>      
    </visual>    
    <collision>      
      <origin xyz="0 0 0" rpy="0 -0 0"/>      
      <geometry>        
        <mesh filename="package:///meshes/left_2xl430_gears_3_collision.stl"/>        
      </geometry>      
    </collision>    
    <inertial>      
      <origin xyz="0.00044890447619516703551 0.011592905379904264868 -0.024576144788197775565" rpy="0 0 0"/>      
      <mass value="0.11800003674524908726"/>      
      <inertia ixx="3.5775739835741886643e-05" ixy="2.334971012477968339e-08" ixz="6.5715119654911433603e-07" iyy="2.7511021050427295537e-05" iyz="9.0043904314901125793e-07" izz="3.27961978433465731e-05"/>      
    </inertial>    
  </link>  

  <link name="spur_1m_24t_drive_3">    
    <visual>      
      <origin xyz="0 0 0" rpy="0 -0 0"/>      
      <geometry>        
        <mesh filename="package:///meshes/left_spur_1m_24t_drive_3_visual.stl"/>        
      </geometry>      
      <material name="spur_1m_24t_drive_3_material">        
        <color rgba="0.61568627450980406568 0.81176470588235294379 0.92941176470588238168 1.0"/>        
      </material>      
    </visual>    
    <collision>      
      <origin xyz="0 0 0" rpy="0 -0 0"/>      
      <geometry>        
        <mesh filename="package:///meshes/left_spur_1m_24t_drive_3_collision.stl"/>        
      </geometry>      
    </collision>    
    <inertial>      
      <origin xyz="3.0326539266682488924e-15 -3.3909557259597738952e-16 0.004809645147409304794" rpy="0 0 0"/>      
      <mass value="0.0032000000000000001533"/>      
      <inertia ixx="1.409759888701696132e-07" ixy="1.556282311437739129e-15" ixz="-1.8235547395955791874e-37" iyy="1.4097598803635998845e-07" iyz="-5.9472593219276696462e-37" izz="2.4107776386988835496e-07"/>      
    </inertial>    
  </link>  

  <joint name="left_wrist_pitch_drive" type="revolute">    
    <origin xyz="-1.5244671348201973698e-10 0.024000000358068290796 -0.0080000000000027861324" rpy="-4.3526989296690041628e-14 -1.012303054589254389e-13 -1.5707963267948548136"/>    
    <parent link="2xl430_gears_3"/>    
    <child link="spur_1m_24t_drive_3"/>    
    <axis xyz="0 0 1"/>    
    <limit effort="1" velocity="20" lower="-1.9198621771937625091" upper="1.3962634015954635824"/>    
    <joint_properties friction="0.0"/>    
  </joint>  

  <link name="gripper_connector">    
    <visual>      
      <origin xyz="0 0 0" rpy="0 -0 0"/>      
      <geometry>        
        <mesh filename="package:///meshes/left_gripper_connector_visual.stl"/>        
      </geometry>      
      <material name="gripper_connector_material">        
        <color rgba="0.61568627450980395466 0.81176470588235294379 0.92941176470588238168 1.0"/>        
      </material>      
    </visual>    
    <collision>      
      <origin xyz="0 0 0" rpy="0 -0 0"/>      
      <geometry>        
        <mesh filename="package:///meshes/left_gripper_connector_collision.stl"/>        
      </geometry>      
    </collision>    
    <inertial>      
      <origin xyz="-0.00018842170188954562057 -0.022508162473387258173 -0.010896047477464287576" rpy="0 0 0"/>      
      <mass value="0.0099999999999999967387"/>      
      <inertia ixx="5.9456375734536726584e-06" ixy="-2.4479055491886681531e-08" ixz="-4.0329437936864279052e-08" iyy="4.2603724874314054683e-06" iyz="4.585261274976229064e-07" izz="2.4669632528047159756e-06"/>      
    </inertial>    
  </link>  

  <link name="left_rail_guide">    
    <visual>      
      <origin xyz="0 0 0" rpy="0 -0 0"/>      
      <geometry>        
        <mesh filename="package:///meshes/left_rail_guide_visual.stl"/>        
      </geometry>      
      <material name="left_rail_guide_material">        
        <color rgba="0.63181718041513335038 0.80465605329635436771 0.89972875975946808857 1.0"/>        
      </material>      
    </visual>    
    <collision>      
      <origin xyz="0 0 0" rpy="0 -0 0"/>      
      <geometry>        
        <mesh filename="package:///meshes/left_rail_guide_collision.stl"/>        
      </geometry>      
    </collision>    
    <inertial>      
      <origin xyz="0.010819518839780870034 0.0021116106205359632016 -7.6871709864913219043e-05" rpy="0 0 0"/>      
      <mass value="0.031121017612416673748"/>      
      <inertia ixx="7.8532725551086577254e-06" ixy="2.0671876731375216749e-06" ixz="4.0098876287871815401e-06" iyy="2.7330594711584456634e-05" iyz="-8.9062740055664937356e-07" izz="3.0532648647413076451e-05"/>      
    </inertial>    
  </link>  

  <link name="rail">    
    <visual>      
      <origin xyz="0 0 0" rpy="0 -0 0"/>      
      <geometry>        
        <mesh filename="package:///meshes/left_rail_visual.stl"/>        
      </geometry>      
      <material name="rail_material">        
        <color rgba="0.64705882352941179736 0.64705882352941179736 0.64705882352941179736 1.0"/>        
      </material>      
    </visual>    
    <collision>      
      <origin xyz="0 0 0" rpy="0 -0 0"/>      
      <geometry>        
        <mesh filename="package:///meshes/left_rail_collision.stl"/>        
      </geometry>      
    </collision>    
    <inertial>      
      <origin xyz="0.029554714214719168819 -0.015933051259988686987 -0.010638774525132309312" rpy="0 0 0"/>      
      <mass value="0.017100000000000004086"/>      
      <inertia ixx="3.6591938331681682466e-06" ixy="2.101313841244636705e-08" ixz="-1.1335092663308559672e-07" iyy="4.7380338190523213965e-06" iyz="3.1225833654311399591e-08" izz="6.0956112819844626417e-06"/>      
    </inertial>    
  </link>  

  <joint name="left_gripper_pinion" type="prismatic">    
    <origin xyz="-0.028872600000000164799 -0.015974999999999989209 -0.0053499999999998826272" rpy="-3.141592653589793116 1.5707963267948943376 0"/>    
    <parent link="left_rail_guide"/>    
    <child link="rail"/>    
    <axis xyz="0 0 1"/>    
    <limit effort="1" velocity="20" lower="-0.025000000000000001388" upper="0"/>    
    <joint_properties friction="0.0"/>    
  </joint>  

  <link name="rail_2">    
    <visual>      
      <origin xyz="0 0 0" rpy="0 -0 0"/>      
      <geometry>        
        <mesh filename="package:///meshes/left_rail_2_visual.stl"/>        
      </geometry>      
      <material name="rail_2_material">        
        <color rgba="0.64705882352941179736 0.64705882352941179736 0.64705882352941179736 1.0"/>        
      </material>      
    </visual>    
    <collision>      
      <origin xyz="0 0 0" rpy="0 -0 0"/>      
      <geometry>        
        <mesh filename="package:///meshes/left_rail_2_collision.stl"/>        
      </geometry>      
    </collision>    
    <inertial>      
      <origin xyz="0.029554714214719168819 -0.015933051259988697396 -0.010638774525132309312" rpy="0 0 0"/>      
      <mass value="0.017100000000000004086"/>      
      <inertia ixx="3.6591938331681682466e-06" ixy="2.101313841244636705e-08" ixz="-1.1335092663308559672e-07" iyy="4.7380338190523213965e-06" iyz="3.1225833654311399591e-08" izz="6.0956112819844626417e-06"/>      
    </inertial>    
  </link>  

  <joint name="left_gripper_pinion_mirror" type="prismatic">    
    <origin xyz="0.062872600000000139486 0.015974999999999992678 -0.0053499999999998826272" rpy="4.5102810356081756005e-17 1.5707963267948943376 0"/>    
    <parent link="left_rail_guide"/>    
    <child link="rail_2"/>    
    <axis xyz="0 0 1"/>    
    <limit effort="1" velocity="20" lower="-0.025000000000000001388" upper="0"/>    
    <joint_properties friction="0.0"/>    
  </joint>  

  <link name="xc330">    
    <visual>      
      <origin xyz="0 0 0" rpy="0 -0 0"/>      
      <geometry>        
        <mesh filename="package:///meshes/left_xc330_visual.stl"/>        
      </geometry>      
      <material name="xc330_material">        
        <color rgba="0.66932535752643762539 0.72911795671409951325 0.67547870389434383487 1.0"/>        
      </material>      
    </visual>    
    <collision>      
      <origin xyz="0 0 0" rpy="0 -0 0"/>      
      <geometry>        
        <mesh filename="package:///meshes/left_xc330_collision.stl"/>        
      </geometry>      
    </collision>    
    <inertial>      
      <origin xyz="0.0080045171539637974961 -0.015558009851629327203 -0.011717805512823017966" rpy="0 0 0"/>      
      <mass value="0.026599999993091757305"/>      
      <inertia ixx="3.8683410666521895126e-06" ixy="-7.7688424003112006139e-10" ixz="5.7969695833402896073e-10" iyy="2.1626767907501911835e-06" iyz="8.3590274794495044522e-09" izz="3.3158761130057114888e-06"/>      
    </inertial>    
  </link>  

  <link name="spur_gear_(18_teeth)">    
    <visual>      
      <origin xyz="0 0 0" rpy="0 -0 0"/>      
      <geometry>        
        <mesh filename="package:///meshes/left_spur_gear_(18_teeth)_visual.stl"/>        
      </geometry>      
      <material name="spur_gear_(18_teeth)_material">        
        <color rgba="0.91764705882352926025 0.91764705882352926025 0.91764705882352926025 1.0"/>        
      </material>      
    </visual>    
    <collision>      
      <origin xyz="0 0 0" rpy="0 -0 0"/>      
      <geometry>        
        <mesh filename="package:///meshes/left_spur_gear_(18_teeth)_collision.stl"/>        
      </geometry>      
    </collision>    
    <inertial>      
      <origin xyz="6.4184768611141862493e-17 -3.8163916471489756077e-17 -0.0025000000000000351802" rpy="0 0 0"/>      
      <mass value="0.0012999999999999999403"/>      
      <inertia ixx="3.3282842836137718203e-08" ixy="-1.5693871188436038975e-22" ixz="-1.7407521658115461729e-36" iyy="3.3282842836137460123e-08" iyz="1.3305382458620200286e-36" izz="6.1149428795799489038e-08"/>      
    </inertial>    
  </link>  

  <joint name="left_gripper_rack" type="revolute">    
    <origin xyz="0.0079999999999991987243 -0.022499999999989410415 -0.026000000000007045253" rpy="-6.0998081585770428182e-13 -5.3836237079920826632e-14 3.1415926535897362726"/>    
    <parent link="xc330"/>    
    <child link="spur_gear_(18_teeth)"/>    
    <axis xyz="0 0 1"/>    
    <limit effort="1" velocity="20" lower="0" upper="2.7052603405912107881"/>    
    <joint_properties friction="0.0"/>    
  </joint>  

  <joint name="left_gripper_motor" type="fixed">    
    <origin xyz="-0.02195000000000000423 0.022600000000000005501 0.023300000000000015143" rpy="4.1904291285340139929e-27 -4.2723316019681090438e-30 3.8731841363269910881e-30"/>    
    <parent link="left_rail_guide"/>    
    <child link="xc330"/>    
    <axis xyz="0 0 1"/>    
    <limit effort="1" velocity="20"/>    
    <joint_properties friction="0.0"/>    
  </joint>  

  <joint name="left_gripper_fixed" type="fixed">    
    <origin xyz="3.4694469519536141888e-18 -0.037000000000000005107 -0.036000000000000004219" rpy="-1.5707963267948923392 -1.5707963267948945596 0"/>    
    <parent link="gripper_connector"/>    
    <child link="left_rail_guide"/>    
    <axis xyz="0 0 1"/>    
    <limit effort="1" velocity="20"/>    
    <joint_properties friction="0.0"/>    
  </joint>  

  <joint name="left_wrist_roll" type="revolute">    
    <origin xyz="0.0190000000000069523 -3.5808195297803990798e-10 -0.027000000152449583901" rpy="-5.2304162520204924206e-14 1.5707963267947342434 0"/>    
    <parent link="2xl430_gears_3"/>    
    <child link="gripper_connector"/>    
    <axis xyz="0 0 1"/>    
    <limit effort="1" velocity="20" lower="-1.9198621771937625091" upper="1.3962634015954635824"/>    
    <joint_properties friction="0.0"/>    
  </joint>  

  <link name="wrist_bearing_plate">    
    <visual>      
      <origin xyz="0 0 0" rpy="0 -0 0"/>      
      <geometry>        
        <mesh filename="package:///meshes/left_wrist_bearing_plate_visual.stl"/>        
      </geometry>      
      <material name="wrist_bearing_plate_material">        
        <color rgba="0.71932243125689065977 0.63128434304969727187 0.52422389360984933404 1.0"/>        
      </material>      
    </visual>    
    <collision>      
      <origin xyz="0 0 0" rpy="0 -0 0"/>      
      <geometry>        
        <mesh filename="package:///meshes/left_wrist_bearing_plate_collision.stl"/>        
      </geometry>      
    </collision>    
    <inertial>      
      <origin xyz="-0.0075835583121500122275 -0.015499999999999973868 -0.0018386323705903270722" rpy="0 0 0"/>      
      <mass value="0.0049000367468305548388"/>      
      <inertia ixx="4.9707430109150065605e-07" ixy="8.6939968023150419247e-23" ixz="1.8100904820814035248e-08" iyy="7.126852360353850012e-07" iyz="2.1431646046406056847e-23" izz="1.1919657811600107117e-06"/>      
    </inertial>    
  </link>  

  <joint name="left_wrist_pitch_fixed" type="fixed">    
    <origin xyz="0.015500000000001491751 -8.0768725041480138316e-15 -0.045000000000001545708" rpy="-2.3964771139741255694e-14 -1.2834872054056844396e-13 -1.5707963267947808728"/>    
    <parent link="2xl430_gears_3"/>    
    <child link="wrist_bearing_plate"/>    
    <axis xyz="0 0 1"/>    
    <limit effort="1" velocity="20"/>    
    <joint_properties friction="0.0"/>    
  </joint>  

  <joint name="left_wrist_pitch_driven" type="revolute">    
    <origin xyz="0 6.3108872417680944433e-30 -0.0016000000000000005104" rpy="-1.1497747198776528831e-14 -1.1323324151998767252e-14 -1.570796326794896558"/>    
    <parent link="spur_1m_24t_driven_3"/>    
    <child link="2xl430_gears_3"/>    
    <axis xyz="0 0 1"/>    
    <limit effort="1" velocity="20" lower="-1.3962634015954635824" upper="1.9198621771937625091"/>    
    <joint_properties friction="0.0"/>    
  </joint>  

  <joint name="left_wrist_roll_fixed" type="fixed">    
    <origin xyz="0 -0.025299999999999999573 -0.05200000000000001843" rpy="1.570796326794896558 -1.570796326794896558 0"/>    
    <parent link="elb_yaw_link"/>    
    <child link="spur_1m_24t_driven_3"/>    
    <axis xyz="0 0 1"/>    
    <limit effort="1" velocity="20"/>    
    <joint_properties friction="0.0"/>    
  </joint>  

  <joint name="left_elbow_yaw_fixed" type="fixed">    
    <origin xyz="0 0 0.0016000000000000180744" rpy="3.141592653589793116 1.6076875098280159747e-30 -1.570796326794896558"/>    
    <parent link="spur_1m_24t_driven_2"/>    
    <child link="elb_yaw_link"/>    
    <axis xyz="0 0 1"/>    
    <limit effort="1" velocity="20"/>    
    <joint_properties friction="0.0"/>    
  </joint>  

  <joint name="left_elbow_yaw_driven" type="revolute">    
    <origin xyz="-3.5806306877828042445e-10 -0.027000000152460831848 -0.018999999999996998457" rpy="1.5707963267946301045 -3.8080649744640572174e-14 1.8610630468591325517e-14"/>    
    <parent link="2xl430_gears_2"/>    
    <child link="spur_1m_24t_driven_2"/>    
    <axis xyz="0 0 1"/>    
    <limit effort="1" velocity="20" lower="-2.6179938779914944114" upper="2.6179938779914944114"/>    
    <joint_properties friction="0.0"/>    
  </joint>  

  <joint name="left_elbow_roll" type="revolute">    
    <origin xyz="-3.4694469519536141888e-18 -0.019000000000000002998 -0.058999999999999976075" rpy="1.570796326794896558 6.8561441953598501935e-15 1.0275284166515774965e-14"/>    
    <parent link="sho_yaw_link"/>    
    <child link="2xl430_gears_2"/>    
    <axis xyz="0 0 1"/>    
    <limit effort="1" velocity="20" lower="-1.9198621771937625091" upper="2.4434609527920612138"/>    
    <joint_properties friction="0.0"/>    
  </joint>  

  <joint name="left_sho_yaw_fixed" type="fixed">    
    <origin xyz="0 7.8886090522101180541e-31 0.0016000000000000041966" rpy="3.1415926535897629179 2.2803010536375530635e-31 -2.1481139489452393748e-30"/>    
    <parent link="spur_1m_24t_driven"/>    
    <child link="sho_yaw_link"/>    
    <axis xyz="0 0 1"/>    
    <limit effort="1" velocity="20"/>    
    <joint_properties friction="0.0"/>    
  </joint>  

  <joint name="left_sho_yaw_driven" type="revolute">    
    <origin xyz="-3.5806558759676754278e-10 -0.027000000152452598851 -0.019000000000006039835" rpy="1.5707963267950022512 -1.1972614697765140736e-14 1.2707074635707766131e-13"/>    
    <parent link="2xl430_gears"/>    
    <child link="spur_1m_24t_driven"/>    
    <axis xyz="0 0 1"/>    
    <limit effort="1" velocity="20" lower="-2.6179938779914944114" upper="2.6179938779914944114"/>    
    <joint_properties friction="0.0"/>    
  </joint>  

  <joint name="left_sho_roll" type="revolute">    
    <origin xyz="-0.018999999999999933609 -2.4431845435657347395e-17 0.026999999999999909489" rpy="3.1415926535897913396 1.5707963267948392705 0"/>    
    <parent link="sho_pitch_link"/>    
    <child link="2xl430_gears"/>    
    <axis xyz="0 0 1"/>    
    <limit effort="1" velocity="20" lower="-1.570796326794896558" upper="0.34906585039886589561"/>    
    <joint_properties friction="0.0"/>    
  </joint>  


</robot>