<?xml version="1.0" ?>
<robot name="sysID_2XL430">
  <link name="2xl430">
    <visual>
      <origin xyz="0 0 0" rpy="0 -0 0"/>
      <geometry>
        <mesh filename="package:///meshes/2xl430_visual.stl"/>
      </geometry>
      <material name="2xl430_material">
        <color rgba="0.74774239611736703637 0.8401414674150439188 0.89001491737990734432 1.0"/>
      </material>
    </visual>
    <collision>
      <origin xyz="0 0 0" rpy="0 -0 0"/>
      <geometry>
        <mesh filename="package:///meshes/2xl430_collision.stl"/>
      </geometry>
    </collision>
    <inertial>
      <origin xyz="0.074637808447704387382 0.017802872414827662639 0.0060007862055428658546" rpy="0 0 0"/>
      <mass value="0.12784999999841853424"/>
      <inertia ixx="4.4888939210807774166e-05" ixy="-5.9504395818475997514e-06" ixz="-6.9374906701103295362e-07" iyy="4.3761239815176726313e-05" iyz="-1.7042449579308966748e-07" izz="5.7422593236642129088e-05"/>
    </inertial>
  </link>

  <link name="arm_430">
    <visual>
      <origin xyz="0 0 0" rpy="0 -0 0"/>
      <geometry>
        <mesh filename="package:///meshes/arm_430_visual.stl"/>
      </geometry>
      <material name="arm_430_material">
        <color rgba="0.63059283987567626983 0.65298952457695413898 0.67418901807298270423 1.0"/>
      </material>
    </visual>
    <collision>
      <origin xyz="0 0 0" rpy="0 -0 0"/>
      <geometry>
        <mesh filename="package:///meshes/arm_430_collision.stl"/>
      </geometry>
    </collision>
    <inertial>
      <origin xyz="-0.07779038703199558924 1.3637865612826256597e-05 -0.018999999999999885036" rpy="0 0 0"/>
      <mass value="0.25549999999999994937"/>
      <inertia ixx="0.0002442614437637843027" ixy="-9.4015858833451833388e-08" ixz="5.2159369462844190991e-20" iyy="0.00041073874164066647872" iyz="1.4859910756754919957e-16" izz="0.00022084196523238381607"/>
    </inertial>
  </link>

  <joint name="joint_0" type="revolute">
    <origin xyz="0.057999999999999982125 0.032699858285928966317 0.0056193957935184602609" rpy="1.570796326794896558 -2.2412627309618028409e-15 -1.5707963267949029973"/>
    <parent link="2xl430"/>
    <child link="arm_430"/>
    <axis xyz="0 0 1"/>
    <limit effort="1" velocity="20" lower="-1.570796326794896558" upper="1.570796326794896558"/>
    <joint_properties friction="0.0"/>
  </joint>


</robot>