<?xml version="1.0" ?><robot name="toddlerbot_active">  
  <link name="torso">    
    <visual>      
      <origin xyz="0 0 0" rpy="0 -0 0"/>      
      <geometry>        
        <mesh filename="package:///meshes/torso_visual.stl"/>        
      </geometry>      
      <material name="torso_material">        
        <color rgba="0.63761324738265867662 0.79140018897832409284 0.89744804913511855293 1.0"/>        
      </material>      
    </visual>    
    <collision>      
      <origin xyz="0 0 0" rpy="0 -0 0"/>      
      <geometry>        
        <mesh filename="package:///meshes/torso_collision.stl"/>        
      </geometry>      
    </collision>    
    <inertial>      
      <origin xyz="-0.0045319089141771587426 -0.003304684919445583912 0.065594108502290693341" rpy="0 0 0"/>      
      <mass value="1.1369659631012025702"/>      
      <inertia ixx="0.0029825917743578653045" ixy="8.1730614288441110122e-05" ixz="2.1951370741857522675e-05" iyy="0.0023969506399989367815" iyz="-2.9575017351927617657e-05" izz="0.0025126356523908575241"/>      
    </inertial>    
  </link>  

  <link name="spur_1m_20t">    
    <visual>      
      <origin xyz="0 0 0" rpy="0 -0 0"/>      
      <geometry>        
        <mesh filename="package:///meshes/spur_1m_20t_visual.stl"/>        
      </geometry>      
      <material name="spur_1m_20t_material">        
        <color rgba="0.64705882352941179736 0.64705882352941179736 0.64705882352941179736 1.0"/>        
      </material>      
    </visual>    
    <collision>      
      <origin xyz="0 0 0" rpy="0 -0 0"/>      
      <geometry>        
        <mesh filename="package:///meshes/spur_1m_20t_collision.stl"/>        
      </geometry>      
    </collision>    
    <inertial>      
      <origin xyz="1.033113693395190359e-19 -8.1190949670117685889e-18 0.0033842321054344710884" rpy="0 0 0"/>      
      <mass value="0.0015778025963746002049"/>      
      <inertia ixx="4.5874424196602091527e-08" ixy="6.4004493355995885587e-24" ixz="-7.1097175513400442172e-39" iyy="4.5874424196602051822e-08" iyz="7.8419015231486103005e-38" izz="8.1737050837173876176e-08"/>      
    </inertial>    
  </link>  

  <joint name="neck_yaw_drive" type="fixed">    
    <origin xyz="-0.0049999999999995221878 3.1860588521011854095e-18 0.12148651076281755112" rpy="1.1607298201443905188e-14 1.6509758832059179101e-15 -5.3832337592600790636e-15"/>    
    <parent link="torso"/>    
    <child link="spur_1m_20t"/>    
    <axis xyz="0 0 1"/>    
    <limit effort="1" velocity="20"/>    
    <joint_properties friction="0.0"/>    
  </joint>  

  <link name="neck_yaw_link_v2">    
    <visual>      
      <origin xyz="0 0 0" rpy="0 -0 0"/>      
      <geometry>        
        <mesh filename="package:///meshes/neck_yaw_link_v2_visual.stl"/>        
      </geometry>      
      <material name="neck_yaw_link_v2_material">        
        <color rgba="0.2313725490196078538 0.38039215686274507888 0.7058823529411765163 1.0"/>        
      </material>      
    </visual>    
    <collision>      
      <origin xyz="0 0 0" rpy="0 -0 0"/>      
      <geometry>        
        <mesh filename="package:///meshes/neck_yaw_link_v2_collision.stl"/>        
      </geometry>      
    </collision>    
    <inertial>      
      <origin xyz="-1.1403990895369465715e-06 -1.1841855622439994436e-10 0.0082571849701004954719" rpy="0 0 0"/>      
      <mass value="0.0067298837334394080376"/>      
      <inertia ixx="5.2266067624768075857e-07" ixy="-6.304640333971203666e-15" ixz="1.1949403084466792453e-09" iyy="6.1218519979556577564e-07" iyz="-2.6012871963985172886e-15" izz="2.8062851709981919258e-07"/>      
    </inertial>    
  </link>  

  <link name="head">    
    <visual>      
      <origin xyz="0 0 0" rpy="0 -0 0"/>      
      <geometry>        
        <mesh filename="package:///meshes/head_visual.stl"/>        
      </geometry>      
      <material name="head_material">        
        <color rgba="0.62873939703496806164 0.7936429130509347063 0.87330110949792505437 1.0"/>        
      </material>      
    </visual>    
    <collision>      
      <origin xyz="0 0 0" rpy="0 -0 0"/>      
      <geometry>        
        <mesh filename="package:///meshes/head_collision.stl"/>        
      </geometry>      
    </collision>    
    <inertial>      
      <origin xyz="-0.045316002313821455993 -0.011276855645191822403 -0.0010251236602530926136" rpy="0 0 0"/>      
      <mass value="0.13722101760550836635"/>      
      <inertia ixx="0.00011880807294044726621" ixy="1.1390016804751229894e-06" ixz="1.8378816154934641622e-06" iyy="0.0001048907611543299336" iyz="-9.2536559812160149003e-06" izz="9.189462406161218557e-05"/>      
    </inertial>    
  </link>  

  <link name="motor_plate">    
    <visual>      
      <origin xyz="0 0 0" rpy="0 -0 0"/>      
      <geometry>        
        <mesh filename="package:///meshes/motor_plate_visual.stl"/>        
      </geometry>      
      <material name="motor_plate_material">        
        <color rgba="0.64705882352941179736 0.64705882352941179736 0.64705882352941179736 1.0"/>        
      </material>      
    </visual>    
    <collision>      
      <origin xyz="0 0 0" rpy="0 -0 0"/>      
      <geometry>        
        <mesh filename="package:///meshes/motor_plate_collision.stl"/>        
      </geometry>      
    </collision>    
    <inertial>      
      <origin xyz="-6.9388939039072283776e-18 3.4694469519536141888e-18 -0.0028281768943845498818" rpy="0 0 0"/>      
      <mass value="0.0016999999999999996884"/>      
      <inertia ixx="4.8050290733103710363e-08" ixy="1.0773753257370483397e-09" ixz="-2.8434898612727701604e-36" iyy="5.1782428339099023582e-08" iyz="-8.7187946076336322982e-37" izz="9.2194729037862222859e-08"/>      
    </inertial>    
  </link>  

  <joint name="neck_pitch_act" type="fixed">    
    <origin xyz="-0.032615697718560709983 -0.027000000000000072553 0.0024999999999998486974" rpy="-3.1415926535897655825 -3.1793530896719215746e-13 -3.1415926535897407135"/>    
    <parent link="head"/>    
    <child link="motor_plate"/>    
    <axis xyz="0 0 1"/>    
    <limit effort="1" velocity="20"/>    
    <joint_properties friction="0.0"/>    
  </joint>  

  <joint name="neck_pitch" type="revolute">    
    <origin xyz="-1.1796119636642288242e-16 0.0040000000000001215139 0.019400000000000056088" rpy="-1.5707963267904627713 1.5671692223466835436 -3.1415926535886637971"/>    
    <parent link="neck_yaw_link_v2"/>    
    <child link="head"/>    
    <axis xyz="0 0 1"/>    
    <limit effort="1" velocity="20" lower="-1.3962634015954635824" upper="0.61086523819801530344"/>    
    <joint_properties friction="0.0"/>    
  </joint>  

  <joint name="neck_yaw" type="revolute">    
    <origin xyz="0.016000000000000621364 3.9122381713629107253e-19 0.12248651076281739936" rpy="1.5470695466536949876e-14 -3.0902695541116811913e-15 -8.6007558735577539147e-16"/>    
    <parent link="torso"/>    
    <child link="neck_yaw_link_v2"/>    
    <axis xyz="0 0 1"/>    
    <limit effort="1" velocity="20" lower="-2.6179938779914944114" upper="2.6179938779914944114"/>    
    <joint_properties friction="0.0"/>    
  </joint>  

  <link name="waist_gears">    
    <visual>      
      <origin xyz="0 0 0" rpy="0 -0 0"/>      
      <geometry>        
        <mesh filename="package:///meshes/waist_gears_visual.stl"/>        
      </geometry>      
      <material name="waist_gears_material">        
        <color rgba="0.29673072126509864033 0.50090014891145351328 0.63316042503557934396 1.0"/>        
      </material>      
    </visual>    
    <collision>      
      <origin xyz="0 0 0" rpy="0 -0 0"/>      
      <geometry>        
        <mesh filename="package:///meshes/waist_gears_collision.stl"/>        
      </geometry>      
    </collision>    
    <inertial>      
      <origin xyz="-2.9089024302909189004e-07 5.5035553755153612958e-08 -0.012592985430860509713" rpy="0 0 0"/>      
      <mass value="0.026337180140419174518"/>      
      <inertia ixx="1.5367047941033429584e-06" ixy="1.8828487086599981261e-11" ixz="4.0600521957861406794e-10" iyy="7.302471227545090993e-06" iyz="3.2911737859652650917e-12" izz="6.9859065635059832685e-06"/>      
    </inertial>    
  </link>  

  <link name="waist_link">    
    <visual>      
      <origin xyz="0 0 0" rpy="0 -0 0"/>      
      <geometry>        
        <mesh filename="package:///meshes/waist_link_visual.stl"/>        
      </geometry>      
      <material name="waist_link_material">        
        <color rgba="0.64205964988973118768 0.7711287811580390672 0.80455743168009152821 1.0"/>        
      </material>      
    </visual>    
    <collision>      
      <origin xyz="0 0 0" rpy="0 -0 0"/>      
      <geometry>        
        <mesh filename="package:///meshes/waist_link_collision.stl"/>        
      </geometry>      
    </collision>    
    <inertial>      
      <origin xyz="2.5172956114443687607e-17 -0.024647143936899578581 -0.024243097328500301524" rpy="0 0 0"/>      
      <mass value="0.10819999998618361203"/>      
      <inertia ixx="4.7479700735675130414e-05" ixy="-1.5521113616368442163e-20" ixz="-5.6250747313535612066e-09" iyy="9.6352172992787143437e-05" iyz="1.5514215856083339115e-06" izz="6.7249246473032026463e-05"/>      
    </inertial>    
  </link>  

  <link name="spiral_bevel_1m_14t_30deg">    
    <visual>      
      <origin xyz="0 0 0" rpy="0 -0 0"/>      
      <geometry>        
        <mesh filename="package:///meshes/spiral_bevel_1m_14t_30deg_visual.stl"/>        
      </geometry>      
      <material name="spiral_bevel_1m_14t_30deg_material">        
        <color rgba="0.64705882352941179736 0.64705882352941179736 0.64705882352941179736 1.0"/>        
      </material>      
    </visual>    
    <collision>      
      <origin xyz="0 0 0" rpy="0 -0 0"/>      
      <geometry>        
        <mesh filename="package:///meshes/spiral_bevel_1m_14t_30deg_collision.stl"/>        
      </geometry>      
    </collision>    
    <inertial>      
      <origin xyz="7.4971447105998123561e-10 7.1802237376281108361e-10 0.0066868955018979173155" rpy="0 0 0"/>      
      <mass value="0.00073261524436595481732"/>      
      <inertia ixx="1.3495056019478193356e-08" ixy="4.0596681659866829791e-17" ixz="8.5992550143797901999e-16" iyy="1.3495056150237195634e-08" iyz="-6.7913008253774851108e-16" izz="1.4355986549816403445e-08"/>      
    </inertial>    
  </link>  

  <joint name="waist_act_1" type="fixed">    
    <origin xyz="-4.154099128902266823e-18 -0.019600000000000009776 -0.012749999999999997446" rpy="1.570796326794896558 -4.2197094403377693023e-17 -3.1415926535897922278"/>    
    <parent link="waist_link"/>    
    <child link="spiral_bevel_1m_14t_30deg"/>    
    <axis xyz="0 0 1"/>    
    <limit effort="1" velocity="20"/>    
    <joint_properties friction="0.0"/>    
  </joint>  

  <link name="spiral_bevel_1m_14t_30deg_2">    
    <visual>      
      <origin xyz="0 0 0" rpy="0 -0 0"/>      
      <geometry>        
        <mesh filename="package:///meshes/spiral_bevel_1m_14t_30deg_2_visual.stl"/>        
      </geometry>      
      <material name="spiral_bevel_1m_14t_30deg_2_material">        
        <color rgba="0.64705882352941179736 0.64705882352941179736 0.64705882352941179736 1.0"/>        
      </material>      
    </visual>    
    <collision>      
      <origin xyz="0 0 0" rpy="0 -0 0"/>      
      <geometry>        
        <mesh filename="package:///meshes/spiral_bevel_1m_14t_30deg_2_collision.stl"/>        
      </geometry>      
    </collision>    
    <inertial>      
      <origin xyz="3.6393116818744797314e-10 -9.7220472341022490248e-10 -0.0066868955018979207849" rpy="0 0 0"/>      
      <mass value="0.00073261524436595481732"/>      
      <inertia ixx="1.349505601235447918e-08" ixy="2.5804135905735602914e-17" ixz="-1.0694296050112956767e-15" iyy="1.3495056157360913119e-08" iyz="-2.3876736972330581756e-16" izz="1.4355986549816403445e-08"/>      
    </inertial>    
  </link>  

  <joint name="waist_act_2" type="fixed">    
    <origin xyz="2.7485882474720598084e-16 -0.019600000000000093042 -0.032750000000001479317" rpy="-1.5707963267948972241 -1.7671435491839250779e-16 3.1415926535897904515"/>    
    <parent link="waist_link"/>    
    <child link="spiral_bevel_1m_14t_30deg_2"/>    
    <axis xyz="0 0 1"/>    
    <limit effort="1" velocity="20"/>    
    <joint_properties friction="0.0"/>    
  </joint>  

  <link name="left_leg_reorder">    
    <visual>      
      <origin xyz="0 0 0" rpy="0 -0 0"/>      
      <geometry>        
        <mesh filename="package:///meshes/left_leg_reorder_visual.stl"/>        
      </geometry>      
      <material name="left_leg_reorder_material">        
        <color rgba="0.67653026596252763269 0.66851610566566943561 0.5118046884622382553 1.0"/>        
      </material>      
    </visual>    
    <collision>      
      <origin xyz="0 0 0" rpy="0 -0 0"/>      
      <geometry>        
        <mesh filename="package:///meshes/left_leg_reorder_collision.stl"/>        
      </geometry>      
    </collision>    
    <inertial>      
      <origin xyz="-0.14003533244392912804 0.0074816434907124008957 0.017702532858638337504" rpy="0 0 0"/>      
      <mass value="0.546053205592126778"/>      
      <inertia ixx="0.00027861717893925603716" ixy="0.00013407375775040218115" ixz="4.2427014236119938253e-05" iyy="0.0047236295394571655923" iyz="3.3456178487671456099e-06" izz="0.0048793523265029175792"/>      
    </inertial>    
  </link>  

  <joint name="left_hip_pitch" type="revolute">    
    <origin xyz="0.056000000000000015044 -0.040100000000000010636 -0.022750000000000002859" rpy="-1.570796326794896558 -1.6808384623469704457e-15 1.570796326794896336"/>    
    <parent link="waist_link"/>    
    <child link="left_leg_reorder"/>    
    <axis xyz="0 0 1"/>    
    <limit effort="1" velocity="20" lower="-1.570796326794896558" upper="2.356194490192344837"/>    
    <joint_properties friction="0.0"/>    
  </joint>  

  <link name="right_leg_reorder">    
    <visual>      
      <origin xyz="0 0 0" rpy="0 -0 0"/>      
      <geometry>        
        <mesh filename="package:///meshes/right_leg_reorder_visual.stl"/>        
      </geometry>      
      <material name="right_leg_reorder_material">        
        <color rgba="0.6780141176317181495 0.6650225861008666195 0.50162016666551234589 1.0"/>        
      </material>      
    </visual>    
    <collision>      
      <origin xyz="0 0 0" rpy="0 -0 0"/>      
      <geometry>        
        <mesh filename="package:///meshes/right_leg_reorder_collision.stl"/>        
      </geometry>      
    </collision>    
    <inertial>      
      <origin xyz="-0.14090597371374000146 -0.0074810456244045527713 0.017759864717391802419" rpy="0 0 0"/>      
      <mass value="0.53305320559212687748"/>      
      <inertia ixx="0.0002758333726599210018" ixy="-0.00014442015043751647808" ixz="4.1713196684259657202e-05" iyy="0.0046962475176865548301" iyz="-4.9410665672428709884e-06" izz="0.0048511997479020020976"/>      
    </inertial>    
  </link>  

  <joint name="right_hip_pitch" type="revolute">    
    <origin xyz="-0.056000000000002179978 -0.040100000000000593503 -0.022750000000000956957" rpy="1.5707963267948985564 1.7970109073518299728e-14 1.5707963267948970021"/>    
    <parent link="waist_link"/>    
    <child link="right_leg_reorder"/>    
    <axis xyz="0 0 1"/>    
    <limit effort="1" velocity="20" lower="-2.356194490192344837" upper="1.570796326794896558"/>    
    <joint_properties friction="0.0"/>    
  </joint>  

  <joint name="waist_roll" type="revolute">    
    <origin xyz="-0.022707865260692954024 -1.0976272054580614745e-17 -0.014000000000000498157" rpy="1.5707963267948972241 -2.7656869310564038127e-15 -1.570796326794896336"/>    
    <parent link="waist_gears"/>    
    <child link="waist_link"/>    
    <axis xyz="0 0 1"/>    
    <limit effort="1" velocity="20" lower="-0.52359877559829881566" upper="0.52359877559829881566"/>    
    <joint_properties friction="0.0"/>    
  </joint>  

  <joint name="waist_yaw" type="revolute">    
    <origin xyz="1.4224732503009818174e-15 -5.7311832421417698645e-19 5.6666698187758810186e-18" rpy="1.754162223695985754e-17 -3.9276012762146003886e-15 3.1415926535897922278"/>    
    <parent link="torso"/>    
    <child link="waist_gears"/>    
    <axis xyz="0 0 1"/>    
    <limit effort="1" velocity="20" lower="-1.570796326794896558" upper="1.570796326794896558"/>    
    <joint_properties friction="0.0"/>    
  </joint>  

  <link name="left_arm_gripper">    
    <visual>      
      <origin xyz="0 0 0" rpy="0 -0 0"/>      
      <geometry>        
        <mesh filename="package:///meshes/left_arm_gripper_visual.stl"/>        
      </geometry>      
      <material name="left_arm_gripper_material">        
        <color rgba="0.71478780303500455418 0.81796287183937121945 0.87230604980696380135 1.0"/>        
      </material>      
    </visual>    
    <collision>      
      <origin xyz="0 0 0" rpy="0 -0 0"/>      
      <geometry>        
        <mesh filename="package:///meshes/left_arm_gripper_collision.stl"/>        
      </geometry>      
    </collision>    
    <inertial>      
      <origin xyz="-0.0019746660314624358765 0.10961718139409448725 0.033696051741592944473" rpy="0 0 0"/>      
      <mass value="0.52042116458808618251"/>      
      <inertia ixx="0.0032095240823484302156" ixy="7.0016245872938344071e-05" ixz="5.0731735621282124146e-06" iyy="0.00025041152058739895225" iyz="0.00010641626953588179236" izz="0.0032523701154431095862"/>      
    </inertial>    
  </link>  

  <joint name="left_sho_pitch" type="revolute">    
    <origin xyz="-0.0035000000000004437284 0.067000000000001058709 0.104236510762817286" rpy="-1.5707963267949092145 -4.1522341120980961897e-14 3.464089692039239269e-14"/>    
    <parent link="torso"/>    
    <child link="left_arm_gripper"/>    
    <axis xyz="0 0 1"/>    
    <limit effort="1" velocity="20" lower="-3.141592653589793116" upper="1.570796326794896558"/>    
    <joint_properties friction="0.0"/>    
  </joint>  

  <link name="right_arm_gripper">    
    <visual>      
      <origin xyz="0 0 0" rpy="0 -0 0"/>      
      <geometry>        
        <mesh filename="package:///meshes/right_arm_gripper_visual.stl"/>        
      </geometry>      
      <material name="right_arm_gripper_material">        
        <color rgba="0.71479482658733595191 0.81796331111759057464 0.87230200259414114594 1.0"/>        
      </material>      
    </visual>    
    <collision>      
      <origin xyz="0 0 0" rpy="0 -0 0"/>      
      <geometry>        
        <mesh filename="package:///meshes/right_arm_gripper_collision.stl"/>        
      </geometry>      
    </collision>    
    <inertial>      
      <origin xyz="0.0017712351941345954622 0.10961044652576736047 0.033703365927060247031" rpy="0 0 0"/>      
      <mass value="0.52038428376188905489"/>      
      <inertia ixx="0.0032091551606731488246" ixy="-9.1112179043615116355e-05" ixz="-4.8462420630839266543e-06" iyy="0.00025075576470972888322" iyz="0.00010605698159843219164" izz="0.0032524112322552386697"/>      
    </inertial>    
  </link>  

  <joint name="right_sho_pitch" type="revolute">    
    <origin xyz="-0.0034999999999986777799 -0.067000000000001072586 0.10423651076281732764" rpy="-1.5707963267948872321 3.624878175401132949e-14 -3.1415926535897562566"/>    
    <parent link="torso"/>    
    <child link="right_arm_gripper"/>    
    <axis xyz="0 0 1"/>    
    <limit effort="1" velocity="20" lower="-1.570796326794896558" upper="3.141592653589793116"/>    
    <joint_properties friction="0.0"/>    
  </joint>  


</robot>