<mujoco model="toddlerbot_active">
  <compiler angle="radian" autolimits="true"/>
  <asset>
    <mesh name="torso_visual" file="assemblies/toddlerbot_active/meshes/torso_visual.stl"/>
    <mesh name="spur_1m_20t_visual" file="assemblies/toddlerbot_active/meshes/spur_1m_20t_visual.stl"/>
    <mesh name="neck_yaw_link_v2_visual" file="assemblies/toddlerbot_active/meshes/neck_yaw_link_v2_visual.stl"/>
    <mesh name="head_visual" file="assemblies/toddlerbot_active/meshes/head_visual.stl"/>
    <mesh name="motor_plate_visual" file="assemblies/toddlerbot_active/meshes/motor_plate_visual.stl"/>
    <mesh name="waist_gears_visual" file="assemblies/toddlerbot_active/meshes/waist_gears_visual.stl"/>
    <mesh name="waist_link_visual" file="assemblies/toddlerbot_active/meshes/waist_link_visual.stl"/>
    <mesh name="spiral_bevel_1m_14t_30deg_visual" file="assemblies/toddlerbot_active/meshes/spiral_bevel_1m_14t_30deg_visual.stl"/>
    <mesh name="spiral_bevel_1m_14t_30deg_2_visual" file="assemblies/toddlerbot_active/meshes/spiral_bevel_1m_14t_30deg_2_visual.stl"/>
    <mesh name="left_2xc430_visual" file="assemblies/left_leg_active/meshes/left_2xc430_visual.stl"/>
    <mesh name="left_hip_yaw_link_visual" file="assemblies/left_leg_active/meshes/left_hip_yaw_link_visual.stl"/>
    <mesh name="left_spur_gear_21_teeth_visual" file="assemblies/left_leg_active/meshes/left_spur_gear_21_teeth_visual.stl"/>
    <mesh name="left_hip_pitch_link_visual" file="assemblies/left_leg_active/meshes/left_hip_pitch_link_visual.stl"/>
    <mesh name="left_spur_gear_18_teeth_visual" file="assemblies/left_leg_active/meshes/left_spur_gear_18_teeth_visual.stl"/>
    <mesh name="left_calf_link_visual" file="assemblies/left_leg_active/meshes/left_calf_link_visual.stl"/>
    <mesh name="left_ank_pitch_link_visual" file="assemblies/left_leg_active/meshes/left_ank_pitch_link_visual.stl"/>
    <mesh name="left_ank_roll_link_visual" file="assemblies/left_leg_active/meshes/left_ank_roll_link_visual.stl"/>
    <mesh name="left_xm430_plate_visual" file="assemblies/left_leg_active/meshes/left_xm430_plate_visual.stl"/>
    <mesh name="right_2xc430_visual" file="assemblies/right_leg_active/meshes/right_2xc430_visual.stl"/>
    <mesh name="right_hip_yaw_link_visual" file="assemblies/right_leg_active/meshes/right_hip_yaw_link_visual.stl"/>
    <mesh name="right_spur_gear_21_teeth_visual" file="assemblies/right_leg_active/meshes/right_spur_gear_21_teeth_visual.stl"/>
    <mesh name="right_hip_pitch_link_visual" file="assemblies/right_leg_active/meshes/right_hip_pitch_link_visual.stl"/>
    <mesh name="right_spur_gear_18_teeth_visual" file="assemblies/right_leg_active/meshes/right_spur_gear_18_teeth_visual.stl"/>
    <mesh name="right_calf_link_visual" file="assemblies/right_leg_active/meshes/right_calf_link_visual.stl"/>
    <mesh name="right_ank_pitch_link_visual" file="assemblies/right_leg_active/meshes/right_ank_pitch_link_visual.stl"/>
    <mesh name="right_ank_roll_link_visual" file="assemblies/right_leg_active/meshes/right_ank_roll_link_visual.stl"/>
    <mesh name="right_xm430_plate_visual" file="assemblies/right_leg_active/meshes/right_xm430_plate_visual.stl"/>
    <mesh name="left_sho_pitch_link_visual" file="assemblies/left_arm_active/meshes/left_sho_pitch_link_visual.stl"/>
    <mesh name="left_2xl430_gears_visual" file="assemblies/left_arm_active/meshes/left_2xl430_gears_visual.stl"/>
    <mesh name="left_spur_1m_24t_drive_visual" file="assemblies/left_arm_active/meshes/left_spur_1m_24t_drive_visual.stl"/>
    <mesh name="left_spur_1m_24t_driven_visual" file="assemblies/left_arm_active/meshes/left_spur_1m_24t_driven_visual.stl"/>
    <mesh name="left_sho_yaw_link_visual" file="assemblies/left_arm_active/meshes/left_sho_yaw_link_visual.stl"/>
    <mesh name="left_2xl430_gears_2_visual" file="assemblies/left_arm_active/meshes/left_2xl430_gears_2_visual.stl"/>
    <mesh name="left_spur_1m_24t_drive_2_visual" file="assemblies/left_arm_active/meshes/left_spur_1m_24t_drive_2_visual.stl"/>
    <mesh name="left_spur_1m_24t_driven_2_visual" file="assemblies/left_arm_active/meshes/left_spur_1m_24t_driven_2_visual.stl"/>
    <mesh name="left_elb_yaw_link_visual" file="assemblies/left_arm_active/meshes/left_elb_yaw_link_visual.stl"/>
    <mesh name="left_spur_1m_24t_driven_3_visual" file="assemblies/left_arm_active/meshes/left_spur_1m_24t_driven_3_visual.stl"/>
    <mesh name="left_2xl430_gears_3_visual" file="assemblies/left_arm_active/meshes/left_2xl430_gears_3_visual.stl"/>
    <mesh name="left_spur_1m_24t_drive_3_visual" file="assemblies/left_arm_active/meshes/left_spur_1m_24t_drive_3_visual.stl"/>
    <mesh name="left_hand_visual" file="assemblies/left_arm_active/meshes/left_hand_visual.stl"/>
    <mesh name="left_wrist_bearing_plate_visual" file="assemblies/left_arm_active/meshes/left_wrist_bearing_plate_visual.stl"/>
    <mesh name="right_sho_pitch_link_visual" file="assemblies/right_arm_active/meshes/right_sho_pitch_link_visual.stl"/>
    <mesh name="right_2xl430_gears_visual" file="assemblies/right_arm_active/meshes/right_2xl430_gears_visual.stl"/>
    <mesh name="right_spur_1m_24t_drive_visual" file="assemblies/right_arm_active/meshes/right_spur_1m_24t_drive_visual.stl"/>
    <mesh name="right_spur_1m_24t_driven_visual" file="assemblies/right_arm_active/meshes/right_spur_1m_24t_driven_visual.stl"/>
    <mesh name="right_sho_yaw_link_visual" file="assemblies/right_arm_active/meshes/right_sho_yaw_link_visual.stl"/>
    <mesh name="right_2xl430_gears_2_visual" file="assemblies/right_arm_active/meshes/right_2xl430_gears_2_visual.stl"/>
    <mesh name="right_spur_1m_24t_drive_2_visual" file="assemblies/right_arm_active/meshes/right_spur_1m_24t_drive_2_visual.stl"/>
    <mesh name="right_spur_1m_24t_driven_2_visual" file="assemblies/right_arm_active/meshes/right_spur_1m_24t_driven_2_visual.stl"/>
    <mesh name="right_elb_yaw_link_visual" file="assemblies/right_arm_active/meshes/right_elb_yaw_link_visual.stl"/>
    <mesh name="right_spur_1m_24t_driven_3_visual" file="assemblies/right_arm_active/meshes/right_spur_1m_24t_driven_3_visual.stl"/>
    <mesh name="right_2xl430_gears_3_visual" file="assemblies/right_arm_active/meshes/right_2xl430_gears_3_visual.stl"/>
    <mesh name="right_spur_1m_24t_drive_3_visual" file="assemblies/right_arm_active/meshes/right_spur_1m_24t_drive_3_visual.stl"/>
    <mesh name="right_hand_visual" file="assemblies/right_arm_active/meshes/right_hand_visual.stl"/>
    <mesh name="right_wrist_bearing_plate_visual" file="assemblies/right_arm_active/meshes/right_wrist_bearing_plate_visual.stl"/>
  </asset>
  <worldbody>
    <body name="torso" pos="0 0 0.33605" quat="1 0 0 0">
      <site name='imu' size='0.01' pos='0.0 0.0 0.0' />

      <inertial pos="-0.00453191 -0.00330468 0.0655941" quat="1.0 0.0 0.0 0.0" mass="1.13697" diaginertia="2.98259e-03 2.39695e-03 2.51264e-03"/>
      <freejoint/>
      <geom type="mesh" rgba="0.637613 0.7914 0.897448 1" mesh="torso_visual" class="visual"/>
      <geom name="torso_collision" size="0.0705 0.0688 0.0727486" pos="-0.0285 -5.00008e-05 0.0706882" type="box" rgba="0.637613 0.7914 0.897448 1" class="collision"/>
      <geom pos="-0.005 0 0.121487" quat="1 0 0 0" type="mesh" rgba="0.647059 0.647059 0.647059 1" mesh="spur_1m_20t_visual" class="visual"/>
      <body name="neck_yaw_link_v2" pos="0.016 0 0.122487" quat="1 0 0 0">
        <inertial pos="-1.1404e-06 -1.18419e-10 0.00825718" quat="0.707105 -0.00174547 -0.00174547 0.707105" mass="0.00672988" diaginertia="6.12185e-07 5.22667e-07 2.80623e-07"/>
        <!-- <joint name="neck_yaw" pos="0 0 0" axis="0 0 1" range="-2.61799 2.61799" damping="0.134" armature="0.0035" frictionloss="0.014"/> -->
        <geom type="mesh" rgba="0.231373 0.380392 0.705882 1" mesh="neck_yaw_link_v2_visual" class="visual"/>
        <body name="head" pos="0 0.004 0.0194" quat="0.499092 0.499092 0.500906 -0.500906">
          <inertial pos="-0.0451606 -0.0114693 -0.000947377" quat="0.969732 -0.240186 -0.0271575 0.0345491" mass="0.138921" diaginertia="0.000119519 0.000110008 8.7766e-05"/>
          <!-- <joint name="neck_pitch" pos="0 0 0" axis="0 0 1" range="-1.39626 0.610865" damping="0.134" armature="0.0035" frictionloss="0.014"/> -->
          <geom type="mesh" rgba="0.628739 0.793643 0.873301 1" mesh="head_visual" class="visual"/>
          <geom pos="-0.0326157 -0.027 0.0025" quat="0 0 1 0" type="mesh" rgba="0.647059 0.647059 0.647059 1" mesh="motor_plate_visual" class="visual"/>
        </body>
      </body>
      <body name="waist_gears" pos="0 0 0" quat="0 0 0 1">
        <inertial pos="-2.9089e-07 5.50356e-08 -0.012593" quat="0.49998 0.500022 0.500015 0.499983" mass="0.0263372" diaginertia="7.30247e-06 6.98591e-06 1.5367e-06"/>
        <joint name="waist_yaw" pos="0 0 0" axis="0 0 1" range="-1.5708 1.5708" damping="0.127" armature="0.004" frictionloss="0.069"/>
        <geom type="mesh" rgba="0.296731 0.5009 0.63316 1" mesh="waist_gears_visual" class="visual"/>
        <body name="waist_link" pos="-0.0227079 0 -0.014" quat="0.5 0.5 -0.5 -0.5">
          <inertial pos="-7.43965e-12 -0.0244904 -0.0242231" quat="0.48682 0.512839 0.486675 0.512982" mass="0.109665" diaginertia="9.66106e-05 6.73954e-05 4.78555e-05"/>
          <joint name="waist_roll" pos="0 0 0" axis="0 0 1" range="-0.523599 0.523599" damping="0.127" armature="0.004" frictionloss="0.069"/>
          <geom type="mesh" rgba="0.64206 0.771129 0.804557 1" mesh="waist_link_visual" class="visual"/>
          <geom name="waist_link_collision" size="0.06 0.02875 0.035" pos="0 -0.02185 -0.02275" type="box" rgba="0.64206 0.771129 0.804557 1" class="collision"/>
          <geom pos="0 -0.0196 -0.01275" quat="0 0 -0.707107 -0.707107" type="mesh" rgba="0.647059 0.647059 0.647059 1" mesh="spiral_bevel_1m_14t_30deg_visual" class="visual"/>
          <geom pos="0 -0.0196 -0.03275" quat="0 0 -0.707107 0.707107" type="mesh" rgba="0.647059 0.647059 0.647059 1" mesh="spiral_bevel_1m_14t_30deg_2_visual" class="visual"/>
          <body name="2xc430" pos="0.056 -0.0401 -0.02275" quat="0.5 -0.5 -0.5 0.5">
            <inertial pos="-0.0120002 0.000495888 0.018504" quat="0.652088 0.27349 0.654458 0.267712" mass="0.1106" diaginertia="3.14464e-05 3.02975e-05 2.28182e-05"/>
            <joint name="left_hip_pitch" pos="0 0 0" axis="0 0 1" range="-1.5708 2.35619" damping="0.075" armature="0.0044" frictionloss="0.252"/>
            <geom type="mesh" rgba="0.516987 0.503478 0.490506 1" mesh="left_2xc430_visual" class="visual"/>
            <body name="hip_yaw_link" pos="-0.024 0.019 0.019" quat="0.5 -0.5 -0.5 -0.5">
              <inertial pos="2.39745e-12 -0.0178994 -0.0190049" quat="1 0.000346963 0 0" mass="0.0154" diaginertia="6.26665e-06 5.14227e-06 3.21168e-06"/>
              <joint name="left_hip_roll" pos="0 0 0" axis="0 0 1" range="-0.785398 0.785398" damping="0.075" armature="0.0044" frictionloss="0.252"/>
              <geom type="mesh" rgba="0.615686 0.811765 0.929412 1" mesh="left_hip_yaw_link_visual" class="visual"/>
              <geom pos="0 -0.028 -0.019" quat="0.5 -0.5 0.5 0.5" type="mesh" rgba="0.615686 0.811765 0.929412 1" mesh="left_spur_gear_21_teeth_visual" class="visual"/>
              <body name="left_hip_pitch_link" pos="0 -0.033 -0.019" quat="0.5 0.5 0.5 -0.5">
                <inertial pos="-0.00919639 -0.00507672 0.0392927" quat="0.652573 0.0927289 0.0709361 0.748677" mass="0.16239" diaginertia="0.000102538 8.77299e-05 4.52534e-05"/>
                <joint name="left_hip_yaw" pos="0 0 0" axis="0 0 1" range="-1.5708 1.5708" damping="0.134" armature="0.0035" frictionloss="0.014"/>
                <geom type="mesh" rgba="0.796183 0.721207 0.385409 1" mesh="left_hip_pitch_link_visual" class="visual"/>
                <geom name="left_hip_pitch_link_collision" size="0.0358429 0.0166321" pos="-0.00558776 -0.00497145 0.052475" type="capsule" rgba="0.796183 0.721207 0.385409 1" class="collision"/>
                <geom pos="-0.0192 0.0002 0" quat="0 -1 0 0" type="mesh" rgba="0.615686 0.811765 0.929412 1" mesh="left_spur_gear_18_teeth_visual" class="visual"/>
                <geom pos="0 0.01245 0.0445" quat="0.5 -0.5 0.5 0.5" type="mesh" rgba="0.615686 0.811765 0.929412 1" mesh="left_xm430_plate_visual" class="visual"/>
                <body name="left_calf_link" pos="0 -0.00875 0.08595" quat="0 0 0.707107 0.707107">
                  <inertial pos="-0.00434501 0.040753 0.00871161" quat="0.705174 0.708416 -0.0106668 -0.0276204" mass="0.031" diaginertia="3.31471e-05 2.80287e-05 7.65658e-06"/>
                  <joint name="left_knee" pos="0 0 0" axis="0 0 1" range="-2.0944 0" damping="0.08" armature="0.0012" frictionloss="0.134"/>
                  <geom type="mesh" rgba="0.615686 0.811765 0.929412 1" mesh="left_calf_link_visual" class="visual"/>
                  <body name="left_ank_pitch_link" pos="0 0.1 0.02775" quat="0 -1 0 0">
                    <inertial pos="0.0177702 0.0123013 0.0188135" quat="-0.00892062 0.704442 0.00690611 0.709672" mass="0.176764" diaginertia="0.000121859 0.000107094 4.72493e-05"/>
                    <joint name="left_ank_pitch" pos="0 0 0" axis="0 0 1" range="-1.74533 0.785398" damping="0.08" armature="0.0012" frictionloss="0.134"/>
                    <geom type="mesh" rgba="0.703217 0.645149 0.404847 1" mesh="left_ank_pitch_link_visual" class="visual"/>
                    <geom name="left_ank_pitch_link_collision" size="0.0424 0.02325 0.0212" pos="0.01935 0.012 0.0168" type="box" rgba="0.703217 0.645149 0.404847 1" class="collision"/>
                    <body name="ank_roll_link" pos="0.02275 0 0.019" quat="0.5 -0.5 -0.5 0.5">
                      <inertial pos="-0.0270031 -2.00573e-12 0.033764" quat="0.706436 -0.0307857 -0.0307857 0.706436" mass="0.0426" diaginertia="3.75893e-05 3.74934e-05 9.88147e-06"/>
                      <joint name="left_ank_roll" pos="0 0 0" axis="0 0 1" range="-1.5708 1.5708" damping="0.127" armature="0.004" frictionloss="0.069"/>
                      <geom type="mesh" rgba="0.615686 0.811765 0.929412 1" mesh="left_ank_roll_link_visual" class="visual"/>
                      <geom name="ank_roll_link_collision" size="0.0245 0.021 0.06" pos="-0.0145 0 0.039" type="box" rgba="0.615686 0.811765 0.929412 1" class="collision"/>
                      <site name="left_foot_center" pos="-0.039 0.0 0.039" type="sphere" size="0.005" rgba="0.9 0.1 0.1 0.8"/>
                     <body name="left_toe_link" pos="-0.02 0.0 0.08"/>

                    </body>
                  </body>
                </body>
              </body>
            </body>
          </body>
          <body name="2xc430_2" pos="-0.056 -0.0401 -0.02275" quat="0.5 0.5 0.5 0.5">
            <inertial pos="-0.0120002 0.000495888 0.018504" quat="0.652088 0.27349 0.654458 0.267712" mass="0.1106" diaginertia="3.14464e-05 3.02975e-05 2.28182e-05"/>
            <joint name="right_hip_pitch" pos="0 0 0" axis="0 0 1" range="-2.35619 1.5708" damping="0.075" armature="0.0044" frictionloss="0.252"/>
            <geom type="mesh" rgba="0.516987 0.503478 0.490506 1" mesh="right_2xc430_visual" class="visual"/>
            <body name="hip_yaw_link_2" pos="-0.024 0.019 0.019" quat="0.5 -0.5 -0.5 -0.5">
              <inertial pos="2.39745e-12 -0.0178994 -0.0190049" quat="1 0.000346963 0 0" mass="0.0154" diaginertia="6.26665e-06 5.14227e-06 3.21168e-06"/>
              <joint name="right_hip_roll" pos="0 0 0" axis="0 0 1" range="-0.785398 0.785398" damping="0.075" armature="0.0044" frictionloss="0.252"/>
              <geom type="mesh" rgba="0.615686 0.811765 0.929412 1" mesh="right_hip_yaw_link_visual" class="visual"/>
              <geom pos="0 -0.028 -0.019" quat="0.5 -0.5 0.5 0.5" type="mesh" rgba="0.615686 0.811765 0.929412 1" mesh="right_spur_gear_21_teeth_visual" class="visual"/>
              <body name="right_hip_pitch_link" pos="0 -0.033 -0.019" quat="0.5 0.5 0.5 -0.5">
                <inertial pos="0.0100762 -0.00519985 0.0385928" quat="0.752724 -0.0722708 -0.0940458 0.647564" mass="0.14939" diaginertia="8.82658e-05 7.61441e-05 4.06702e-05"/>
                <joint name="right_hip_yaw" pos="0 0 0" axis="0 0 1" range="-1.5708 1.5708" damping="0.134" armature="0.0035" frictionloss="0.014"/>
                <geom type="mesh" rgba="0.812311 0.713116 0.336801 1" mesh="right_hip_pitch_link_visual" class="visual"/>
                <geom name="right_hip_pitch_link_collision" size="0.03583 0.016645" pos="0.00591051 -0.00426985 0.052475" type="capsule" rgba="0.812311 0.713116 0.336801 1" class="collision"/>
                <geom pos="0.0192 0.0002 0" quat="0 -1 0 0" type="mesh" rgba="0.615686 0.811765 0.929412 1" mesh="right_spur_gear_18_teeth_visual" class="visual"/>
                <geom pos="0 0.01245 0.0445" quat="0.707107 -0.707107 0 0" type="mesh" rgba="0.615686 0.811765 0.929412 1" mesh="right_xm430_plate_visual" class="visual"/>
                <body name="right_calf_link" pos="0 -0.00875 0.08595" quat="0.707107 -0.707107 0 0">
                  <inertial pos="-0.00434501 -0.040753 0.00871161" quat="0.708416 0.705174 0.0276204 0.0106668" mass="0.031" diaginertia="3.31471e-05 2.80287e-05 7.65658e-06"/>
                  <joint name="right_knee" pos="0 0 0" axis="0 0 1" range="0 2.0944" damping="0.08" armature="0.0012" frictionloss="0.134"/>
                  <geom type="mesh" rgba="0.615686 0.811765 0.929412 1" mesh="right_calf_link_visual" class="visual"/>
                  <body name="right_ank_pitch_link" pos="0 -0.1 0.02775" quat="0 0 1 0">
                    <inertial pos="-0.0177702 0.0123013 0.0188145" quat="0.00698765 0.709966 -0.00883923 0.704146" mass="0.176764" diaginertia="0.00012186 0.000107094 4.72484e-05"/>
                    <joint name="right_ank_pitch" pos="0 0 0" axis="0 0 1" range="-0.785398 1.74533" damping="0.08" armature="0.0012" frictionloss="0.134"/>
                    <geom type="mesh" rgba="0.703217 0.645149 0.404847 1" mesh="right_ank_pitch_link_visual" class="visual"/>
                    <geom name="right_ank_pitch_link_collision" size="0.0424 0.02325 0.0212" pos="-0.01935 0.012 0.0168" type="box" rgba="0.703217 0.645149 0.404847 1" class="collision"/>
                    <body name="ank_roll_link_2" pos="-0.02275 0 0.019" quat="0.5 0.5 0.5 0.5">
                      <inertial pos="-0.0270031 -2.00573e-12 0.033764" quat="0.706436 -0.0307857 -0.0307857 0.706436" mass="0.0426" diaginertia="3.75893e-05 3.74934e-05 9.88147e-06"/>
                      <joint name="right_ank_roll" pos="0 0 0" axis="0 0 1" range="-1.5708 1.5708" damping="0.127" armature="0.004" frictionloss="0.069"/>
                      <geom type="mesh" rgba="0.615686 0.811765 0.929412 1" mesh="right_ank_roll_link_visual" class="visual"/>
                      <geom name="ank_roll_link_2_collision" size="0.0245 0.021 0.06" pos="-0.0145 0 0.039" type="box" rgba="0.615686 0.811765 0.929412 1" class="collision"/>
                      <site name="right_foot_center" pos="-0.039 0.0 0.039" type="sphere" size="0.005" rgba="0.9 0.1 0.1 0.8"/>
                     <body name="right_toe_link" pos="-0.02 0.0 0.08"/>

                    </body>
                  </body>
                </body>
              </body>
            </body>
          </body>
        </body>
      </body>
      <body name="sho_pitch_link" pos="-0.0035 0.067 0.104237" quat="0.707107 -0.707107 0 0">
        <inertial pos="0 0 0.0129133" quat="0.5 0.5 0.5 0.5" mass="0.0086" diaginertia="4.01109e-06 3.51605e-06 1.83656e-06"/>
        <joint name="left_sho_pitch" pos="0 0 0" axis="0 0 1" range="-3.14159 1.5708" damping="0.127" armature="0.004" frictionloss="0.069"/>
        <geom type="mesh" rgba="0.615686 0.811765 0.929412 1" mesh="left_sho_pitch_link_visual" class="visual"/>
        <body name="2xl430_gears" pos="-0.019 0 0.027" quat="0 -0.707107 0 0.707107">
          <inertial pos="-0.0119205 -0.0029885 -0.0185629" quat="-0.0490457 0.703336 -0.0602024 0.706604" mass="0.1212" diaginertia="3.79285e-05 3.34115e-05 2.90762e-05"/>
          <joint name="left_sho_roll" pos="0 0 0" axis="0 0 1" range="-1.5708 0.349066" damping="0.12" armature="0.0042" frictionloss="0.292"/>
          <geom type="mesh" rgba="0.759148 0.855604 0.905195 1" mesh="left_2xl430_gears_visual" class="visual"/>
          <geom name="2xl430_gears_collision" size="0.031174" pos="-0.0117086 -0.00266316 -0.019869" rgba="0.759148 0.855604 0.905195 1" class="collision"/>
          <geom pos="-0.024 -0.019 -0.019" quat="0.707107 0.707107 0 0" type="mesh" rgba="0.615686 0.811765 0.929412 1" mesh="left_spur_1m_24t_drive_visual" class="visual"/>
          <body name="spur_1m_24t_driven" pos="-3.5807e-10 -0.027 -0.019" quat="0.707107 0.707107 0 0">
            <inertial pos="0 0 0.0219761" mass="0.0172" diaginertia="1.10453e-05 7.62509e-06 4.73924e-06"/>
            <joint name="left_sho_yaw" pos="0 0 0" axis="0 0 1" range="-2.61799 2.61799" damping="0.12" armature="0.0042" frictionloss="0.292"/>
            <geom type="mesh" rgba="0.231373 0.380392 0.705882 1" mesh="left_spur_1m_24t_driven_visual" class="visual"/>
            <geom pos="0 0 0.0016" quat="0 -1 0 0" type="mesh" rgba="0.615686 0.811765 0.929412 1" mesh="left_sho_yaw_link_visual" class="visual"/>
            <body name="2xl430_gears_2" pos="0 0.019 0.0606" quat="0.707107 -0.707107 0 0">
              <inertial pos="-0.0119205 -0.0029885 -0.0185629" quat="-0.0490457 0.703336 -0.0602024 0.706604" mass="0.1212" diaginertia="3.79285e-05 3.34115e-05 2.90762e-05"/>
              <joint name="left_elbow_roll" pos="0 0 0" axis="0 0 1" range="-1.91986 2.44346" damping="0.12" armature="0.0042" frictionloss="0.292"/>
              <geom type="mesh" rgba="0.759148 0.855604 0.905195 1" mesh="left_2xl430_gears_2_visual" class="visual"/>
              <geom name="2xl430_gears_2_collision" size="0.0311725" pos="-0.0117101 -0.00266333 -0.0198676" rgba="0.759148 0.855604 0.905195 1" class="collision"/>
              <geom pos="-0.024 -0.019 -0.019" quat="0.707107 0.707107 0 0" type="mesh" rgba="0.615686 0.811765 0.929412 1" mesh="left_spur_1m_24t_drive_2_visual" class="visual"/>
              <body name="spur_1m_24t_driven_2" pos="-3.58064e-10 -0.027 -0.019" quat="0.5 0.5 0.5 -0.5">
                <inertial pos="4.05998e-08 0.00116401 0.0253225" quat="0.939825 -0.341655 0 0" mass="0.0229" diaginertia="1.98383e-05 1.1604e-05 1.01997e-05"/>
                <!-- <joint name="left_elbow_yaw" pos="0 0 0" axis="0 0 1" range="-2.61799 2.61799" damping="0.12" armature="0.0042" frictionloss="0.292"/> -->
                <geom type="mesh" rgba="0.231373 0.380392 0.705882 1" mesh="left_spur_1m_24t_driven_2_visual" class="visual"/>
                <geom pos="0 0 0.0016" quat="0 -1 0 0" type="mesh" rgba="0.615686 0.811765 0.929412 1" mesh="left_elb_yaw_link_visual" class="visual"/>
                <geom pos="0 0.0253 0.0536" quat="0.5 -0.5 0.5 0.5" type="mesh" rgba="0.231373 0.380392 0.705882 1" mesh="left_spur_1m_24t_driven_3_visual" class="visual"/>
                <body name="2xl430_gears_3" pos="0 0.0237 0.0536" quat="0.707107 -0.707107 0 0">
                  <inertial pos="0.000420069 0.011752 -0.0248985" quat="0.652142 0.756426 -0.0332481 0.0377536" mass="0.1261" diaginertia="4.11412e-05 3.47956e-05 3.19683e-05"/>
                  <!-- <joint name="left_wrist_pitch" pos="0 0 0" axis="0 0 1" range="-1.39626 1.91986" damping="0.12" armature="0.0042" frictionloss="0.292"/> -->
                  <geom type="mesh" rgba="0.759148 0.855604 0.905195 1" mesh="left_2xl430_gears_3_visual" class="visual"/>
                  <geom name="2xl430_gears_3_collision" size="0.0311601" pos="-0.000853385 0.0117191 -0.0243374" rgba="0.759148 0.855604 0.905195 1" class="collision"/>
                  <geom pos="-1.52441e-10 0.024 -0.008" quat="0.707107 0 0 -0.707107" type="mesh" rgba="0.615686 0.811765 0.929412 1" mesh="left_spur_1m_24t_drive_3_visual" class="visual"/>
                  <geom pos="0.0155 0 -0.045" quat="0.707107 0 0 -0.707107" type="mesh" rgba="0.719322 0.631284 0.524224 1" mesh="left_wrist_bearing_plate_visual" class="visual"/>
                  <body name="hand" pos="0.019 -3.58082e-10 -0.027" quat="0 0.707107 0 0.707107">
                    <inertial pos="-0.00370787 0.0421273 -0.0184903" quat="0.857226 -0.00187348 0.000260562 0.514937" mass="0.0395" diaginertia="2.58069e-05 2.4304e-05 1.34665e-05"/>
                    <!-- <joint name="left_wrist_roll" pos="0 0 0" axis="0 0 1" range="-1.91986 1.39626" damping="0.12" armature="0.0042" frictionloss="0.292"/> -->
                    <geom type="mesh" rgba="0.641499 0.676247 0.697096 1" mesh="left_hand_visual" class="visual"/>
                    <geom name="hand_collision" size="0.025 0.03375 0.037" pos="-0.0045 0.02325 -0.019" type="box" rgba="0.641499 0.676247 0.697096 1" class="collision"/>
                  </body>
                </body>
              </body>
            </body>
          </body>
        </body>
      </body>
      <body name="sho_pitch_link_2" pos="-0.0035 -0.067 0.104237" quat="0 0 0.707107 -0.707107">
        <inertial pos="0 0 0.0129133" quat="0.5 0.5 0.5 0.5" mass="0.0086" diaginertia="4.01109e-06 3.51605e-06 1.83656e-06"/>
        <joint name="right_sho_pitch" pos="0 0 0" axis="0 0 1" range="-1.5708 3.14159" damping="0.127" armature="0.004" frictionloss="0.069"/>
        <geom type="mesh" rgba="0.615686 0.811765 0.929412 1" mesh="right_sho_pitch_link_visual" class="visual"/>
        <body name="2xl430_gears_4" pos="-0.019 0 0.027" quat="0 0.707107 0 -0.707107">
          <inertial pos="-0.0119205 -0.0029885 -0.0185629" quat="-0.0490457 0.703336 -0.0602024 0.706604" mass="0.1212" diaginertia="3.79285e-05 3.34115e-05 2.90762e-05"/>
          <joint name="right_sho_roll" pos="0 0 0" axis="0 0 1" range="-1.5708 0.349066" damping="0.12" armature="0.0042" frictionloss="0.292"/>
          <geom type="mesh" rgba="0.759148 0.855604 0.905195 1" mesh="right_2xl430_gears_visual" class="visual"/>
          <geom name="2xl430_gears_4_collision" size="0.031174" pos="-0.0117086 -0.00266316 -0.019869" rgba="0.759148 0.855604 0.905195 1" class="collision"/>
          <geom pos="-0.024 -0.019 -0.019" quat="0.707107 0.707107 0 0" type="mesh" rgba="0.615686 0.811765 0.929412 1" mesh="right_spur_1m_24t_drive_visual" class="visual"/>
          <body name="spur_1m_24t_driven_4" pos="-3.58068e-10 -0.027 -0.019" quat="0.707107 0.707107 0 0">
            <inertial pos="0 0 0.0219761" mass="0.0172" diaginertia="1.10453e-05 7.62509e-06 4.73924e-06"/>
            <joint name="right_sho_yaw" pos="0 0 0" axis="0 0 1" range="-2.61799 2.61799" damping="0.12" armature="0.0042" frictionloss="0.292"/>
            <geom type="mesh" rgba="0.231373 0.380392 0.705882 1" mesh="right_spur_1m_24t_driven_visual" class="visual"/>
            <geom pos="0 0 0.0016" quat="0 1 0 0" type="mesh" rgba="0.615686 0.811765 0.929412 1" mesh="right_sho_yaw_link_visual" class="visual"/>
            <body name="2xl430_gears_5" pos="0 0.019 0.0606" quat="-0.707107 0.707107 0 0">
              <inertial pos="-0.0119205 -0.0029885 -0.0185629" quat="-0.0490457 0.703336 -0.0602024 0.706604" mass="0.1212" diaginertia="3.79285e-05 3.34115e-05 2.90762e-05"/>
              <joint name="right_elbow_roll" pos="0 0 0" axis="0 0 1" range="-1.91986 2.44346" damping="0.12" armature="0.0042" frictionloss="0.292"/>
              <geom type="mesh" rgba="0.759148 0.855604 0.905195 1" mesh="right_2xl430_gears_2_visual" class="visual"/>
              <geom name="2xl430_gears_5_collision" size="0.0311733" pos="-0.0117096 -0.00266342 -0.0198686" rgba="0.759148 0.855604 0.905195 1" class="collision"/>
              <geom pos="-0.024 -0.019 -0.019" quat="0.707107 0.707107 0 0" type="mesh" rgba="0.615686 0.811765 0.929412 1" mesh="right_spur_1m_24t_drive_2_visual" class="visual"/>
              <body name="spur_1m_24t_driven_5" pos="-3.58073e-10 -0.027 -0.019" quat="0.707107 0.707107 0 0">
                <inertial pos="0.00116401 -4.05998e-08 0.0253225" quat="0.664557 0.241587 0.241587 0.664557" mass="0.0229" diaginertia="1.98383e-05 1.1604e-05 1.01997e-05"/>
                <!-- <joint name="right_elbow_yaw" pos="0 0 0" axis="0 0 1" range="-2.61799 2.61799" damping="0.12" armature="0.0042" frictionloss="0.292"/> -->
                <geom type="mesh" rgba="0.231373 0.380392 0.705882 1" mesh="right_spur_1m_24t_driven_2_visual" class="visual"/>
                <geom pos="0 0 0.0016" quat="0 0.707107 -0.707107 0" type="mesh" rgba="0.615686 0.811765 0.929412 1" mesh="right_elb_yaw_link_visual" class="visual"/>
                <geom pos="0.0253 0 0.0536" quat="0 0.707107 0 0.707107" type="mesh" rgba="0.231373 0.380392 0.705882 1" mesh="right_spur_1m_24t_driven_3_visual" class="visual"/>
                <body name="2xl430_gears_6" pos="0.0237 0 0.0536" quat="-0.5 0.5 -0.5 0.5">
                  <inertial pos="0.000420069 0.011752 -0.0248985" quat="0.652142 0.756426 -0.0332481 0.0377536" mass="0.1261" diaginertia="4.11412e-05 3.47956e-05 3.19683e-05"/>
                  <!-- <joint name="right_wrist_pitch" pos="0 0 0" axis="0 0 1" range="-1.91986 1.39626" damping="0.12" armature="0.0042" frictionloss="0.292"/> -->
                  <geom type="mesh" rgba="0.759148 0.855604 0.905195 1" mesh="right_2xl430_gears_3_visual" class="visual"/>
                  <geom name="2xl430_gears_6_collision" size="0.0311601" pos="-0.000853385 0.0117191 -0.0243374" rgba="0.759148 0.855604 0.905195 1" class="collision"/>
                  <geom pos="-1.52443e-10 0.024 -0.008" quat="0.707107 0 0 -0.707107" type="mesh" rgba="0.615686 0.811765 0.929412 1" mesh="right_spur_1m_24t_drive_3_visual" class="visual"/>
                  <geom pos="0.0155 0 -0.045" quat="0.707107 0 0 -0.707107" type="mesh" rgba="0.719322 0.631284 0.524224 1" mesh="right_wrist_bearing_plate_visual" class="visual"/>
                  <body name="hand_2" pos="0.019 -3.58067e-10 -0.027" quat="0.707107 0 0.707107 0">
                    <inertial pos="0.00370787 -0.0421273 -0.0195097" quat="0.857226 -0.00187348 0.000260562 0.514937" mass="0.0395" diaginertia="2.58069e-05 2.4304e-05 1.34665e-05"/>
                    <!-- <joint name="right_wrist_roll" pos="0 0 0" axis="0 0 1" range="-1.39626 1.91986" damping="0.12" armature="0.0042" frictionloss="0.292"/> -->
                    <geom type="mesh" rgba="0.641499 0.676247 0.697096 1" mesh="right_hand_visual" class="visual"/>
                    <geom name="hand_2_collision" size="0.025 0.03375 0.037" pos="0.0045 -0.02325 -0.019" type="box" rgba="0.641499 0.676247 0.697096 1" class="collision"/>
                  </body>
                </body>
              </body>
            </body>
          </body>
        </body>
      </body>
    </body>
  </worldbody>
  <option>
    <flag eulerdamp="disable"/>
  </option>
  <equality/>
  <keyframe>
    <key name="home" qpos="0 0 0.3267 1 0 0 0
     0 0 0.145689 0 0 -0.534732 -0.379457 0 -0.145689 0 0 0.534732 0.379457 0 0.174533 -0.261799 -1.0472 0.523599 -0.174533 -0.261799 1.0472 0.523599  "/>
  </keyframe>
  <!-- <contact>
    <pair geom1="torso_collision" geom2="floor"/>
    <pair geom1="waist_link_collision" geom2="floor"/>
    <pair geom1="left_hip_pitch_link_collision" geom2="floor"/>
    <pair geom1="left_ank_pitch_link_collision" geom2="floor"/>
    <pair geom1="ank_roll_link_collision" geom2="floor"/>
    <pair geom1="right_hip_pitch_link_collision" geom2="floor"/>
    <pair geom1="right_ank_pitch_link_collision" geom2="floor"/>
    <pair geom1="ank_roll_link_2_collision" geom2="floor"/>
    <pair geom1="2xl430_gears_collision" geom2="floor"/>
    <pair geom1="2xl430_gears_2_collision" geom2="floor"/>
    <pair geom1="2xl430_gears_3_collision" geom2="floor"/>
    <pair geom1="hand_collision" geom2="floor"/>
    <pair geom1="2xl430_gears_4_collision" geom2="floor"/>
    <pair geom1="2xl430_gears_5_collision" geom2="floor"/>
    <pair geom1="2xl430_gears_6_collision" geom2="floor"/>
    <pair geom1="hand_2_collision" geom2="floor"/>
    <pair geom1="left_ank_pitch_link_collision" geom2="right_ank_pitch_link_collision"/>
    <pair geom1="ank_roll_link_collision" geom2="ank_roll_link_2_collision"/>
    <exclude body1="torso" body2="waist_link"/>
    <exclude body1="torso" body2="left_hip_pitch_link"/>
    <exclude body1="torso" body2="left_ank_pitch_link"/>
    <exclude body1="torso" body2="ank_roll_link"/>
    <exclude body1="torso" body2="right_hip_pitch_link"/>
    <exclude body1="torso" body2="right_ank_pitch_link"/>
    <exclude body1="torso" body2="ank_roll_link_2"/>
    <exclude body1="torso" body2="2xl430_gears"/>
    <exclude body1="torso" body2="2xl430_gears_2"/>
    <exclude body1="torso" body2="2xl430_gears_3"/>
    <exclude body1="torso" body2="hand"/>
    <exclude body1="torso" body2="2xl430_gears_4"/>
    <exclude body1="torso" body2="2xl430_gears_5"/>
    <exclude body1="torso" body2="2xl430_gears_6"/>
    <exclude body1="torso" body2="hand_2"/>
    <exclude body1="waist_link" body2="left_hip_pitch_link"/>
    <exclude body1="waist_link" body2="left_ank_pitch_link"/>
    <exclude body1="waist_link" body2="ank_roll_link"/>
    <exclude body1="waist_link" body2="right_hip_pitch_link"/>
    <exclude body1="waist_link" body2="right_ank_pitch_link"/>
    <exclude body1="waist_link" body2="ank_roll_link_2"/>
    <exclude body1="waist_link" body2="2xl430_gears"/>
    <exclude body1="waist_link" body2="2xl430_gears_2"/>
    <exclude body1="waist_link" body2="2xl430_gears_3"/>
    <exclude body1="waist_link" body2="hand"/>
    <exclude body1="waist_link" body2="2xl430_gears_4"/>
    <exclude body1="waist_link" body2="2xl430_gears_5"/>
    <exclude body1="waist_link" body2="2xl430_gears_6"/>
    <exclude body1="waist_link" body2="hand_2"/>
    <exclude body1="left_hip_pitch_link" body2="left_ank_pitch_link"/>
    <exclude body1="left_hip_pitch_link" body2="ank_roll_link"/>
    <exclude body1="left_hip_pitch_link" body2="right_hip_pitch_link"/>
    <exclude body1="left_hip_pitch_link" body2="right_ank_pitch_link"/>
    <exclude body1="left_hip_pitch_link" body2="ank_roll_link_2"/>
    <exclude body1="left_hip_pitch_link" body2="2xl430_gears"/>
    <exclude body1="left_hip_pitch_link" body2="2xl430_gears_2"/>
    <exclude body1="left_hip_pitch_link" body2="2xl430_gears_3"/>
    <exclude body1="left_hip_pitch_link" body2="hand"/>
    <exclude body1="left_hip_pitch_link" body2="2xl430_gears_4"/>
    <exclude body1="left_hip_pitch_link" body2="2xl430_gears_5"/>
    <exclude body1="left_hip_pitch_link" body2="2xl430_gears_6"/>
    <exclude body1="left_hip_pitch_link" body2="hand_2"/>
    <exclude body1="left_ank_pitch_link" body2="ank_roll_link"/>
    <exclude body1="left_ank_pitch_link" body2="right_hip_pitch_link"/>
    <exclude body1="left_ank_pitch_link" body2="ank_roll_link_2"/>
    <exclude body1="left_ank_pitch_link" body2="2xl430_gears"/>
    <exclude body1="left_ank_pitch_link" body2="2xl430_gears_2"/>
    <exclude body1="left_ank_pitch_link" body2="2xl430_gears_3"/>
    <exclude body1="left_ank_pitch_link" body2="hand"/>
    <exclude body1="left_ank_pitch_link" body2="2xl430_gears_4"/>
    <exclude body1="left_ank_pitch_link" body2="2xl430_gears_5"/>
    <exclude body1="left_ank_pitch_link" body2="2xl430_gears_6"/>
    <exclude body1="left_ank_pitch_link" body2="hand_2"/>
    <exclude body1="ank_roll_link" body2="right_hip_pitch_link"/>
    <exclude body1="ank_roll_link" body2="right_ank_pitch_link"/>
    <exclude body1="ank_roll_link" body2="2xl430_gears"/>
    <exclude body1="ank_roll_link" body2="2xl430_gears_2"/>
    <exclude body1="ank_roll_link" body2="2xl430_gears_3"/>
    <exclude body1="ank_roll_link" body2="hand"/>
    <exclude body1="ank_roll_link" body2="2xl430_gears_4"/>
    <exclude body1="ank_roll_link" body2="2xl430_gears_5"/>
    <exclude body1="ank_roll_link" body2="2xl430_gears_6"/>
    <exclude body1="ank_roll_link" body2="hand_2"/>
    <exclude body1="right_hip_pitch_link" body2="right_ank_pitch_link"/>
    <exclude body1="right_hip_pitch_link" body2="ank_roll_link_2"/>
    <exclude body1="right_hip_pitch_link" body2="2xl430_gears"/>
    <exclude body1="right_hip_pitch_link" body2="2xl430_gears_2"/>
    <exclude body1="right_hip_pitch_link" body2="2xl430_gears_3"/>
    <exclude body1="right_hip_pitch_link" body2="hand"/>
    <exclude body1="right_hip_pitch_link" body2="2xl430_gears_4"/>
    <exclude body1="right_hip_pitch_link" body2="2xl430_gears_5"/>
    <exclude body1="right_hip_pitch_link" body2="2xl430_gears_6"/>
    <exclude body1="right_hip_pitch_link" body2="hand_2"/>
    <exclude body1="right_ank_pitch_link" body2="ank_roll_link_2"/>
    <exclude body1="right_ank_pitch_link" body2="2xl430_gears"/>
    <exclude body1="right_ank_pitch_link" body2="2xl430_gears_2"/>
    <exclude body1="right_ank_pitch_link" body2="2xl430_gears_3"/>
    <exclude body1="right_ank_pitch_link" body2="hand"/>
    <exclude body1="right_ank_pitch_link" body2="2xl430_gears_4"/>
    <exclude body1="right_ank_pitch_link" body2="2xl430_gears_5"/>
    <exclude body1="right_ank_pitch_link" body2="2xl430_gears_6"/>
    <exclude body1="right_ank_pitch_link" body2="hand_2"/>
    <exclude body1="ank_roll_link_2" body2="2xl430_gears"/>
    <exclude body1="ank_roll_link_2" body2="2xl430_gears_2"/>
    <exclude body1="ank_roll_link_2" body2="2xl430_gears_3"/>
    <exclude body1="ank_roll_link_2" body2="hand"/>
    <exclude body1="ank_roll_link_2" body2="2xl430_gears_4"/>
    <exclude body1="ank_roll_link_2" body2="2xl430_gears_5"/>
    <exclude body1="ank_roll_link_2" body2="2xl430_gears_6"/>
    <exclude body1="ank_roll_link_2" body2="hand_2"/>
    <exclude body1="2xl430_gears" body2="2xl430_gears_2"/>
    <exclude body1="2xl430_gears" body2="2xl430_gears_3"/>
    <exclude body1="2xl430_gears" body2="hand"/>
    <exclude body1="2xl430_gears" body2="2xl430_gears_4"/>
    <exclude body1="2xl430_gears" body2="2xl430_gears_5"/>
    <exclude body1="2xl430_gears" body2="2xl430_gears_6"/>
    <exclude body1="2xl430_gears" body2="hand_2"/>
    <exclude body1="2xl430_gears_2" body2="2xl430_gears_3"/>
    <exclude body1="2xl430_gears_2" body2="hand"/>
    <exclude body1="2xl430_gears_2" body2="2xl430_gears_4"/>
    <exclude body1="2xl430_gears_2" body2="2xl430_gears_5"/>
    <exclude body1="2xl430_gears_2" body2="2xl430_gears_6"/>
    <exclude body1="2xl430_gears_2" body2="hand_2"/>
    <exclude body1="2xl430_gears_3" body2="hand"/>
    <exclude body1="2xl430_gears_3" body2="2xl430_gears_4"/>
    <exclude body1="2xl430_gears_3" body2="2xl430_gears_5"/>
    <exclude body1="2xl430_gears_3" body2="2xl430_gears_6"/>
    <exclude body1="2xl430_gears_3" body2="hand_2"/>
    <exclude body1="hand" body2="2xl430_gears_4"/>
    <exclude body1="hand" body2="2xl430_gears_5"/>
    <exclude body1="hand" body2="2xl430_gears_6"/>
    <exclude body1="hand" body2="hand_2"/>
    <exclude body1="2xl430_gears_4" body2="2xl430_gears_5"/>
    <exclude body1="2xl430_gears_4" body2="2xl430_gears_6"/>
    <exclude body1="2xl430_gears_4" body2="hand_2"/>
    <exclude body1="2xl430_gears_5" body2="2xl430_gears_6"/>
    <exclude body1="2xl430_gears_5" body2="hand_2"/>
    <exclude body1="2xl430_gears_6" body2="hand_2"/>
  </contact> -->
  <actuator>
    <!-- <motor name="neck_yaw" joint="neck_yaw" class="XC330"/> -->
    <!-- <motor name="neck_pitch" joint="neck_pitch" class="XC330"/> -->
    <motor name="waist_roll" joint="waist_roll" class="XC430"/>
    <motor name="waist_yaw" joint="waist_yaw" class="XC430"/>
    <motor name="left_hip_pitch" joint="left_hip_pitch" class="2XC430"/>
    <motor name="left_hip_roll" joint="left_hip_roll" class="2XC430"/>
    <motor name="left_hip_yaw" joint="left_hip_yaw" class="XC330"/>
    <motor name="left_knee" joint="left_knee" class="XM430"/>
    <motor name="left_ank_roll" joint="left_ank_roll" class="XC430"/>
    <motor name="left_ank_pitch" joint="left_ank_pitch" class="XM430"/>
    <motor name="right_hip_pitch" joint="right_hip_pitch" class="2XC430"/>
    <motor name="right_hip_roll" joint="right_hip_roll" class="2XC430"/>
    <motor name="right_hip_yaw" joint="right_hip_yaw" class="XC330"/>
    <motor name="right_knee" joint="right_knee" class="XM430"/>
    <motor name="right_ank_roll" joint="right_ank_roll" class="XC430"/>
    <motor name="right_ank_pitch" joint="right_ank_pitch" class="XM430"/>
    <motor name="left_sho_pitch" joint="left_sho_pitch" class="XC430"/>
    <motor name="left_sho_roll" joint="left_sho_roll" class="2XL430"/>
    <motor name="left_sho_yaw" joint="left_sho_yaw" class="2XL430"/>
    <motor name="left_elbow_roll" joint="left_elbow_roll" class="2XL430"/>
    <!-- <motor name="left_elbow_yaw" joint="left_elbow_yaw" class="2XL430"/> -->
    <!-- <motor name="left_wrist_pitch" joint="left_wrist_pitch" class="2XL430"/> -->
    <!-- <motor name="left_wrist_roll" joint="left_wrist_roll" class="2XL430"/> -->
    <motor name="right_sho_pitch" joint="right_sho_pitch" class="XC430"/>
    <motor name="right_sho_roll" joint="right_sho_roll" class="2XL430"/>
    <motor name="right_sho_yaw" joint="right_sho_yaw" class="2XL430"/>
    <motor name="right_elbow_roll" joint="right_elbow_roll" class="2XL430"/>
    <!-- <motor name="right_elbow_yaw" joint="right_elbow_yaw" class="2XL430"/> -->
    <!-- <motor name="right_wrist_pitch" joint="right_wrist_pitch" class="2XL430"/> -->
    <!-- <motor name="right_wrist_roll" joint="right_wrist_roll" class="2XL430"/> -->
  </actuator>
  <sensor>
        <framequat name="orientation" objtype="site" objname="imu" />
        <gyro name="angular-velocity" site="imu" />
    </sensor>

  <default>
    <default class="visual">
      <geom type="mesh" contype="0" conaffinity="0" group="2"/>
    </default>
    <default class="collision">
      <geom group="3"/>
    </default>
    <default class="XM430">
      <motor ctrlrange="-3 3"/>
    </default>
    <default class="XC430">
      <motor ctrlrange="-2 2"/>
    </default>
    <default class="2XC430">
      <motor ctrlrange="-2 2"/>
    </default>
    <default class="2XL430">
      <motor ctrlrange="-2 2"/>
    </default>
    <default class="XC330">
      <motor ctrlrange="-1 1"/>
    </default>
  </default>

  <!-- setup scene -->
  <statistic center="1.0 0.7 1.0" extent="0.8"/>
  <visual>
    <headlight diffuse="0.6 0.6 0.6" ambient="0.1 0.1 0.1" specular="0.9 0.9 0.9"/>
    <rgba haze="0.15 0.25 0.35 1"/>
    <global azimuth="-140" elevation="-20" offwidth="2080" offheight="1170"/>
  </visual>
  <asset>
     <texture type="skybox" builtin="gradient" rgb1="1 1 1" rgb2="1 1 1" width="800" height="800"/>
    <texture type="2d" name="groundplane" builtin="checker" mark="edge" rgb1="1 1 1" rgb2="1 1 1" markrgb="0 0 0"
      width="300" height="300"/>
    <material name="groundplane" texture="groundplane" texuniform="true" texrepeat="5 5" reflectance="0"/>
    <texture type="skybox" builtin="gradient" rgb1=".4 .5 .6" rgb2="0 0 0" width="100" height="100"/>
    <texture builtin="flat" height="1278" mark="cross" markrgb="1 1 1" name="texgeom" random="0.01" rgb1="0.8 0.6 0.4" rgb2="0.8 0.6 0.4" type="cube" width="127"/>
    <texture name="texplane" builtin="checker" height="512" width="512" rgb1=".2 .3 .4" rgb2=".1 .15 .2" type="2d" />
    <material name="MatPlane" reflectance="0.5" shininess="0.01" specular="0.1" texrepeat="1 1" texture="texplane" texuniform="true" />
    <material name="geom" texture="texgeom" texuniform="true"/>
  </asset>
  <worldbody>
    <geom name="floor" size="0 0 0.01" type="plane" material="groundplane" contype="1" conaffinity="0" priority="1"
      friction="0.6" condim="3"/>

        <light diffuse=".5 .5 .5" pos="-3 -3 5" dir="3 3 -5" castshadow="true"/>

  </worldbody>
</mujoco>