<?xml version="1.0" ?><robot name="right_leg_XM430">  
  <link name="hip_yaw_link">    
    <visual>      
      <origin xyz="0 0 0" rpy="0 -0 0"/>      
      <geometry>        
        <mesh filename="package:///meshes/right_hip_yaw_link_visual.stl"/>        
      </geometry>      
      <material name="hip_yaw_link_material">        
        <color rgba="0.61568627450980395466 0.81176470588235294379 0.92941176470588238168 1.0"/>        
      </material>      
    </visual>    
    <collision>      
      <origin xyz="0 0 0" rpy="0 -0 0"/>      
      <geometry>        
        <mesh filename="package:///meshes/right_hip_yaw_link_collision.stl"/>        
      </geometry>      
    </collision>    
    <inertial>      
      <origin xyz="2.6052892110043261802e-19 4.5779561945300561906e-19 -0.0098390489054829104176" rpy="0 0 0"/>      
      <mass value="0.017999999999999988232"/>      
      <inertia ixx="2.6385033891442523914e-06" ixy="0" ixz="0" iyy="7.6596731957046873405e-06" iyz="0" izz="7.7220708070894735956e-06"/>      
    </inertial>    
  </link>  

  <link name="hip_roll_link">    
    <visual>      
      <origin xyz="0 0 0" rpy="0 -0 0"/>      
      <geometry>        
        <mesh filename="package:///meshes/right_hip_roll_link_visual.stl"/>        
      </geometry>      
      <material name="hip_roll_link_material">        
        <color rgba="0.51698661238356047321 0.50347815951093488618 0.49050589017722012741 1.0"/>        
      </material>      
    </visual>    
    <collision>      
      <origin xyz="0 0 0" rpy="0 -0 0"/>      
      <geometry>        
        <mesh filename="package:///meshes/right_hip_roll_link_collision.stl"/>        
      </geometry>      
    </collision>    
    <inertial>      
      <origin xyz="-0.011999849582182775878 -0.00049598090794319277513 -0.018504111838597465944" rpy="0 0 0"/>      
      <mass value="0.11059999999836234164"/>      
      <inertia ixx="2.2818802599018211805e-05" ixy="-4.6520143286279465858e-08" ixz="-4.6888548259070895301e-08" iyy="3.0871632082338065545e-05" iyz="-5.7477343899720890612e-07" izz="3.0871666424467947309e-05"/>      
    </inertial>    
  </link>  

  <link name="right_hip_pitch_link_xm430">    
    <visual>      
      <origin xyz="0 0 0" rpy="0 -0 0"/>      
      <geometry>        
        <mesh filename="package:///meshes/right_hip_pitch_link_xm430_visual.stl"/>        
      </geometry>      
      <material name="right_hip_pitch_link_xm430_material">        
        <color rgba="0.8707222135732954893 0.72641010956094265172 0.24785169615220692396 1.0"/>        
      </material>      
    </visual>    
    <collision>      
      <origin xyz="0 0 0" rpy="0 -0 0"/>      
      <geometry>        
        <mesh filename="package:///meshes/right_hip_pitch_link_xm430_collision.stl"/>        
      </geometry>      
    </collision>    
    <inertial>      
      <origin xyz="0.00075715881371283015253 -0.050714784778880722671 -0.012656153620121983125" rpy="0 0 0"/>      
      <mass value="0.11480090135030567022"/>      
      <inertia ixx="6.607278648938489003e-05" ixy="4.6010682906021260133e-07" ixz="1.8171597853315155815e-07" iyy="2.3633665181581639092e-05" iyz="1.4125296519934706645e-06" izz="6.2221763055418004632e-05"/>      
    </inertial>    
  </link>  

  <link name="right_calf_link">    
    <visual>      
      <origin xyz="0 0 0" rpy="0 -0 0"/>      
      <geometry>        
        <mesh filename="package:///meshes/right_calf_link_visual.stl"/>        
      </geometry>      
      <material name="right_calf_link_material">        
        <color rgba="0.616547745550632742 0.71757541342472208612 0.74372657889541438081 1.0"/>        
      </material>      
    </visual>    
    <collision>      
      <origin xyz="0 0 0" rpy="0 -0 0"/>      
      <geometry>        
        <mesh filename="package:///meshes/right_calf_link_collision.stl"/>        
      </geometry>      
    </collision>    
    <inertial>      
      <origin xyz="0.0016330560292394454176 0.050045526484800137434 -0.0099079425237753124961" rpy="0 0 0"/>      
      <mass value="0.086799999986183554168"/>      
      <inertia ixx="4.9519076588877077342e-05" ixy="-3.6911123877145733517e-06" ixz="4.1819052274331339443e-07" iyy="1.5531229308366343087e-05" iyz="-4.6072292079354113904e-07" izz="5.314827806205983451e-05"/>      
    </inertial>    
  </link>  

  <link name="bearing_683">    
    <visual>      
      <origin xyz="0 0 0" rpy="0 -0 0"/>      
      <geometry>        
        <mesh filename="package:///meshes/right_bearing_683_visual.stl"/>        
      </geometry>      
      <material name="bearing_683_material">        
        <color rgba="0.64705882352941179736 0.64705882352941179736 0.64705882352941179736 1.0"/>        
      </material>      
    </visual>    
    <collision>      
      <origin xyz="0 0 0" rpy="0 -0 0"/>      
      <geometry>        
        <mesh filename="package:///meshes/right_bearing_683_collision.stl"/>        
      </geometry>      
    </collision>    
    <inertial>      
      <origin xyz="1.0732094295239739393e-19 2.4186774283161266214e-19 -0.0015500000000000016803" rpy="0 0 0"/>      
      <mass value="0.00048694686130641793437"/>      
      <inertia ixx="2.1551456503319895657e-09" ixy="2.3175595566406579266e-27" ixz="2.4896541890902438623e-38" iyy="2.1551456503319883249e-09" iyz="5.4460298433450471486e-38" izz="3.5303647444715305817e-09"/>      
    </inertial>    
  </link>  

  <joint name="right_knee_front_rev_2" type="revolute">    
    <origin xyz="-0.0057402514854763431879 -0.013858192987669382124 -0.026199999999999987188" rpy="4.9452523641215521159e-15 -3.1674356695639584582e-16 3.1359672412492258786"/>    
    <parent link="right_calf_link"/>    
    <child link="bearing_683"/>    
    <axis xyz="0 0 1"/>    
    <limit effort="1" velocity="20" lower="-6.283185307179586232" upper="6.283185307179586232"/>    
    <joint_properties friction="0.0"/>    
  </joint>  

  <link name="bearing_683_2">    
    <visual>      
      <origin xyz="0 0 0" rpy="0 -0 0"/>      
      <geometry>        
        <mesh filename="package:///meshes/right_bearing_683_2_visual.stl"/>        
      </geometry>      
      <material name="bearing_683_2_material">        
        <color rgba="0.64705882352941179736 0.64705882352941179736 0.64705882352941179736 1.0"/>        
      </material>      
    </visual>    
    <collision>      
      <origin xyz="0 0 0" rpy="0 -0 0"/>      
      <geometry>        
        <mesh filename="package:///meshes/right_bearing_683_2_collision.stl"/>        
      </geometry>      
    </collision>    
    <inertial>      
      <origin xyz="1.0732094295240485691e-19 2.418677428316700067e-19 -0.0015499999999999977771" rpy="0 0 0"/>      
      <mass value="0.00048694686130641793437"/>      
      <inertia ixx="2.1551456503319887385e-09" ixy="9.4016331328971133286e-28" ixz="6.4941734545542371767e-38" iyy="2.1551456503319874977e-09" iyz="1.5195108877220808957e-37" izz="3.5303647444715322361e-09"/>      
    </inertial>    
  </link>  

  <joint name="right_knee_back_rev_2" type="revolute">    
    <origin xyz="0.0057402514854763692087 0.013858192987669243346 -0.026199999999999990657" rpy="-2.5000942521723397481e-14 5.2473395102998583317e-16 3.1360672427763174319"/>    
    <parent link="right_calf_link"/>    
    <child link="bearing_683_2"/>    
    <axis xyz="0 0 1"/>    
    <limit effort="1" velocity="20" lower="-6.283185307179586232" upper="6.283185307179586232"/>    
    <joint_properties friction="0.0"/>    
  </joint>  

  <link name="ank_pitch_link">    
    <visual>      
      <origin xyz="0 0 0" rpy="0 -0 0"/>      
      <geometry>        
        <mesh filename="package:///meshes/right_ank_pitch_link_visual.stl"/>        
      </geometry>      
      <material name="ank_pitch_link_material">        
        <color rgba="0.63189161126160264814 0.7266866879354088038 0.78356373393969258601 1.0"/>        
      </material>      
    </visual>    
    <collision>      
      <origin xyz="0 0 0" rpy="0 -0 0"/>      
      <geometry>        
        <mesh filename="package:///meshes/right_ank_pitch_link_collision.stl"/>        
      </geometry>      
    </collision>    
    <inertial>      
      <origin xyz="0.00059528282565814453955 4.0269684199612070023e-08 -7.7616092347959137447e-08" rpy="0 0 0"/>      
      <mass value="0.0042238381753791614387"/>      
      <inertia ixx="3.9782741364678847766e-07" ixy="1.6834347545013802175e-13" ixz="-2.0919187193369323082e-14" iyy="4.3705254067423273522e-07" iyz="-1.6428822295928359723e-12" izz="8.8858574534611122958e-08"/>      
    </inertial>    
  </link>  

  <link name="ank_roll_link">    
    <visual>      
      <origin xyz="0 0 0" rpy="0 -0 0"/>      
      <geometry>        
        <mesh filename="package:///meshes/right_ank_roll_link_visual.stl"/>        
      </geometry>      
      <material name="ank_roll_link_material">        
        <color rgba="0.61568627450980395466 0.81176470588235294379 0.92941176470588227065 1.0"/>        
      </material>      
    </visual>    
    <collision>      
      <origin xyz="0 0 0" rpy="0 -0 0"/>      
      <geometry>        
        <mesh filename="package:///meshes/right_ank_roll_link_collision.stl"/>        
      </geometry>      
    </collision>    
    <inertial>      
      <origin xyz="-3.2206255610852239928e-10 0.030487683096149048589 0.0047792578419041014184" rpy="0 0 0"/>      
      <mass value="0.027200000000000008893"/>      
      <inertia ixx="2.2943463470325713448e-05" ixy="-2.016722948171777719e-13" ixz="4.0806229578615081037e-12" iyy="2.5276617323505065215e-05" iyz="-7.4169474455435566413e-07" izz="5.0976619075837788231e-06"/>      
    </inertial>    
  </link>  

  <link name="ank_rr_link">    
    <visual>      
      <origin xyz="0 0 0" rpy="0 -0 0"/>      
      <geometry>        
        <mesh filename="package:///meshes/right_ank_rr_link_visual.stl"/>        
      </geometry>      
      <material name="ank_rr_link_material">        
        <color rgba="0.61568627450980395466 0.81176470588235294379 0.92941176470588238168 1.0"/>        
      </material>      
    </visual>    
    <collision>      
      <origin xyz="0 0 0" rpy="0 -0 0"/>      
      <geometry>        
        <mesh filename="package:///meshes/right_ank_rr_link_collision.stl"/>        
      </geometry>      
    </collision>    
    <inertial>      
      <origin xyz="-4.5249610960602645664e-05 -0.0063096429836314027462 2.0009406464677816885e-19" rpy="0 0 0"/>      
      <mass value="0.0014499999999999999001"/>      
      <inertia ixx="2.9739579267716163268e-08" ixy="-2.4213146797977880987e-10" ixz="-3.5523394884432796266e-14" iyy="2.7430027724071957055e-08" iyz="4.4497301223652303834e-32" izz="4.2921949116163672436e-08"/>      
    </inertial>    
  </link>  

  <link name="ank_motor_rod_long">    
    <visual>      
      <origin xyz="0 0 0" rpy="0 -0 0"/>      
      <geometry>        
        <mesh filename="package:///meshes/right_ank_motor_rod_long_visual.stl"/>        
      </geometry>      
      <material name="ank_motor_rod_long_material">        
        <color rgba="0.63549975559783222767 0.7077439301702044272 0.75109043491362770251 1.0"/>        
      </material>      
    </visual>    
    <collision>      
      <origin xyz="0 0 0" rpy="0 -0 0"/>      
      <geometry>        
        <mesh filename="package:///meshes/right_ank_motor_rod_long_collision.stl"/>        
      </geometry>      
    </collision>    
    <inertial>      
      <origin xyz="2.4855090373658416808e-10 0.034559019974062320235 0.00093851704878454773103" rpy="0 0 0"/>      
      <mass value="0.0021712857268636710437"/>      
      <inertia ixx="8.5350290058000421993e-07" ixy="1.4884244055558907074e-14" ixz="4.5749525025468555809e-11" iyy="1.3237321792739598881e-08" iyz="-4.3668910960859711191e-09" izz="8.5812217519451768749e-07"/>      
    </inertial>    
  </link>  

  <joint name="right_ank_long_rev_2" type="revolute">    
    <origin xyz="-3.4694469519536141888e-18 -0.0099999999999999533706 -6.9388939039072283776e-18" rpy="-1.570796326794896558 -1.3320366994106251912 -1.5707963267948779063"/>    
    <parent link="ank_rr_link"/>    
    <child link="ank_motor_rod_long"/>    
    <axis xyz="0 0 1"/>    
    <limit effort="1" velocity="20" lower="-1.570796326794896558" upper="1.570796326794896558"/>    
    <joint_properties friction="0.0"/>    
  </joint>  

  <joint name="right_ank_long_rev_1" type="revolute">    
    <origin xyz="0.01799999999999999864 0.015999999999999764411 -0.020600000000000132094" rpy="-7.8386807614170502355e-15 7.211088289180617976e-16 0.018223085043007757056"/>    
    <parent link="ank_roll_link"/>    
    <child link="ank_rr_link"/>    
    <axis xyz="0 0 1"/>    
    <limit effort="1" velocity="20" lower="-1.570796326794896558" upper="1.570796326794896558"/>    
    <joint_properties friction="0.0"/>    
  </joint>  

  <link name="ank_rr_link_2">    
    <visual>      
      <origin xyz="0 0 0" rpy="0 -0 0"/>      
      <geometry>        
        <mesh filename="package:///meshes/right_ank_rr_link_2_visual.stl"/>        
      </geometry>      
      <material name="ank_rr_link_2_material">        
        <color rgba="0.61568627450980395466 0.81176470588235294379 0.92941176470588238168 1.0"/>        
      </material>      
    </visual>    
    <collision>      
      <origin xyz="0 0 0" rpy="0 -0 0"/>      
      <geometry>        
        <mesh filename="package:///meshes/right_ank_rr_link_2_collision.stl"/>        
      </geometry>      
    </collision>    
    <inertial>      
      <origin xyz="-4.5249610960599182994e-05 0.0063096429836314591247 -2.0009406464667284455e-19" rpy="0 0 0"/>      
      <mass value="0.0014499999999999999001"/>      
      <inertia ixx="2.9739579267716163268e-08" ixy="2.4213146797977886157e-10" ixz="3.5523394884432796266e-14" iyy="2.7430027724071963673e-08" iyz="7.1669291072376189503e-32" izz="4.2921949116163672436e-08"/>      
    </inertial>    
  </link>  

  <link name="ank_motor_rod_short">    
    <visual>      
      <origin xyz="0 0 0" rpy="0 -0 0"/>      
      <geometry>        
        <mesh filename="package:///meshes/right_ank_motor_rod_short_visual.stl"/>        
      </geometry>      
      <material name="ank_motor_rod_short_material">        
        <color rgba="0.41222606689734719865 0.58339100346020766885 0.8110726643598615837 1.0"/>        
      </material>      
    </visual>    
    <collision>      
      <origin xyz="0 0 0" rpy="0 -0 0"/>      
      <geometry>        
        <mesh filename="package:///meshes/right_ank_motor_rod_short_collision.stl"/>        
      </geometry>      
    </collision>    
    <inertial>      
      <origin xyz="2.6038943231632549872e-10 0.023830465465870847436 0.00090403506359630625422" rpy="0 0 0"/>      
      <mass value="0.0017000000000000001221"/>      
      <inertia ixx="3.3153416252669976544e-07" ixy="8.7419768119858657143e-15" ixz="4.5749941567677183029e-11" iyy="1.0947363610305713008e-08" iyz="-3.5863098646420718289e-09" izz="3.3621340447865204927e-07"/>      
    </inertial>    
  </link>  

  <joint name="right_ank_short_rev_2" type="revolute">    
    <origin xyz="0 0.010000000000000008882 0" rpy="-1.570796326794896558 1.2119133862909121646 -1.5707963267948537034"/>    
    <parent link="ank_rr_link_2"/>    
    <child link="ank_motor_rod_short"/>    
    <axis xyz="0 0 1"/>    
    <limit effort="1" velocity="20" lower="-1.570796326794896558" upper="1.570796326794896558"/>    
    <joint_properties friction="0.0"/>    
  </joint>  

  <joint name="right_ank_short_rev_1" type="revolute">    
    <origin xyz="-0.018000000000000009048 0.015999999999999764411 -0.020600000000000118217" rpy="2.411086010918130345e-14 -1.3088994399411267302e-14 3.1154741050824821258"/>    
    <parent link="ank_roll_link"/>    
    <child link="ank_rr_link_2"/>    
    <axis xyz="0 0 1"/>    
    <limit effort="1" velocity="20" lower="-1.570796326794896558" upper="1.570796326794896558"/>    
    <joint_properties friction="0.0"/>    
  </joint>  

  <joint name="right_ank_roll" type="revolute">    
    <origin xyz="0.001499999999999998947 8.3266726846886740532e-17 1.3660947373317355868e-17" rpy="6.1391486757704172424e-30 1.5707963267948927832 0"/>    
    <parent link="ank_pitch_link"/>    
    <child link="ank_roll_link"/>    
    <axis xyz="0 0 1"/>    
    <limit effort="1" velocity="20" lower="-0.785398163397448279" upper="0.785398163397448279"/>    
    <joint_properties friction="0.0"/>    
  </joint>  

  <joint name="right_ank_pitch" type="revolute">    
    <origin xyz="3.4616201395293281188e-16 0.10000000000000006106 -0.010399999999999975236" rpy="-3.1415926535897922278 1.9667427410937738729e-16 -3.1415926535897926719"/>    
    <parent link="right_calf_link"/>    
    <child link="ank_pitch_link"/>    
    <axis xyz="0 0 1"/>    
    <limit effort="1" velocity="20" lower="-1.0471975511965976313" upper="0.785398163397448279"/>    
    <joint_properties friction="0.0"/>    
  </joint>  

  <link name="ank_motor_arm">    
    <visual>      
      <origin xyz="0 0 0" rpy="0 -0 0"/>      
      <geometry>        
        <mesh filename="package:///meshes/right_ank_motor_arm_visual.stl"/>        
      </geometry>      
      <material name="ank_motor_arm_material">        
        <color rgba="0.62483822591633164656 0.70971956673896574586 0.76585356440212004614 1.0"/>        
      </material>      
    </visual>    
    <collision>      
      <origin xyz="0 0 0" rpy="0 -0 0"/>      
      <geometry>        
        <mesh filename="package:///meshes/right_ank_motor_arm_collision.stl"/>        
      </geometry>      
    </collision>    
    <inertial>      
      <origin xyz="0.014032842952293483885 -1.1875681526054779929e-09 0.0040383546575275923451" rpy="0 0 0"/>      
      <mass value="0.0021359401157891211472"/>      
      <inertia ixx="2.920977652832815804e-08" ixy="-4.6752001422563860023e-14" ixz="-3.1659407525131065532e-08" iyy="1.7718014185775859225e-07" iyz="-2.5844346951013690337e-15" izz="1.8139327643022011445e-07"/>      
    </inertial>    
  </link>  

  <joint name="right_ank_act_1" type="revolute">    
    <origin xyz="0.013499999999996006514 0.04450000000000683964 0.0040000000000046075088" rpy="-3.1559662337880072911e-13 -4.3224762083389784551e-14 0.21173394130152450865"/>    
    <parent link="right_calf_link"/>    
    <child link="ank_motor_arm"/>    
    <axis xyz="0 0 1"/>    
    <limit effort="1" velocity="20" lower="-1.3089969389957472057" upper="1.3089969389957472057"/>    
    <joint_properties friction="0.0"/>    
  </joint>  

  <link name="ank_motor_arm_2">    
    <visual>      
      <origin xyz="0 0 0" rpy="0 -0 0"/>      
      <geometry>        
        <mesh filename="package:///meshes/right_ank_motor_arm_2_visual.stl"/>        
      </geometry>      
      <material name="ank_motor_arm_2_material">        
        <color rgba="0.62483822591633164656 0.70971956673896574586 0.76585356440212004614 1.0"/>        
      </material>      
    </visual>    
    <collision>      
      <origin xyz="0 0 0" rpy="0 -0 0"/>      
      <geometry>        
        <mesh filename="package:///meshes/right_ank_motor_arm_2_collision.stl"/>        
      </geometry>      
    </collision>    
    <inertial>      
      <origin xyz="0.014032842952293506436 -1.187568081600947684e-09 0.0040383546575275958146" rpy="0 0 0"/>      
      <mass value="0.0021359401157891211472"/>      
      <inertia ixx="2.9209776528328204362e-08" ixy="-4.6752001607133292608e-14" ixz="-3.1659407525131217734e-08" iyy="1.7718014185775922752e-07" iyz="-2.5844347378765580252e-15" izz="1.8139327643022061737e-07"/>      
    </inertial>    
  </link>  

  <joint name="right_ank_act_2" type="revolute">    
    <origin xyz="0.013500000000003113676 0.064500000000006912915 -0.024800000000002909994" rpy="-3.1415926535895573046 -1.7198897169567297797e-13 0.22995607267273157626"/>    
    <parent link="right_calf_link"/>    
    <child link="ank_motor_arm_2"/>    
    <axis xyz="0 0 1"/>    
    <limit effort="1" velocity="20" lower="-1.3089969389957472057" upper="1.3089969389957472057"/>    
    <joint_properties friction="0.0"/>    
  </joint>  

  <joint name="right_knee_pitch" type="revolute">    
    <origin xyz="-2.9733995392255427503e-17 -0.096000000000000001998 -0.0091999999999999963751" rpy="-2.1337098754749728925e-16 3.9898639968108458448e-17 3.1415926535897846783"/>    
    <parent link="right_hip_pitch_link_xm430"/>    
    <child link="right_calf_link"/>    
    <axis xyz="0 0 1"/>    
    <limit effort="1" velocity="20" lower="-1.9198621771937625091" upper="0"/>    
    <joint_properties friction="0.0"/>    
  </joint>  

  <link name="xm430_plate">    
    <visual>      
      <origin xyz="0 0 0" rpy="0 -0 0"/>      
      <geometry>        
        <mesh filename="package:///meshes/right_xm430_plate_visual.stl"/>        
      </geometry>      
      <material name="xm430_plate_material">        
        <color rgba="0.61568627450980395466 0.81176470588235294379 0.9294117647058824927 1.0"/>        
      </material>      
    </visual>    
    <collision>      
      <origin xyz="0 0 0" rpy="0 -0 0"/>      
      <geometry>        
        <mesh filename="package:///meshes/right_xm430_plate_collision.stl"/>        
      </geometry>      
    </collision>    
    <inertial>      
      <origin xyz="8.2761015112156068591e-19 3.9608123405210419363e-18 -0.0024039046431217972466" rpy="0 0 0"/>      
      <mass value="0.0026999999999999992756"/>      
      <inertia ixx="2.6720434385876688324e-07" ixy="-6.8936588702566374239e-08" ixz="2.5793754136946577579e-36" iyy="1.2933116645363405536e-07" iyz="-5.5772549530744028788e-36" izz="3.8533537562751439267e-07"/>      
    </inertial>    
  </link>  

  <link name="knee_rod">    
    <visual>      
      <origin xyz="0 0 0" rpy="0 -0 0"/>      
      <geometry>        
        <mesh filename="package:///meshes/right_knee_rod_visual.stl"/>        
      </geometry>      
      <material name="knee_rod_material">        
        <color rgba="0.62051618944235198416 0.78640765248647581664 0.88594253031295022716 1.0"/>        
      </material>      
    </visual>    
    <collision>      
      <origin xyz="0 0 0" rpy="0 -0 0"/>      
      <geometry>        
        <mesh filename="package:///meshes/right_knee_rod_collision.stl"/>        
      </geometry>      
    </collision>    
    <inertial>      
      <origin xyz="0.014594553522267959475 3.7292099839724583211e-05 -0.0015996227373186720257" rpy="0 0 0"/>      
      <mass value="0.0031629468613064179276"/>      
      <inertia ixx="2.5895923315130376932e-08" ixy="-3.1325283435871752107e-10" ixz="4.1682992324833837119e-10" iyy="6.015326150335526925e-07" iyz="1.0650865822052022654e-12" izz="6.2266847407077561114e-07"/>      
    </inertial>    
  </link>  

  <joint name="right_knee_front_rev_1" type="revolute">    
    <origin xyz="-0.005740251485476348392 -0.013858192987669298857 -0.0050000000000000027062" rpy="1.2660330546546102165e-14 -5.760640040579399853e-15 1.5651709144543408669"/>    
    <parent link="xm430_plate"/>    
    <child link="knee_rod"/>    
    <axis xyz="0 0 1"/>    
    <limit effort="1" velocity="20" lower="-6.283185307179586232" upper="6.283185307179586232"/>    
    <joint_properties friction="0.0"/>    
  </joint>  

  <link name="knee_rod_2">    
    <visual>      
      <origin xyz="0 0 0" rpy="0 -0 0"/>      
      <geometry>        
        <mesh filename="package:///meshes/right_knee_rod_2_visual.stl"/>        
      </geometry>      
      <material name="knee_rod_2_material">        
        <color rgba="0.62051618944235198416 0.78640765248647581664 0.88594253031295022716 1.0"/>        
      </material>      
    </visual>    
    <collision>      
      <origin xyz="0 0 0" rpy="0 -0 0"/>      
      <geometry>        
        <mesh filename="package:///meshes/right_knee_rod_2_collision.stl"/>        
      </geometry>      
    </collision>    
    <inertial>      
      <origin xyz="0.014594557105585477183 3.4373169586153155656e-05 -0.0015996227373184820734" rpy="0 0 0"/>      
      <mass value="0.0031629468613064179276"/>      
      <inertia ixx="2.5895802916981975736e-08" ixy="-2.8873395407690157505e-10" ixz="4.1683002558550294754e-10" iyy="6.0153267523314955379e-07" iyz="9.8172003926880134242e-13" izz="6.2266841387223807044e-07"/>      
    </inertial>    
  </link>  

  <joint name="right_knee_back_rev_1" type="revolute">    
    <origin xyz="0.0057402514854763509941 0.013858192987669298857 -0.0050000000000000061756" rpy="1.7600934488845652939e-14 7.4447456537463636708e-16 1.5652709159814237605"/>    
    <parent link="xm430_plate"/>    
    <child link="knee_rod_2"/>    
    <axis xyz="0 0 1"/>    
    <limit effort="1" velocity="20" lower="-6.283185307179586232" upper="6.283185307179586232"/>    
    <joint_properties friction="0.0"/>    
  </joint>  

  <joint name="right_knee_act" type="revolute">    
    <origin xyz="0.0001500000000000903009 -0.061499999999999978295 -0.030400000000000013817" rpy="-2.110221371875480467e-15 -1.2104358314278240034e-14 3.1415926535897811256"/>    
    <parent link="right_hip_pitch_link_xm430"/>    
    <child link="xm430_plate"/>    
    <axis xyz="0 0 1"/>    
    <limit effort="1" velocity="20" lower="-1.9198621771937625091" upper="0"/>    
    <joint_properties friction="0.0"/>    
  </joint>  

  <joint name="right_hip_pitch" type="revolute">    
    <origin xyz="-0.024000000716142756707 -0.019000000152441819112 -0.019000000152452952568" rpy="1.5707963267951126074 1.5707963267947429031 0"/>    
    <parent link="hip_roll_link"/>    
    <child link="right_hip_pitch_link_xm430"/>    
    <axis xyz="0 0 1"/>    
    <limit effort="1" velocity="20" lower="-1.570796326794896558" upper="1.570796326794896558"/>    
    <joint_properties friction="0.0"/>    
  </joint>  

  <joint name="right_hip_roll" type="revolute">    
    <origin xyz="-0.018999999999999999528 3.350043889036771243e-18 -0.026000000000000002276" rpy="-6.1629758220389864097e-33 -1.5707963267948785724 0"/>    
    <parent link="hip_yaw_link"/>    
    <child link="hip_roll_link"/>    
    <axis xyz="0 0 1"/>    
    <limit effort="1" velocity="20" lower="-0.785398163397448279" upper="0.785398163397448279"/>    
    <joint_properties friction="0.0"/>    
  </joint>  


</robot>