<?xml version="1.0" ?><robot name="left_arm_active">  
  <link name="sho_pitch_link">    
    <visual>      
      <origin xyz="0 0 0" rpy="0 -0 0"/>      
      <geometry>        
        <mesh filename="package:///meshes/left_sho_pitch_link_visual.stl"/>        
      </geometry>      
      <material name="sho_pitch_link_material">        
        <color rgba="0.61568627450980395466 0.81176470588235294379 0.92941176470588227065 1.0"/>        
      </material>      
    </visual>    
    <collision>      
      <origin xyz="0 0 0" rpy="0 -0 0"/>      
      <geometry>        
        <mesh filename="package:///meshes/left_sho_pitch_link_collision.stl"/>        
      </geometry>      
    </collision>    
    <inertial>      
      <origin xyz="2.844942307502240611e-19 -2.0629817293647713033e-18 0.012913250798677606071" rpy="0 0 0"/>      
      <mass value="0.0085999999999999982708"/>      
      <inertia ixx="1.8365636406635808026e-06" ixy="0" ixz="0" iyy="4.0110869076839143695e-06" iyz="0" izz="3.5160516450492489574e-06"/>      
    </inertial>    
  </link>  

  <link name="2xl430_gears">    
    <visual>      
      <origin xyz="0 0 0" rpy="0 -0 0"/>      
      <geometry>        
        <mesh filename="package:///meshes/left_2xl430_gears_visual.stl"/>        
      </geometry>      
      <material name="2xl430_gears_material">        
        <color rgba="0.7591476792056923717 0.85560384745670925444 0.90519468321360618823 1.0"/>        
      </material>      
    </visual>    
    <collision>      
      <origin xyz="0 0 0" rpy="0 -0 0"/>      
      <geometry>        
        <mesh filename="package:///meshes/left_2xl430_gears_collision.stl"/>        
      </geometry>      
    </collision>    
    <inertial>      
      <origin xyz="-0.011592905737981712769 -0.0024238553642539671998 -0.018551095523800652243" rpy="0 0 0"/>      
      <mass value="0.11800003674524907338"/>      
      <inertia ixx="2.7511021050425133908e-05" ixy="9.0043904315059330372e-07" ixz="-2.3349710123437291678e-08" iyy="3.2796197843345773501e-05" iyz="-6.5715119654595532665e-07" izz="3.577573983574187309e-05"/>      
    </inertial>    
  </link>  

  <link name="spur_1m_24t_drive">    
    <visual>      
      <origin xyz="0 0 0" rpy="0 -0 0"/>      
      <geometry>        
        <mesh filename="package:///meshes/left_spur_1m_24t_drive_visual.stl"/>        
      </geometry>      
      <material name="spur_1m_24t_drive_material">        
        <color rgba="0.61568627450980395466 0.81176470588235294379 0.92941176470588238168 1.0"/>        
      </material>      
    </visual>    
    <collision>      
      <origin xyz="0 0 0" rpy="0 -0 0"/>      
      <geometry>        
        <mesh filename="package:///meshes/left_spur_1m_24t_drive_collision.stl"/>        
      </geometry>      
    </collision>    
    <inertial>      
      <origin xyz="3.0325499508169297121e-15 -3.3903525173049749467e-16 0.0048096451474093056613" rpy="0 0 0"/>      
      <mass value="0.003200000000000000587"/>      
      <inertia ixx="1.409759888701696132e-07" ixy="1.5562823101719447534e-15" ixz="1.3007821291259216684e-36" iyy="1.4097598803636001492e-07" iyz="2.0801757662181525674e-36" izz="2.4107776386988840789e-07"/>      
    </inertial>    
  </link>  

  <joint name="left_sho_yaw_drive" type="fixed">    
    <origin xyz="-0.024000000716141004636 -0.019000000152450600283 -0.019000000152443286688" rpy="1.5707963267948328312 -1.2258104172924911424e-15 7.6362147953450801566e-14"/>    
    <parent link="2xl430_gears"/>    
    <child link="spur_1m_24t_drive"/>    
    <axis xyz="0 0 1"/>    
    <limit effort="1" velocity="20"/>    
    <joint_properties friction="0.0"/>    
  </joint>  

  <link name="spur_1m_24t_driven">    
    <visual>      
      <origin xyz="0 0 0" rpy="0 -0 0"/>      
      <geometry>        
        <mesh filename="package:///meshes/left_spur_1m_24t_driven_visual.stl"/>        
      </geometry>      
      <material name="spur_1m_24t_driven_material">        
        <color rgba="0.2313725490196078538 0.38039215686274507888 0.7058823529411765163 1.0"/>        
      </material>      
    </visual>    
    <collision>      
      <origin xyz="0 0 0" rpy="0 -0 0"/>      
      <geometry>        
        <mesh filename="package:///meshes/left_spur_1m_24t_driven_collision.stl"/>        
      </geometry>      
    </collision>    
    <inertial>      
      <origin xyz="-2.9213946397903144375e-18 -1.6882049367809079234e-15 -0.00097237500038395430213" rpy="0 0 0"/>      
      <mass value="0.0026999999999999992756"/>      
      <inertia ixx="1.2202334915684080498e-07" ixy="-5.4145940442873835343e-38" ixz="-1.2988080445849957547e-37" iyy="1.2202334915684064616e-07" iyz="-1.77752564560030155e-37" izz="2.3180293204341252239e-07"/>      
    </inertial>    
  </link>  

  <link name="sho_yaw_link">    
    <visual>      
      <origin xyz="0 0 0" rpy="0 -0 0"/>      
      <geometry>        
        <mesh filename="package:///meshes/left_sho_yaw_link_visual.stl"/>        
      </geometry>      
      <material name="sho_yaw_link_material">        
        <color rgba="0.61568627450980395466 0.81176470588235294379 0.92941176470588227065 1.0"/>        
      </material>      
    </visual>    
    <collision>      
      <origin xyz="0 0 0" rpy="0 -0 0"/>      
      <geometry>        
        <mesh filename="package:///meshes/left_sho_yaw_link_collision.stl"/>        
      </geometry>      
    </collision>    
    <inertial>      
      <origin xyz="-1.286384586061391173e-18 3.5695430205023123066e-18 -0.024649285094360075254" rpy="0 0 0"/>      
      <mass value="0.014499999999999997266"/>      
      <inertia ixx="9.2365904614004456494e-06" ixy="3.5862833440692663253e-13" ixz="2.4228256401784178556e-43" iyy="5.8163826335078791714e-06" iyz="1.6375773286667065811e-35" izz="4.5074356741562122031e-06"/>      
    </inertial>    
  </link>  

  <link name="2xl430_gears_2">    
    <visual>      
      <origin xyz="0 0 0" rpy="0 -0 0"/>      
      <geometry>        
        <mesh filename="package:///meshes/left_2xl430_gears_2_visual.stl"/>        
      </geometry>      
      <material name="2xl430_gears_2_material">        
        <color rgba="0.7591476792056923717 0.85560384745670925444 0.90519468321360618823 1.0"/>        
      </material>      
    </visual>    
    <collision>      
      <origin xyz="0 0 0" rpy="0 -0 0"/>      
      <geometry>        
        <mesh filename="package:///meshes/left_2xl430_gears_2_collision.stl"/>        
      </geometry>      
    </collision>    
    <inertial>      
      <origin xyz="-0.011592905737977807906 -0.0024238553642531254252 -0.018551095523810002402" rpy="0 0 0"/>      
      <mass value="0.11800003674524907338"/>      
      <inertia ixx="2.7511021050425465945e-05" ixy="9.0043904315422591039e-07" ixz="-2.334971012485675677e-08" iyy="3.2796197843347501448e-05" iyz="-6.5715119654968068343e-07" izz="3.577573983574221868e-05"/>      
    </inertial>    
  </link>  

  <link name="spur_1m_24t_drive_2">    
    <visual>      
      <origin xyz="0 0 0" rpy="0 -0 0"/>      
      <geometry>        
        <mesh filename="package:///meshes/left_spur_1m_24t_drive_2_visual.stl"/>        
      </geometry>      
      <material name="spur_1m_24t_drive_2_material">        
        <color rgba="0.61568627450980395466 0.81176470588235294379 0.92941176470588238168 1.0"/>        
      </material>      
    </visual>    
    <collision>      
      <origin xyz="0 0 0" rpy="0 -0 0"/>      
      <geometry>        
        <mesh filename="package:///meshes/left_spur_1m_24t_drive_2_collision.stl"/>        
      </geometry>      
    </collision>    
    <inertial>      
      <origin xyz="3.0394888447208369405e-15 -3.390352517563468395e-16 0.0048096451474092995898" rpy="0 0 0"/>      
      <mass value="0.003200000000000000587"/>      
      <inertia ixx="1.409759888701696132e-07" ixy="1.5562823134806672036e-15" ixz="-3.6361635223987515727e-36" iyy="1.4097598803636001492e-07" iyz="4.7806671134578107202e-36" izz="2.4107776386988840789e-07"/>      
    </inertial>    
  </link>  

  <joint name="left_elbow_yaw_drive" type="fixed">    
    <origin xyz="-0.024000000716137528251 -0.019000000152447529822 -0.019000000152459547986" rpy="1.5707963267950562081 -2.470884284845533208e-13 -1.8325179342287309205e-13"/>    
    <parent link="2xl430_gears_2"/>    
    <child link="spur_1m_24t_drive_2"/>    
    <axis xyz="0 0 1"/>    
    <limit effort="1" velocity="20"/>    
    <joint_properties friction="0.0"/>    
  </joint>  

  <link name="spur_1m_24t_driven_2">    
    <visual>      
      <origin xyz="0 0 0" rpy="0 -0 0"/>      
      <geometry>        
        <mesh filename="package:///meshes/left_spur_1m_24t_driven_2_visual.stl"/>        
      </geometry>      
      <material name="spur_1m_24t_driven_2_material">        
        <color rgba="0.2313725490196078538 0.38039215686274507888 0.7058823529411765163 1.0"/>        
      </material>      
    </visual>    
    <collision>      
      <origin xyz="0 0 0" rpy="0 -0 0"/>      
      <geometry>        
        <mesh filename="package:///meshes/left_spur_1m_24t_driven_2_collision.stl"/>        
      </geometry>      
    </collision>    
    <inertial>      
      <origin xyz="-2.921394639791806648e-18 -1.6884437429067410177e-15 -0.00097237500038395083268" rpy="0 0 0"/>      
      <mass value="0.0026999999999999992756"/>      
      <inertia ixx="1.2202334915684080498e-07" ixy="7.4096137295016845706e-48" ixz="1.4947377821783810374e-36" iyy="1.2202334915684064616e-07" iyz="-3.3166193969048702202e-38" izz="2.3180293204341252239e-07"/>      
    </inertial>    
  </link>  

  <link name="elb_yaw_link">    
    <visual>      
      <origin xyz="0 0 0" rpy="0 -0 0"/>      
      <geometry>        
        <mesh filename="package:///meshes/left_elb_yaw_link_visual.stl"/>        
      </geometry>      
      <material name="elb_yaw_link_material">        
        <color rgba="0.61568627450980395466 0.81176470588235294379 0.92941176470588227065 1.0"/>        
      </material>      
    </visual>    
    <collision>      
      <origin xyz="0 0 0" rpy="0 -0 0"/>      
      <geometry>        
        <mesh filename="package:///meshes/left_elb_yaw_link_collision.stl"/>        
      </geometry>      
    </collision>    
    <inertial>      
      <origin xyz="5.3127688027528164616e-08 0.0019833638641961631212 -0.023416643551549959357" rpy="0 0 0"/>      
      <mass value="0.017500000000000005135"/>      
      <inertia ixx="1.4134344903109199776e-05" ixy="1.6945783921983928598e-12" ixz="-1.128639872186547351e-11" iyy="6.6435900776211365815e-06" iyz="1.0545227077253057579e-06" izz="8.9925290757999010654e-06"/>      
    </inertial>    
  </link>  

  <link name="spur_1m_24t_driven_3">    
    <visual>      
      <origin xyz="0 0 0" rpy="0 -0 0"/>      
      <geometry>        
        <mesh filename="package:///meshes/left_spur_1m_24t_driven_3_visual.stl"/>        
      </geometry>      
      <material name="spur_1m_24t_driven_3_material">        
        <color rgba="0.2313725490196078538 0.38039215686274507888 0.7058823529411765163 1.0"/>        
      </material>      
    </visual>    
    <collision>      
      <origin xyz="0 0 0" rpy="0 -0 0"/>      
      <geometry>        
        <mesh filename="package:///meshes/left_spur_1m_24t_driven_3_collision.stl"/>        
      </geometry>      
    </collision>    
    <inertial>      
      <origin xyz="-2.9213946397903379339e-18 -1.6882049367809096984e-15 -0.0025723750003839584988" rpy="0 0 0"/>      
      <mass value="0.0026999999999999992756"/>      
      <inertia ixx="1.2202334915684085792e-07" ixy="-7.597511869414336567e-37" ixz="-3.9737463676803417348e-37" iyy="1.2202334915684064616e-07" iyz="1.9991124742867757866e-36" izz="2.3180293204341262827e-07"/>      
    </inertial>    
  </link>  

  <link name="2xl430_gears_3">    
    <visual>      
      <origin xyz="0 0 0" rpy="0 -0 0"/>      
      <geometry>        
        <mesh filename="package:///meshes/left_2xl430_gears_3_visual.stl"/>        
      </geometry>      
      <material name="2xl430_gears_3_material">        
        <color rgba="0.7591476792056923717 0.85560384745670925444 0.90519468321360618823 1.0"/>        
      </material>      
    </visual>    
    <collision>      
      <origin xyz="0 0 0" rpy="0 -0 0"/>      
      <geometry>        
        <mesh filename="package:///meshes/left_2xl430_gears_3_collision.stl"/>        
      </geometry>      
    </collision>    
    <inertial>      
      <origin xyz="0.00044890447620203491417 0.011592905379898174253 -0.024576144788197706176" rpy="0 0 0"/>      
      <mass value="0.11800003674524907338"/>      
      <inertia ixx="3.577573983574154783e-05" ixy="2.334971012357644331e-08" ixz="6.5715119654891581268e-07" iyy="2.7511021050426397682e-05" iyz="9.0043904315387936804e-07" izz="3.279619784334573962e-05"/>      
    </inertial>    
  </link>  

  <link name="spur_1m_24t_drive_3">    
    <visual>      
      <origin xyz="0 0 0" rpy="0 -0 0"/>      
      <geometry>        
        <mesh filename="package:///meshes/left_spur_1m_24t_drive_3_visual.stl"/>        
      </geometry>      
      <material name="spur_1m_24t_drive_3_material">        
        <color rgba="0.61568627450980395466 0.81176470588235294379 0.92941176470588238168 1.0"/>        
      </material>      
    </visual>    
    <collision>      
      <origin xyz="0 0 0" rpy="0 -0 0"/>      
      <geometry>        
        <mesh filename="package:///meshes/left_spur_1m_24t_drive_3_collision.stl"/>        
      </geometry>      
    </collision>    
    <inertial>      
      <origin xyz="3.0325499508169301065e-15 -3.3903525173049739606e-16 0.004809645147409304794" rpy="0 0 0"/>      
      <mass value="0.003200000000000000587"/>      
      <inertia ixx="1.4097598887016963967e-07" ixy="1.5562823188040112298e-15" ixz="-7.1146411252036594681e-36" iyy="1.4097598803636006786e-07" iyz="4.8797988584967110948e-37" izz="2.4107776386988840789e-07"/>      
    </inertial>    
  </link>  

  <joint name="left_wrist_pitch_drive" type="fixed">    
    <origin xyz="-1.524411552671568168e-10 0.024000000358058659611 -0.008000000000006885284" rpy="9.3688120281041050571e-15 -2.4754138690627644039e-13 -1.570796326794971387"/>    
    <parent link="2xl430_gears_3"/>    
    <child link="spur_1m_24t_drive_3"/>    
    <axis xyz="0 0 1"/>    
    <limit effort="1" velocity="20"/>    
    <joint_properties friction="0.0"/>    
  </joint>  

  <link name="hand">    
    <visual>      
      <origin xyz="0 0 0" rpy="0 -0 0"/>      
      <geometry>        
        <mesh filename="package:///meshes/left_hand_visual.stl"/>        
      </geometry>      
      <material name="hand_material">        
        <color rgba="0.64149913129808888712 0.67624720774385715938 0.69709605361131798951 1.0"/>        
      </material>      
    </visual>    
    <collision>      
      <origin xyz="0 0 0" rpy="0 -0 0"/>      
      <geometry>        
        <mesh filename="package:///meshes/left_hand_collision.stl"/>        
      </geometry>      
    </collision>    
    <inertial>      
      <origin xyz="-0.0037078693787434419127 0.042127339671143335109 -0.018490328271618890893" rpy="0 0 0"/>      
      <mass value="0.039499999999999972633"/>      
      <inertia ixx="2.4635502047218478788e-05" ixy="6.2323015589611017782e-07" ixz="1.4391446178023840611e-08" iyy="2.547520722095687786e-05" iyz="-4.087043358761638553e-08" izz="1.3466679248868386926e-05"/>      
    </inertial>    
  </link>  

  <joint name="left_wrist_roll" type="revolute">    
    <origin xyz="0.019000000000007885581 -3.580815921555569048e-10 -0.027000000152448064283" rpy="3.141592653589793116 -1.5707963267945475039 0"/>    
    <parent link="2xl430_gears_3"/>    
    <child link="hand"/>    
    <axis xyz="0 0 1"/>    
    <limit effort="1" velocity="20" lower="-1.9198621771937625091" upper="1.3962634015954635824"/>    
    <joint_properties friction="0.0"/>    
  </joint>  

  <link name="wrist_bearing_plate">    
    <visual>      
      <origin xyz="0 0 0" rpy="0 -0 0"/>      
      <geometry>        
        <mesh filename="package:///meshes/left_wrist_bearing_plate_visual.stl"/>        
      </geometry>      
      <material name="wrist_bearing_plate_material">        
        <color rgba="0.71932243125689065977 0.63128434304969727187 0.52422389360984933404 1.0"/>        
      </material>      
    </visual>    
    <collision>      
      <origin xyz="0 0 0" rpy="0 -0 0"/>      
      <geometry>        
        <mesh filename="package:///meshes/left_wrist_bearing_plate_collision.stl"/>        
      </geometry>      
    </collision>    
    <inertial>      
      <origin xyz="-0.0075835583121500104928 -0.015499999999999980807 -0.0018386323705903283732" rpy="0 0 0"/>      
      <mass value="0.0049000367468305548388"/>      
      <inertia ixx="4.9707430109150118544e-07" ixy="9.772578403706156965e-23" ixz="1.8100904820814061718e-08" iyy="7.1268523603538531883e-07" iyz="2.8274327301707633769e-24" izz="1.1919657811600109234e-06"/>      
    </inertial>    
  </link>  

  <joint name="left_wrist_pitch_fixed" type="fixed">    
    <origin xyz="0.015500000000007495629 -1.7430501486614957685e-14 -0.044999999999998895051" rpy="4.0578651550042264519e-14 -2.8213542612434331081e-13 -1.570796326794906328"/>    
    <parent link="2xl430_gears_3"/>    
    <child link="wrist_bearing_plate"/>    
    <axis xyz="0 0 1"/>    
    <limit effort="1" velocity="20"/>    
    <joint_properties friction="0.0"/>    
  </joint>  

  <joint name="left_wrist_pitch" type="revolute">    
    <origin xyz="5.5511151231257827021e-17 -1.0768204908351701201e-16 -0.0015999999999999989925" rpy="-2.6917187154893222538e-14 -2.664535259100368755e-14 -1.5707963267948947816"/>    
    <parent link="spur_1m_24t_driven_3"/>    
    <child link="2xl430_gears_3"/>    
    <axis xyz="0 0 1"/>    
    <limit effort="1" velocity="20" lower="-1.3962634015954635824" upper="1.9198621771937625091"/>    
    <joint_properties friction="0.0"/>    
  </joint>  

  <joint name="left_wrist_roll_fixed" type="fixed">    
    <origin xyz="-1.0768204908351070112e-16 -0.025300000000000003042 -0.052000000000000046185" rpy="1.5707963267949236474 -1.5707963267948696906 0"/>    
    <parent link="elb_yaw_link"/>    
    <child link="spur_1m_24t_driven_3"/>    
    <axis xyz="0 0 1"/>    
    <limit effort="1" velocity="20"/>    
    <joint_properties friction="0.0"/>    
  </joint>  

  <joint name="left_elbow_yaw_fixed" type="fixed">    
    <origin xyz="1.7349786990156647659e-17 0 0.0015999999999999764411" rpy="-3.141592653589793116 1.7371588864105923723e-15 -2.0739916668533996057e-29"/>    
    <parent link="spur_1m_24t_driven_2"/>    
    <child link="elb_yaw_link"/>    
    <axis xyz="0 0 1"/>    
    <limit effort="1" velocity="20"/>    
    <joint_properties friction="0.0"/>    
  </joint>  

  <joint name="left_elbow_yaw" type="revolute">    
    <origin xyz="-3.5806395001780622067e-10 -0.027000000152452907631 -0.019000000000006594947" rpy="1.5707963267949571762 1.5707963267947395725 0"/>    
    <parent link="2xl430_gears_2"/>    
    <child link="spur_1m_24t_driven_2"/>    
    <axis xyz="0 0 1"/>    
    <limit effort="1" velocity="20" lower="-2.6179938779914944114" upper="2.6179938779914944114"/>    
    <joint_properties friction="0.0"/>    
  </joint>  

  <joint name="left_elbow_roll" type="revolute">    
    <origin xyz="0 -0.018999999999999999528 -0.05900000000000000383" rpy="1.570796326794896558 -8.2694607970959069176e-16 -2.2204460490005989148e-16"/>    
    <parent link="sho_yaw_link"/>    
    <child link="2xl430_gears_2"/>    
    <axis xyz="0 0 1"/>    
    <limit effort="1" velocity="20" lower="-1.9198621771937625091" upper="2.4434609527920612138"/>    
    <joint_properties friction="0.0"/>    
  </joint>  

  <joint name="left_sho_yaw_fixed" type="fixed">    
    <origin xyz="0 -3.9443045261050590271e-31 0.0016000000000000041966" rpy="-3.1415926535897917837 7.7715611727616959238e-16 7.7715611725338728944e-16"/>    
    <parent link="spur_1m_24t_driven"/>    
    <child link="sho_yaw_link"/>    
    <axis xyz="0 0 1"/>    
    <limit effort="1" velocity="20"/>    
    <joint_properties friction="0.0"/>    
  </joint>  

  <joint name="left_sho_yaw" type="revolute">    
    <origin xyz="-3.5807028869738743992e-10 -0.027000000152450923108 -0.018999999999999878098" rpy="1.5707963267948492625 8.0395273179087848749e-14 9.4924068605497912938e-14"/>    
    <parent link="2xl430_gears"/>    
    <child link="spur_1m_24t_driven"/>    
    <axis xyz="0 0 1"/>    
    <limit effort="1" velocity="20" lower="-2.6179938779914944114" upper="2.6179938779914944114"/>    
    <joint_properties friction="0.0"/>    
  </joint>  

  <joint name="left_sho_roll" type="revolute">    
    <origin xyz="-0.018999999999999999528 9.3241386866726118567e-18 0.027000000000000006634" rpy="-3.141592653589793116 1.5707963267948936714 0"/>    
    <parent link="sho_pitch_link"/>    
    <child link="2xl430_gears"/>    
    <axis xyz="0 0 1"/>    
    <limit effort="1" velocity="20" lower="-1.570796326794896558" upper="0.34906585039886589561"/>    
    <joint_properties friction="0.0"/>    
  </joint>  


</robot>