<mujoco model="T1">
    <compiler angle="radian" meshdir="meshes/" />
    <default>
        <motor ctrlrange="-1 1" ctrllimited="true"/>
        <!-- <joint actuatorfrclimited="true" type="hinge"/> -->
    </default>
    <asset>
        <mesh name="Trunk" file="Trunk.STL" />
        <mesh name="H1" file="H1.STL" />
        <mesh name="H2" file="H2.STL" />
        <mesh name="AL1" file="AL1.STL" />
        <mesh name="AL2" file="AL2.STL" />
        <mesh name="AL3" file="AL3.STL" />
        <mesh name="AL4" file="AL4.STL" />
        <mesh name="AL5" file="AL5.STL" />
        <mesh name="AL6" file="AL6.STL" />
        <mesh name="AL7" file="AL7.STL" />
        <mesh name="AR1" file="AR1.STL" />
        <mesh name="AR2" file="AR2.STL" />
        <mesh name="AR3" file="AR3.STL" />
        <mesh name="AR4" file="AR4.STL" />
        <mesh name="AR5" file="AR5.STL" />
        <mesh name="AR6" file="AR6.STL" />
        <mesh name="AR7" file="AR7.STL" />
        <mesh name="Waist" file="Waist.STL" />
        <mesh name="Hip_Pitch_Left" file="Hip_Pitch_Left.STL" />
        <mesh name="Hip_Roll_Left" file="Hip_Roll_Left.STL" />
        <mesh name="Hip_Yaw_Left" file="Hip_Yaw_Left.STL" />
        <mesh name="Shank_Left" file="Shank_Left.STL" />
        <mesh name="Ankle_Cross_Left" file="Ankle_Cross_Left.STL" />
        <mesh name="left_foot_link" file="left_foot_link.STL" />
        <mesh name="Hip_Pitch_Right" file="Hip_Pitch_Right.STL" />
        <mesh name="Hip_Roll_Right" file="Hip_Roll_Right.STL" />
        <mesh name="Hip_Yaw_Right" file="Hip_Yaw_Right.STL" />
        <mesh name="Shank_Right" file="Shank_Right.STL" />
        <mesh name="Ankle_Cross_Right" file="Ankle_Cross_Right.STL" />
        <mesh name="right_foot_link" file="right_foot_link.STL" />
    </asset>
    <worldbody>
        <body name="Trunk" pos="0 0 0.7">
            <inertial pos="0.0551365 -1.42058e-06 0.105062" quat="0.99996 1.40561e-05 -0.00899532 -1.39249e-05" mass="11.7" diaginertia="0.0915404 0.0767787 0.0556055" />
            <site name='imu' size='0.01' pos='0.0 0.0 0.0' />
            <joint type="free" />
            <geom type="mesh" contype="0" conaffinity="0" group="1" rgba="0.76 0.76 0.76 1.0" mesh="Trunk" />
            <geom size="0.075 0.1 0.15" pos="0.06 0 0.12" type="box" rgba="0.76 0.76 0.76 0.0" />
            <body name="H1" pos="0.0625 0 0.243">
                <inertial pos="-0.000508 -0.001403 0.057432" quat="0.763881 -0.0132172 0.00173419 0.645219" mass="0.44391" diaginertia="0.000241549 0.00022351 0.000149941" />
                <geom type="mesh" contype="0" conaffinity="0" group="1" rgba="0.4 0.4 0.4 1.0" mesh="H1" />
                <body name="H2" pos="0 0 0.06185">
                    <inertial pos="0.007802 0.001262 0.098631" quat="0.988453 0.106172 -0.0745686 -0.0782786" mass="0.631019" diaginertia="0.00203553 0.00192467 0.00172381" />
                    <geom type="mesh" contype="0" conaffinity="0" group="1" rgba="0.4 0.4 0.4 1.0" mesh="H2" />
                    <geom size="0.08" pos="0.01 0 0.11" rgba="0.4 0.4 0.4 0.0" />
                </body>
            </body>

            <body name="AL1" pos="0.0575 0.1063 0.219" quat="1 0 0.000440565 0">
                <inertial pos="-0.000677 0.044974 0" quat="0.50423 0.495734 -0.50423 0.495734" mass="0.53" diaginertia="0.001367 0.00129329 0.000292711" />
                <joint name="Left_Shoulder_Pitch" pos="0 0 0" axis="0 1 0" limited="true" range="-3.31 1.22" />
                <geom type="mesh" contype="0" conaffinity="0" group="1" rgba="0.76 0.76 0.76 1.0" mesh="AL1" />
                <body name="AL2" pos="0 0.047 0">
                    <inertial pos="0.003862 0.037976 0" quat="0.487991 0.511727 -0.487991 0.511727" mass="0.16" diaginertia="0.000401 0.00034538 0.00017662" />
                    <joint name="Left_Shoulder_Roll" pos="0 0 0" axis="1 0 0" limited="true" range="-1.74 1.57" />
                    <geom type="mesh" contype="0" conaffinity="0" group="1" rgba="0.4 0.4 0.4 1.0" mesh="AL2" />
                    <body name="AL3" pos="0.00025 0.0605 0">
                        <inertial pos="0 0.085353 -9.9e-05" quat="0.70641 0.707803 0 0" mass="1.02" diaginertia="0.012869 0.012798 0.000620953" />
                        <joint name="Left_Elbow_Pitch" pos="0 0 0" axis="0 1 0" limited="true" range="-2.27 2.27" />
                        <geom type="mesh" contype="0" conaffinity="0" group="1" rgba="0.4 0.4 0.4 1.0" mesh="AL3" />
                        <geom size="0.03 0.075" pos="0 0.05 0" quat="0.707105 0.707108 0 0" type="cylinder" rgba="0.4 0.4 0.4 0.0" />
                        <body name="AL4" pos="0 0.1471 0">
                            <inertial pos="-0.00046851 0.062372 0.0015178" quat="0.708114 0.706086 -0.00272503 -0.00309075" mass="0.5570" diaginertia="0.0016731 0.00160801 0.00021389" />
                            <!-- <joint name="Left_Elbow_Yaw" pos="0 0 0" axis="0 0 1" limited="true" range="-2.27 2.27" /> -->
                            <joint name="Left_Elbow_Yaw" pos="0 0 0" axis="0 0 1" limited="true" range="-2.27 0.0" />
                            <geom size="0.04 0.07" pos="0 0.08 0" quat="0.707105 0.707108 0 0" type="cylinder" rgba="0.4 0.4 0.4 0.0" />
                            <geom type="mesh" contype="0" conaffinity="0" group="1" rgba="0.75294 0.75294 0.75294 1" mesh="AL4" />
                            <body name="AL5" pos="0 0.105 0.00025">
                                <inertial pos="-3.8402e-05 0.036076 0.0056711" quat="0.763252 0.646101 0 0" mass="0.43402" diaginertia="0.000823 0.000801406 0.000199594" />
                                <joint name="Left_Wrist_Pitch" pos="0 0 0" axis="0 1 0" limited="true" range="-2.27 2.27" />
                                <geom type="mesh" contype="0" conaffinity="0" group="1" rgba="0.75294 0.75294 0.75294 1" mesh="AL5" />
                                <body name="AL6" pos="0 0.042 0">
                                    <inertial pos="-0.00072939 0.056578 -0.0056257" quat="0.701498 0.712537 0.00305334 -0.0134832" mass="0.47922" diaginertia="0.00117124 0.00113821 0.000165544" />
                                    <joint name="Left_Wrist_Yaw" pos="0 0 0" axis="0 0 1" limited="true" range="-2.27 2.27" />
                                    <geom type="mesh" contype="0" conaffinity="0" group="1" rgba="0.75294 0.75294 0.75294 1" mesh="AL6" />
                                    <body name="left_hand_link" pos="0.00475 0.07 0.0015">
                                        <inertial pos="-0.0067917 0.06373 0.011867" quat="0.486792 0.512522 -0.512399 0.487649" mass="0.30603" diaginertia="0.00244446 0.002302 0.000301541"/>
                                        <!-- <inertial pos="-0.0067917 0.06373 0.011867" quat="0.441572 0.342654 -0.554142 0.61687" mass="0.24875" diaginertia="0.00165553 0.00156059 0.000219879" /> -->
                                        <joint name="Left_Hand_Roll" pos="0 0 0" axis="1 0 0" limited="true" range="-2.27 2.27" />
                                        <geom size="0.06 0.075" pos="0 0.1 0" quat="0.707105 0.707108 0 0" type="cylinder" rgba="0.4 0.4 0.4 0.0" />
                                        <geom type="mesh" contype="0" conaffinity="0" group="1" rgba="0.75294 0.75294 0.75294 1" mesh="AL7" />
                                    </body>
                                </body>
                            </body>
                        </body>
                    </body>
                </body>
            </body>
            <body name="AR1" pos="0.0575 -0.1063 0.219" quat="1 0 0.000440565 0">
                <inertial pos="-0.000677 -0.044974 0" quat="0.50423 0.495734 -0.50423 0.495734" mass="0.53" diaginertia="0.001367 0.00129329 0.000292711" />
                <joint name="Right_Shoulder_Pitch" pos="0 0 0" axis="0 1 0" limited="true" range="-3.31 1.22" />
                <geom type="mesh" contype="0" conaffinity="0" group="1" rgba="0.76 0.76 0.76 1.0" mesh="AR1" />
                <body name="AR2" pos="0 -0.047 0">
                    <inertial pos="0.003862 -0.037976 0" quat="0.511727 0.487991 -0.511727 0.487991" mass="0.16" diaginertia="0.000401 0.00034538 0.00017662" />
                    <joint name="Right_Shoulder_Roll" pos="0 0 0" axis="1 0 0" limited="true" range="-1.57 1.74" />
                    <geom type="mesh" contype="0" conaffinity="0" group="1" rgba="0.4 0.4 0.4 1.0" mesh="AR2" />
                    <body name="AR3" pos="0.00025 -0.0605 0">
                        <inertial pos="0 -0.085353 -9.9e-05" quat="0.707803 0.70641 0 0" mass="1.02" diaginertia="0.012869 0.012798 0.000620953" />
                        <joint name="Right_Elbow_Pitch" pos="0 0 0" axis="0 1 0" limited="true" range="-2.27 2.27" />
                        <geom type="mesh" contype="0" conaffinity="0" group="1" rgba="0.4 0.4 0.4 1.0" mesh="AR3" />
                        <geom size="0.03 0.075" pos="0 -0.05 0" quat="0.707105 0.707108 0 0" type="cylinder" rgba="0.4 0.4 0.4 0.0" />
                        <body name="AR4" pos="0 -0.1471 0">
                            <inertial pos="-0.0004573 -0.067734 0.0017465" quat="0.706214 0.70799 0.00258227 0.0022281" mass="0.5570" diaginertia="0.0022921 0.00222301 0.000233892" />
                            <!-- <joint name="Right_Elbow_Yaw" pos="0 0 0" axis="0 0 1" limited="true" range="-2.27 2.27" /> -->
                            <joint name="Right_Elbow_Yaw" pos="0 0 0" axis="0 0 1" limited="true" range="0.0 2.27" />
                            <geom size="0.04 0.07" pos="0 -0.08 0" quat="0.707105 0.707108 0 0" type="cylinder" rgba="0.4 0.4 0.4 0.0" />
                            <geom type="mesh" contype="0" conaffinity="0" group="1" rgba="0.75294 0.75294 0.75294 1" mesh="AR4" />
                            <body name="AR5" pos="0 -0.105 0.00025">
                                <inertial pos="3.7355e-05 -0.035638 0.0053147" quat="0.648697 0.761046 0 0" mass="0.43402" diaginertia="0.000836 0.000812239 0.000204761" />
                                <joint name="Right_Wrist_Pitch" pos="0 0 0" axis="0 1 0" limited="true" range="-2.27 2.27" />
                                <geom type="mesh" contype="0" conaffinity="0" group="1" rgba="0.75294 0.75294 0.75294 1" mesh="AR5" />
                                <body name="AR6" pos="0 -0.042 0">
                                    <inertial pos="-0.0011437 -0.056205 -0.0056621" quat="0.711908 0.702081 0.0164127 -0.000464544" mass="0.47922" diaginertia="0.00123856 0.00121017 0.000181264" />
                                    <joint name="Right_Wrist_Yaw" pos="0 0 0" axis="0 0 1" limited="true" range="-2.27 2.27" />
                                    <geom type="mesh" contype="0" conaffinity="0" group="1" rgba="0.75294 0.75294 0.75294 1" mesh="AR6" />
                                    <body name="right_hand_link" pos="0.00475 -0.07 0.0015">
                                        <inertial pos="-0.0047758 -0.064411 0.011992" quat="0.488328 0.51175 -0.511877 0.487473" mass="0.30603" diaginertia="0.00242288 0.002287 0.000287116"/>
                                        <!-- <inertial pos="-0.0047758 -0.064411 0.011992" quat="0.348921 0.444269 -0.615118 0.550009" mass="0.24612" diaginertia="0.00164385 0.00156207 0.000212082" /> -->
                                        <joint name="Right_Hand_Roll" pos="0 0 0" axis="1 0 0" limited="true" range="-2.27 2.27" />
                                        <geom size="0.06 0.075" pos="0 -0.1 0" quat="0.707105 0.707108 0 0" type="cylinder" rgba="0.4 0.4 0.4 0.0" />
                                        <geom type="mesh" contype="0" conaffinity="0" group="1" rgba="0.75294 0.75294 0.75294 1" mesh="AR7" />
                                    </body>
                                </body>
                            </body>
                        </body>
                    </body>
                </body>
            </body>
            <body name="Waist" pos="0.0625 0 -0.1155">
                <inertial pos="0.002284 3e-06 0.007301" quat="0.983649 0.000360386 -0.180076 0.00269791" mass="2.581" diaginertia="0.00536742 0.005299 0.00474258" />
                <joint name="Waist" pos="0 0 0" axis="0 0 1" limited="true" range="-1.57 1.57" />
                <geom type="mesh" contype="0" conaffinity="0" group="1" rgba="0.4 0.4 0.4 1.0" mesh="Waist" />
                <body name="Hip_Pitch_Left" pos="0 0.106 0">
                    <inertial pos="0.000534 -0.007296 -0.018083" quat="0.975141 0.2211 0.0145808 0.0017406" mass="1.021" diaginertia="0.00180547 0.00145926 0.00125327" />
                    <joint name="Left_Hip_Pitch" pos="0 0 0" axis="0 1 0" limited="true" range="-1.8 1.57" />
                    <geom type="mesh" contype="0" conaffinity="0" group="1" rgba="0.76 0.76 0.76 1.0" mesh="Hip_Pitch_Left" />
                    <body name="Hip_Roll_Left" pos="0 0 -0.02">
                        <inertial pos="0.001101 2.4e-05 -0.05375" quat="0.707081 -0.00599604 -0.00599604 0.707081" mass="0.385" diaginertia="0.001743 0.00151729 0.000514712" />
                        <joint name="Left_Hip_Roll" pos="0 0 0" axis="1 0 0" limited="true" range="-0.3 1.57" />
                        <geom type="mesh" contype="0" conaffinity="0" group="1" rgba="0.4 0.4 0.4 1.0" mesh="Hip_Roll_Left" />
                        <geom size="0.05 0.08" pos="0 0 -0.08" type="cylinder" rgba="0.4 0.4 0.4 0.0" />
                        <body name="Hip_Yaw_Left" pos="0 0 -0.081854">
                            <inertial pos="-0.007233 0.000206 -0.089184" quat="0.696808 -0.033953 -0.0315708 0.715758" mass="2.166" diaginertia="0.0257334 0.0253024 0.00259215" />
                            <joint name="Left_Hip_Yaw" pos="0 0 0" axis="0 0 1" limited="true" range="-1 1" />
                            <geom type="mesh" contype="0" conaffinity="0" group="1" rgba="0.4 0.4 0.4 1.0" mesh="Hip_Yaw_Left" />
                            <geom size="0.05 0.04" pos="-0.015 0 -0.135" quat="0.707141 0.707073 0 0" type="cylinder" rgba="0.4 0.4 0.4 0.0" />
                            <body name="Shank_Left" pos="-0.014 0 -0.134">
                                <inertial pos="-0.006012 0.000259 -0.124318" quat="0.997573 0.00144024 -0.023949 0.0653706" mass="1.73" diaginertia="0.0346951 0.0345375 0.00185844" />
                                <joint name="Left_Knee_Pitch" pos="0 0 0" axis="0 1 0" limited="true" range="0 2.34" />
                                <geom type="mesh" contype="0" conaffinity="0" group="1" rgba="0.4 0.4 0.4 1.0" mesh="Shank_Left" />
                                <geom size="0.05 0.04 0.05" pos="0 0 -0.13" type="box" rgba="0.4 0.4 0.4 0.0" />
                                <body name="Ankle_Cross_Left" pos="0 0 -0.28">
                                    <inertial pos="-0.003722 0 -0.007981" quat="0.443136 0.551027 0.551027 0.443136" mass="0.073" diaginertia="2.9e-05 2.56589e-05 1.13411e-05" />
                                    <joint name="Left_Ankle_Pitch" pos="0 0 0" axis="0 1 0" limited="true" range="-0.87 0.35" />
                                    <geom type="mesh" contype="0" conaffinity="0" group="1" rgba="0.4 0.4 0.4 1.0" mesh="Ankle_Cross_Left" />
                                    <body name="left_foot_link" pos="0 0.00025 -0.012">
                                        <inertial pos="-0.000249 0 -0.00914" quat="0 0.599183 0 0.800612" mass="0.685" diaginertia="0.0027142 0.002385 0.0021708" />
                                        <joint name="Left_Ankle_Roll" pos="0 0 0" axis="1 0 0" limited="true" range="-0.44 0.44" />
                                        <geom type="mesh" contype="0" conaffinity="0" group="1" rgba="0.4 0.4 0.4 1.0" mesh="left_foot_link" />
                                        <geom size="0.1115 0.05 0.015" pos="0.01 0 -0.015" type="box" rgba="0.4 0.4 0.4 0.0" />
                                        <body name="left_toe_link" pos="0.1 0.0 -0.02"/>
                                    </body>
                                </body>
                            </body>
                        </body>
                    </body>
                </body>
                <body name="Hip_Pitch_Right" pos="0 -0.106 0">
                    <inertial pos="0.000534 0.007514 -0.018082" quat="0.973446 -0.228403 0.0147148 -0.00419349" mass="1.021" diaginertia="0.00180552 0.0014632 0.00124928" />
                    <joint name="Right_Hip_Pitch" pos="0 0 0" axis="0 1 0" limited="true" range="-1.8 1.57" />
                    <geom type="mesh" contype="0" conaffinity="0" group="1" rgba="0.76 0.76 0.76 1.0" mesh="Hip_Pitch_Right" />
                    <body name="Hip_Roll_Right" pos="0 0 -0.02">
                        <inertial pos="0.001099 2.4e-05 -0.053748" quat="0.707081 -0.00599604 -0.00599604 0.707081" mass="0.385" diaginertia="0.001743 0.00151729 0.000514712" />
                        <joint name="Right_Hip_Roll" pos="0 0 0" axis="1 0 0" limited="true" range="-1.57 0.3" />
                        <geom type="mesh" contype="0" conaffinity="0" group="1" rgba="0.4 0.4 0.4 1.0" mesh="Hip_Roll_Right" />
                        <geom size="0.05 0.08" pos="0 0 -0.08" type="cylinder" rgba="0.4 0.4 0.4 0.0" />
                        <body name="Hip_Yaw_Right" pos="0 0 -0.081854">
                            <inertial pos="-0.007191 -0.000149 -0.08922" quat="0.714468 -0.0315638 -0.0336391 0.698146" mass="2.17" diaginertia="0.0257623 0.0253298 0.00259389" />
                            <joint name="Right_Hip_Yaw" pos="0 0 0" axis="0 0 1" limited="true" range="-1 1" />
                            <geom type="mesh" contype="0" conaffinity="0" group="1" rgba="0.4 0.4 0.4 1.0" mesh="Hip_Yaw_Right" />
                            <geom size="0.05 0.04" pos="-0.015 0 -0.135" quat="0.707141 0.707073 0 0" type="cylinder" rgba="0.4 0.4 0.4 0.0" />
                            <body name="Shank_Right" pos="-0.014 0 -0.134">
                                <inertial pos="-0.005741 -0.000541 -0.122602" quat="0.99926 -0.000580963 -0.023461 -0.0304754" mass="1.79" diaginertia="0.0351717 0.0349574 0.00196589" />
                                <joint name="Right_Knee_Pitch" pos="0 0 0" axis="0 1 0" limited="true" range="0 2.34" />
                                <geom type="mesh" contype="0" conaffinity="0" group="1" rgba="0.4 0.4 0.4 1.0" mesh="Shank_Right" />
                                <geom size="0.05 0.04 0.05" pos="0 0 -0.13" type="box" rgba="0.4 0.4 0.4 0.0" />
                                <body name="Ankle_Cross_Right" pos="0 0 -0.28">
                                    <inertial pos="-0.003722 0 -0.007981" quat="0.443136 0.551027 0.551027 0.443136" mass="0.073" diaginertia="2.9e-05 2.56589e-05 1.13411e-05" />
                                    <joint name="Right_Ankle_Pitch" pos="0 0 0" axis="0 1 0" limited="true" range="-0.87 0.35" />
                                    <geom type="mesh" contype="0" conaffinity="0" group="1" rgba="0.4 0.4 0.4 1.0" mesh="Ankle_Cross_Right" />
                                    <body name="right_foot_link" pos="0 -0.00025 -0.012">
                                        <inertial pos="-0.000248 0 -0.00914" quat="0 0.599183 0 0.800612" mass="0.685" diaginertia="0.0027142 0.002385 0.0021708" />
                                        <joint name="Right_Ankle_Roll" pos="0 0 0" axis="1 0 0" limited="true" range="-0.44 0.44" />
                                        <geom type="mesh" contype="0" conaffinity="0" group="1" rgba="0.4 0.4 0.4 1.0" mesh="right_foot_link" />
                                        <geom size="0.1115 0.05 0.015" pos="0.01 0 -0.015" type="box" rgba="0.4 0.4 0.4 0.0" />
                                        <body name="right_toe_link" pos="0.1 0.0 -0.02"/>
                                    </body>
                                </body>
                            </body>
                        </body>
                    </body>
                </body>
            </body>
        </body>
    </worldbody>
    <actuator>
        <motor name="Left_Shoulder_Pitch" joint="Left_Shoulder_Pitch" ctrlrange="-18.0 18.0" ctrllimited="true" />
        <motor name="Left_Shoulder_Roll" joint="Left_Shoulder_Roll" ctrlrange="-18.0 18.0" ctrllimited="true" />
        <motor name="Left_Elbow_Pitch" joint="Left_Elbow_Pitch" ctrlrange="-18.0 18.0" ctrllimited="true" />
        <motor name="Left_Elbow_Yaw" joint="Left_Elbow_Yaw" ctrlrange="-18.0 18.0" ctrllimited="true" />
        <motor name="Left_Wrist_Pitch" joint="Left_Wrist_Pitch" ctrlrange="-18.0 18.0" ctrllimited="true" />
        <motor name="Left_Wrist_Yaw" joint="Left_Wrist_Yaw" ctrlrange="-18.0 18.0" ctrllimited="true" />
        <motor name="Left_Hand_Roll" joint="Left_Hand_Roll" ctrlrange="-18.0 18.0" ctrllimited="true" />
        <motor name="Right_Shoulder_Pitch" joint="Right_Shoulder_Pitch" ctrlrange="-18.0 18.0" ctrllimited="true" />
        <motor name="Right_Shoulder_Roll" joint="Right_Shoulder_Roll" ctrlrange="-18.0 18.0" ctrllimited="true" />
        <motor name="Right_Elbow_Pitch" joint="Right_Elbow_Pitch" ctrlrange="-18.0 18.0" ctrllimited="true" />
        <motor name="Right_Elbow_Yaw" joint="Right_Elbow_Yaw" ctrlrange="-18.0 18.0" ctrllimited="true" />
        <motor name="Right_Wrist_Pitch" joint="Right_Wrist_Pitch" ctrlrange="-18.0 18.0" ctrllimited="true" />
        <motor name="Right_Wrist_Yaw" joint="Right_Wrist_Yaw" ctrlrange="-18.0 18.0" ctrllimited="true" />
        <motor name="Right_Hand_Roll" joint="Right_Hand_Roll" ctrlrange="-18.0 18.0" ctrllimited="true" />
        <motor name="Waist" joint="Waist" ctrlrange="-30.0 30.0" ctrllimited="true" />
        <motor name="Left_Hip_Pitch" joint="Left_Hip_Pitch" ctrlrange="-45.0 45.0" ctrllimited="true" />
        <motor name="Left_Hip_Roll" joint="Left_Hip_Roll" ctrlrange="-45.0 45.0" ctrllimited="true" />
        <motor name="Left_Hip_Yaw" joint="Left_Hip_Yaw" ctrlrange="-30.0 30.0" ctrllimited="true" />
        <motor name="Left_Knee_Pitch" joint="Left_Knee_Pitch" ctrlrange="-65.0 65.0" ctrllimited="true" />
        <motor name="Left_Ankle_Pitch" joint="Left_Ankle_Pitch" ctrlrange="-24.0 24.0" ctrllimited="true" />
        <motor name="Left_Ankle_Roll" joint="Left_Ankle_Roll" ctrlrange="-15.0 15.0" ctrllimited="true" />
        <motor name="Right_Hip_Pitch" joint="Right_Hip_Pitch" ctrlrange="-45.0 45.0" ctrllimited="true" />
        <motor name="Right_Hip_Roll" joint="Right_Hip_Roll" ctrlrange="-45.0 45.0" ctrllimited="true" />
        <motor name="Right_Hip_Yaw" joint="Right_Hip_Yaw" ctrlrange="-30.0 30.0" ctrllimited="true" />
        <motor name="Right_Knee_Pitch" joint="Right_Knee_Pitch" ctrlrange="-65.0 65.0" ctrllimited="true" />
        <motor name="Right_Ankle_Pitch" joint="Right_Ankle_Pitch" ctrlrange="-24.0 24.0" ctrllimited="true" />
        <motor name="Right_Ankle_Roll" joint="Right_Ankle_Roll" ctrlrange="-15.0 15.0" ctrllimited="true" />
    </actuator>
    <sensor>
        <framequat name="orientation" objtype="site" objname="imu" />
        <gyro name="angular-velocity" site="imu" />
    </sensor>

    <!-- setup scene -->
    <statistic center="1.0 0.7 1.0" extent="0.8"/>
    <visual>
        <headlight diffuse="0.6 0.6 0.6" ambient="0.1 0.1 0.1" specular="0.9 0.9 0.9"/>
        <rgba haze="0.15 0.25 0.35 1"/>
        <global azimuth="-140" elevation="-20" offwidth="2080" offheight="1170"/>
    </visual>
    <asset>
         <texture type="skybox" builtin="gradient" rgb1="1 1 1" rgb2="1 1 1" width="800" height="800"/>
    <texture type="2d" name="groundplane" builtin="checker" mark="edge" rgb1="1 1 1" rgb2="1 1 1" markrgb="0 0 0"
      width="300" height="300"/>
    <material name="groundplane" texture="groundplane" texuniform="true" texrepeat="5 5" reflectance="0"/>
        <texture type="skybox" builtin="gradient" rgb1=".4 .5 .6" rgb2="0 0 0" width="100" height="100"/>
        <texture builtin="flat" height="1278" mark="cross" markrgb="1 1 1" name="texgeom" random="0.01" rgb1="0.8 0.6 0.4" rgb2="0.8 0.6 0.4" type="cube" width="127"/>
        <texture name="texplane" builtin="checker" height="512" width="512" rgb1=".2 .3 .4" rgb2=".1 .15 .2" type="2d" />
        <material name="MatPlane" reflectance="0.5" shininess="0.01" specular="0.1" texrepeat="1 1" texture="texplane" texuniform="true" />
        <material name="geom" texture="texgeom" texuniform="true"/>
    </asset>
    <worldbody>
        <geom name="floor" size="0 0 0.01" type="plane" material="groundplane" contype="1" conaffinity="0" priority="1"
      friction="0.6" condim="3"/>
      <!-- <light diffuse=".5 .5 .5" pos="0 0 5" dir="0 0 -1" castshadow="true"/> -->

          <light diffuse=".5 .5 .5" pos="-3 -3 5" dir="3 3 -5" castshadow="true"/>


    </worldbody>
</mujoco>
